Workbook

Sheet Inputs
A1: Barnes & Noble - Colorado Springs, CO (3173 Cinema Point) | METAL FRAMING & DRYWALL TAKEOFF
A2: Bid set: Barnes _ Noble - Colorado Springs, CO - COMBINED BID SET - 250918.pdf · 2026-10-24 · Edit ONLY the yellow cells.
A4: PARAMETER | B4: VALUE | C4: NOTE / SOURCE
A5: Waste - ALL METAL, any type | B5: 0.15 | C5: Estimator standing rule: 15% on everything that is metal.
A6: Waste - EVERYTHING THAT IS NOT METAL | B6: 0.06 | C6: Estimator standing rule: same figure as board.
A7: Board sheet width (ft) | B7: 4 | C7: Sheet size is a parameter; buy the size that wastes least.
A8: Board sheet length (ft) | B8: 12 | C8: Change it and every sheet count re-rounds.
A9: SF per board sheet | B9: =B7*B8 -> 48 | C9: Width x length.
A10: Stud stock length (ft) | B10: 20 | C10: Stud, header, framed opening and stud blocking: sticks.
A11: Track stock length (ft) | B11: 10 | C11: Track, sill track and purlin: runs.
A12: Floor plan scale (pt/ft) | B12: n/a | C12: Project value (not used in this take-off: heights are per wall in the Partition Takeoff).
A13: B.O. Deck (ft) | B13: n/a | C13: Project value (not used in this take-off: heights are per wall in the Partition Takeoff).
A14: T.O. Parapet (ft) | B14: n/a | C14: Project value (not used in this take-off: heights are per wall in the Partition Takeoff).
A15: Sealant coverage (LF per tube) | B15: 25 | C15: Sealant yield per tube - set your supplier's figure.
A16: C.R. channel stock length (ft) | B16: 16 | C16: 1-1/2" cold-rolled channel (bracing, carrying channel).
A17: Hat / furring channel stock (ft) | B17: 12 | C17: 7/8" hat furring channel.
A18: Trim stick length (ft) | B18: 10 | C18: Corner bead, casing bead, shadow molding, PVC trim.
A19: Hanger wire purchase | B19: continuous coil (LF) | C19: Bought by LF from a continuous coil; the hanger count goes on its own PCS row.
A20: Drywall screws per SF of board | B20: 1.2 | C20: YIELD: estimator 1.2 / SF; products per A-410 note 8.E (Type S 25/20 ga, Type S-12 18/16/14 ga) and A-001A Div 09 A.5.
A21: Framing screws per stud piece | B21: 4 | C21: YIELD: 2 per stud-to-track connection, each end.
A22: Power-driven pin spacing (ft) | B22: 1.333333 | C22: YIELD: A-410 note 8.F spacing, one row @ 16" O.C. = 1.333 ft per pin (estimator decision 2026-10-27, RFI-ACC-slab-pins B).
A23: Joint compound (lb per SF) | B23: 0.072 | C23: YIELD: 72 lb per 1,000 SF; Level 4 finish printed on A-001A Div 09 A.8 "PROVIDE AT A MINIMUM A LEVEL 4 FINISH".
A24: Joint tape (LF per SF) | B24: 0.37 | C24: YIELD: 370 LF per 1,000 SF.
A25: Expansion anchor spacing (ft) | B25: 0.66666667 | C25: YIELD: exterior bottom track on slab.
A26: 2x lumber stock length (ft) | B26: 16 | C26: 2x wood / FRT blocking: 16 ft sticks (estimator decision 2026-10-27).
A27: Drywall grid main tee length (ft) | B27: 12 | C27: USG DGLW26 main tee (manufacturer length).
A28: Drywall grid cross tee length (ft) | B28: 4 | C28: USG DGLW424 cross tee (manufacturer length).
A29: Grid channel / angle molding length (ft) | B29: 12 | C29: USG DGCM27 / DGWM24 molding (manufacturer length).
A30: FRP panel (SF per panel) | B30: 40 | C30: FRP-1 panel 4'x10' (estimator to confirm the panel size).

Sheet Partition Takeoff
A1: ORGANIZED PARTITION TAKEOFF - Barnes & Noble - Colorado Springs, CO (3173 Cinema Point)
A2: Grouped by partition type. Every row cites its DETAIL/SHEET and its status.
A4: Partition / Scope | B4: Wall # | C4: Length (LF) | D4: Height (FT) | E4: Layers | F4: Stud Size | G4: Stud O.C. (in) | H4: Board (SF) | I4: Location | J4: Source (DETAIL/SHEET) | K4: Status
A5: TYPE 2
A6: 2 #W2-01+W2-02 - Storage 112 south wall (door 14, 3'-0" printed, inside wall) + Storage 112 west wall | B6: W2-01+W2-02 | C6: 53.76 | D6: 25 | E6: 2 | F6: 3-5/8" 14 ga SJ | G6: 16 | H6: 2688 | I6: Storage 112 south wall (door 14, 3'-0" printed, inside wall) + Storage 112 west wall | J6: 2/A-410 | K6: [DERIVED]
A7: 2 #W2-03 - Stock Room 111 / Sales + Corridor 110 (door 11 inside wall) | B7: W2-03 | C7: 94.24 | D7: 25 | E7: 2 | F7: 3-5/8" 14 ga SJ | G7: 16 | H7: 4508.64 | I7: Stock Room 111 / Sales + Corridor 110 (door 11 inside wall) | Board by face: A Stock Room 111 94.24 x 25 ft (5/8 type X); B Sales Area 101 81.12 x 25 ft (5/8 type X); B Corridor 110 13.12 x 9.5 ft (5/8 type X) | J7: 2/A-410 | K7: [DERIVED]
A8: 2 #W2-04 - BOH north wall: Corridor 110 to Manager's Office 105 (Sales side) (door 4 inside wall) | B8: W2-04 | C8: 56.76 | D8: 25 | E8: 2 | F8: 3-5/8" 14 ga SJ | G8: 16 | H8: 1958.22 | I8: BOH north wall: Corridor 110 to Manager's Office 105 (Sales side) (door 4 inside wall) | Board by face: A Sales Area 101 56.76 x 25 ft (5/8 type X); B Corridor 110 29.04 x 9.5 ft (5/8 type X); B Break Room 106 19.03 x 9.5 ft (5/8 type X); B Manager's Office 105 8.69 x 9.5 ft (5/8 type X) | J8: 2/A-410 | K8: [DERIVED]
A9: 2 #W2-05 - Corridor 110 / Women's 109 | B9: W2-05 | C9: 12.92 | D9: 25 | E9: 2 | F9: 3-5/8" 14 ga SJ | G9: 16 | H9: 241.73 | I9: Corridor 110 / Women's 109 | Board by face: A Corridor 110 12.92 x 9.5 ft (5/8 type X); B Corridor 110 5.41 x 9.5 ft (5/8 type X); B Women's Restroom 109 7.51 x 9 ft (5/8 type X WR) | J9: 2/A-410 | K9: [DERIVED]
A10: 2 #W2-06.1+W2-06.2+W2-06.3+W2-06.4+W2-06.5 - Restrooms 108/109 + Janitor 107 north run with chase jog (doors 9, 8, 7 inside) | B10: W2-06.1+W2-06.2+W2-06.3+W2-06.4+W2-06.5 | C10: 27.54 | D10: 25 | E10: 2 | F10: 3-5/8" 14 ga SJ | G10: 16 | H10: 580.04 | I10: Restrooms 108/109 + Janitor 107 north run with chase jog (doors 9, 8, 7 inside) | Board by face: W2-06.1 A Corridor 110 6.92 x 9.5 ft (5/8 type X); W2-06.1 B Women's Restroom 109 6.92 x 9 ft (5/8 type X WR); W2-06.2 A Women's Restroom 109 2.23 x 9 ft (5/8 type X WR); W2-06.2 B Corridor 110 2.23 x 9.5 ft (5/8 type X WR); W2-06.3 A Corridor 110 4.87 x 9.5 ft (5/8 type X WR); W2-06.3 B Women's Restroom 109 2.41 x 9 ft (5/8 type X WR); W2-06.3 B Men's Restroom 108 2.46 x 9 ft (5/8 type X WR); W2-06.4 A Corridor 110 2.23 x 9.5 ft (5/8 type X WR); W2-06.4 B Men's Restroom 108 2.23 x 9 ft (5/8 type X WR); W2-06.5 A Corridor 110 11.29 x 9.5 ft (5/8 type X); W2-06.5 B Men's Restroom 108 6.88 x 9 ft (5/8 type X WR); W2-06.5 B Janitor Closet 107 4.41 x 25 ft (5/8 type X WR) | J10: 2/A-410 | K10: [DERIVED]
A11: 2 #W2-07 - Men's 108 / Janitor 107 | B11: W2-07 | C11: 7.51 | D11: 25 | E11: 2 | F11: 3-5/8" 14 ga SJ | G11: 16 | H11: 255.34 | I11: Men's 108 / Janitor 107 | Board by face: A Men's Restroom 108 7.51 x 9 ft (5/8 type X WR); B Janitor Closet 107 7.51 x 25 ft (5/8 type X WR) | J11: 2/A-410 | K11: [DERIVED]
A12: 2 #W2-08 - Janitor 107 / Break Room 106 (door 5 inside wall) | B12: W2-08 | C12: 12.92 | D12: 25 | E12: 2 | F12: 3-5/8" 14 ga SJ | G12: 16 | H12: 361.89 | I12: Janitor 107 / Break Room 106 (door 5 inside wall) | Board by face: A Corridor 110 5.41 x 9.5 ft (5/8 type X); A Janitor Closet 107 7.51 x 25 ft (5/8 type X WR); B Break Room 106 12.92 x 9.5 ft (5/8 type X) | J12: 2/A-410 | K12: [DERIVED]
A13: 2 #W2-09 - Break Room 106 / Manager's Office 105 (door 6 inside wall) | B13: W2-09 | C13: 12.92 | D13: 25 | E13: 2 | F13: 3-5/8" 14 ga SJ | G13: 16 | H13: 245.48 | I13: Break Room 106 / Manager's Office 105 (door 6 inside wall) | Board by face: A Break Room 106 12.92 x 9.5 ft (5/8 type X); B Manager's Office 105 12.92 x 9.5 ft (5/8 type X) | J13: 2/A-410 | K13: [DERIVED]
B14: SUBTOTAL TYPE 2 | C14: =SUM(C6:C13) -> 278.57 | H14: =SUM(H6:H13) -> 10839.34
A15: TYPE 5
A16: 5 #W5-01 - Plumbing wall between Women's 109 / Men's 108 | B16: W5-01 | C16: 5.7 | D16: 25 | E16: 2 | F16: 6" 20 ga SJ | G16: 16 | H16: 102.6 | I16: Plumbing wall between Women's 109 / Men's 108 | Board by face: A Women's Restroom 109 5.7 x 9 ft (5/8 type X WR); B Men's Restroom 108 5.7 x 9 ft (5/8 type X WR) | J16: 5/A-410 | K16: [DERIVED]
B17: SUBTOTAL TYPE 5 | C17: =SUM(C16:C16) -> 5.7 | H17: =SUM(H16:H16) -> 102.6
A18: TYPE 3
A19: 3 #W3-01 - Cafe Seating 102, west low wall - west end post | B19: W3-01 | C19: 3.67 | D19: 8 | E19: 1 | F19: 3-5/8" 20 ga | G19: 16 | H19: 29.36 | I19: Cafe Seating 102, west low wall - west end post | J19: 3/A-410 | K19: [DERIVED]
A20: 3 #W3-02 - Cafe Seating 102, west low wall - run | B20: W3-02 | C20: 12 | D20: 8 | E20: 1 | F20: 3-5/8" 20 ga | G20: 16 | H20: 96 | I20: Cafe Seating 102, west low wall - run | J20: 3/A-410 | K20: [DERIVED]
A21: 3 #W3-03 - Cafe Seating 102, east low wall - run | B21: W3-03 | C21: 12 | D21: 8 | E21: 1 | F21: 3-5/8" 20 ga | G21: 16 | H21: 96 | I21: Cafe Seating 102, east low wall - run | J21: 3/A-410 | K21: [DERIVED]
A22: 3 #W3-04 - Cafe Seating 102, east low wall - east end post | B22: W3-04 | C22: 3.67 | D22: 8 | E22: 1 | F22: 3-5/8" 20 ga | G22: 16 | H22: 29.36 | I22: Cafe Seating 102, east low wall - east end post | J22: 3/A-410 | K22: [DERIVED]
A23: 3 #W3-05 - Cafe Seating 102, west low wall - east end post | B23: W3-05 | C23: 3.67 | D23: 8 | E23: 1 | F23: 3-5/8" 20 ga | G23: 16 | H23: 29.36 | I23: Cafe Seating 102, west low wall - east end post | J23: 3/A-410 | K23: [DERIVED]
A24: 3 #W3-06 - Cafe Seating 102, east low wall - west end post | B24: W3-06 | C24: 3.67 | D24: 8 | E24: 1 | F24: 3-5/8" 20 ga | G24: 16 | H24: 29.36 | I24: Cafe Seating 102, east low wall - west end post | J24: 3/A-410 | K24: [DERIVED]
B25: SUBTOTAL TYPE 3 | C25: =SUM(C19:C24) -> 38.68 | H25: =SUM(H19:H24) -> 309.44
A26: TYPE 4
A27: 4 #W4-28a+W4-28b+W4-28c - Hourglass display feature, north end cap: bar + Hourglass display feature, north end cap: west end return + Hourglass display feature, north end cap: east end return | B27: W4-28a+W4-28b+W4-28c | C27: 12.68 | D27: 7.5 | E27: 1 | F27: 3-5/8" 20 ga | G27: 16 | H27: 95.1 | I27: Hourglass display feature, north end cap: bar + Hourglass display feature, north end cap: west end return + Hourglass display feature, north end cap: east end return | J27: 4/A-410 | K27: [DERIVED]
A28: 4 #W4-28d - Hourglass display feature, north end cap: west angled leg from end return to curved wall | B28: W4-28d | C28: 1.77 | D28: 7.5 | E28: 1 | F28: 3-5/8" 20 ga | G28: 16 | H28: 13.28 | I28: Hourglass display feature, north end cap: west angled leg from end return to curved wall | J28: 4/A-410 | K28: [DERIVED]
A29: 4 #W4-28e - Hourglass display feature, north end cap: east angled leg from end return to curved wall | B29: W4-28e | C29: 1.72 | D29: 7.5 | E29: 1 | F29: 3-5/8" 20 ga | G29: 16 | H29: 12.9 | I29: Hourglass display feature, north end cap: east angled leg from end return to curved wall | J29: 4/A-410 | K29: [DERIVED]
A30: 4 #W4-29a - Hourglass display feature, west curved wall (R=32'-9"), chord 1/6 from north (tagged) | B30: W4-29a | C30: 4.27 | D30: 7.5 | E30: 1 | F30: 3-5/8" 20 ga | G30: 16 | H30: 32.02 | I30: Hourglass display feature, west curved wall (R=32'-9"), chord 1/6 from north (tagged) | J30: 4/A-410 | K30: [DERIVED]
A31: 4 #W4-29b - Hourglass display feature, west curved wall (R=32'-9"), chord 2/6 from north | B31: W4-29b | C31: 4.27 | D31: 7.5 | E31: 1 | F31: 3-5/8" 20 ga | G31: 16 | H31: 32.02 | I31: Hourglass display feature, west curved wall (R=32'-9"), chord 2/6 from north | J31: 4/A-410 | K31: [DERIVED]
A32: 4 #W4-29c - Hourglass display feature, west curved wall (R=32'-9"), chord 3/6 from north | B32: W4-29c | C32: 4.29 | D32: 7.5 | E32: 1 | F32: 3-5/8" 20 ga | G32: 16 | H32: 32.17 | I32: Hourglass display feature, west curved wall (R=32'-9"), chord 3/6 from north | J32: 4/A-410 | K32: [DERIVED]
A33: 4 #W4-29d - Hourglass display feature, west curved wall (R=32'-9"), chord 4/6 from north | B33: W4-29d | C33: 4.29 | D33: 7.5 | E33: 1 | F33: 3-5/8" 20 ga | G33: 16 | H33: 32.17 | I33: Hourglass display feature, west curved wall (R=32'-9"), chord 4/6 from north | J33: 4/A-410 | K33: [DERIVED]
A34: 4 #W4-29e - Hourglass display feature, west curved wall (R=32'-9"), chord 5/6 from north | B34: W4-29e | C34: 4.27 | D34: 7.5 | E34: 1 | F34: 3-5/8" 20 ga | G34: 16 | H34: 32.02 | I34: Hourglass display feature, west curved wall (R=32'-9"), chord 5/6 from north | J34: 4/A-410 | K34: [DERIVED]
A35: 4 #W4-29f - Hourglass display feature, west curved wall (R=32'-9"), chord 6/6 from north | B35: W4-29f | C35: 4.29 | D35: 7.5 | E35: 1 | F35: 3-5/8" 20 ga | G35: 16 | H35: 32.17 | I35: Hourglass display feature, west curved wall (R=32'-9"), chord 6/6 from north | J35: 4/A-410 | K35: [DERIVED]
A36: 4 #W4-30a - Hourglass display feature, east curved wall (R=32'-9"), chord 1/6 from north (tagged) | B36: W4-30a | C36: 4.28 | D36: 7.5 | E36: 1 | F36: 3-5/8" 20 ga | G36: 16 | H36: 32.1 | I36: Hourglass display feature, east curved wall (R=32'-9"), chord 1/6 from north (tagged) | J36: 4/A-410 | K36: [DERIVED]
A37: 4 #W4-30b - Hourglass display feature, east curved wall (R=32'-9"), chord 2/6 from north | B37: W4-30b | C37: 4.28 | D37: 7.5 | E37: 1 | F37: 3-5/8" 20 ga | G37: 16 | H37: 32.1 | I37: Hourglass display feature, east curved wall (R=32'-9"), chord 2/6 from north | J37: 4/A-410 | K37: [DERIVED]
A38: 4 #W4-30c - Hourglass display feature, east curved wall (R=32'-9"), chord 3/6 from north | B38: W4-30c | C38: 4.28 | D38: 7.5 | E38: 1 | F38: 3-5/8" 20 ga | G38: 16 | H38: 32.1 | I38: Hourglass display feature, east curved wall (R=32'-9"), chord 3/6 from north | J38: 4/A-410 | K38: [DERIVED]
... A44: 4 #W4-31e - Hourglass display feature, south end cap: east angled leg from end return to curved wall (untagged TYP. copy of the PT0037 north cap) | B44: W4-31e | C44: 1.68 | D44: 7.5 | E44: 1 | F44: 3-5/8" 20 ga | G44: 16 | H44: 12.6 | I44: Hourglass display feature, south end cap: east angled leg from end return to curved wall (untagged TYP. copy of the PT0037 north cap) | J44: 4/A-410 | K44: [DERIVED]
B45: SUBTOTAL TYPE 4 | C45: =SUM(C27:C44) -> 83.64 | H45: =SUM(H27:H44) -> 627.27
A46: TYPE H1
...

Sheet Material Summary
A1: MATERIAL SUMMARY - NET / WASTE / PURCHASE
A2: Waste lives HERE, in its own column, applied ONCE: Pieces = ROUNDUP(Net x (1 + waste) / stock). Every stock length, coverage and yield is an Inputs cell.
A3: Material | B3: Unit | C3: Net | D3: Waste % | E3: Waste | F3: Purchase | G3: Selling unit | H3: Pieces to buy | I3: Where it comes from | J3: Yield check (live formula)
A4: Bottom track 3-5/8" | B4: LF | C4: 450.02 | D4: =Inputs!$B$5 -> 0.15 | E4: =C4*D4 -> 67.503 | F4: =C4+E4 -> 517.523 | G4: run 10 ft | H4: =ROUNDUP(F4/Inputs!$B$11,0) -> 52 | I4: N/SHEET: 2/A-410, 3/A-410, 4/A-410, G/A-221, F/A-221, A/A-221, B/A-221, D/A-221, C/A-221 | Breakdown [DERIVED]: W2-01 48.77 + W2-02 4.99 + W2-03 94.24 + W2-04 56.76 + W2-05 12.92 + W2-06.1 6.92 + W2-06.2 2.23 + W2-06.3 4.87 + W2-06.4 2.23 + W2-06.5 11.29 + W2-07 7.51 + W2-08 12.92 + W2-09 12.92 + W3-01 3.67 + W3-02 12 + W3-05 3.67 + W3-03 12 + W3-06 3.67 + W3-04 3.67 + W4-28a 9 + W4-28b 1.84 + W4-28c 1.84 + W4-28d 1.77 + W4-28e 1.72 + W4-29a 4.27 + W4-29b 4.27 + W4-29c 4.29 + W4-29d 4.29 + W4-29e 4.27 + W4-29f 4.29 + W4-30a 4.28 + W4-30b 4.28 + W4-30c 4.28 + W4-30d 4.28 + W4-30e 4.28 + W4-30f 4.28 + W4-31a 9 + W4-31b 1.84 + W4-31c 1.84 + W4-31d 1.75 + W4-31e 1.68 + C-H2a 12.17 + C-H2b 1.95 + C-F 3.26 + C-A-1 9.89 + C-A-2 4.14 + C-A-3 6.24 + C-B 3.17 + C-D 5.14 + C-C 3.17 = 450.02 LF (wall length x rows) | Track gauge = stud gauge (A-410 schedule note 2): 14 ga SJ 295.95 LF; 20 ga 154.07 LF
A5: Bottom track 6" | B5: LF | C5: 118.59 | D5: =Inputs!$B$5 -> 0.15 | E5: =C5*D5 -> 17.7885 | F5: =C5+E5 -> 136.3785 | G5: run 10 ft | H5: =ROUNDUP(F5/Inputs!$B$11,0) -> 14 | I5: N/SHEET: 5/A-410, G/A-221, H/A-221, E/A-221, I/A-221 | Breakdown [DERIVED]: W5-01 5.7 + C-H1-N 29.98 + C-H1-W 12.17 + C-H3a 4.08 + C-H3b 6.17 + C-E2 29.3 + C-E1-S 23.46 + C-I-P.1 1 + C-E1-P.2 2.11 + C-E1-B 2.31 + C-I 2.31 = 118.59 LF (wall length x rows) | Track gauge = stud gauge (A-410 schedule note 2): 20 ga SJ 118.59 LF
A6: Bottom track - other framing (not a partition type, see source) | B6: LF | C6: 72 | D6: =Inputs!$B$5 -> 0.15 | E6: =C6*D6 -> 10.8 | F6: =C6+E6 -> 82.8 | G6: run 10 ft | H6: =ROUNDUP(F6/Inputs!$B$11,0) -> 9 | I6: N/SHEET: C25/A-101 | Breakdown [DERIVED]: CW-01 8 + CW-02 8 + CW-03 8 + CW-04 8 + CW-05 8 + CW-06 8 + CW-07 8 + CW-08 8 + CW-09 8 = 72 LF (wall length x rows) | Track gauge = stud gauge (A-410 schedule note 2): 20 ga 72 LF
A7: Top / deflection track 3-5/8" | B7: LF | C7: 450.02 | D7: =Inputs!$B$5 -> 0.15 | E7: =C7*D7 -> 67.503 | F7: =C7+E7 -> 517.523 | G7: run 10 ft | H7: =ROUNDUP(F7/Inputs!$B$11,0) -> 52 | I7: N/SHEET: 2/A-410, 3/A-410, 4/A-410, G/A-221, F/A-221, A/A-221, B/A-221, D/A-221, C/A-221 | Breakdown [DERIVED]: W2-01 48.77 + W2-02 4.99 + W2-03 94.24 + W2-04 56.76 + W2-05 12.92 + W2-06.1 6.92 + W2-06.2 2.23 + W2-06.3 4.87 + W2-06.4 2.23 + W2-06.5 11.29 + W2-07 7.51 + W2-08 12.92 + W2-09 12.92 + W3-01 3.67 + W3-02 12 + W3-05 3.67 + W3-03 12 + W3-06 3.67 + W3-04 3.67 + W4-28a 9 + W4-28b 1.84 + W4-28c 1.84 + W4-28d 1.77 + W4-28e 1.72 + W4-29a 4.27 + W4-29b 4.27 + W4-29c 4.29 + W4-29d 4.29 + W4-29e 4.27 + W4-29f 4.29 + W4-30a 4.28 + W4-30b 4.28 + W4-30c 4.28 + W4-30d 4.28 + W4-30e 4.28 + W4-30f 4.28 + W4-31a 9 + W4-31b 1.84 + W4-31c 1.84 + W4-31d 1.75 + W4-31e 1.68 + C-H2a 12.17 + C-H2b 1.95 + C-F 3.26 + C-A-1 9.89 + C-A-2 4.14 + C-A-3 6.24 + C-B 3.17 + C-D 5.14 + C-C 3.17 = 450.02 LF (wall length x rows) | Track gauge = stud gauge (A-410 schedule note 2): 14 ga SJ 295.95 LF; 20 ga 154.07 LF
A8: Top / deflection track 6" | B8: LF | C8: 118.59 | D8: =Inputs!$B$5 -> 0.15 | E8: =C8*D8 -> 17.7885 | F8: =C8+E8 -> 136.3785 | G8: run 10 ft | H8: =ROUNDUP(F8/Inputs!$B$11,0) -> 14 | I8: N/SHEET: 5/A-410, G/A-221, H/A-221, E/A-221, I/A-221 | Breakdown [DERIVED]: W5-01 5.7 + C-H1-N 29.98 + C-H1-W 12.17 + C-H3a 4.08 + C-H3b 6.17 + C-E2 29.3 + C-E1-S 23.46 + C-I-P.1 1 + C-E1-P.2 2.11 + C-E1-B 2.31 + C-I 2.31 = 118.59 LF (wall length x rows) | Track gauge = stud gauge (A-410 schedule note 2): 20 ga SJ 118.59 LF
A9: Top / deflection track - other framing (not a partition type, see source) | B9: LF | C9: 72 | D9: =Inputs!$B$5 -> 0.15 | E9: =C9*D9 -> 10.8 | F9: =C9+E9 -> 82.8 | G9: run 10 ft | H9: =ROUNDUP(F9/Inputs!$B$11,0) -> 9 | I9: N/SHEET: C25/A-101 | Breakdown [DERIVED]: CW-01 8 + CW-02 8 + CW-03 8 + CW-04 8 + CW-05 8 + CW-06 8 + CW-07 8 + CW-08 8 + CW-09 8 = 72 LF (wall length x rows) | Track gauge = stud gauge (A-410 schedule note 2): 20 ga 72 LF
A10: 8" stud (all gauges) | B10: LF | C10: 25.33 | D10: =Inputs!$B$5 -> 0.15 | E10: =C10*D10 -> 3.7995 | F10: =C10+E10 -> 29.1295 | G10: stick 20 ft | H10: =ROUNDUP(F10/Inputs!$B$10,0) -> 2 | I10: N/SHEET: 8/A-210 | Breakdown [DERIVED]: VEST-BOX-BEAM-STUD 25.33 = 25.33 LF (per wall: field + jambs + nodes + cripples x height; plus listed elements)
A11: 6" metal stud (LF of material) | B11: LF | C11: 3162.5 | D11: =Inputs!$B$5 -> 0.15 | E11: =C11*D11 -> 474.375 | F11: =C11+E11 -> 3636.875 | G11: stick 20 ft | H11: =ROUNDUP(F11/Inputs!$B$10,0) -> 182 | I11: N/SHEET: 5/A-410, G/A-221, H/A-221, E/A-221, I/A-221, 3/A-221, 8/A-410 | Breakdown [DERIVED]: W5-01 175 + C-H1-N 650 + C-H1-W 300 + C-H3a 150 + C-H3b 175 + C-E2 575 + C-E1-S 525 + C-I-P.1 75 + C-E1-P.2 75 + C-E1-B 125 + C-I 75 + SS-GG 107.5 + CROSS-MEMBERS-8-A410-6 155 = 3,162.5 LF (per wall: field + jambs + nodes + cripples x height; plus listed elements) | By gauge (A-410 Metal Stud Schedule): 20 ga SJ 3,007.5 LF; elements (gauge in their operation) 155 LF
A12: 3-5/8" metal stud (LF of material) | B12: LF | C12: 11601.59 | D12: =Inputs!$B$5 -> 0.15 | E12: =C12*D12 -> 1740.2385 | F12: =C12+E12 -> 13341.828 | G12: stick 20 ft | H12: =ROUNDUP(F12/Inputs!$B$10,0) -> 668 | I12: N/SHEET: 2/A-410, 3/A-410, 4/A-410, G/A-221, F/A-221, A/A-221, B/A-221, D/A-221, C/A-221, 2/A-221, C25/A-101, 7/A-210, 8/A-410 | Breakdown [DERIVED]: W2-01 1,061 + W2-02 125 + W2-03 1,879 + W2-04 1,211 + W2-05 300 + W2-06.1 311 + W2-06.2 100 + W2-06.3 150 + W2-06.4 100 + W2-06.5 447 + W2-07 200 + W2-08 386 + W2-09 386 + W3-01 32 + W3-02 96 + W3-05 32 + W3-03 96 + W3-06 32 + W3-04 32 + W4-28a 75 + W4-28b 30 + W4-28c 30 + W4-28d 30 + W4-28e 30 + W4-29a 45 + W4-29b 45 + W4-29c 45 + W4-29d 45 + W4-29e 45 + W4-29f 45 + W4-30a 45 + W4-30b 45 + W4-30c 45 + W4-30d 45 + W4-30e 45 + W4-30f 45 + W4-31a 75 + W4-31b 30 + W4-31c 30 + W4-31d 22.5 + W4-31e 22.5 + C-H2a 376 + C-H2b 100 + C-F 125 + C-A-1 29.79 + C-A-2 16.25 + C-A-3 18.96 + C-B 16.25 + C-D 6 + C-C 10.83 + SS-N 280 + SS-E 126 + SS-IN-N 243 + SS-IN-E 81 + CW-01 96 + CW-02 96 + CW-03 96 + CW-04 96 + CW-05 96 + CW-06 96 + CW-07 96 + CW-08 96 + CW-09 96 + DIAG-BRACES-T2 468 + VEST-POSTS-STUD 126 + WH-BACKING-STUD 8 + WH-STEEL-BLOCKING 2.67 + DIAG-BRACES-CAFE 44 + CROSS-MEMBERS-8-A410-3 550 + SOFFIT-CROSS-BRACING-2-A221 90 + F-NESTED-BRACING 6.52 + NESTED-BRACING-T3-T4 122.32 = 11,601.59 LF (per wall: field + jambs + nodes + cripples x height; plus listed elements) | By gauge (A-410 Metal Stud Schedule): 14 ga SJ 7,257 LF; 20 ga 2,927.08 LF; elements (gauge in their operation) 1,417.51 LF
A13: Ceiling perimeter track at GWB ceilings (size not printed, RFI) | B13: LF | C13: 180.99 | D13: =Inputs!$B$5 -> 0.15 | E13: =C13*D13 -> 27.1485 | F13: =C13+E13 -> 208.1385 | G13: run 10 ft | H13: =ROUNDUP(F13/Inputs!$B$11,0) -> 21 | I13: N/SHEET: 1/A-121, 5/A-121 | Breakdown [DERIVED]: Women's Restroom 109 32.33 + Men's Restroom 108 32.33 + Cafe 103 - 11'-6" GWB band 52.51 + Cafe 103 - 9'-0" GWB band 43.33 + Grab & Go 20.49 = 180.99 LF
A14: Bracing 1-1/2" C.R. channel @ 48" O.C. | B14: LF | C14: 2883.65 | D14: =Inputs!$B$5 -> 0.15 | E14: =C14*D14 -> 432.5475 | F14: =C14+E14 -> 3316.1975 | G14: C.R. channel 16 ft | H14: =ROUNDUP(F14/Inputs!$B$16,0) -> 208 | I14: N/SHEET: 5/A-410, 2/A-410, 5/A-410, 3/A-410, 4/A-410, C25/A-101, G/A-221, H/A-221, E/A-221, I/A-221, F/A-221, 2/A-221, 3/A-221 | Breakdown [DERIVED]: W2-01 292.62 + W2-02 29.94 + W2-03 565.44 + W2-04 340.56 + W2-05 77.52 + W2-06.1 41.52 + W2-06.2 13.38 + W2-06.3 29.22 + W2-06.4 13.38 + W2-06.5 67.74 + W2-07 45.06 + W2-08 77.52 + W2-09 77.52 + W5-01 34.2 + W3-01 3.67 + W3-02 12 + W3-05 3.67 + W3-03 12 + W3-06 3.67 + W3-04 3.67 + W4-28a 9 + W4-28b 1.84 + W4-28c 1.84 + W4-28d 1.77 + W4-28e 1.72 + W4-29a 4.27 + W4-29b 4.27 + W4-29c 4.29 + W4-29d 4.29 + W4-29e 4.27 + W4-29f 4.29 + W4-30a 4.28 + W4-30b 4.28 + W4-30c 4.28 + W4-30d 4.28 + W4-30e 4.28 + W4-30f 4.28 + W4-31a 9 + W4-31b 1.84 + W4-31c 1.84 + W4-31d 1.75 + W4-31e 1.68 + CW-01 8 + CW-02 8 + CW-03 8 + CW-04 8 + CW-05 8 + CW-06 8 + CW-07 8 + CW-08 8 + CW-09 8 + C-H1-N 179.88 + C-H1-W 73.02 + C-H2a 73.02 + C-H2b 11.7 + C-H3a 24.48 + C-H3b 37.02 + C-E2 175.8 + C-E1-S 140.76 + C-I-P.1 6 + C-E1-P.2 12.66 + C-E1-B 13.86 + C-F 19.56 + C-I 13.86 + SS-N 68.31 + SS-E 30.36 + SS-IN-N 60 + SS-IN-E 18.75 + SS-GG 24.67 = 2,883.65 LF (rows = ROUNDUP(H x 12 / 48) - 1, x length)
A15: Furring channel (ceilings) | B15: LF | C15: 207.45 | D15: =Inputs!$B$5 -> 0.15 | E15: =C15*D15 -> 31.1175 | F15: =C15+E15 -> 238.5675 | G15: hat channel 12 ft | H15: =ROUNDUP(F15/Inputs!$B$17,0) -> 20 | I15: N/SHEET: 5/A-121, 1/A-121 | Breakdown [DERIVED]: Women's Restroom 109 42.36 + Men's Restroom 108 42.31 + Cafe 103 - 11'-6" GWB band 68.78 + Cafe 103 - 9'-0" GWB band 29.34 + Grab & Go 24.67 = 207.46 LF
A16: Carrying channel (ceilings) | B16: LF | C16: 159.16 | D16: =Inputs!$B$5 -> 0.15 | E16: =C16*D16 -> 23.874 | F16: =C16+E16 -> 183.034 | G16: C.R. channel 16 ft | H16: =ROUNDUP(F16/Inputs!$B$16,0) -> 12 | I16: N/SHEET: 5/A-121, 1/A-121 | Breakdown [DERIVED]: Women's Restroom 109 24.48 + Men's Restroom 108 24.44 + Cafe 103 - 11'-6" GWB band 60 + Cafe 103 - 9'-0" GWB band 38 + Grab & Go 12.24 = 159.16 LF
A17: Hanger wire | B17: LF | C17: 2689.79 | D17: =Inputs!$B$5 -> 0.15 | E17: =C17*D17 -> 403.4685 | F17: =C17+E17 -> 3093.2585 | G17: continuous coil (LF) | H17: =ROUNDUP(F17,0) -> 3094 | I17: N/SHEET: 5/A-121, 1/A-121 | Breakdown [DERIVED]: Women's Restroom 109 144 + Men's Restroom 108 144 + Cafe 103 - 11'-6" GWB band 243 + Cafe 103 - 9'-0" GWB band 192 + Cafe Seating Area 102 - GWB cloud 715 + Grab & Go 107.5 + HANGERS-FIXTURES-5-A121 401 + SPLAY-WIRES-5-A121 743.29 = 2,689.79 LF (hangers @ 48" O.C. x drop to deck per room)
A18: Blocking FRT / 2X FRT wood | B18: LF | C18: 568.27 | D18: =Inputs!$B$6 -> 0.06 | E18: =C18*D18 -> 34.0962 | F18: =C18+E18 -> 602.3662 | G18: 2x lumber 16 ft | H18: =ROUNDUP(F18/Inputs!$B$26,0) -> 38 | I18: N/SHEET: 7/A-413, 8A/A-413, 4/A-412, 6/A-412, 4/A-101 | Breakdown [DERIVED]: BLK-STOCK 387 + BLK-RECEIVING 69 + BLK-OFFICE 85.6 + BLK-BREAK 10.67 + BLK-FE-CABINETS 16 = 568.27 LF
A19: 5/8" gypsum board, Type X | B19: SF | C19: 14266.95 | D19: =Inputs!$B$6 -> 0.06 | E19: =C19*D19 -> 856.017 | F19: =C19+E19 -> 15122.967 | G19: 4x12 ft sheet (Inputs) | H19: =ROUNDUP(F19/Inputs!$B$9,0) -> 316 | I19: N/SHEET: 2/A-410, 3/A-410, 4/A-410, C25/A-101, G/A-221, H/A-221, I/A-221, 2/A-221, 3/A-221, 5/A-121, 4/A-121, 4/A-210, 2/A-210, A-001A | Breakdown [DERIVED]: W2-01 2,438.5 + W2-02 249.5 + W2-03 4,508.64 + W2-04 1,958.22 + W2-05 174.14 + W2-06.1 65.74 + W2-06.5 107.25 + W2-08 174.14 + W2-09 245.48 + W3-01 29.36 + W3-02 96 + W3-05 29.36 + W3-03 96 + W3-06 29.36 + W3-04 29.36 + W4-28a 67.5 + W4-28b 13.8 + W4-28c 13.8 + W4-28d 13.28 + W4-28e 12.9 + W4-29a 32.02 + W4-29b 32.02 + W4-29c 32.17 + W4-29d 32.17 + W4-29e 32.02 + W4-29f 32.17 + W4-30a 32.1 + W4-30b 32.1 + W4-30c 32.1 + W4-30d 32.1 + W4-30e 32.1 + W4-30f 32.1 + W4-31a 67.5 + W4-31b 13.8 + W4-31c 13.8 + W4-31d 13.12 + W4-31e 12.6 + CW-01 64 + CW-02 64 + CW-03 64 + CW-04 64 + CW-05 64 + CW-06 64 + CW-07 64 + CW-08 64 + CW-09 64 + C-H1-N 678.44 + C-H1-W 115.61 + C-H2a 304.25 + C-H3a 71.74 + C-H3b 151.68 + C-I-P.1 10 + C-I 23.1 + SS-N 227.7 + SS-E 101.2 + SS-IN-N 10 + SS-IN-E 3.12 + SS-GG 61.67 + C-I-E1 6.03 + C-I-E2 6.03 + ceiling Cafe 103 - 11'-6" GWB band 125.07 + ceiling Cafe 103 - 9'-0" GWB band 50.67 + ceiling Cafe Seating Area 102 - GWB cloud 573.69 + ceiling Cafe 103 - 11'-0" GWB zone 109.65 + ceiling Grab & Go 25.16 + VEST-GWB 105.5 + SS-GG-BOTTOM-GWB 3.73 + VEST-GWB-BANDS 14.96 + CLOUD-FASCIA-GWB 53.6 = 14,266.92 SF (faces: length x face height x layers - openings; ceilings: RCP area)
A20: 5/8" gypsum board, Type X W.R. (water resistant) | B20: SF | C20: 1092.59 | D20: =Inputs!$B$6 -> 0.06 | E20: =C20*D20 -> 65.5554 | F20: =C20+E20 -> 1158.1454 | G20: 4x12 ft sheet (Inputs) | H20: =ROUNDUP(F20/Inputs!$B$9,0) -> 25 | I20: N/SHEET: 2/A-410, 5/A-410, 5/A-121, 22/A-201, A-001A | Breakdown [DERIVED]: W2-05 67.59 + W2-06.1 62.28 + W2-06.2 41.25 + W2-06.3 90.1 + W2-06.4 41.25 + W2-06.5 172.17 + W2-07 255.34 + W2-08 187.75 + W5-01 102.6 + ceiling Women's Restroom 109 61.19 + ceiling Men's Restroom 108 61.11 + RESTROOM-BASE-WR-DEDUCT -50.04 = 1,092.59 SF (faces: length x face height x layers - openings; ceilings: RCP area)
A21: 8" metal joist (ceiling box) | B21: LF | C21: 88 | D21: =Inputs!$B$5 -> 0.15 | E21: =C21*D21 -> 13.2 | F21: =C21+E21 -> 101.2 | G21: stick 20 ft | H21: =ROUNDUP(F21/Inputs!$B$10,0) -> 6 | I21: N/SHEET: 4/A-210 | 8" JOISTS @ 16" O.C.: ROUNDUP(152/16)+1 = 11 x (7'-8" + 2" + 2" = 8.0 ft) = 88.0 LF (1/A-210 12'-8" N-S)
A22: USG drywall suspension main tee DGLW26 | B22: LF | C22: 194.16 | D22: =Inputs!$B$5 -> 0.15 | E22: =C22*D22 -> 29.124 | F22: =C22+E22 -> 223.284 | G22: main tee 12 ft | H22: =ROUNDUP(F22/Inputs!$B$27,0) -> 19 | I22: N/SHEET: 4/A-121, 1/A-121 | USG drywall suspension grid: main tee ROUNDUP(14.773/4.0)+1 = 5 x 38.833 = 194.16; cross tee ROUNDUP(38.833/1.333)+1 = 31 x 14.773 = 457.96; channel + angle molding 107.21 each
A23: USG drywall suspension cross tee DGLW424 | B23: LF | C23: 457.96 | D23: =Inputs!$B$5 -> 0.15 | E23: =C23*D23 -> 68.694 | F23: =C23+E23 -> 526.654 | G23: cross tee 4 ft | H23: =ROUNDUP(F23/Inputs!$B$28,0) -> 132 | I23: N/SHEET: 4/A-121, 1/A-121 | USG drywall suspension grid: main tee ROUNDUP(14.773/4.0)+1 = 5 x 38.833 = 194.16; cross tee ROUNDUP(38.833/1.333)+1 = 31 x 14.773 = 457.96; channel + angle molding 107.21 each
A24: USG channel molding DGCM27 | B24: LF | C24: 107.21 | D24: =Inputs!$B$5 -> 0.15 | E24: =C24*D24 -> 16.0815 | F24: =C24+E24 -> 123.2915 | G24: molding 12 ft | H24: =ROUNDUP(F24/Inputs!$B$29,0) -> 11 | I24: N/SHEET: 4/A-121, 1/A-121 | USG drywall suspension grid: main tee ROUNDUP(14.773/4.0)+1 = 5 x 38.833 = 194.16; cross tee ROUNDUP(38.833/1.333)+1 = 31 x 14.773 = 457.96; channel + angle molding 107.21 each
A25: USG angle molding DGWM24 | B25: LF | C25: 107.21 | D25: =Inputs!$B$5 -> 0.15 | E25: =C25*D25 -> 16.0815 | F25: =C25+E25 -> 123.2915 | G25: molding 12 ft | H25: =ROUNDUP(F25/Inputs!$B$29,0) -> 11 | I25: N/SHEET: 4/A-121, 1/A-121 | USG drywall suspension grid: main tee ROUNDUP(14.773/4.0)+1 = 5 x 38.833 = 194.16; cross tee ROUNDUP(38.833/1.333)+1 = 31 x 14.773 = 457.96; channel + angle molding 107.21 each
A26: Clip angle 16 ga (5/A-410 bracing clips + 7/A-210 nested header clips) | B26: PCS | C26: 2522 | D26: =Inputs!$B$5 -> 0.15 | E26: =C26*D26 -> 378.3 | F26: =C26+E26 -> 2900.3 | G26: piece | H26: =ROUNDUP(F26,0) -> 2901 | I26: N/SHEET: 5/A-410, 7/A-210 | Breakdown [DERIVED]: CLIP-ANGLES-5-A410 2,518 + CLIP-ANGLES-7-A210 4 = 2,522 PCS | 2" x 2" 16 GA. CLIP ANGLE at each stud per bracing row, (4) TEK SCREWS (5/A-410): rows x studs = W2-01 6x38 + W2-02 6x5 + W2-03 6x72 + W2-04 6x44 + W2-05 6x11 + W2-06.1 6x7 + W2-06.2 6x3 + W2-06.3 6x5 + W2-06.4 6x3 + W2-06.5 6x10 + W2-07 6x7 + W2-08 6x11 + W2-09 6x11 + W5-01 6x6 + W3-01 1x4 + W3-02 1x10 + W3-05 1x4 + W3-03 1x10 + W3-06 1x4 + W3-04 1x4 + W4-28a 1x8 + W4-28b 1x3 + W4-28c 1x3 + W4-28d 1x3 + W4-28e 1x3 + W4-29a 1x5 + W4-29b 1x5 + W4-29c 1x5 + W4-29d 1x5 + W4-29e 1x5 + W4-29f 1x5 + W4-30a 1x5 + W4-30b 1x5 + W4-30c 1x5 + W4-30d 1x5 + W4-30e 1x5 + W4-30f 1x5 + W4-31a 1x8 + W4-31b 1x3 + W4-31c 1x3 + W4-31d 1x3 + W4-31e 1x3 + CW-01 1x12 + CW-02 1x12 + CW-03 1x12 + CW-04 1x12 + CW-05 1x12 + CW-06 1x12 + CW-07 1x12 + CW-08 1x12 + CW-09 1x12 + C-H1-N 6x24 + C-H1-W 6x11 + C-H2a 6x11 + C-H2b 6x3 + C-H3a 6x5 + C-H3b 6x6 + C-E2 6x23 + C-E1-S 6x19 + C-I-P.1 6x2 + C-E1-P.2 6x3 + C-E1-B 6x3 + C-F 6x4 + C-I 6x3 + SS-N 3x19 + SS-E 3x9 + SS-IN-N 3x16 + SS-IN-E 3x6 + SS-GG 4x6 = 2518 pcs; 3"x3"x16 GA. CLIP ANGLES at the nested header to jamb connection (7/A-210): 2 header ends x 2 (front / back) = 4 pcs (conservative; count not printed - RFI-51)
A27: #8 pan head self-tapping screws, relief channel to structure (8/A-410) | B27: PCS | C27: 291 | D27: =Inputs!$B$5 -> 0.15 | E27: =C27*D27 -> 43.65 | F27: =C27+E27 -> 334.65 | G27: piece | H27: =ROUNDUP(F27,0) -> 335 | I27: N/SHEET: 8/A-410 | Breakdown [DERIVED]: PAN-HEAD-8-A410 291 = 291 PCS | 8/A-410 "CONTINUOUS 20 GA. X 2" MIN DEEP RELIEF CHANNEL - ANCHOR TO STEEL PLATE WITH #8 PAN HEAD SELF TAPPING SCREWS AT 24" O.C. AND 6" FROM ENDS": sum(ROUNDUP(L / 2) + 1) over 32 runs to structure (479.85 LF) = 291 pcs; note 8.C X-EDNI = alternative in RFI-51)
A28: #10-16 x 3/4" Tek screws, pan head, at 16 ga clip angles and nested header / column / beam (5/A-410; 7/A-210; 8/A-210; A-410 note 8.A) | B28: PCS | C28: 10668 | D28: =Inputs!$B$5 -> 0.15 | E28: =C28*D28 -> 1600.2 | F28: =C28+E28 -> 12268.2 | G28: piece | H28: =ROUNDUP(F28,0) -> 12269 | I28: N/SHEET: 5/A-410, 7/A-210, 8/A-210, 1/A-210 | Breakdown [DERIVED]: TEK-SCREWS-CLIPS 10,668 = 10,668 PCS | 5/A-410 "2" x 2" 16 GA. CLIP ANGLE ... (4) TEK SCREWS": 2518 clips x 4 = 10072 + 7/A-210 "(4) #10-16 SCREWS": 4 clips x 4 = 16 + 7/A-210 "RUNNER TRACK ATTACHED TO HEADER SUING (2) TEK SCREWS AT 16" O.C" top and bottom runner: 2 runners x 2 x (ROUNDUP(12.667 / 1.333) + 1) = 44 + 8/A-210 "(8) #10-16 TEKS 16"O.C., TYP.": nested beam (ROUNDUP(12.667 / 1.333) + 1) x 8 = 88 + nested columns 6 x (ROUNDUP(10.5 / 1.333) + 1) x 8 = 432 + 7/A-210 head attachment "#10-16 TEK SCREWS (TYP.)": 2 clips x 8 = 16; total 10668 pcs. Header 12'-8" = 1/A-210 front dimension chain (152"). Size: 5/A-410 prints none; the clip is 16 ga, so A-410 note 8.A "18/16 GAUGE - #10 - 16 X 3/4" TEKS" applies (7/A-210 and 8/A-210 print #10-16)
A29: 16 ga wire at seismic brace points (5/A-121) | B29: LF | C29: 131.42 | D29: =Inputs!$B$5 -> 0.15 | E29: =C29*D29 -> 19.713 | F29: =C29+E29 -> 151.133 | G29: continuous coil (LF) | H29: =ROUNDUP(F29,0) -> 152 | I29: N/SHEET: 5/A-121 | Breakdown [DERIVED]: SEISMIC-VERTICAL-WIRE-5-A121 131.42 = 131.42 LF | 5/A-121 "16 GA. WIRE 12'-0\" O.C. EACH WAY AND WITHIN 6'-0\" OF EACH WALL" vertical wire at each brace point: groups Women's 1 x drop 16.0; Men's 1 x drop 16.0; Cafe 11'-6" band 1 x drop 13.5; Cafe 9'-0" band 1 x drop 16.0; Cafe cloud 4 x drop 13.0; Grab & Go 1 x drop 17.917 -> sum(groups x drop) = 131.42 LF (conservative - RFI-38) the 1-5/8" x 16 ga metal joist framing @ 48" O.C. on 5/A-121 is the horizontal carrying member (no post drawn)
A30: P.A.F. 3/16" x 3/8" at cross member ends (8/A-410) | B30: PCS | C30: 282 | D30: =Inputs!$B$5 -> 0.15 | E30: =C30*D30 -> 42.3 | F30: =C30+E30 -> 324.3 | G30: piece | H30: =ROUNDUP(F30,0) -> 325 | I30: N/SHEET: 8/A-410 | Breakdown [DERIVED]: PAF-CROSS-MEMBERS-8-A410 282 = 282 PCS | 8/A-410 PARALLEL TO STRUCTURE "METAL STUD PER SCHEDULE W/ (1) 3/16" 3/8" P.A.F. AT EACH END": 141 cross members x 2 = 282 pcs (RFI-41)
A31: 5/8" cement board (tile base) | B31: SF | C31: 50.04 | D31: =Inputs!$B$6 -> 0.06 | E31: =C31*D31 -> 3.0024 | F31: =C31+E31 -> 53.0424 | G31: 4x12 ft sheet (Inputs) | H31: =ROUNDUP(F31/Inputs!$B$9,0) -> 2 | I31: N/SHEET: 22/A-201 | Breakdown [DERIVED]: RESTROOM-BASE-CEMENT 50.04 = 50.04 SF | 5/8" CEMENT BOARD BASE 1'-2" (22/A-201; A-001A Div 09 J.2): W2-05 7.51 + W2-06.1 6.92 + W2-06.2 2.23 + W2-06.3 2.41 + W2-06.3 2.46 + W2-06.4 2.23 + W2-06.5 6.88 + W2-07 7.51 + W5-01 5.7 + W5-01 5.7 = 49.55 LF - doors 8, 9 (6.66) = 42.89 LF x 1'-2" = 50.04 SF
A32: Plywood screws #10-24 x 1-1/4" Teks/3 (A-410 note 8.D) | B32: PCS | C32: 2331 | D32: =Inputs!$B$5 -> 0.15 | E32: =C32*D32 -> 349.65 | F32: =C32+E32 -> 2680.65 | G32: piece | H32: =ROUNDUP(F32,0) -> 2681 | I32: N/SHEET: A-410 | Breakdown [DERIVED]: PLYWOOD-SCREWS-8D 2,331 = 2,331 PCS | A-410 Partition Notes 8.D "#10-24 X 1-1/4\" TEKS/3 ... 24\" O.C. FIELD, 12\" O.C. PERIMETER": 4x8 sheet on studs @ 16" = 24 perimeter + 10 field = 34 screws / 32 SF; 2192.98 SF FRT plywood x 34/32 = 2331 pcs
A33: Cement board screws 1-1/4" (manufacturer spacing) | B33: PCS | C33: 1686 | D33: =Inputs!$B$5 -> 0.15 | E33: =C33*D33 -> 252.9 | F33: =C33+E33 -> 1938.9 | G33: piece | H33: =ROUNDUP(F33,0) -> 1939 | I33: N/SHEET: E/A-221, A/A-221, B/A-221, C/A-221, D/A-221, 22/A-201 | Breakdown [DERIVED]: CEMENT-BOARD-SCREWS 1,686 = 1,686 PCS | cement board screws @ 8" O.C. on studs @ 16" (manufacturer standard, spacing not printed - RFI-51): 3x5 board = 4 studs x 8 = 32 screws / 15 SF; 789.94 SF x 32/15 = 1686 pcs
A34: Nested inner runner at the deflection head (3/A-410) | B34: LF | C34: 479.85 | D34: =Inputs!$B$5 -> 0.15 | E34: =C34*D34 -> 71.9775 | F34: =C34+E34 -> 551.8275 | G34: run 10 ft | H34: =ROUNDUP(F34/Inputs!$B$11,0) -> 56 | I34: N/SHEET: 3/A-410 | Breakdown [DERIVED]: NESTED-RUNNER-3-A410 479.85 = 479.85 LF | 3/A-410 "METAL RUNNER AT STUDS - SECURE GWB TO METAL RUNNER" + "DO NOT SECURE METAL STUDS OR GWB TO DEEP LEG TRACK": inner runner = length of every wall / soffit side to deck = W2-01 48.77 + W2-02 4.99 + W2-03 94.24 + W2-04 56.76 + W2-05 12.92 + W2-06.1 6.92 + W2-06.2 2.23 + W2-06.3 4.87 + W2-06.4 2.23 + W2-06.5 11.29 + W2-07 7.51 + W2-08 12.92 + W2-09 12.92 + W5-01 5.7 + C-H1-N 29.98 + C-H1-W 12.17 + C-H2a 12.17 + C-H2b 1.95 + C-H3a 4.08 + C-H3b 6.17 + C-E2 29.3 + C-E1-S 23.46 + C-I-P.1 1.0 + C-E1-P.2 2.11 + C-E1-B 2.31 + C-F 3.26 + C-I 2.31 + SS-N 22.77 + SS-E 10.12 + SS-IN-N 20.0 + SS-IN-E 6.25 + SS-GG 6.167 = 479.85 LF (RFI-40 confirms the reading)
A35: METAL trim - corner bead, casing bead, shadow molding, gypsum edge trim | B35: LF | C35: 957.03 | D35: =Inputs!$B$5 -> 0.15 | E35: =C35*D35 -> 143.5545 | F35: =C35+E35 -> 1100.5845 | G35: trim stick 10 ft | H35: =ROUNDUP(F35/Inputs!$B$18,0) -> 111 | I35: N/SHEET: 3/A-410, 4/A-410, 4/A-121 | Breakdown [DERIVED]: CORNER-BEAD-SOFFITS 65.31 + Corner bead - type 3 partial height walls (top edges + free ends) 205.36 + Corner bead - type 4 partial height walls (top edges + free ends) 164.94 + Corner bead - corridor recess (drinking fountain alcove, W2-06) outside corners 19 + Corner bead - column surrounds C25 (9 ea) outside corners 288 + Corner bead - Cafe Seating GWB cloud bottom edge 107.21 + J-bead - Cafe Seating GWB cloud top of fascia 107.21 = 957.03 LF
A36: 1/2" cement board / cementitious backer | B36: SF | C36: 434.28 | D36: =Inputs!$B$6 -> 0.06 | E36: =C36*D36 -> 26.0568 | F36: =C36+E36 -> 460.3368 | G36: 4x12 ft sheet (Inputs) | H36: =ROUNDUP(F36/Inputs!$B$9,0) -> 10 | I36: N/SHEET: E/A-221, A/A-221, B/A-221, D/A-221, C/A-221 | Breakdown [DERIVED]: C-E1-S Cafe 103 228 + C-E1-P.2 Cafe 103 25.32 + C-E1-B Cafe 103 26.57 + C-A-1 Cafe 103 26.78 + C-A-1 Cafe 103 26.78 + C-A-2 Cafe 103 11.21 + C-A-2 Cafe 103 11.21 + C-A-3 Cafe 103 16.9 + C-A-3 Cafe 103 16.9 + C-B Cafe 103 8.58 + C-B Cafe 103 8.58 + C-D Cafe 103 5.14 + C-D Cafe 103 5.14 + C-C Cafe 103 8.58 + C-C Cafe 103 8.58 = 434.27 SF
A37: FRP panels | B37: SF | C37: 1967.38 | D37: =Inputs!$B$6 -> 0.06 | E37: =C37*D37 -> 118.0428 | F37: =C37+E37 -> 2085.4228 | G37: FRP panel 40 SF (Inputs) | H37: =ROUNDUP(F37/Inputs!$B$30,0) -> 53 | I37: N/SHEET: 3/A-410, 4/A-410, 1/A-226B, 2/A-226B, 3/A-226B, 4/A-226B, 9/A-200, 10/A-200, 11/A-200, 12/A-200 | Breakdown [DERIVED]: FRP-TYPES-3-4 936.74 + FRP-1-CAFE-WORKROOM 875.2 + FRP-1-JANITOR 155.44 = 1,967.38 SF | 3/A-410, 4/A-410 "F.R.P. OVER 5/8" PLYWOOD WHERE SHELVING OCCURS": one face, type 3 38.68 x 8.0 + type 4 83.64 x 7.5 = 936.74 SF (estimator decision 2026-10-27, RFI-22 B); Cafe Work Room 104 FRP-1 full height to the 10'-0" ceiling: 87.52 LF x 10.0 = 875.20 SF gross, doors not deducted (estimator decision 2026-10-27, RFI-13 B); Janitor 107 FRP-1 to 8'-0": 19.43 LF x 8.0 = 155.44 SF gross (estimator decision 2026-10-27, RFI-13 B)
A38: Track 3-5/8" (14 ga 157.81 LF + 16 ga 5.00 LF + 20 ga 118.28 LF) at soffits, fire stop at ceiling line and nested columns | B38: LF | C38: 281.09 | D38: =Inputs!$B$5 -> 0.15 | E38: =C38*D38 -> 42.1635 | F38: =C38+E38 -> 323.2535 | G38: run 10 ft | H38: =ROUNDUP(F38/Inputs!$B$11,0) -> 33 | I38: N/SHEET: 3/A-410, 2/A-221, 8/A-210 | Breakdown [DERIVED]: SS-N 45.54 + SS-E 20.24 + SS-IN-N 40 + SS-IN-E 12.5 + VEST-POSTS-TRACK 5 + FIRESTOP-W2-04 56.76 + FIRESTOP-W2-05 12.92 + FIRESTOP-W2-06.1 6.92 + FIRESTOP-W2-06.2 2.23 + FIRESTOP-W2-06.3 4.87 + FIRESTOP-W2-06.4 2.23 + FIRESTOP-W2-06.5 11.29 + FIRESTOP-W2-07 7.51 + FIRESTOP-W2-08 12.92 + FIRESTOP-W2-09 12.92 + FIRESTOP-C-H2a 12.17 + FIRESTOP-W2-03 13.12 + FIRESTOP-C-H2b 1.95 = 281.09 LF
A39: Track 6" (16 ga 25.33 LF + 20 ga 118.73 LF) at soffits, fire stop at ceiling line and nested beam | B39: LF | C39: 144.06 | D39: =Inputs!$B$5 -> 0.15 | E39: =C39*D39 -> 21.609 | F39: =C39+E39 -> 165.669 | G39: run 10 ft | H39: =ROUNDUP(F39/Inputs!$B$11,0) -> 17 | I39: N/SHEET: 3/A-410, 3/A-221, 8/A-210 | Breakdown [DERIVED]: SS-GG 12.33 + VEST-BOX-BEAM-TRACK 25.33 + FIRESTOP-W5-01 5.7 + FIRESTOP-C-H1-N 29.98 + FIRESTOP-C-H1-W 12.17 + FIRESTOP-C-E2 29.3 + FIRESTOP-C-H3a 4.08 + FIRESTOP-C-H3b 6.17 + FIRESTOP-C-E1-S 19 = 144.06 LF
A40: 8" ledger track (gauge not printed, RFI-54) (4/A-210) | B40: LF | C40: 12.67 | D40: =Inputs!$B$5 -> 0.15 | E40: =C40*D40 -> 1.9005 | F40: =C40+E40 -> 14.5705 | G40: run 10 ft | H40: =ROUNDUP(F40/Inputs!$B$11,0) -> 2 | I40: N/SHEET: 4/A-210 | Breakdown [DERIVED]: VEST-LEDGER 12.67 = 12.67 LF
...

Sheet Pending Items
A1: RFI | B1: Question / condition | C1: Delta of each alternative
A2: RFI-ACC-slab-pins | B2: CLOSED - estimator decision 2026-10-27: One row @ 16" O.C. (A-410 note 8.F spacing). N/SHEET: A-410 note 8.F; 9/A-410. | C2: Applied: slab pins 777.43 -> 388.72 (518.29 LF / 1.333; -388.71).
A3: RFI-ACC-stud-reinforcement-mep | B3: CLOSED - estimator decision 2026-10-27: Counted on M-102 + A-101: 8 duct crossings at the full-height walls (types 2 / 5) + 2 TG-1 transfer grille openings (W2-03, W2-02). N/SHEET: M-102; A-101. | C3: Applied: stud reinforcement plates 0 -> 10 (8 ducts x 1 + 2 TG-1); duct sleeves 0 -> 8 (rfi_mep_cruces/CRUCES.md).
A4: RFI-01 | B4: CLOSED - estimator decision 2026-10-24 (rev1): perimeter walls types 1 / 1A / 1B / 1C are EXISTING (1/DM-101 legend solid = to remain + key note 3 "EXTERIOR WALL PATCH AND REPAIR AS REQUIRED TO MAINTAIN EXISTING FIRE RATING"; A-101 Construction Legend "EXISTING EXTERIOR WALL" / "EXISTING PARTITION"; A-002 "PERIMETER STUDS, INSULATION, VAPOR BARRIER F/I BY LL"). Perimeter framing (studs, track, bracing, 1B sheathing) EXCLUDED. Interior face patch & repair (1/DM-101 key note 3, A-101 C5) = ALLOWANCE, amount: $ ________ (blank, estimator to fill). rev2 (estimator decision 2026-10-25): break room kitchenette W.R. on existing EXT-07 (6/A-412, 7/A-412) is INSIDE this patch & repair allowance; allowance amount stays BLANK (decided). A-410 types 1, 1A, 1B, 1C label the interior board "5/8" GYP BD BY FUTURE TENANT": EXCLUDED with that citation, consistent with this decision. A-413 7/8A general note "IF SHELVING IS TO BE INSTALLED ON EXISTING WALL, G.C. IS TO REMOVE AND REPLACE GYP. BOARD AS REQUIRED FOR INSTALLATION OF WOOD BLOCKING": inside this patch & repair allowance. | C4: Applied: - 417.43 LF of perimeter walls (17 walls); 3-5/8" stud 16,812.96 -> 10,120.39 LF; 8" stud 2,332.99 -> 0; 1/2" exterior sheathing 2,469.22 -> 0 SF; bottom / top track 1,051.87 -> 634.44 LF each; bracing 5,230.74 -> 2,827.81 LF. Allowance: blank.; board by future tenant on the existing perimeter (A-410 types 1 / 1A / 1B / 1C): upper bound 417.43 LF x 25.0 = 10,436 SF 5/8" Type X if it were ever in our scope.
A5: RFI-02 | B5: N/A after RFI-01 (perimeter walls existing, rev1): the north 1A / 1 boundary no longer affects the take-off (both types are existing, excluded). | C5: none
A6: RFI-03 | B6: CLOSED - estimator decision 2026-10-27: B.O. deck 25'-0" kept. N/SHEET: 1/A-400A; 1/A-400B. | C6: No change.
A7: RFI-04 | B7: CLOSED - Review Item rev3 (estimator decision 2026-10-26): type 2 > 22 ft: 3-5/8" 14 ga SJ + diagonal braces @ 32" O.C. to structure (3/A-410 Top Track Detail "PROVIDE DIAGONAL BRACING AT 32" O.C. TO STRUCTURE ABOVE (TYP.)"); brace member / length not printed - estimator choice 3-5/8" 20 ga stud x 4 ft at 45 deg. same precedent applied to the Cafe 3-5/8" walls to deck (C-H2a, C-H2b, C-F): 14 ga SJ + 11 diagonal braces = 44.0 LF. | C7: Applied: 117 braces x 4.0 ft = 468.0 LF (type 2) + 44.0 LF (Cafe) 3-5/8" 20 ga stud (member and length = estimator choice). Citation history: rev0-rev2 cited the partition type 3 section, rev3-rev6 cited 8/A-410 (that bubble is the Typ. Connection Detail); the Top Track Detail is bubble 3/A-410.
A8: RFI-05 | B8: CLOSED - estimator decision 2026-10-27: Closed: types E1 / E2 counted once; type 1 existing per RFI-01. N/SHEET: E/A-221; A-410. | C8: No change.
A9: RFI-06 | B9: CLOSED - Review Item rev3 (estimator decision 2026-10-26): Cafe walls H1, H2a, H2b, H3a, H3b, F studs TO DECK 25'-0" (1/A-400B draws the Cafe walls floor to B.O. DECK; A-226A elevations break at the top; no section prints a stud top). Board per face = ceiling + 6" (A-410 partition note 3): Workroom ACT-1 10'-0" -> 10'-6"; Grab & Go GWB 7'-1" -> 7'-7"; Cafe open-to-deck strip at H2a (1/A-121 PT-6 OPEN TO DECK) -> to deck. | C9: Applied (faces already at these heights in rev2; RCP evidence on 1/A-121).
A10: RFI-07 | B10: N/A after RFI-01 (perimeter walls existing, rev1): exterior furring 3-5/8" over 22'-0" (types 1, 1A, 1C) is existing, excluded. | C10: none
A11: RFI-08 | B11: CLOSED - Review Item rev3 (estimator decision 2026-10-26): type I WD-1 top = 15'-0" A.F.F. (6/A-226A; elevation bubble on 1/A-221 looks west at the type I face, verified). | C11: Applied (rev3 + rev5): type I 5/8" FRT plywood floor to 15'-0" (6/A-226A) = (C-I 2.31 + C-I-P.1 1.00 + end faces C-I-E1 / C-I-E2 1.21) 4.52 LF x 15.0 = 67.74 SF; GWB 15'-0" to deck 4.52 x 10.0 = 45.16 SF.
A12: RFI-09 | B12: CLOSED - estimator decision 2026-10-27: 2-piece track header at every door. N/SHEET: A-500 door schedule; 1/A-500. | C12: Applied: head track at door openings 10.67 -> 83.32 LF ((R.O. + 1'-4") x 2 at every door in a new wall; replaces RFI-31).
... A57: RFI-54 | B57: CLOSED - estimator decision 2026-10-27: Perimeter track kept (conservative); 8" ledger = 16 ga like the 8/A-210 nested members. N/SHEET: 5/A-121; 4/A-210; 8/A-210. | C57: No change in LF.

Sheet Review Items
A1: 0 questions in total, asked ONE at a time in this order: floor plan (partition types A-Z), then the details the floor plan calls, in order
A2: # | B2: Phase | C2: Type / order | D2: Item | E2: Sheet + detail | F2: Image

Sheet Scope Checklist
A1: Scope ID | B1: Scope | C1: Status | D1: Note (quantity, NOT APPLICABLE + sheet, or RFI)
A2: ALC-01 | B2: Interior partition framing (studs + tracks) | C2: QUANTIFIED | D2: Quantified (rev1): partition types 2, 5, 3, 4 (A-410) and Cafe types H1, H2a, H2b, H3a, H3b, E2, E1, F, I, A, B, D, C (A-221) on A-101 / A-221; 3-5/8" and 6" stud families in Material Summary. Perimeter types 1 / 1A / 1B / 1C EXISTING - EXCLUDED (RFI-01).
A3: ALC-02 | B3: Exterior wall framing (CFMF) | C3: NOT APPLICABLE | D3: NOT APPLICABLE (rev1, estimator decision RFI-01): perimeter walls types 1 / 1A / 1B / 1C are existing; their interior board is labeled "5/8" GYP BD BY FUTURE TENANT" on 1, 1A, 1B, 1C/A-410 - EXCLUDED with that citation.
A4: ALC-03 | B4: Parapet framing | C4: NOT APPLICABLE | D4: NOT APPLICABLE: no parapet framing in scope - partition schedule A-410 and sections A-400A, A-400B show no parapet type; M-301 (p50) mention is a mechanical roof-edge note
A5: ALC-04 | B5: Top / deflection and bottom track | C5: QUANTIFIED | D5: Bottom track and top / deflection track = partition LF per type (A-101, A-221; 2/A-410, 3/A-410); + fire stop track at ceiling line (own rows by size, 3/A-410) (3/A-410, RFI-35) and additional head track 83.32 LF (RFI-31); M-302 (p51) mention is plumbing expansion fittings; nested inner runner at deflection heads (3/A-410, RFI-40); 8/A-410 #8 pan head screws + P.A.F. + #8 screws (own rows); X-EDNI 8.C = alternative in RFI-51; cross members at walls parallel to joists (8/A-410 Typ. Connection, RFI-41).
A6: ALC-05 | B6: Headers, sills and jambs at openings | C6: RFI | D6: RFI-09 door headers: no header schedule in the set and 1/A-500 shows no header; jambs carried as studs; sill track not called (A-500 door schedule)
A7: ALC-06 | B7: Bracing / bridging | C7: QUANTIFIED | D7: Bracing C.R. channel @ 4'-0" O.C. per A-410 partition note 4 and 5/A-410 = 2,883.65 LF; diagonal bracing type 2 > 22'-0" per 3/A-410 Top Track Detail (RFI-04 CLOSED rev3: 117 braces = 468.0 LF) + 2" x 2" 16 ga clip angles at every stud per bracing row (5/A-410) and 2/A-221 soffit cross bracing (RFI-42).
A8: ALC-07 | B8: Gypsum board on walls (layers per type) | C8: QUANTIFIED | D8: Quantified (rev6): 5/8" Type X 14,266.95 SF + 5/8" Type X W.R. 1,092.59 SF (A-410, A-001A, RFI-27, RFI-11); no 5/8" regular. Perimeter walls existing (RFI-01).
A9: ALC-08 | B9: Moisture / abuse / special board at wet zones | C9: QUANTIFIED | D9: Quantified (rev6): 5/8" Type X W.R. 1,092.59 SF = all faces of Women's 109, Men's 108, Janitor 107 and drinking fountain alcove corridor faces (A-410 Partition Notes 2 and 7, '*' note, 2/A-410, 5/A-410) + restroom GWB ceilings 122.30 SF (A-410 Partition Notes 2); Cafe Work Room 104 = FRT plywood + FRP-1, no gypsum (G/A-221, A-510); existing EXT-07 faces = patch allowance.
A10: ALC-09 | B10: Exterior gypsum / glass mat sheathing | C10: NOT APPLICABLE | D10: NOT APPLICABLE (rev1): the only sheathing in the set is 1/2 in exterior gyp sheathing of type 1B (1B/A-410), an EXISTING perimeter wall - EXCLUDED (RFI-01, 1/DM-101, A-002); M-301 (p50) 'plastic sheathing' is temporary protection.
A11: ALC-10 | B11: FRT plywood sheathing / substrate | C11: QUANTIFIED | D11: FRT plywood 5/8" 2,686.45 SF (Cafe types G, H, E2, F, I and Grab & Go soffit 3/A-221; soffit faces 2/A-221) + 3/4" 370.46 SF (counters A/B, menu boards 4/A-226A, restroom backing 21/A-201, vestibule 4/A-210, 5/A-210, janitor 11/A-200) - breakdown in Material Summary EXCLUDED (estimator decision 2026-10-27, RFI-50): server room 4'x8' FRT plywood BY GC (2/E-103). Types 3 / 4 one face 5/8" FRT plywood + FRP added (RFI-22).
A12: ALC-11 | B12: Gypsum board ceilings | C12: QUANTIFIED | D12: Quantified (rev7): suspended GWB ceilings and soffits per A-121 (5/A-121, 4/A-121) and 2/A-221 = 1,006.54 SF (incl. Grab & Go 7'-1" 25.16 SF): 5/8" Type X + restroom ceilings 5/8" Type X W.R. (A-410 Partition Notes 2).
... A31: ALC-X30 | B31: batt insulation | C31: NOT APPLICABLE | D31: EXCLUDED (estimator criterion: no insulation)

Sheet _reglas
A1: reglas.py compuerta OK
A2: {"canon": "54a2985ce868bef5f4c86f781a371493b3c8a301911697047c99b99bfdd32ea4", "evidencias": "82f4ec13c901d7191f9772989e98854d158340ab19499f6cfbada96ca6cbd21e", "familias_out": "7b57a39cc3c109040dd7d70891acabfb54c970e8bd928b5acae84020f0009372", "reglas": "ba8bd6e1d9f05fc9d972b956fc70d6670e442c3778886e8c3bd2d878c81dab17", "version": "v73"}
