Workbook

Sheet Inputs
A1: BANK OF AMERICA - BROOMFIELD, CO | METAL FRAMING & DRYWALL TAKEOFF
A2: Permit / Bid Set, 95 sheets. Every quantity below is driven by a live formula. Edit ONLY the yellow cells: the whole workbook recalculates.
A4: PARAMETER | B4: VALUE | C4: NOTE / SOURCE
A5: Waste - ALL METAL, any type | B5: 0.15 | C5: Estimator standing rule, 11-Oct-2026: 15% on everything that is metal, whatever type it is - stud, track, channel, clip, hanger wire, metal trim. No type-by-type exceptions.
A6: Waste - EVERYTHING THAT IS NOT METAL | B6: 0.06 | C6: Estimator standing rule, 11-Oct-2026: everything that is not metal takes the SAME figure as drywall / gypsum board, 6%. That covers board of every type, plywood, FRP, substrates, FRT wood blocking and non-metal trim. This cell is the single source of the 6%; nothing else carries its own copy.
A7: Board sheet width (ft) | B7: 4 | C7: Sheet size is a PARAMETER, never fixed at 4x8 - buy the size that wastes least.
A8: Board sheet length (ft) | B8: 12 | C8: Change it and every piece count below re-rounds up.
A9: SF per board sheet | B9: =B7*B8 -> 48 | C9: Width x length.
A10: Stud stock length (ft) | B10: 20 | C10: Stud is bought in sticks; pieces are converted to sticks in Material Summary.
A11: Track stock length (ft) | B11: 10 | C11: Track is bought in 10 ft runs unless the supplier says otherwise.
A12: Floor plan scale (pt/ft) | B12: 18 | C12: A02.01 at 1/4"=1'-0" -> 18.0 pt/ft, 1.5 pt per real inch. Every length came from vector geometry at this scale.
A13: B.O. Deck north of grid B (ft) | B13: 15.375 | C13: S2.20: T/STEEL 15'-4 1/2", NO SLOPE north of grid B.
A14: T.O. Parapet 1 (ft) | B14: 17.75 | C14: Exterior elevations A09.01 / A09.02 datum T.O. PARAPET 1 = 17'-9".
A15: Sealant coverage (LF per tube) | B15: 25 | C15: Acoustical sealant yield per tube - set your supplier's figure.
A16: C.R. channel stock length (ft) | B16: 16 | C16: 1-1/2" cold-rolled channel ships in 16 ft and 20 ft - NOT in 10 ft track lengths.
A17: Hat / furring channel stock (ft) | B17: 12 | C17: 7/8" hat furring channel ships in 12 ft.
A18: Trim stick length (ft) | B18: 10 | C18: Corner bead, casing bead and shadow molding ship in 8 ft and 10 ft sticks - NOT in 20 ft stud lengths.
A19: Wood blocking waste - SUPERSEDED, do not use | C19: SUPERSEDED 11-Oct-2026. This used to be its own parameter, left at 0 because FRT wood blocking was neither metal nor board and the old 15%/6% rule had no row for it. The rule now covers it: everything that is not metal takes the same figure as board, so wood blocking reads the 'EVERYTHING THAT IS NOT METAL' cell above like every other non-metal material. The cell is left empty on purpose - two cells meaning the same 6% is a second source of truth, which is how the figures drift apart.
A20: Drywall screws per SF of board | B20: 1.2 | C20: YIELD, not a drawing quantity. GA-216: field 12" O.C., perimeter 8" O.C. over framing at 16" O.C. Set your own figure.
A21: Framing screws per stud piece | B21: 4 | C21: YIELD: 2 per stud-to-track connection at each end. Clips and bracing are counted separately.
A22: Power-driven pin spacing (ft) | B22: 2 | C22: YIELD: 4/A12.01 calls POWER DRIVEN FASTENERS @ 2'-0" O.C. alternating sides on the bottom track.
A23: Joint compound (lb per SF) | B23: 0.072 | C23: YIELD: 72 lb per 1,000 SF, typical level 4 finish. Set your supplier's figure.
A24: Joint tape (LF per SF) | B24: 0.37 | C24: YIELD: 370 LF per 1,000 SF.
A26: LEGEND
A27: Blue text on yellow fill = input you may edit
A28: Black text = live formula, do not overwrite
A29: Green text = pulled from another sheet
A31: EXAMPLE ROW (format reference, not part of the takeoff)
A32: A1 #1 | Corridor 111 / Break Room 118 | L 16.42 LF | H 15.375 FT | Layers 2 | 3-5/8" 362S137-33 MST @ 16" O.C., 33 mil | 1 layer 5/8" gyp per face

Sheet Partition Takeoff
A1: ORGANIZED PARTITION TAKEOFF ESTIMATOR - BANK OF AMERICA, BROOMFIELD CO
A2: Grouped by partition type, longest first inside each type. Stud columns are in LF of MATERIAL (pieces x height) and never mix two stud sizes. Quantities are NET - waste lives in its own cells on Material Summary.
A4: Partition / Scope | B4: Wall # | C4: Length (LF) | D4: Height (FT) | E4: Layers | F4: Stud Size | G4: Stud (pcs) | H4: 6" Metal Stud (LF) | I4: 3-5/8" Metal Stud (LF) | J4: 1-5/8" Metal Stud (LF) | K4: 5/8" Gyp Board (SF) | L4: FRP-1 (SF) | M4: FRP-2 (SF) | N4: Durock / Cement Bd (SF) | O4: Demolition (SF) | P4: Labor (Hrs) | Q4: Bottom Track (LF) | R4: Top / Deflection Track (LF) | S4: Bracing (LF) | T4: Clips (pcs) | U4: Blocking (LF) | V4: Insulation (SF) | W4: Ext. Gypsum Sheathing, deck to parapet (SF) | X4: Ext. Sheathing FRT+Polyiso (SF) | Y4: Ballistic Panel 3/8" UL752 (SF) | Z4: 3/8" Gyp Board (SF) | AA4: FRT Plywood Substrate (SF) | AB4: Level 5 Finish (SF) | AC4: Trim - corner/casing/shadow (LF) | AD4: Extra Framing - sistered, furring, MEP (LF) | AE4: Fasteners (pcs) | AF4: Sealant (LF) | AG4: Header / Box Beam (LF) | AH4: Sill Track (LF) | AI4: Openings | AJ4: Status | AK4: Source / Seal | AL4: Stud (LF of material) | AM4: Addl Head Track >4'-0" opening (LF) | AN4: Ext. Glass Mat Sheathing at stud face (SF) | AO4: Gypsum Board Jamb Return (SF) | AP4: Detail sequence (plan → section → detail → schedule)
A5: TYPE A1
A6: A1 #8 - Corridor 111 / Break Room 118 + Electrical 120 + NER 121 - the long wall (tags #8 and #10). Stud 3-5/8" 362S137-33 MST @ 16" O.C.; bracing 1-1/2" C.R. channel @ 48" O.C. Corridor 111: 1 layer(s) 5/8 GYP @ 9.000 FT | Break Room 118: 1 layer(s) 5/8 GYP @ 9.000 FT | Electrical 120: 1 layer(s) 5/8 GYP @ 12.820 FT | NER 121: 1 layer(s) 5/8 GYP @ 12.690 FT (1 instance) | B6: 8 | C6: 17.06 | D6: 12.89 | E6: 1.95 | F6: 3-5/8" | G6: 21 | H6: =IF($F6="6""",$AL6,0) -> 0 | I6: =IF($F6="3-5/8""",$AL6,0) -> 270.69 | J6: =IF($F6="1-5/8""",$AL6,0) -> 0 | K6: =SUMIFS('Board by Face'!$I$5:$I$115,'Board by Face'!$A$5:$A$115,$B6) -> 349.6456 | Q6: 17.06 | R6: 17.06 | S6: 51.18 | U6: 21.97 | AA6: 106.66 | AF6: 34.12 | AG6: 3.33 | AI6: door 118B 3.33 x 7.00 | AJ6: CLOSED | AK6: seal f6f3ebf997a3f559 | AL6: 270.69 | AP6: A02.01 → A04.01 → S2.20 → 2/A11.03 → 3/A11.03 → 4/A11.03 → 5/A11.03 → 7/A11.03 → 1/A12.01 → 3/A12.01 → 4/A12.01 → A09.01 → 10/A12.02 → 11/A12.02 → 1/S5.20 → 2/S5.20 → 4/S5.20 → 7/S5.20 → 9/S5.20 → A00.01 → A00.30 → A09.27 → A09.33 → E02.01 → M01.01 → P01.01 → P01.02
A7: A1 #1 - Central Zone 103 / Calling Cubes 122 - north wall of Calling Cubes. Stud 3-5/8" 362S137-33 MST @ 16" O.C.; bracing 1-1/2" C.R. channel @ 48" O.C. Central Zone 103: 1 layer(s) 5/8 GYP @ 12.000 FT | Calling Cubes 122: 1 layer(s) 5/8 GYP @ 9.000 FT (1 instance) | B7: 1 | C7: 16.42 | D7: 15.375 | E7: 2 | F7: 3-5/8" | G7: 16 | H7: =IF($F7="6""",$AL7,0) -> 0 | I7: =IF($F7="3-5/8""",$AL7,0) -> 246 | J7: =IF($F7="1-5/8""",$AL7,0) -> 0 | K7: =SUMIFS('Board by Face'!$I$5:$I$115,'Board by Face'!$A$5:$A$115,$B7) -> 344.82 | Q7: 16.42 | R7: 16.42 | S7: 49.26 | U7: 32.84 | AF7: 32.84 | AI7: none | AJ7: CLOSED | AK7: seal 0b6d1dcbcf676ced | AL7: 246 | AP7: A02.01 → A04.01 → S2.20 → 1/A12.01 → 3/A12.01 → 4/A12.01 → A09.01 → 10/A12.02 → 11/A12.02 → 1/S5.20 → 4/S5.20 → 7/S5.20 → A00.01 → A00.30 → A09.27 → A09.33 → E02.01 → M01.01 → P01.01 → P01.02
A8: A1 #5 - Calling Cubes 122 / Break Room 118 - carries MW21 on the south face. Stud 3-5/8" 362S137-33 MST @ 16" O.C.; bracing 1-1/2" C.R. channel @ 48" O.C. Calling Cubes 122: 1 layer(s) 5/8 GYP @ 9.000 FT | Break Room 118: 1 layer(s) 5/8 GYP @ 9.000 FT (1 instance) | B8: 5 | C8: 15.23 | D8: 12.971 | E8: 2 | F8: 3-5/8" | G8: 14 | H8: =IF($F8="6""",$AL8,0) -> 0 | I8: =IF($F8="3-5/8""",$AL8,0) -> 181.59 | J8: =IF($F8="1-5/8""",$AL8,0) -> 0 | K8: =SUMIFS('Board by Face'!$I$5:$I$115,'Board by Face'!$A$5:$A$115,$B8) -> 274.14 | Q8: 15.23 | R8: 15.23 | S8: 45.69 | U8: 40.46 | AF8: 30.46 | AI8: none | AJ8: CLOSED | AK8: seal b142fb73ec3b93d8 | AL8: 181.59 | AP8: A02.01 → A04.01 → S2.20 → 1/A12.01 → 3/A12.01 → 4/A12.01 → A09.01 → 10/A12.02 → 11/A12.02 → 1/S5.20 → 4/S5.20 → 7/S5.20 → A00.01 → A00.30 → A09.27 → A09.33 → A12.04 → A12.06 → E02.01 → M01.01 → P01.01 → P01.02
A9: A1 #9 - Cash Window 116 / Work Room 119 - north wall of the Work Room, carries MW12 and door 119. Stud 3-5/8" 362S137-33 MST @ 16" O.C.; bracing 1-1/2" C.R. channel @ 48" O.C. Cash Window 116: 1 layer(s) 5/8 GYP @ 9.500 FT | Work Room 119: 1 layer(s) 5/8 GYP @ 9.000 FT (1 instance) | B9: 9 | C9: 11.667 | D9: 12.775 | E9: 2 | F9: 3-5/8" | G9: 23 | H9: =IF($F9="6""",$AL9,0) -> 0 | I9: =IF($F9="3-5/8""",$AL9,0) -> 293.82 | J9: =IF($F9="1-5/8""",$AL9,0) -> 0 | K9: =SUMIFS('Board by Face'!$I$5:$I$115,'Board by Face'!$A$5:$A$115,$B9) -> 169.235 | Q9: 11.667 | R9: 11.667 | S9: 35 | U9: 46.27 | AF9: 23.33 | AG9: 5.33 | AH9: 2 | AI9: door 119 3.33 x 7.00 + framed opening 8" duct M01.01 (solid run) 1.00 x 1.00 + framed opening 8" duct M01.01 (over the 119 header) 1.00 x 1.00 | AJ9: CLOSED | AK9: seal 5ae93fd71c06450b | AL9: 293.82 | AP9: A02.01 → A04.01 → S2.20 → 1/A12.01 → 3/A12.01 → 4/A12.01 → A09.01 → 10/A12.02 → 11/A12.02 → 1/S5.20 → 2/S5.20 → 4/S5.20 → 6/S5.20 → 7/S5.20 → 9/S5.20 → A00.01 → A00.30 → A09.27 → A09.33 → A12.05 → E02.01 → M01.01 → P01.01 → P01.02
A10: A1 #6 - Break Room 118 / Future FCAM - carries door 118A. Stud 3-5/8" 362S137-33 MST @ 16" O.C.; bracing 1-1/2" C.R. channel @ 48" O.C. Cash Window 116: 1 layer(s) 5/8 GYP @ 9.500 FT | Break Room 118: 1 layer(s) 5/8 GYP @ 9.000 FT (1 instance) | B10: 6 | C10: 5.5 | D10: 12.927 | E10: 2 | F10: 3-5/8" | G10: 11 | H10: =IF($F10="6""",$AL10,0) -> 0 | I10: =IF($F10="3-5/8""",$AL10,0) -> 142.2 | J10: =IF($F10="1-5/8""",$AL10,0) -> 0 | K10: =SUMIFS('Board by Face'!$I$5:$I$115,'Board by Face'!$A$5:$A$115,$B10) -> 48.43 | Q10: 5.5 | R10: 5.5 | S10: 16.5 | U10: 13 | AF10: 11 | AG10: 3.33 | AI10: door 118A 3.33 x 8.00 | AJ10: CLOSED | AK10: seal 330ea163b4a7954b | AL10: 142.2 | AP10: A02.01 → A04.01 → S2.20 → 1/A12.01 → 3/A12.01 → 4/A12.01 → A09.01 → 10/A12.02 → 11/A12.02 → 1/S5.20 → 2/S5.20 → 4/S5.20 → 7/S5.20 → 9/S5.20 → A00.01 → A00.30 → A09.27 → A09.33 → E02.01 → M01.01 → P01.01 → P01.02
A11: A1 #4 - Corridor 111 - jambs of door 111, entry from Central Zone. Stud 3-5/8" 362S137-33 MST @ 16" O.C.; bracing 1-1/2" C.R. channel @ 48" O.C. Corridor 111: 1 layer(s) 5/8 GYP @ 9.000 FT | Corridor 111 (face 2): 1 layer(s) 5/8 GYP @ 9.000 FT (1 instance) | B11: 4 | C11: 5 | D11: 15.375 | E11: 2 | F11: 3-5/8" | G11: 10 | H11: =IF($F11="6""",$AL11,0) -> 0 | I11: =IF($F11="3-5/8""",$AL11,0) -> 153.75 | J11: =IF($F11="1-5/8""",$AL11,0) -> 0 | K11: =SUMIFS('Board by Face'!$I$5:$I$115,'Board by Face'!$A$5:$A$115,$B11) -> 36.68 | Q11: 5 | R11: 5 | S11: 15 | U11: 12 | AF11: 10 | AG11: 3.33 | AI11: door 111 3.33 x 8.00 | AJ11: CLOSED | AK11: seal bad128ab97504e87 | AL11: 153.75 | AP11: A02.01 → A04.01 → S2.20 → 1/A12.01 → 3/A12.01 → 4/A12.01 → A09.01 → 10/A12.02 → 11/A12.02 → 1/S5.20 → 2/S5.20 → 4/S5.20 → 7/S5.20 → 9/S5.20 → A00.01 → A00.30 → A09.27 → A09.33 → E02.01 → M01.01 → P01.01 → P01.02
A12: A1 #2 - MW01 niche / Calling Cubes 122 - back of the printer cabinet. Stud 3-5/8" 362S137-33 MST @ 16" O.C.; bracing 1-1/2" C.R. channel @ 48" O.C. Calling Cubes 122: 1 layer(s) 5/8 GYP @ 9.000 FT | MW01 niche: 1 layer(s) 5/8 GYP @ 9.000 FT (1 instance) | B12: 2 | C12: 3.13 | D12: 15.375 | E12: 2 | F12: 3-5/8" | G12: 5 | H12: =IF($F12="6""",$AL12,0) -> 0 | I12: =IF($F12="3-5/8""",$AL12,0) -> 76.88 | J12: =IF($F12="1-5/8""",$AL12,0) -> 0 | K12: =SUMIFS('Board by Face'!$I$5:$I$115,'Board by Face'!$A$5:$A$115,$B12) -> 56.34 | Q12: 3.13 | R12: 3.13 | S12: 9.39 | U12: 12.52 | AF12: 6.26 | AI12: none | AJ12: CLOSED | AK12: seal f9459712ac3d5e8f | AL12: 76.88 | AP12: A02.01 → A04.01 → S2.20 → 1/A12.01 → 3/A12.01 → 4/A12.01 → A09.01 → 10/A12.02 → 11/A12.02 → 1/S5.20 → 4/S5.20 → 7/S5.20 → A00.01 → A00.30 → A09.27 → A09.33 → A12.03 → A12.04 → A12.05 → E02.01 → M01.01 → P01.01 → P01.02
A13: A1 #3 - MW01 niche / Calling Cubes 122 - south close of the niche. Stud 3-5/8" 362S137-33 MST @ 16" O.C.; bracing 1-1/2" C.R. channel @ 48" O.C. Calling Cubes 122: 1 layer(s) 5/8 GYP @ 9.000 FT | MW01 niche: 1 layer(s) 5/8 GYP @ 9.000 FT (1 instance) | B13: 3 | C13: 2.63 | D13: 15.375 | E13: 2 | F13: 3-5/8" | G13: 4 | H13: =IF($F13="6""",$AL13,0) -> 0 | I13: =IF($F13="3-5/8""",$AL13,0) -> 61.5 | J13: =IF($F13="1-5/8""",$AL13,0) -> 0 | K13: =SUMIFS('Board by Face'!$I$5:$I$115,'Board by Face'!$A$5:$A$115,$B13) -> 47.34 | Q13: 2.63 | R13: 2.63 | S13: 7.89 | U13: 5.26 | AF13: 5.26 | AI13: none | AJ13: CLOSED | AK13: seal de2d6c733839b704 | AL13: 61.5 | AP13: A02.01 → A04.01 → S2.20 → 1/A12.01 → 3/A12.01 → 4/A12.01 → A09.01 → 10/A12.02 → 11/A12.02 → 7/A12.04 → 1/S5.20 → 4/S5.20 → 7/S5.20 → A00.01 → A00.30 → A09.27 → A09.33 → E02.01 → M01.01 → P01.01 → P01.02
A14: A1 #7 - Break Room 118 / Cash Window 116 - vertical return between walls A1-5 and A1-6. Stud 3-5/8" 362S137-33 MST @ 16" O.C.; bracing 1-1/2" C.R. channel @ 48" O.C. Break Room 118: 1 layer(s) 5/8 GYP @ 9.000 FT | Cash Window 116: 1 layer(s) 5/8 GYP @ 9.500 FT (1 instance) | B14: 7 | C14: 1.73 | D14: 12.963 | E14: 2 | F14: 3-5/8" | G14: 4 | H14: =IF($F14="6""",$AL14,0) -> 0 | I14: =IF($F14="3-5/8""",$AL14,0) -> 51.85 | J14: =IF($F14="1-5/8""",$AL14,0) -> 0 | K14: =SUMIFS('Board by Face'!$I$5:$I$115,'Board by Face'!$A$5:$A$115,$B14) -> 32.005 | Q14: 1.73 | R14: 1.73 | S14: 5.19 | U14: 3.46 | AF14: 3.46 | AI14: none | AJ14: CLOSED | AK14: seal 59b6ae489514c65f | AL14: 51.85 | AP14: A02.01 → A04.01 → S2.20 → 1/A12.01 → 3/A12.01 → 4/A12.01 → A09.01 → 10/A12.02 → 11/A12.02 → 1/S5.20 → 4/S5.20 → 7/S5.20 → A00.01 → A00.30 → A09.27 → A09.33 → E02.01 → M01.01 → P01.01 → P01.02
A15: TYPE A1K
A16: A1K #11 - NORTH head of Cash Window 116 / CSR line (banda y 1120.68/1128.48). Stud 3-5/8" 362S137-68 MST @ 24" O.C.; bracing 1-1/2" C.R. channel @ 48" O.C. Lado norte (linea de teller, contra el wall G-47): 1 layer(s) 5/8 GYP 1 layer @ 15.375 FT | Cash Window 116: 1 layer(s) 5/8 GYP 1 layer @ 15.375 FT (1 instance) | B16: 11 | C16: 3.417 | D16: 15.375 | E16: 2 | F16: 3-5/8" | G16: 4 | H16: =IF($F16="6""",$AL16,0) -> 0 | I16: =IF($F16="3-5/8""",$AL16,0) -> 61.5 | J16: =IF($F16="1-5/8""",$AL16,0) -> 0 | K16: =SUMIFS('Board by Face'!$I$5:$I$115,'Board by Face'!$A$5:$A$115,$B16) -> 105.07275 | Q16: 3.42 | R16: 3.42 | S16: 10.25 | Y16: 27.34 | Z16: 25.2 | AC16: 6.83 | AE16: 6 | AF16: 13.67 | AI16: none | AJ16: CLOSED | AK16: seal 55ac0f1c5756bccf | AL16: 61.5 | AP16: A02.01 → S2.20 → 4/A12.01 → 1/S5.20 → 7/S5.20 → A09.01 → A00.01 → A09.27 → A09.33
A17: A1K #12 - SOUTH head of Cash Window 116 (banda y 1344.72/1352.64). Stud 3-5/8" 362S137-68 MST @ 24" O.C.; bracing 1-1/2" C.R. channel @ 48" O.C. Cash Window 116: 1 layer(s) 5/8 GYP 1 layer @ 12.933 FT | Lado sur (zona del FUTURE FCAM): 1 layer(s) 5/8 GYP 1 layer @ 12.933 FT (1 instance) | B17: 12 | C17: 3.413 | D17: 12.933 | E17: 2 | F17: 3-5/8" | G17: 4 | H17: =IF($F17="6""",$AL17,0) -> 0 | I17: =IF($F17="3-5/8""",$AL17,0) -> 51.73 | J17: =IF($F17="1-5/8""",$AL17,0) -> 0 | K17: =SUMIFS('Board by Face'!$I$5:$I$115,'Board by Face'!$A$5:$A$115,$B17) -> 88.280658 | Q17: 3.41 | R17: 3.41 | S17: 10.24 | Y17: 27.3 | Z17: 16.84 | AC17: 6.83 | AE17: 6 | AF17: 13.65 | AI17: none | AJ17: CLOSED | AK17: seal 7fa175fb06948b14 | AL17: 51.73 | AP17: A02.01 → S2.20 → 4/A12.01 → 1/S5.20 → 7/S5.20 → A09.01 → A00.01 → A09.27 → A09.33
A18: A1K #13 - Southwest return at Cash Window 116 (banda y 1355.28/1363.08). Stud 3-5/8" 362S137-68 MST @ 24" O.C.; bracing 1-1/2" C.R. channel @ 48" O.C. Lado norte: 1 layer(s) 5/8 GYP 1 layer @ 12.921 FT | Lado sur (zona del FUTURE FCAM): 1 layer(s) 5/8 GYP 1 layer @ 12.921 FT (1 instance) | B18: 13 | C18: 1.16 | D18: 12.921 | E18: 2 | F18: 3-5/8" | G18: 3 | H18: =IF($F18="6""",$AL18,0) -> 0 | I18: =IF($F18="3-5/8""",$AL18,0) -> 38.76 | J18: =IF($F18="1-5/8""",$AL18,0) -> 0 | K18: =SUMIFS('Board by Face'!$I$5:$I$115,'Board by Face'!$A$5:$A$115,$B18) -> 29.97672 | Q18: 1.16 | R18: 1.16 | S18: 3.48 | Y18: 9.28 | Z18: 5.71 | AC18: 2.32 | AE18: 4 | AF18: 4.64 | AI18: none | AJ18: CLOSED | AK18: seal e3169842073623f7 | AL18: 38.76 | AP18: A02.01 → S2.20 → 4/A12.01 → 1/S5.20 → 7/S5.20 → A09.01 → A00.01 → A09.27 → A09.33
A19: TYPE A5
A20: A5 #14 - Calling Cubes 122 / Office 4 CB 108. Stud 6" 600S137-33 MST @ 16" O.C.; bracing 1-1/2" C.R. channel @ 48" O.C. Calling Cubes 122: 1 layer(s) 5/8 GYP @ 9.000 FT | Office 4 CB 108: 1 layer(s) 5/8 GYP @ 9.500 FT (1 instance) | B20: 14 | C20: 19 | D20: 15.375 | E20: 2 | F20: 6" | G20: 15 | H20: =IF($F20="6""",$AL20,0) -> 223.66 | I20: =IF($F20="3-5/8""",$AL20,0) -> 0 | J20: =IF($F20="1-5/8""",$AL20,0) -> 0 | K20: =SUMIFS('Board by Face'!$I$5:$I$115,'Board by Face'!$A$5:$A$115,$B20) -> 351.5 | Q20: 19 | R20: 19 | S20: 57 | U20: 38 | AF20: 38 | AI20: none | AJ20: CLOSED | AK20: seal 95c67946c0f7261d | AL20: 223.66 | AP20: A02.01 → A04.01 → 3/A12.01 → 1/S5.20 → 4/S5.20 → 7/S5.20 → A09.01 → A00.30 → A09.27 → A09.33
A21: A5 #15 - Calling Cubes 122 / Corridor 111. Stud 6" 600S137-33 MST @ 16" O.C.; bracing 1-1/2" C.R. channel @ 48" O.C. Calling Cubes 122: 1 layer(s) 5/8 GYP @ 9.000 FT | Corridor 111: 1 layer(s) 5/8 GYP @ 9.000 FT (1 instance) | B21: 15 | C21: 11 | D21: 15.375 | E21: 2 | F21: 6" | G21: 9 | H21: =IF($F21="6""",$AL21,0) -> 138.38 | I21: =IF($F21="3-5/8""",$AL21,0) -> 0 | J21: =IF($F21="1-5/8""",$AL21,0) -> 0 | K21: =SUMIFS('Board by Face'!$I$5:$I$115,'Board by Face'!$A$5:$A$115,$B21) -> 198 | Q21: 11 | R21: 11 | S21: 33 | U21: 41.88 | AF21: 22 | AI21: none | AJ21: CLOSED | AK21: seal 4742d9e4779e1bab | AL21: 138.38 | AP21: A02.01 → A04.01 → S2.20 → 3/A12.01 → 1/S5.20 → 4/S5.20 → 7/S5.20 → A09.01 → A00.30 → A09.27 → A09.33 → A12.05
A22: A5 #16 - Corridor 111 / Calling Cubes 122. Stud 6" 600S137-33 MST @ 16" O.C.; bracing 1-1/2" C.R. channel @ 48" O.C. Corridor 111: 1 layer(s) 5/8 GYP @ 9.000 FT | Calling Cubes 122: 1 layer(s) 5/8 GYP @ 9.000 FT (1 instance) | B22: 16 | C22: 5.41 | D22: 13.052 | E22: 2 | F22: 6" | G22: 9 | H22: =IF($F22="6""",$AL22,0) -> 119.79 | I22: =IF($F22="3-5/8""",$AL22,0) -> 0 | J22: =IF($F22="1-5/8""",$AL22,0) -> 0 | K22: =SUMIFS('Board by Face'!$I$5:$I$115,'Board by Face'!$A$5:$A$115,$B22) -> 50.76 | Q22: 5.41 | R22: 5.41 | S22: 16.23 | U22: 10.82 | AF22: 10.82 | AG22: 3.33 | AI22: door 122 3.33 x 7.00 | AJ22: CLOSED | AK22: seal 33f26d5ec19f564f | AL22: 119.79 | AP22: A02.01 → A04.01 → 3/A12.01 → A09.01 → 10/A12.02 → 1/S5.20 → 4/S5.20 → 7/S5.20 → 9/S5.20 → A00.30 → A09.27 → A09.33
A23: A5 #17 - Break Room 118 / Cash Window 116. Stud 6" 600S137-33 MST @ 16" O.C.; bracing 1-1/2" C.R. channel @ 48" O.C. Break Room 118: 1 layer(s) 5/8 GYP @ 9.000 FT | Cash Window 116: 1 layer(s) 5/8 GYP @ 9.500 FT (1 instance) | B23: 17 | C23: 3.71 | D23: 12.927 | E23: 2 | F23: 6" | G23: 3 | H23: =IF($F23="6""",$AL23,0) -> 38.78 | I23: =IF($F23="3-5/8""",$AL23,0) -> 0 | J23: =IF($F23="1-5/8""",$AL23,0) -> 0 | K23: =SUMIFS('Board by Face'!$I$5:$I$115,'Board by Face'!$A$5:$A$115,$B23) -> 68.635 | Q23: 3.71 | R23: 3.71 | S23: 11.13 | U23: 7.42 | AF23: 7.42 | AI23: none | AJ23: CLOSED | AK23: seal e3797658ed2d6b14 | AL23: 38.78 | AP23: A02.01 → A04.01 → S2.20 → 3/A12.01 → 1/S5.20 → 4/S5.20 → 7/S5.20 → A09.01 → A00.30 → A09.27 → A09.33
A24: TYPE B
A25: B #23 - Electrical 120 + NER 121 / Break Room 118 (east wall). Stud 3-5/8" 362S137-33 MST @ 16" O.C.; bracing 1-1/2" C.R. channel @ 48" O.C. Electrical 120: 1 layer(s) 5/8 GYP @ 12.831 FT | NER 121: 1 layer(s) 5/8 GYP @ 12.831 FT | Break Room 118: 1 layer(s) 5/8 GYP @ 12.831 FT (1 instance) | B25: 23 | C25: 14.15 | D25: 12.831 | E25: 2 | F25: 3-5/8" | G25: 19 | H25: =IF($F25="6""",$AL25,0) -> 0 | I25: =IF($F25="3-5/8""",$AL25,0) -> 243.79 | J25: =IF($F25="1-5/8""",$AL25,0) -> 0 | K25: =SUMIFS('Board by Face'!$I$5:$I$115,'Board by Face'!$A$5:$A$115,$B25) -> 269.74899 | Q25: 14.15 | R25: 14.15 | S25: 42.45 | AF25: 56.6 | AG25: 6.66 | AI25: door 120 3.33 x 7.00 + door 121 3.33 x 7.00 | AJ25: CLOSED | AK25: seal 94fc9636f6965f50 | AL25: 243.79 | AP25: A02.01 → S2.20 → 1/A12.01 → A09.01 → 10/A12.02 → 11/A12.02 → 1/S5.20 → 4/S5.20 → 7/S5.20 → 9/S5.20 → A00.30 → A09.27 → A09.33
A26: B #20 - Janitor Closet 112 / Storage 117 (horizontal wall, with door 112). Stud 3-5/8" 362S137-33 MST @ 16" O.C.; bracing 1-1/2" C.R. channel @ 48" O.C. Janitor Closet 112: 1 layer(s) 5/8 GYP @ 12.748 FT | Storage 117: 1 layer(s) 5/8 GYP @ 12.748 FT (1 instance) | B26: 20 | C26: 11.83 | D26: 12.748 | E26: 2 | F26: 3-5/8" | G26: 13 | H26: =IF($F26="6""",$AL26,0) -> 0 | I26: =IF($F26="3-5/8""",$AL26,0) -> 165.72 | J26: =IF($F26="1-5/8""",$AL26,0) -> 0 | K26: =SUMIFS('Board by Face'!$I$5:$I$115,'Board by Face'!$A$5:$A$115,$B26) -> 259.61768 | Q26: 11.83 | R26: 11.83 | S26: 35.49 | AF26: 47.32 | AG26: 3 | AI26: door 112 3.00 x 7.00 | AJ26: CLOSED | AK26: seal cf6621bf33cfc512 | AL26: 165.72 | AP26: A02.01 → S2.20 → 1/A12.01 → A09.01 → 10/A12.02 → 11/A12.02 → 1/S5.20 → 4/S5.20 → 7/S5.20 → 9/S5.20 → A00.30 → A09.27 → A09.33
A27: B #21 - Janitor Closet 112 + Storage 117 / Wellness 115. Stud 3-5/8" 362S137-33 MST @ 16" O.C.; bracing 1-1/2" C.R. channel @ 48" O.C. Wellness 115: 1 layer(s) 5/8 GYP @ 12.666 FT | Janitor Closet 112: 1 layer(s) 5/8 GYP @ 12.666 FT | Storage 117: 1 layer(s) 5/8 GYP @ 12.666 FT (1 instance) | B27: 21 | C27: 11.73 | D27: 12.666 | E27: 2 | F27: 3-5/8" | G27: 9 | H27: =IF($F27="6""",$AL27,0) -> 0 | I27: =IF($F27="3-5/8""",$AL27,0) -> 113.99 | J27: =IF($F27="1-5/8""",$AL27,0) -> 0 | K27: =SUMIFS('Board by Face'!$I$5:$I$115,'Board by Face'!$A$5:$A$115,$B27) -> 297.14436 | Q27: 11.73 | R27: 11.73 | S27: 35.19 | AF27: 46.92 | AI27: none | AJ27: CLOSED | AK27: seal 97c412d53363891c | AL27: 113.99 | AP27: A02.01 → S2.20 → 1/A12.01 → 1/S5.20 → 4/S5.20 → 7/S5.20 → A09.01 → A00.30 → A09.27 → A09.33
A28: B #18 - Electrical 120 / Break Room 118 (north wall of Electrical). Stud 3-5/8" 362S137-33 MST @ 16" O.C.; bracing 1-1/2" C.R. channel @ 48" O.C. Break Room 118: 1 layer(s) 5/8 GYP @ 12.827 FT | Electrical 120: 1 layer(s) 5/8 GYP @ 12.827 FT (1 instance) | B28: 18 | C28: 9.99 | D28: 12.827 | E28: 2 | F28: 3-5/8" | G28: 8 | H28: =IF($F28="6""",$AL28,0) -> 0 | I28: =IF($F28="3-5/8""",$AL28,0) -> 102.62 | J28: =IF($F28="1-5/8""",$AL28,0) -> 0 | K28: =SUMIFS('Board by Face'!$I$5:$I$115,'Board by Face'!$A$5:$A$115,$B28) -> 256.28346 | Q28: 9.99 | R28: 9.99 | S28: 29.97 | AA28: 76.32 | AF28: 39.96 | AI28: none | AJ28: CLOSED | AK28: seal 22cceb27f4d24f0a | AL28: 102.62 | AP28: A02.01 → S2.20 → 2/A11.03 → 3/A11.03 → 4/A11.03 → 1/A12.01 → 1/S5.20 → 4/S5.20 → 7/S5.20 → A09.01 → A00.30 → A09.27 → A09.33
A29: B #22 - Electrical 120 / NER 121 (south wall of Electrical). Stud 3-5/8" 362S137-33 MST @ 16" O.C.; bracing 1-1/2" C.R. channel @ 48" O.C. Electrical 120: 1 layer(s) 5/8 GYP @ 12.698 FT | NER 121: 1 layer(s) 5/8 GYP @ 12.698 FT (1 instance) | B29: 22 | C29: 9.58 | D29: 12.698 | E29: 2 | F29: 3-5/8" | G29: 8 | H29: =IF($F29="6""",$AL29,0) -> 0 | I29: =IF($F29="3-5/8""",$AL29,0) -> 101.58 | J29: =IF($F29="1-5/8""",$AL29,0) -> 0 | K29: =SUMIFS('Board by Face'!$I$5:$I$115,'Board by Face'!$A$5:$A$115,$B29) -> 243.29368 | Q29: 9.58 | R29: 9.58 | S29: 28.74 | AA29: 76.16 | AF29: 38.32 | AI29: none | AJ29: CLOSED | AK29: seal 1f8b6511c9a47902 | AL29: 101.58 | AP29: A02.01 → S2.20 → 2/A11.03 → 3/A11.03 → 4/A11.03 → 1/A12.01 → 1/S5.20 → 4/S5.20 → 7/S5.20 → A09.01 → A00.30 → A09.27 → A09.33
A30: B #19 - Janitor Closet 112 / Storage 117 (also carries tag #20, same wall). Stud 3-5/8" 362S137-33 MST @ 16" O.C.; bracing 1-1/2" C.R. channel @ 48" O.C. Janitor Closet 112: 1 layer(s) 5/8 GYP @ 12.743 FT | Storage 117: 1 layer(s) 5/8 GYP @ 12.743 FT (1 instance) | B30: 19 | C30: 3.5 | D30: 12.743 | E30: 2 | F30: 3-5/8" | G30: 3 | H30: =IF($F30="6""",$AL30,0) -> 0 | I30: =IF($F30="3-5/8""",$AL30,0) -> 38.23 | J30: =IF($F30="1-5/8""",$AL30,0) -> 0 | K30: =SUMIFS('Board by Face'!$I$5:$I$115,'Board by Face'!$A$5:$A$115,$B30) -> 89.201 | Q30: 3.5 | R30: 3.5 | S30: 10.5 | U30: 29.22 | AE30: 1 | AF30: 14 | AI30: none | AJ30: CLOSED | AK30: seal 3fed9fd55804aca5 | AL30: 38.23 | AP30: A02.01 → S2.20 → 1/A12.01 → 1/S5.20 → 4/S5.20 → 6/S5.20 → 7/S5.20 → A09.01 → A00.30 → A09.27 → A09.33 → M01.01
A31: TYPE B2
A32: B2 #27 - Corridor 111 / Men's Restroom 113 + Storage 117 + Wellness 115 (lleva tambien el tag #29, mismo wall). Stud 6" 600S137-33 MST @ 16" O.C.; bracing 1-1/2" C.R. channel @ 48" O.C. Men's Restroom 113: 1 layer(s) 5/8 GYP @ 13.052 FT | Storage 117: 1 layer(s) 5/8 GYP @ 13.052 FT | Wellness 115: 1 layer(s) 5/8 GYP @ 13.052 FT | Corridor 111: 1 layer(s) 5/8 GYP @ 13.052 FT (1 instance) | B32: 27 | C32: 15.787 | D32: 13.052 | E32: 2 | F32: 6" | G32: 24 | H32: =IF($F32="6""",$AL32,0) -> 313.25 | I32: =IF($F32="3-5/8""",$AL32,0) -> 0 | J32: =IF($F32="1-5/8""",$AL32,0) -> 0 | K32: =SUMIFS('Board by Face'!$I$5:$I$115,'Board by Face'!$A$5:$A$115,$B32) -> 272.1108 | L32: 10.9 | N32: 1.09 | Q32: 15.79 | R32: 15.79 | S32: 47.36 | U32: 6 | AE32: 3 | AF32: 63.15 | AG32: 10 | AI32: door 113 3.33 x 7.00 + door 117 3.33 x 7.00 + door 115 3.33 x 7.00 | AJ32: CLOSED | AK32: seal 7730432fa7356abd | AL32: 313.25 | AP32: A02.01 → B/A08.01 → S2.20 → 1/A12.01 → 3/A12.01 → A09.01 → 9/A00.41 → 10/A12.02 → 11/A12.02 → 1/S5.20 → 4/S5.20 → 6/S5.20 → 7/S5.20 → 9/S5.20 → A00.30 → A09.27 → A09.33 → E02.01 → M01.01 → P01.01 → P01.02
A33: B2 #28 - Break Room 118 / Cash Window 116 + Work Room 119 (lleva tambien el tag #30, mismo wall). Stud 6" 600S137-33 MST @ 16" O.C.; bracing 1-1/2" C.R. channel @ 48" O.C. Break Room 118: 1 layer(s) 5/8 GYP @ 13.052 FT | Cash Window 116: 1 layer(s) 5/8 GYP @ 13.052 FT | Work Room 119: 1 layer(s) 5/8 GYP @ 13.052 FT (1 instance) | B33: 28 | C33: 11.74 | D33: 13.052 | E33: 1.97 | F33: 6" | G33: 13 | H33: =IF($F33="6""",$AL33,0) -> 169.68 | I33: =IF($F33="3-5/8""",$AL33,0) -> 0 | J33: =IF($F33="1-5/8""",$AL33,0) -> 0 | K33: =SUMIFS('Board by Face'!$I$5:$I$115,'Board by Face'!$A$5:$A$115,$B33) -> 301.1488 | Q33: 11.74 | R33: 11.74 | S33: 35.22 | U33: 24.9 | AF33: 46.96 | AG33: 3.33 | AI33: none | AJ33: CLOSED | AK33: seal 038efd60d5bbdd8f | AL33: 169.68 | AP33: A02.01 → S2.20 → 1/A12.01 → 3/A12.01 → A09.01 → 7/A12.04 → 10/A12.04 → 11/A12.04 → 9/A12.05 → 1/S5.20 → 7/S5.20 → 9/S5.20 → A00.30 → A09.27 → A09.33 → A12.06 → E02.01 → M01.01 → P01.01 → P01.02
A34: B2 #25 - ATM Room 102 / Central Zone 103 (wall de la door 102). Stud 6" 600S137-33 MST @ 16" O.C.; bracing 1-1/2" C.R. channel @ 48" O.C. ATM Room 102: 1 layer(s) 5/8 GYP @ 15.375 FT | Central Zone 103: 1 layer(s) 5/8 GYP @ 15.375 FT (1 instance) | B34: 25 | C34: 5.667 | D34: 15.375 | E34: 2 | F34: 6" | G34: 9 | H34: =IF($F34="6""",$AL34,0) -> 138.38 | I34: =IF($F34="3-5/8""",$AL34,0) -> 0 | J34: =IF($F34="1-5/8""",$AL34,0) -> 0 | K34: =SUMIFS('Board by Face'!$I$5:$I$115,'Board by Face'!$A$5:$A$115,$B34) -> 112.94025 | Q34: 5.67 | R34: 5.67 | S34: 17 | AF34: 22.67 | AG34: 3.83 | AI34: door 102 3.83 x 8.00 | AJ34: CLOSED | AK34: seal dc201c1d1b0c9138 | AL34: 138.38 | AP34: A02.01 → S2.20 → 1/A12.01 → 3/A12.01 → A09.01 → 10/A12.02 → 11/A12.02 → 1/S5.20 → 7/S5.20 → 9/S5.20 → A00.30 → A09.27 → A09.33 → E02.01 → M01.01 → P01.01 → P01.02
A35: B2 #26 - Women's Restroom 114 / Corridor 111 (jamb sur de la door 114). Stud 6" 600S137-33 MST @ 16" O.C.; bracing 1-1/2" C.R. channel @ 48" O.C. Women's Restroom 114: 1 layer(s) 5/8 GYP @ 13.052 FT | Corridor 111: 1 layer(s) 5/8 GYP @ 13.052 FT (1 instance) | B35: 26 | C35: 1.82 | D35: 13.052 | E35: 2 | F35: 6" | G35: 6 | H35: =IF($F35="6""",$AL35,0) -> 78.31 | I35: =IF($F35="3-5/8""",$AL35,0) -> 0 | J35: =IF($F35="1-5/8""",$AL35,0) -> 0 | K35: =SUMIFS('Board by Face'!$I$5:$I$115,'Board by Face'!$A$5:$A$115,$B35) -> 47.50928 | L35: 9.1 | N35: 0.91 | Q35: 1.82 | R35: 1.82 | S35: 5.46 | U35: 2 | AF35: 7.28 | AG35: 3.33 | AI35: none | AJ35: CLOSED | AK35: seal 87cfa9ebe94dc6bf | AL35: 78.31 | AP35: A02.01 → 2/A08.01 → B/A08.01 → S2.20 → 1/A12.01 → 3/A12.01 → 1/S5.20 → 4/S5.20 → 7/S5.20 → 9/S5.20 → A09.01 → A00.30 → A09.27 → A09.33
A36: TYPE B2K
A37: B2K #31 - Office 4 CB 108 (customer side) / Cash Window 116 (teller side). Stud 6" 600S137-68 MST @ 24" O.C.; bracing 1-1/2" C.R. channel @ 48" O.C. Office 4 CB 108: 1 layer(s) 5/8 GYP @ 15.375 FT | Cash Window 116: 1 layer(s) 5/8 GYP @ 15.375 FT (1 instance) | B37: 31 | C37: 1.26 | D37: 15.375 | E37: 2 | F37: 6" | G37: 2 | H37: =IF($F37="6""",$AL37,0) -> 30.75 | I37: =IF($F37="3-5/8""",$AL37,0) -> 0 | J37: =IF($F37="1-5/8""",$AL37,0) -> 0 | K37: =SUMIFS('Board by Face'!$I$5:$I$115,'Board by Face'!$A$5:$A$115,$B37) -> 38.745 | Q37: 1.26 | R37: 1.26 | S37: 3.78 | Y37: 10.08 | Z37: 9.29 | AC37: 1.26 | AF37: 5.04 | AI37: none | AJ37: CLOSED | AK37: seal f0416b251e71edd3 | AL37: 30.75 | AP37: A02.01 → S2.20 → 4/A12.01 → 1/S5.20 → 4/S5.20 → 5/S5.20 → 7/S5.20 → A09.01 → A00.30 → A09.27 → A09.33 → E02.01 → M01.01 → P01.01 → P01.02
A38: TYPE BULKHEAD-G
A39: BULKHEAD-G #54 - Over the 4 office fronts at Offices 105, 106, 107 and 108 (alineacion x 1622.04/1631.28). Stud 1-5/8" 162S-family MST @ 16" O.C. DOUBLE ROW (2 rows of stud); bracing 1-1/2" C.R. channel @ 48" O.C. Lado oficina (105-108): 2 layer(s) 5/8 GYP x2 layers @ 7.333 FT | Central Zone 103: 2 layer(s) 5/8 GYP x2 layers @ 7.333 FT (1 instance) | B39: 54 | C39: 30 | D39: 7.333 | E39: 4 | F39: 1-5/8" | G39: 64 | H39: =IF($F39="6""",$AL39,0) -> 0 | I39: =IF($F39="3-5/8""",$AL39,0) -> 0 | J39: =IF($F39="1-5/8""",$AL39,0) -> 469.31 | K39: =SUMIFS('Board by Face'!$I$5:$I$115,'Board by Face'!$A$5:$A$115,$B39) -> 879.96 | Q39: 60 | R39: 60 | S39: 60 | U39: 30 | AC39: 120 | AF39: 120 | AG39: 30 | AI39: none | AJ39: CLOSED | AK39: seal 778c08f5074a3f2b | AL39: 469.31 | AP39: A02.01 → S2.20 → 7/A11.01 → 9/A12.01 → 1/S5.20 → 7/S5.20 → A09.01 → A00.01 → A09.27 → A09.33
A40: BULKHEAD-G #55 - Over the 2 office fronts at Offices 109 and 110 (alineacion x 1121.16/1133.88). Stud 1-5/8" 162S-family MST @ 16" O.C. DOUBLE ROW (2 rows of stud); bracing 1-1/2" C.R. channel @ 48" O.C. Lado oficina (109-110): 2 layer(s) 5/8 GYP x2 layers @ 7.333 FT | Area abierta al este (Waiting 104): 2 layer(s) 5/8 GYP x2 layers @ 7.333 FT (1 instance) | B40: 55 | C40: 15 | D40: 7.333 | E40: 4 | F40: 1-5/8" | G40: 32 | H40: =IF($F40="6""",$AL40,0) -> 0 | I40: =IF($F40="3-5/8""",$AL40,0) -> 0 | J40: =IF($F40="1-5/8""",$AL40,0) -> 234.66 | K40: =SUMIFS('Board by Face'!$I$5:$I$115,'Board by Face'!$A$5:$A$115,$B40) -> 439.98 | Q40: 30 | R40: 30 | S40: 30 | U40: 15 | AC40: 60 | AF40: 60 | AG40: 15 | AI40: none | AJ40: CLOSED | AK40: seal c904037bf9ccbc5c | AL40: 234.66 | AP40: A02.01 → S2.20 → 7/A11.01 → 9/A12.01 → 1/S5.20 → 7/S5.20 → A09.01 → A00.01 → A09.27 → A09.33
A41: TYPE C1
...

Sheet Board by Face
A1: BOARD BY FACE - one row per face, because the two faces of a wall rarely share a height
A2: Board (SF) = Length x Height x Layers - Openings deducted. Every row reproduces the sealed closure for that face; the closure's own wording is in SOURCE.
A4: Wall # | B4: Type | C4: Face (room) | D4: Board type | E4: Length (LF) | F4: Height (FT) | G4: Layers | H4: Openings deducted (SF) | I4: Board (SF) | J4: SOURCE - closure wording
A5: 8 | B5: A1 | C5: Corridor 111 | D5: 5/8 GYP | E5: 17.06 | F5: 9 | G5: 1 | H5: 0 | I5: =E5*F5*G5-H5 -> 153.54 | J5: face oeste completa, Corridor 111: 17.06 x 9.00 = 153.54 SF. La door 118B NO se deduce porque su opening cae FUERA de este tramo (entre y=1326.36 y y=1386.36, en el quiebre contra el wall A5 #16); solo se carga aqui su header y sus jamb studs. Height: A04.01 da el tag ACT-4 con dimension impresa 8'-6" en CORRIDOR 111 y 3/A12.01 pone el edge of board 6" por encima del scheduled ceiling = 9.00 ft. Una layer de 5/8" gypsum board por face, fila A1 del schedule de 3/A12.01.
A6: 8 | B6: A1 | C6: Break Room 118 | D6: 5/8 GYP | E6: 2.91 | F6: 9 | G6: 1 | H6: 0 | I6: =E6*F6*G6-H6 -> 26.19 | J6: face este, zona Break Room 118: 2.91 x 9.00 = 26.22 SF. CORREGIDO 5-oct-2026: la face este se mide FACE TO FACE, no de eje a eje. El board de esta face arranca en el extremo norte del wall (y=1386.36) y MUERE en la face norte del primer wall tipo B (y=1438.80): 52.44 pt / 18 = 2.913 ft. Medir hasta el EJE del wall B (y=1442.46) metia 0.204 ft de board que no existe, porque ahi esta el nucleo del wall B; y ademas el cierre de B #18 YA arranca en x=1241.76, la face este de este wall, asi que contar hasta el eje duplicaba. Cielo ACT-5 con dimension impresa 8'-6" en A04.01 + los 6" de 3/A12.01 = 9.00 ft
A7: 8 | B7: A1 | C7: Electrical 120 | D7: 5/8 GYP | E7: 5.83 | F7: 12.82 | G7: 1 | H7: 0 | I7: =E7*F7*G7-H7 -> 74.7406 | J7: face este, zona Electrical 120: 5.83 x 12.82 = 74.78 SF. CORREGIDO 5-oct-2026: face to face entre los dos walls tipo B, y=1446.12 a y=1551.12 = 105.00 pt / 18 = 5.833 ft, que es EXACTAMENTE la dimension impresa 5'-10" de A02.01 (cadena en x=1277.76, ticks localizados descontando el sobretiro de punta de flecha de 6.72 pt, simetrico en los dos extremos). A04.01 le pone a ELECTRICAL 120 los key notes 1 y 10; el 1 es textual 'OPEN TO STRUCTURE ABOVE' y no hay tag ACT ni dimension de cielo: el board sube al DECK. B.O.D. interpolado en el extremo ALTO de la zona (y=1446.12 de A02.01 = y=1429.40 de S2.20) = 13.052 - (200.10/454.6) x 0.521 = 12.82 ft. Una layer de 5/8" gypsum board, fila A1 del schedule de 3/A12.01, que ademas manda el stud a UNDERSIDE OF STRUCTURE con continuous slip track.
A8: 8 | B8: A1 | C8: NER 121 | D8: 5/8 GYP | E8: 7.5 | F8: 12.69 | G8: 1 | H8: 0 | I8: =E8*F8*G8-H8 -> 95.175 | J8: face este, zona NER 121: 7.50 x 12.69 = 95.17 SF. CORREGIDO 5-oct-2026: face to face de la face sur del segundo wall B (y=1558.44) al extremo sur (y=1693.44) = 135.00 pt / 18 = 7.500 ft, que es EXACTAMENTE la dimension impresa 7'-6" de A02.01, misma cadena x=1277.76. A04.01 le pone a NER 121 los mismos key notes 1 y 10: OPEN TO STRUCTURE ABOVE, board al DECK. B.O.D. interpolado en el extremo ALTO de la zona (y=1558.44 de A02.01 = y=1541.72 de S2.20) = 13.052 - (312.42/454.6) x 0.521 = 12.69 ft. Una layer de 5/8" gypsum board, fila A1 del schedule de 3/A12.01.
A9: 1 | B9: A1 | C9: Central Zone 103 | D9: 5/8 GYP | E9: 16.42 | F9: 12 | G9: 1 | H9: 0 | I9: =E9*F9*G9-H9 -> 197.04 | J9: 16.42 LF x 12.00 ft x 1 layer = 197.04 SF = 197.04 SF. 5/8" gypsum board, una layer por face segun la fila A1 de 3/A12.01.
A10: 1 | B10: A1 | C10: Calling Cubes 122 | D10: 5/8 GYP | E10: 16.42 | F10: 9 | G10: 1 | H10: 0 | I10: =E10*F10*G10-H10 -> 147.78 | J10: 16.42 LF x 9.00 ft x 1 layer = 147.78 SF = 147.78 SF. 5/8" gypsum board, una layer por face segun la fila A1 de 3/A12.01.
A11: 5 | B11: A1 | C11: Calling Cubes 122 | D11: 5/8 GYP | E11: 15.23 | F11: 9 | G11: 1 | H11: 0 | I11: =E11*F11*G11-H11 -> 137.07 | J11: 15.23 LF x 9.00 ft x 1 layer = 137.07 SF = 137.07 SF. 5/8" gypsum board, una layer por face segun la fila A1 de 3/A12.01.
A12: 5 | B12: A1 | C12: Break Room 118 | D12: 5/8 GYP | E12: 15.23 | F12: 9 | G12: 1 | H12: 0 | I12: =E12*F12*G12-H12 -> 137.07 | J12: 15.23 LF x 9.00 ft x 1 layer = 137.07 SF = 137.07 SF. 5/8" gypsum board, una layer por face segun la fila A1 de 3/A12.01.
A13: 9 | B13: A1 | C13: Cash Window 116 | D13: 5/8 GYP | E13: 11.67 | F13: 9.5 | G13: 1 | H13: 23.33 | I13: =E13*F13*G13-H13 -> 87.535 | J13: 11.67 LF x 9.50 ft x 1 layer = 110.84 SF; menos la abertura 119 de 3.333 x 7.00 = 23.33 SF = 87.51 SF. 5/8" gypsum board, una layer por face segun la fila A1 de 3/A12.01.
A14: 9 | B14: A1 | C14: Work Room 119 | D14: 5/8 GYP | E14: 11.67 | F14: 9 | G14: 1 | H14: 23.33 | I14: =E14*F14*G14-H14 -> 81.7 | J14: 11.67 LF x 9.00 ft x 1 layer = 105.00 SF; menos la abertura 119 de 3.333 x 7.00 = 23.33 SF = 81.67 SF. 5/8" gypsum board, una layer por face segun la fila A1 de 3/A12.01.
A15: 6 | B15: A1 | C15: Cash Window 116 | D15: 5/8 GYP | E15: 5.5 | F15: 9.5 | G15: 1 | H15: 26.66 | I15: =E15*F15*G15-H15 -> 25.59 | J15: 5.50 LF x 9.50 ft x 1 layer = 52.25 SF; menos la abertura 118A de 3.333 x 8.00 = 26.66 SF = 25.59 SF. 5/8" gypsum board, una layer por face segun la fila A1 de 3/A12.01.
A16: 6 | B16: A1 | C16: Break Room 118 | D16: 5/8 GYP | E16: 5.5 | F16: 9 | G16: 1 | H16: 26.66 | I16: =E16*F16*G16-H16 -> 22.84 | J16: 5.50 LF x 9.00 ft x 1 layer = 49.50 SF; menos la abertura 118A de 3.333 x 8.00 = 26.66 SF = 22.84 SF. 5/8" gypsum board, una layer por face segun la fila A1 de 3/A12.01.
... A115: 53 | B115: G1 | C115: Area abierta al este del office front (Waiting 104) | D115: 5/8 GYP x2 layers | E115: 2.67 | F115: 15.375 | G115: 2 | H115: 0 | I115: =E115*F115*G115-H115 -> 82.1025 | J115: 2.670 LF x 15.375 ft de alto (a underside of structure, 5/A12.01) x 2 layers de 5/8" por face
C116: TOTAL BOARD (SF) | I116: =SUM(I5:I115) -> 15809.1

Sheet Ceilings & Soffits
A1: GYPSUM CEILINGS, SOFFITS AND DRIVE-UP CANOPY - separate tables, never mixed with partitions
A2: A soffit is BUILT: its labor and its material do not look like a flat ceiling's. ACT and open-to-deck areas are excluded and named on Clarifications.
A4: Group | B4: ID | C4: Element | D4: Height A.F.F. (FT) | E4: Area (SF) | F4: Board (SF) | G4: Furring Channel (LF) | H4: Carrying Channel (LF) | I4: Hanger Wire (LF) | J4: 3-5/8" Stud (LF) | K4: 3-5/8" Stud (pcs) | L4: Track (LF) | M4: Bracing (LF) | N4: Sheathing FRT Ply (SF) | O4: Corner Bead / Ceiling Trim (LF) | P4: Blocking (LF) | Q4: Access Panel (pcs) | R4: Status | S4: Seal | T4: Detail sequence (RCP → section → detail → schedule)
A5: CEILING GWB | B5: CIELO-70 | C5: VESTIBULE 100 | E5: 131.3 | F5: 131.3 | G5: 98.48 | H5: 32.83 | I5: 48.38 | Q5: 1 | R5: CLOSED | S5: 5bd1ec5d0fcc167b | T5: A04.01 → A02.01 → S2.20 → A12.01 → 3/A09.33 → 7/A09.33 → 10/A09.33
A6: CEILING GWB | B6: CIELO-71 | C6: 24 HR VESTIBULE 101 | E6: 163.92 | F6: 163.92 | G6: 122.94 | H6: 40.98 | I6: 59.12 | R6: CLOSED | S6: 0d32abc5f7c5bddf | T6: A04.01 → S2.20 → A12.01 → 3/A09.33 → 7/A09.33 → 10/A09.33
A7: CEILING GWB | B7: CIELO-72 | C7: WAITING 104 | E7: 510.8 | F7: 510.8 | G7: 383.1 | H7: 127.7 | I7: 140 | R7: CLOSED | S7: 11d7860858a6b528 | T7: A04.01 → S2.20 → A12.01 → 3/A09.33 → 7/A09.33 → 10/A09.33
A8: CEILING GWB | B8: CIELO-73 | C8: WOMEN'S RESTROOM 114 | E8: 76.75 | F8: 76.75 | G8: 57.56 | H8: 19.19 | I8: 34.38 | R8: CLOSED | S8: ef1501f9315bda5a | T8: A04.01 → A02.01 → S2.20 → A12.01 → 3/A09.33 → 7/A09.33 → 10/A09.33
A9: CEILING GWB | B9: CIELO-74 | C9: MEN'S RESTROOM 113 | E9: 76.17 | F9: 76.17 | G9: 57.13 | H9: 19.04 | I9: 34.38 | R9: CLOSED | S9: c795cff7ebb6a001 | T9: A04.01 → S2.20 → A12.01 → 3/A09.33 → 7/A09.33 → 10/A09.33
A10: SOFFIT | B10: SOFFIT-80 | C10: SOFFIT-80 | E10: 41 | F10: 41 | K10: 26 | L10: 61.7 | O10: 42.86 | P10: 12.01 | R10: CLOSED | S10: 190433897dc8f674 | T10: A04.01 → 9/A12.01 → 10/A09.33
A11: CANOPY | B11: CANOPY-81 | C11: CANOPY-81 | E11: 561.75 | J11: 427.25 | L11: 99.92 | M11: 131.48 | N11: 561.75 | R11: CLOSED | S11: fef35eab36b7ebbd | T11: A04.01 → A02.01 → D/A09.22 → F/A09.22 → A09.01 → A09.02 → A09.21 → 3/A09.26 → 7/A09.26 → 15/A09.27 → 16/A09.27 → 10/A09.33 → 7/S5.20
A12: CANOPY | B12: CANOPY-82 | C12: CANOPY-82 | E12: 474.22 | J12: 356.66 | L12: 87.17 | M12: 113.02 | N12: 474.22 | R12: CLOSED | S12: 37191aedb28a90bb | T12: A04.01 → A02.01 → D/A09.22 → F/A09.22 → A09.01 → A09.02 → A09.21 → 3/A09.26 → 7/A09.26 → 15/A09.27 → 16/A09.27 → 10/A09.33 → 7/S5.20
A13: CANOPY | B13: CANOPY-83 | C13: CANOPY-83 | E13: 230.61 | J13: 176.29 | L13: 123.12 | M13: 57.56 | N13: 230.61 | R13: CLOSED | S13: ecd9ed69f3bcb5e6 | T13: A04.01 → A02.01 → D/A09.22 → F/A09.22 → A09.01 → A09.02 → A09.21 → 3/A09.26 → 7/A09.26 → 15/A09.27 → 16/A09.27 → 10/A09.33 → 7/S5.20
A14: CANOPY | B14: CANOPY-84 | C14: CANOPY-84 | E14: 118.52 | J14: 91.27 | L14: 101.02 | N14: 118.52 | R14: CLOSED | S14: 82e1ba339408e9f8 | T14: A04.01 → A02.01 → D/A09.22 → F/A09.22 → A09.01 → A09.02 → A09.21 → 3/A09.26 → 7/A09.26 → 15/A09.27 → 16/A09.27 → 10/A09.33 → 7/S5.20
A15: CANOPY | B15: CANOPY-85 | C15: CANOPY-85 | E15: 383.28 | J15: 288.92 | L15: 411.24 | N15: 383.28 | R15: CLOSED | S15: 6337f0fad40bbc4c | T15: A04.01 → A02.01 → 1/A09.01 → 2/A09.02 → D/A09.22 → F/A09.22 → A09.21 → 3/A09.26 → 7/A09.26 → 15/A09.27 → 16/A09.27 → 7/S5.20
C16: TOTAL | D16: =SUM(D5:D15) -> 0 | E16: =SUM(E5:E15) -> 2768.32 | F16: =SUM(F5:F15) -> 999.94 | G16: =SUM(G5:G15) -> 719.21 | H16: =SUM(H5:H15) -> 239.74 | I16: =SUM(I5:I15) -> 316.26 | J16: =SUM(J5:J15) -> 1340.39 | K16: =SUM(K5:K15) -> 26 | ... Q16: =SUM(Q5:Q15) -> 1

Sheet Other Scope
A1: SCOPE THAT IS NOT A PARTITION - MEP penetrations, recessed fixture openings, misc
A2: Ground-up job: there is no Demolition Plan, so an MEP penetration is a FRAMED OPENING, not a patch. Every penetration was measured on its own - the 1/4-sheet threshold is never cumulative.
A4: Group | B4: ID | C4: Description | D4: Line item | E4: Qty | F4: Unit | G4: Seal
A5: MEP PENETRATIONS | B5: MEP | C5: MEP | D5: DEDUCCION_BOARD_MEP | E5: 38.36 | F5: SF | G5: 2ee850c5da7659b2
A6: MEP PENETRATIONS | B6: MEP | C6: MEP | D6: FRAMED_OPENING_MEP | E6: 43 | F6: LF | G6: 2ee850c5da7659b2
A7: MEP PENETRATIONS | B7: MEP | C7: MEP | D7: REFUERZO_STUD_MEP | E7: 18 | F7: pcs | G7: 2ee850c5da7659b2
A8: RECESSED FIXTURE OPENINGS | B8: HUECOS | C8: HUECOS | D8: FRAMED_OPENING_DIFUSOR | E8: 10.67 | F8: LF | G8: 7d8caa7409375969
A9: RECESSED FIXTURE OPENINGS | B9: HUECOS | C9: HUECOS | D9: FRAMED_OPENING_RANURA | E9: 112 | F9: LF | G9: 7d8caa7409375969
A10: RECESSED FIXTURE OPENINGS | B10: HUECOS | C10: HUECOS | D10: GYPSUM_EDGE_TRIM | E10: 122.67 | F10: LF | G10: 7d8caa7409375969
A11: RECESSED FIXTURE OPENINGS | B11: HUECOS | C11: HUECOS | D11: RETORNO_BOARD_RANURA | E11: PENDING | F11: LF | G11: no cuantificado - ver Pending Items
A12: MISC SCOPE | B12: LADDER-90 | C12: JANITOR CLOSET 112 (el marcador del key note 9 de A04.01 cae dentro del cuarto, en pt 960, 1541) | D12: BLOCKING_2X_FRT | E12: 6 | F12: LF | G12: 288a5526f7319968
A13: MISC SCOPE | B13: WR-92 | C13: WR-92 | D13: BOARD_REGULAR_A_RESTAR | E13: 100.8 | F13: SF | G13: 289e8bf1446af7d4
A14: MISC SCOPE | B14: WR-92 | C14: WR-92 | D14: BOARD_WR | E14: 100.8 | F14: SF | G14: 289e8bf1446af7d4
A15: MISC SCOPE | B15: PURLIN-97 | C15: Every wall running EAST-WEST that goes up to the deck: 21 walls, 189.08 LF de top track. | D15: PURLIN_1X1X1_16GA | E15: 141.81 | F15: LF | G15: 3c1e4b6e392a0e8b
A16: WET AREAS | B16: HUMEDA-93 | C16: JANITOR CLOSET 112, corner. El marcador del key note 6 del FINISH PLAN cae dentro del cuarto (pt 965.4, 1534.0) y su linea guia apunta al oeste, a pt x=913.7, que es la face interior del wall exterior oeste (x=911.88): el mop sink va en la esquina contra esa face. | D16: PVC INSIDE CORNER TRIM MOLDING | E16: 4 | F16: LF | G16: dbf3f948b58f6fc7
A17: WET AREAS | B17: HUMEDA-93 | C17: JANITOR CLOSET 112, corner. El marcador del key note 6 del FINISH PLAN cae dentro del cuarto (pt 965.4, 1534.0) y su linea guia apunta al oeste, a pt x=913.7, que es la face interior del wall exterior oeste (x=911.88): el mop sink va en la esquina contra esa face. | D17: CLEAR SEALANT | E17: PENDING | F17: LF | G17: no cuantificado - ver Pending Items
A18: WET AREAS | B18: HUMEDA-93 | C18: JANITOR CLOSET 112, corner. El marcador del key note 6 del FINISH PLAN cae dentro del cuarto (pt 965.4, 1534.0) y su linea guia apunta al oeste, a pt x=913.7, que es la face interior del wall exterior oeste (x=911.88): el mop sink va en la esquina contra esa face. | D18: FRP WC-3 | E18: PENDING | F18: SF | G18: no cuantificado - ver Pending Items
A19: WET AREAS | B19: HUMEDA-93 | C19: JANITOR CLOSET 112, corner. El marcador del key note 6 del FINISH PLAN cae dentro del cuarto (pt 965.4, 1534.0) y su linea guia apunta al oeste, a pt x=913.7, que es la face interior del wall exterior oeste (x=911.88): el mop sink va en la esquina contra esa face. | D19: PVC EDGE TRIM MOLDING | E19: PENDING | F19: LF | G19: no cuantificado - ver Pending Items
A20: WET AREAS | B20: HUMEDA-94 | C20: INSIDE face of the west exterior wall (#63) at the restroom runs 113 y 114 -- la wall de los inodoros | D20: BOARD_REGULAR_A_RESTAR | E20: 112.94 | F20: SF | G20: f075a0d59055f329
A21: WET AREAS | B21: HUMEDA-94 | C21: INSIDE face of the west exterior wall (#63) at the restroom runs 113 y 114 -- la wall de los inodoros | D21: BOARD_WR | E21: 112.94 | F21: SF | G21: f075a0d59055f329
A22: MILLWORK BLOCKING | B22: MWBLK-MW11 | C22: CASH WINDOW 116 | D22: BLOCKING | E22: 13.5 | F22: LF | G22: c919275b7d9ef7ac
A23: MILLWORK BLOCKING | B23: MWBLK-MW06A-2 | C23: JANITOR CLOSET 112 (east side) | D23: BLOCKING | E23: 8.22 | F23: LF | G23: 7558a389c353d1a6

Sheet Material Summary
A1: MATERIAL SUMMARY - NET / WASTE / PURCHASE, and purchase converted to real selling units
A2: Waste lives HERE, in its own column, never inside a takeoff quantity. Percentages and sheet/stick sizes come from Inputs - change them there.
A4: Material | B4: Unit | C4: Net | D4: Waste % | E4: Waste | F4: Purchase | G4: Selling unit | H4: Pieces to buy | I4: Where it comes from
A5: METAL FRAMING
A6: 6" metal stud 600S137-33 / -68 (LF of material) | B6: LF | C6: ='Partition Takeoff'!H86 -> 5486.56 | D6: =Inputs!$B$5 -> 0.15 | E6: =C6*D6 -> 822.984 | F6: =C6+E6 -> 6309.544 | G6: ="stick "&TEXT(Inputs!$B$10,"0")&" ft" -> stick 20 ft | H6: =CEILING(F6/Inputs!$B$10,1) -> 316 | I6: Partition Takeoff "6" Metal Stud (LF)". A12.01 PARTITION SCHEDULE gives A5 and B2 a 6" stud with 7-1/4" wall thickness; the exterior walls and B2K are 6" too
A7: 6" parapet infill stud 600S162-54 @ 16" O.C. (LF of material) | B7: LF | C7: =SUMIFS('Partition Takeoff'!$AL$5:$AL$85,'Partition Takeoff'!$F$5:$F$85,"6"" 54mil") -> 973.34 | D7: =Inputs!$B$5 -> 0.15 | E7: =C7*D7 -> 146.001 | F7: =C7+E7 -> 1119.341 | G7: ="stick "&TEXT(Inputs!$B$10,"0")&" ft" -> stick 20 ft | H7: =CEILING(F7/Inputs!$B$10,1) -> 56 | I7: Separate line from the 33 mil stud: 11/S5.10 PARAPET INFILL FRAMING calls the parapet "600S162-54 @ 16" W/ 600T125-54 TOP & BOT." - 54 mil and a 1-5/8" flange, a different product and a different price from the 600S137-33 of the wall below. The wall below stops at the deflection track on the perimeter beam (6/S5.10 and 10/S5.10)
A8: 3-5/8" metal stud 362S137-33 / -68 (LF of material) | B8: LF | C8: ='Partition Takeoff'!I86+'Ceilings & Soffits'!J16 -> 4928.59 | D8: =Inputs!$B$5 -> 0.15 | E8: =C8*D8 -> 739.2885 | F8: =C8+E8 -> 5667.8785 | G8: ="stick "&TEXT(Inputs!$B$10,"0")&" ft" -> stick 20 ft | H8: =CEILING(F8/Inputs!$B$10,1) -> 284 | I8: Partition Takeoff 3-5/8" column + Ceilings & Soffits 3-5/8" column (drive-up canopy)
A9: 1-5/8" metal stud (LF of material) | B9: LF | C9: ='Partition Takeoff'!J86 -> 4547.72 | D9: =Inputs!$B$5 -> 0.15 | E9: =C9*D9 -> 682.158 | F9: =C9+E9 -> 5229.878 | G9: ="stick "&TEXT(Inputs!$B$10,"0")&" ft" -> stick 20 ft | H9: =CEILING(F9/Inputs!$B$10,1) -> 262 | I9: Partition Takeoff "1-5/8" Metal Stud (LF)" - types G, G1 and the office-front bulkhead, double row
A10: Bottom track 6" | B10: LF | C10: =SUMIFS('Partition Takeoff'!$Q$5:$Q$85,'Partition Takeoff'!$F$5:$F$85,"6""") -> 293.04 | D10: =Inputs!$B$5 -> 0.15 | E10: =C10*D10 -> 43.956 | F10: =C10+E10 -> 336.996 | G10: ="run "&TEXT(Inputs!$B$11,"0")&" ft" -> run 10 ft | H10: =CEILING(F10/Inputs!$B$11,1) -> 34 | I10: Track follows the stud of its wall. SUMIFS over the Stud Size column of Partition Takeoff
A11: Bottom track 3-5/8" | B11: LF | C11: =SUMIFS('Partition Takeoff'!$Q$5:$Q$85,'Partition Takeoff'!$F$5:$F$85,"3-5/8""") -> 227.482 | D11: =Inputs!$B$5 -> 0.15 | E11: =C11*D11 -> 34.1223 | F11: =C11+E11 -> 261.6043 | G11: ="run "&TEXT(Inputs!$B$11,"0")&" ft" -> run 10 ft | H11: =CEILING(F11/Inputs!$B$11,1) -> 27 | I11: Partition Takeoff
A12: Parapet bottom track 600T125-54 (PAF to steel beam) | B12: LF | C12: =SUMIFS('Partition Takeoff'!$Q$5:$Q$85,'Partition Takeoff'!$F$5:$F$85,"6"" 54mil") -> 217.64 | D12: =Inputs!$B$5 -> 0.15 | E12: =C12*D12 -> 32.646 | F12: =C12+E12 -> 250.286 | G12: ="run "&TEXT(Inputs!$B$11,"0")&" ft" -> run 10 ft | H12: =CEILING(F12/Inputs!$B$11,1) -> 26 | I12: 11/S5.10: "600T125-54 TOP & BOT." with "PAFs SPACED AT 12" O.C. MAX." into the steel beam - not the Hilti anchor into concrete that the wall below uses
A13: Parapet top track 600T125-54 | B13: LF | C13: =SUMIFS('Partition Takeoff'!$R$5:$R$85,'Partition Takeoff'!$F$5:$F$85,"6"" 54mil") -> 217.64 | D13: =Inputs!$B$5 -> 0.15 | E13: =C13*D13 -> 32.646 | F13: =C13+E13 -> 250.286 | G13: ="run "&TEXT(Inputs!$B$11,"0")&" ft" -> run 10 ft | H13: =CEILING(F13/Inputs!$B$11,1) -> 26 | I13: 11/S5.10: "600T125-54 TOP & BOT.". No deflection track here - the deflection track is the one below, against the beam that moves
A14: Bottom track 1-5/8" | B14: LF | C14: =SUMIFS('Partition Takeoff'!$Q$5:$Q$85,'Partition Takeoff'!$F$5:$F$85,"1-5/8""") -> 285.97 | D14: =Inputs!$B$5 -> 0.15 | E14: =C14*D14 -> 42.8955 | F14: =C14+E14 -> 328.8655 | G14: ="run "&TEXT(Inputs!$B$11,"0")&" ft" -> run 10 ft | H14: =CEILING(F14/Inputs!$B$11,1) -> 33 | I14: Partition Takeoff
A15: Top / deflection track 6" | B15: LF | C15: =SUMIFS('Partition Takeoff'!$R$5:$R$85,'Partition Takeoff'!$F$5:$F$85,"6""") -> 293.04 | D15: =Inputs!$B$5 -> 0.15 | E15: =C15*D15 -> 43.956 | F15: =C15+E15 -> 336.996 | G15: ="run "&TEXT(Inputs!$B$11,"0")&" ft" -> run 10 ft | H15: =CEILING(F15/Inputs!$B$11,1) -> 34 | I15: Separate row from bottom track - never combined. Control: bottom + top = 2 runs per row of stud
A16: Top / deflection track 3-5/8" | B16: LF | C16: =SUMIFS('Partition Takeoff'!$R$5:$R$85,'Partition Takeoff'!$F$5:$F$85,"3-5/8""") -> 227.482 | D16: =Inputs!$B$5 -> 0.15 | E16: =C16*D16 -> 34.1223 | F16: =C16+E16 -> 261.6043 | G16: ="run "&TEXT(Inputs!$B$11,"0")&" ft" -> run 10 ft | H16: =CEILING(F16/Inputs!$B$11,1) -> 27 | I16: Partition Takeoff
A17: Top / deflection track 1-5/8" | B17: LF | C17: =SUMIFS('Partition Takeoff'!$R$5:$R$85,'Partition Takeoff'!$F$5:$F$85,"1-5/8""") -> 285.97 | D17: =Inputs!$B$5 -> 0.15 | E17: =C17*D17 -> 42.8955 | F17: =C17+E17 -> 328.8655 | G17: ="run "&TEXT(Inputs!$B$11,"0")&" ft" -> run 10 ft | H17: =CEILING(F17/Inputs!$B$11,1) -> 33 | I17: Partition Takeoff
A18: Track, ceilings / soffits / canopy | B18: LF | C18: ='Ceilings & Soffits'!L16 -> 884.17 | D18: =Inputs!$B$5 -> 0.15 | E18: =C18*D18 -> 132.6255 | F18: =C18+E18 -> 1016.7955 | G18: ="run "&TEXT(Inputs!$B$11,"0")&" ft" -> run 10 ft | H18: =CEILING(F18/Inputs!$B$11,1) -> 102 | I18: Ceilings & Soffits. On a soffit the track sits at the two ENDS of each stud and on the two side edges
A19: Bracing 1-1/2" C.R. channel @ 48" O.C. | B19: LF | C19: ='Partition Takeoff'!S86+'Ceilings & Soffits'!M16 -> 2557.43 | D19: =Inputs!$B$5 -> 0.15 | E19: =C19*D19 -> 383.6145 | F19: =C19+E19 -> 2941.0445 | G19: ="C.R. channel "&TEXT(Inputs!$B$16,"0")&" ft" -> C.R. channel 16 ft | H19: =CEILING(F19/Inputs!$B$16,1) -> 184 | I19: 7/S5.20 note F: "BRIDGING AND BRACING: 1 1/2" C.R. CHANNEL @ 48" O.C." with CONTINUOUS BRIDGING
A20: Additional head track at openings over 4'-0" wide | B20: LF | C20: ='Partition Takeoff'!AM86 -> 0 | D20: =Inputs!$B$5 -> 0.15 | E20: =C20*D20 -> 0 | F20: =C20+E20 -> 0 | G20: ="run "&TEXT(Inputs!$B$11,"0")&" ft" -> run 10 ft | H20: =CEILING(F20/Inputs!$B$11,1) -> 0 | I20: 2/S5.20 HEAD TRACK @ NON LOAD BRG: "ADD FULL LENGTH ADDL HEAD TRACK @ OPNG >4'-0"". A SECOND head track on every opening wider than 4 ft - the six 8'-0" GL-2 windows on walls 61 and 63. No door reaches 4 ft, so none of them carries it
A21: Header / metal stud box beam | B21: LF | C21: ='Partition Takeoff'!AG86 -> 221.86 | D21: =Inputs!$B$5 -> 0.15 | E21: =C21*D21 -> 33.279 | F21: =C21+E21 -> 255.139 | G21: ="stick "&TEXT(Inputs!$B$10,"0")&" ft" -> stick 20 ft | H21: =CEILING(F21/Inputs!$B$10,1) -> 13 | I21: Each opening with ITS OWN R.O. width + 1.333 ft bearing (8" each side). Includes the ATM metal stud box beam
A22: Sill track | B22: LF | C22: ='Partition Takeoff'!AH86 -> 65.09 | D22: =Inputs!$B$5 -> 0.15 | E22: =C22*D22 -> 9.7635 | F22: =C22+E22 -> 74.8535 | G22: ="run "&TEXT(Inputs!$B$11,"0")&" ft" -> run 10 ft | H22: =CEILING(F22/Inputs!$B$11,1) -> 8 | I22: Only openings WITH a sill: windows (B/GLAZING 6'-6"), the drive-up ATM, and the framed duct opening on wall 9. Doors carry header only
A23: Framed openings - MEP, light slots and diffusers | B23: LF | C23: =SUMIFS('Other Scope'!$E:$E,'Other Scope'!$D:$D,"FRAMED_OPENING_MEP")+SUMIFS('Other Scope'!$E:$E,'Other Scope'!$D:$D,"FRAMED_OPENING_RANURA")+SUMIFS('Other Scope'!$E:$E,'Other Scope'!$D:$D,"FRAMED_OPENING_DIFUSOR") -> 165.67 | D23: =Inputs!$B$5 -> 0.15 | E23: =C23*D23 -> 24.8505 | F23: =C23+E23 -> 190.5205 | G23: ="stick "&TEXT(Inputs!$B$10,"0")&" ft" -> stick 20 ft | H23: =CEILING(F23/Inputs!$B$10,1) -> 10 | I23: Other Scope. Ground-up job, so an MEP penetration is a framed opening, not a patch. Excludes the penetrations already inside walls 43, 46, 47, 48, 49, 50 and 52
A24: Stud reinforcement at MEP penetrations | B24: pcs | C24: =SUMIFS('Other Scope'!$E:$E,'Other Scope'!$D:$D,"REFUERZO_STUD_MEP") -> 18 | F24: =C24 -> 18 | G24: each | H24: =CEILING(F24,1) -> 18 | I24: Other Scope. One per stud the duct crosses. 6/S5.20 WEB PENETRATION limits the web hole and forbids cutting the flanges
A25: 3-5/8" stud, CSR soffit (pieces - length pending) | B25: pcs | C25: ='Ceilings & Soffits'!K16 -> 26 | F25: =C25 -> 26 | G25: each | H25: =CEILING(F25,1) -> 26 | I25: 10/A09.33 CSR soffit: 26 pieces at 16" O.C. BOTH ways. A09.33 labels the soffit framing "3 5/8" METAL STUD FRAMING AND TRACK @ 16" O.C." - size CONFIRMED, individual length PENDING. See Pending Items
A26: Purlin 1x1x1 16 ga, top track to deck | B26: LF | C26: =SUMIFS('Other Scope'!$E:$E,'Other Scope'!$D:$D,"PURLIN_1X1X1_16GA") -> 141.81 | D26: =Inputs!$B$5 -> 0.15 | E26: =C26*D26 -> 21.2715 | F26: =C26+E26 -> 163.0815 | G26: ="run "&TEXT(Inputs!$B$11,"0")&" ft" -> run 10 ft | H26: =CEILING(F26/Inputs!$B$11,1) -> 17 | I26: A09.33, top-track-to-deck detail: "1X1X1 16GA PURLIN, ACROSS MIN. (2) FLUTES" - needed wherever the deck flute runs PARALLEL to the track, because there is no valley to fasten into. 185.61 LF of top track on walls that run east-west and go to deck, at 0.75 LF of purlin per LF of track. The detail itself says VIF FLUTE DIRECTION, so the flute direction is DERIVED from the joist direction on S2.20 and declared on Clarifications. Exterior walls and the inclined wall 40 are not included - see Pending
A27: Furring channel (ceilings) | B27: LF | C27: ='Ceilings & Soffits'!G16 -> 719.21 | D27: =Inputs!$B$5 -> 0.15 | E27: =C27*D27 -> 107.8815 | F27: =C27+E27 -> 827.0915 | G27: ="hat channel "&TEXT(Inputs!$B$17,"0")&" ft" -> hat channel 12 ft | H27: =CEILING(F27/Inputs!$B$17,1) -> 69 | I27: Ceilings & Soffits
A28: Carrying channel (ceilings) | B28: LF | C28: ='Ceilings & Soffits'!H16 -> 239.74 | D28: =Inputs!$B$5 -> 0.15 | E28: =C28*D28 -> 35.961 | F28: =C28+E28 -> 275.701 | G28: ="C.R. channel "&TEXT(Inputs!$B$16,"0")&" ft" -> C.R. channel 16 ft | H28: =CEILING(F28/Inputs!$B$16,1) -> 18 | I28: Ceilings & Soffits
A29: Hanger wire | B29: LF | C29: ='Ceilings & Soffits'!I16 -> 316.26 | D29: =Inputs!$B$5 -> 0.15 | E29: =C29*D29 -> 47.439 | F29: =C29+E29 -> 363.699 | G29: continuous coil | H29: =CEILING(F29,1) -> 364 | I29: Length = B.O. Deck minus that zone's ceiling height. Bought as a continuous coil by gauge, never pre-cut
A30: Extra framing - sistered stud and furring at the ATM recess | B30: LF | C30: ='Partition Takeoff'!AD86 -> 109.87 | D30: =Inputs!$B$5 -> 0.15 | E30: =C30*D30 -> 16.4805 | F30: =C30+E30 -> 126.3505 | G30: ="stick "&TEXT(Inputs!$B$10,"0")&" ft" -> stick 20 ft | H30: =CEILING(F30/Inputs!$B$10,1) -> 7 | I30: 6/A08.11: 2-1/2" stud sistered to the 6" stud, and the furring under the fiber cement panel
A31: BOARD AND SUBSTRATE
A32: 5/8" gypsum board, regular | B32: SF | C32: ='Partition Takeoff'!K86+'Ceilings & Soffits'!F16-SUMIFS('Other Scope'!$E:$E,'Other Scope'!$D:$D,"BOARD_REGULAR_A_RESTAR") -> 16595.3 | D32: =Inputs!$B$6 -> 0.06 | E32: =C32*D32 -> 995.71799 | F32: =C32+E32 -> 17591.018 | G32: =TEXT(Inputs!$B$7,"0")&"x"&TEXT(Inputs!$B$8,"0")&" ft sheet" -> 4x12 ft sheet | H32: =CEILING(F32/Inputs!$B$9,1) -> 367 | I32: Partition Takeoff (fed face by face from Board by Face) + gypsum ceilings and the CSR soffit, MINUS the area that A08.01 sheet note F turns moisture-resistant
A33: 5/8" gypsum board, MOISTURE RESISTANT | B33: SF | C33: =SUMIFS('Other Scope'!$E:$E,'Other Scope'!$D:$D,"BOARD_WR") -> 213.74 | D33: =Inputs!$B$6 -> 0.06 | E33: =C33*D33 -> 12.8244 | F33: =C33+E33 -> 226.5644 | G33: =TEXT(Inputs!$B$7,"0")&"x"&TEXT(Inputs!$B$8,"0")&" ft sheet" -> 4x12 ft sheet | H33: =CEILING(F33/Inputs!$B$9,1) -> 5 | I33: A08.01 sheet note F: "USE MOISTURE RESISTANT GYPSUM BOARD BEHIND TOILET AND LAVATORY". TWO fixtures on TWO different walls: the LAVATORY side is the chase (walls 37 and 39, 100.80 SF) and the TOILET side is the inside face of the west exterior wall in both restrooms (112.94 SF). Reclassification, not new board - the same area comes out of the regular gypsum line
A34: 5/8" EXTERIOR gypsum sheathing (deck to top of parapet) | B34: SF | C34: ='Partition Takeoff'!W86 -> 783.89 | D34: =Inputs!$B$6 -> 0.06 | E34: =C34*D34 -> 47.0334 | F34: =C34+E34 -> 830.9234 | G34: =TEXT(Inputs!$B$7,"0")&"x"&TEXT(Inputs!$B$8,"0")&" ft sheet" -> 4x12 ft sheet | H34: =CEILING(F34/Inputs!$B$9,1) -> 18 | I34: H/A09.23, textual: "5/8" EXTERIOR GYPSUM SHEATHING". It is the INSIDE face of the parapet and it does not exist below the deck - a different material from the interior board, priced on its own line
A35: FRP WC-3 | B35: SF | C35: ='Partition Takeoff'!L86+SUMIFS('Other Scope'!$E:$E,'Other Scope'!$D:$D,"FRP WC-3") -> 132.1 | D35: =Inputs!$B$6 -> 0.06 | E35: =C35*D35 -> 7.926 | F35: =C35+E35 -> 140.026 | G35: =TEXT(Inputs!$B$7,"0")&"x"&TEXT(Inputs!$B$8,"0")&" ft sheet" -> 4x12 ft sheet | H35: =CEILING(F35/Inputs!$B$9,1) -> 3 | I35: Restrooms 113 / 114 up to 4'-6" (5'-0" to top of FRP minus the 6" cove base), plus the mop sink FRP of Janitor Closet 112 - that one is PENDING on width
A36: Cement board (substrate under the FRP cove base band) | B36: SF | C36: ='Partition Takeoff'!N86 -> 14.45 | D36: =Inputs!$B$6 -> 0.06 | E36: =C36*D36 -> 0.867 | F36: =C36+E36 -> 15.317 | G36: =TEXT(Inputs!$B$7,"0")&"x"&TEXT(Inputs!$B$8,"0")&" ft sheet" -> 4x12 ft sheet | H36: =CEILING(F36/Inputs!$B$9,1) -> 1 | I36: Carried under the 6" cove base band only - see Clarifications for exactly where
A37: Exterior sheathing 5/8" FRT plywood bonded to 2-1/2" polyiso | B37: SF | C37: ='Partition Takeoff'!X86 -> 3698.28 | D37: =Inputs!$B$6 -> 0.06 | E37: =C37*D37 -> 221.8968 | F37: =C37+E37 -> 3920.1768 | G37: =TEXT(Inputs!$B$7,"0")&"x"&TEXT(Inputs!$B$8,"0")&" ft sheet" -> 4x12 ft sheet | H37: =CEILING(F37/Inputs!$B$9,1) -> 82 | I37: H/A09.23, textual: "SHEATHING/INSULATION SYSTEM: 5/8" FRT PLYWOOD BONDED TO 2 1/2" POLYISO INSULATION"
A38: 5/8" glass mat sheathing (exterior face of the stud) | B38: SF | C38: ='Partition Takeoff'!AN86 -> 2939.76 | D38: =Inputs!$B$6 -> 0.06 | E38: =C38*D38 -> 176.3856 | F38: =C38+E38 -> 3116.1456 | G38: =TEXT(Inputs!$B$7,"0")&"x"&TEXT(Inputs!$B$8,"0")&" ft sheet" -> 4x12 ft sheet | H38: =CEILING(F38/Inputs!$B$9,1) -> 65 | I38: Found 3-Oct-2026 by following the detail chain. The 1"=1'-0" wall sections do not label this layer, but every detail they point to does: 5/A09.26 SECTION DETAIL @ ACM BASE and 9/A09.27 SECTION DETAIL @ METAL PANEL BASE label "5/8" GLASS MAT SHEATHING" with the arrow on the OUTSIDE face of the 6" metal stud, and 7/A09.26 repeats it at mid height ("SPRAY FOAM INSULATION ON 5/8" GLASS-MAT SHEATHING"). All 95 sheets were swept for "GLASS MAT" / "GLASS-MAT": it appears only on A09.26 and A09.27 and never above the deck, so it is carried slab to B.O.D. and does not continue up the parapet
