Workbook

Sheet Inputs
A1: Bank of America CO1-111 - NWC Hwy 7 and Palisade Pkwy, Broomfield CO | METAL FRAMING & DRYWALL TAKEOFF
A2: Bid set: 2025.08.26_CO1-111_Broomfield_PERMIT SET_BID SET.pdf · 2026-10-20 · Edit ONLY the yellow cells.
A4: PARAMETER | B4: VALUE | C4: NOTE / SOURCE
A5: Waste - ALL METAL, any type | B5: 0.15 | C5: Estimator standing rule: 15% on everything that is metal.
A6: Waste - EVERYTHING THAT IS NOT METAL | B6: 0.06 | C6: Estimator standing rule: same figure as board.
A7: Board sheet width (ft) | B7: 4 | C7: Sheet size is a parameter; buy the size that wastes least.
A8: Board sheet length (ft) | B8: 12 | C8: Change it and every sheet count re-rounds.
A9: SF per board sheet | B9: =B7*B8 -> 48 | C9: Width x length.
A10: Stud stock length (ft) | B10: 20 | C10: Stud, header, framed opening and stud blocking: sticks.
A11: Track stock length (ft) | B11: 10 | C11: Track, sill track and purlin: runs.
A12: Floor plan scale (pt/ft) | B12: 18 | C12: Project value (canon constants).
A13: B.O. Deck (ft) | B13: n/a | C13: Project value (canon constants).
A14: T.O. Parapet (ft) | B14: n/a | C14: Project value (canon constants).
A15: Sealant coverage (LF per tube) | B15: 25 | C15: Sealant yield per tube - set your supplier's figure.
A16: C.R. channel stock length (ft) | B16: 16 | C16: 1-1/2" cold-rolled channel (bracing, carrying channel).
A17: Hat / furring channel stock (ft) | B17: 12 | C17: 7/8" hat furring channel.
A18: Trim stick length (ft) | B18: 10 | C18: Corner bead, casing bead, shadow molding, PVC trim.
A19: Hanger wire purchase | B19: continuous coil (LF) | C19: Bought by LF from a continuous coil; the hanger count goes on its own PCS row.
A20: Drywall screws per SF of board | B20: 1.2 | C20: YIELD (GA-216 field / perimeter spacing).
A21: Framing screws per stud piece | B21: 4 | C21: YIELD: 2 per stud-to-track connection, each end.
A22: Power-driven pin spacing (ft) | B22: 1 | C22: YIELD: bottom track on slab, interior walls.
A23: Joint compound (lb per SF) | B23: 0.072 | C23: YIELD: 72 lb per 1,000 SF, level 4 (estimator criterion).
A24: Joint tape (LF per SF) | B24: 0.37 | C24: YIELD: 370 LF per 1,000 SF.
A25: Expansion anchor spacing (ft) | B25: 0.6667 | C25: YIELD: exterior bottom track on slab.

Sheet Partition Takeoff
A1: ORGANIZED PARTITION TAKEOFF - Bank of America CO1-111 - NWC Hwy 7 and Palisade Pkwy, Broomfield CO
A2: Grouped by partition type. Every row cites its DETAIL/SHEET and its status.
A4: Partition / Scope | B4: Wall # | C4: Length (LF) | D4: Height (FT) | E4: Layers | F4: Stud Size | G4: Stud O.C. (in) | H4: Board (SF) | I4: Location | J4: Source (DETAIL/SHEET) | K4: Status
A5: TYPE EXT-6CFMF
A6: EXT-6CFMF #AE-01 - exterior north wall at Office 105 (grid F, 7-8); exterior / Office 105 | B6: AE-01 | C6: 12.64 | D6: 14.358 | E6: 1 | F6: 6" | G6: 16 | H6: 194.34 | I6: exterior north wall at Office 105 (grid F, 7-8); exterior / Office 105 | J6: F/A09.22 | K6: [DERIVED]
A7: EXT-6CFMF #AE-02+AE-03 - exterior east wall grid 8, F to B (offices 105-108, 116); exterior / interior + exterior east wall grid 8, B to A (Break Room 118, Work Room 119); exterior / interior | B7: AE-02+AE-03 | C7: 77.187 | D7: 13.539 | E7: 1 | F7: 6" | G7: 16 | H7: 1062.74 | I7: exterior east wall grid 8, F to B (offices 105-108, 116); exterior / interior + exterior east wall grid 8, B to A (Break Room 118, Work Room 119); exterior / interior | J7: F/A09.22 | K7: [DERIVED]
A8: EXT-6CFMF #AE-04+AE-04B - exterior south wall grid A, grids 3-6 (Wellness 115 ... Break Room 118), door 123 inside the run + exterior south wall grid A, grids 6-8 (Break Room 118 / Work Room 119) | B8: AE-04+AE-04B | C8: 52.62 | D8: 11.168 | E8: 1 | F8: 6" | G8: 16 | H8: 632.5 | I8: exterior south wall grid A, grids 3-6 (Wellness 115 ... Break Room 118), door 123 inside the run + exterior south wall grid A, grids 6-8 (Break Room 118 / Work Room 119) | J8: F/A09.22 | K8: [DERIVED]
A9: EXT-6CFMF #AE-05+AE-06 - exterior west wall grid 3, D to B (offices 109, 110); exterior (drive-up canopy) / interior + exterior west wall grid 3, B to A (restrooms 113-114, Janitor 112, Wellness 115) | B9: AE-05+AE-06 | C9: 47.873 | D9: 13.083 | E9: 1 | F9: 6" | G9: 16 | H9: 646.11 | I9: exterior west wall grid 3, D to B (offices 109, 110); exterior (drive-up canopy) / interior + exterior west wall grid 3, B to A (restrooms 113-114, Janitor 112, Wellness 115) | J9: F/A09.22 | K9: [DERIVED]
A10: EXT-6CFMF #AE-07 - exterior jog at grid D between grids 2 and 3 (ATM Room 102 / drive-up canopy) | B10: AE-07 | C10: 3.027 | D10: 14.358 | E10: 1 | F10: 6" | G10: 16 | H10: 46.54 | I10: exterior jog at grid D between grids 2 and 3 (ATM Room 102 / drive-up canopy) | J10: F/A09.22 | K10: [DERIVED]
A11: EXT-6CFMF #AE-08 - exterior west wall grid 2 (24 HR Vestibule 101, ATM Room 102) below the vestibule storefront | B11: AE-08 | C11: 21.72 | D11: 14.358 | E11: 1 | F11: 6" | G11: 16 | H11: 326.61 | I11: exterior west wall grid 2 (24 HR Vestibule 101, ATM Room 102) below the vestibule storefront | J11: F/A09.22 | K11: [DERIVED]
A12: TYPE EXT-PARAPET
A13: EXT-PARAPET #AE-21 - parapet on grid 2 | B13: AE-21 | C13: 29.033 | D13: 4.292 | E13: 0 | F13: 6" parapet (600S162-54) | G13: 16 | H13: 0 | I13: parapet on grid 2 | J13: 4/A09.26 | K13: [DERIVED]
A14: EXT-PARAPET #AE-22 - parapet on grid G | B14: AE-22 | C14: 16.393 | D14: 4.292 | E14: 0 | F14: 6" parapet (600S162-54) | G14: 16 | H14: 0 | I14: parapet on grid G | J14: 4/A09.26 | K14: [DERIVED]
A15: EXT-PARAPET #AE-23 - parapet on grid 4 | B15: AE-23 | C15: 3.947 | D15: 4.292 | E15: 0 | F15: 6" parapet (600S162-54) | G15: 16 | H15: 0 | I15: parapet on grid 4 | J15: 4/A09.26 | K15: [DERIVED]
A16: EXT-PARAPET #AE-24 - parapet on grid F | B16: AE-24 | C16: 39.86 | D16: 2.042 | E16: 0 | F16: 6" parapet (600S162-54) | G16: 16 | H16: 0 | I16: parapet on grid F | J16: 4/A09.26 | K16: [DERIVED]
A17: EXT-PARAPET #AE-25+AE-26 - parapet on grid 8 | B17: AE-25+AE-26 | C17: 75.96 | D17: 2.8 | E17: 0 | F17: 6" parapet (600S162-54) | G17: 16 | H17: 0 | I17: parapet on grid 8 | J17: 4/A09.26 | K17: [DERIVED]
A18: EXT-PARAPET #AE-27 - parapet on grid A | B18: AE-27 | C18: 52.347 | D18: 4.886 | E18: 0 | F18: 6" parapet (600S162-54) | G18: 16 | H18: 0 | I18: parapet on grid A | J18: 4/A09.26 | K18: [DERIVED]
A19: EXT-PARAPET #AE-28+AE-29 - parapet on grid 3 | B19: AE-28+AE-29 | C19: 47.927 | D19: 3.244 | E19: 0 | F19: 6" parapet (600S162-54) | G19: 16 | H19: 0 | I19: parapet on grid 3 | J19: 4/A09.26 | K19: [DERIVED]
A20: EXT-PARAPET #AE-30 - parapet on grid D | B20: AE-30 | C20: 3.907 | D20: 4.292 | E20: 0 | F20: 6" parapet (600S162-54) | G20: 16 | H20: 0 | I20: parapet on grid D | J20: 4/A09.26 | K20: [DERIVED]
A21: TYPE CANOPY-COL
A22: CANOPY-COL #AE-51 - drive-up canopy column 1 (grid 1) | B22: AE-51 | C22: 5.667 | D22: 10.5 | E22: 0 | F22: 3-5/8" | G22: 16 | H22: 0 | I22: drive-up canopy column 1 (grid 1) | J22: 5/A09.25 | K22: [DERIVED]
A23: CANOPY-COL #AE-52 - drive-up canopy column 2 (grid 1) | B23: AE-52 | C23: 5.667 | D23: 10.5 | E23: 0 | F23: 3-5/8" | G23: 16 | H23: 0 | I23: drive-up canopy column 2 (grid 1) | J23: 5/A09.25 | K23: [DERIVED]
A24: CANOPY-COL #AE-53 - drive-up canopy column 3 (grid 1) | B24: AE-53 | C24: 5.667 | D24: 10.5 | E24: 0 | F24: 3-5/8" | G24: 16 | H24: 0 | I24: drive-up canopy column 3 (grid 1) | J24: 5/A09.25 | K24: [DERIVED]
A25: CANOPY-COL #AE-54 - drive-up canopy column 4 (grid 1) | B25: AE-54 | C25: 5.667 | D25: 10.5 | E25: 0 | F25: 3-5/8" | G25: 16 | H25: 0 | I25: drive-up canopy column 4 (grid 1) | J25: 5/A09.25 | K25: [DERIVED]
A26: TYPE A1
A27: A1 #A1-01 - Calling Cubes 122 (S) / Waiting 104 - Central Zone (N); west part backs MW01 niche | B27: A1-01 | C27: 17.02 | D27: 15.375 | E27: 2 | F27: 3-5/8" | G27: 16 | H27: 366.95 | I27: Calling Cubes 122 (S) / Waiting 104 - Central Zone (N); west part backs MW01 niche | J27: 3/A12.01 | K27: [DERIVED]
A28: A1 #A1-02 - MW01 niche (W) / Calling Cubes 122 (E) | B28: A1-02 | C28: 3.533 | D28: 15.375 | E28: 2 | F28: 3-5/8" | G28: 16 | H28: 86.12 | I28: MW01 niche (W) / Calling Cubes 122 (E) | J28: 3/A12.01 | K28: [DERIVED]
A29: A1 #A1-03 - MW01 niche (N) / MW07 - Calling Cubes 122 (S) | B29: A1-03 | C29: 2.02 | D29: 15.375 | E29: 2 | F29: 3-5/8" | G29: 16 | H29: 49.24 | I29: MW01 niche (N) / MW07 - Calling Cubes 122 (S) | J29: 3/A12.01 | K29: [DERIVED]
A30: A1 #A1-04 - Lobby corridor east of offices 109/110 (N) / Corridor 111 (S); includes door 111 | B30: A1-04 | C30: 5 | D30: 15.375 | E30: 2 | F30: 3-5/8" | G30: 16 | H30: 50.56 | I30: Lobby corridor east of offices 109/110 (N) / Corridor 111 (S); includes door 111 | J30: 3/A12.01 | K30: [CONFIRMED]
A31: A1 #A1-05 - Calling Cubes 122 (N) / Corridor 118B - MW21 (S) | B31: A1-05 | C31: 15.233 | D31: 12.969 | E31: 2 | F31: 3-5/8" | G31: 16 | H31: 274.2 | I31: Calling Cubes 122 (N) / Corridor 118B - MW21 (S) | J31: 3/A12.01 | K31: [DERIVED]
A32: A1 #A1-06 - Teller queue / Central Zone (N) / Break Room 118 (S); includes door 118A and the untagged A1-thickness stub x=1613.64-1622.16 | B32: A1-06 | C32: 5.5 | D32: 12.925 | E32: 2 | F32: 3-5/8" | G32: 16 | H32: 47.31 | I32: Teller queue / Central Zone (N) / Break Room 118 (S); includes door 118A and the untagged A1-thickness stub x=1613.64-1622.16 | J32: 3/A12.01 | K32: [CONFIRMED]
A33: A1 #A1-07 - MW21 / Corridor 118B (W) / Teller queue - Central Zone (E) | B33: A1-07 | C33: 1.733 | D33: 11.819 | E33: 2 | F33: 3-5/8" | G33: 16 | H33: 32.07 | I33: MW21 / Corridor 118B (W) / Teller queue - Central Zone (E) | J33: 3/A12.01 | K33: [DERIVED]
A34: A1 #A1-08 - Corridor 111 (W) / Break Room 118 - Electrical 120 - NER 121 (E); includes door 118B | B34: A1-08 | C34: 20.521 | D34: 11.819 | E34: 2 | F34: 3-5/8" | G34: 16 | H34: 377.62 | I34: Corridor 111 (W) / Break Room 118 - Electrical 120 - NER 121 (E); includes door 118B | J34: 3/A12.01 | K34: [DERIVED]
A35: A1 #A1-09 - Cash Window 116 (N) / Work Room 119 (S); includes door 119 | B35: A1-09 | C35: 11.667 | D35: 12.773 | E35: 2 | F35: 3-5/8" | G35: 16 | H35: 168.05 | I35: Cash Window 116 (N) / Work Room 119 (S); includes door 119 | J35: 3/A12.01 | K35: [DERIVED]
A36: TYPE A5
A37: A5 #A1-10+A1-10S - Calling Cubes 122 (W) / Teller queue - Central Zone (E) | B37: A1-10+A1-10S | C37: 19.407 | D37: 13.697 | E37: 2 | F37: 6" | G37: 16 | H37: 378.92 | I37: Calling Cubes 122 (W) / Teller queue - Central Zone (E) | J37: 3/A12.01 | K37: [DERIVED]
A38: A5 #A1-11 - Lobby corridor east of offices 109/110 (W) / MW07 - Calling Cubes 122 (E); FEC-1 recess in west face | B38: A1-11 | C38: 11.407 | D38: 15.375 | E38: 2 | F38: 6" | G38: 16 | H38: 239.54 | I38: Lobby corridor east of offices 109/110 (W) / MW07 - Calling Cubes 122 (E); FEC-1 recess in west face | J38: 3/A12.01 | K38: [DERIVED]
A39: A5 #A1-12+A1-12S - Corridor 111 (W) / Calling Cubes 122 (E); includes door 122 | B39: A1-12+A1-12S | C39: 5.28 | D39: 12.284 | E39: 2 | F39: 6" | G39: 16 | H39: 47.26 | I39: Corridor 111 (W) / Calling Cubes 122 (E); includes door 122 | J39: 3/A12.01 | K39: [DERIVED]
A40: A5 #A1-13 - Break Room 118 (W) / Future FCAM - Cash Window 116 (E); includes door 116 | B40: A1-13 | C40: 6.947 | D40: 11.774 | E40: 2 | F40: 6" | G40: 16 | H40: 80.73 | I40: Break Room 118 (W) / Future FCAM - Cash Window 116 (E); includes door 116 | J40: 3/A12.01 | K40: [DERIVED]
A41: TYPE B2K
...

Sheet Material Summary
A1: MATERIAL SUMMARY - NET / WASTE / PURCHASE
A2: Waste lives HERE, in its own column, applied ONCE: Pieces = ROUNDUP(Net x (1 + waste) / stock). Every stock length, coverage and yield is an Inputs cell.
A3: Material | B3: Unit | C3: Net | D3: Waste % | E3: Waste | F3: Purchase | G3: Selling unit | H3: Pieces to buy | I3: Where it comes from | J3: Yield check (live formula)
A4: 6" metal stud (LF of material) | B4: LF | C4: 4561.16 | D4: =Inputs!$B$5 -> 0.15 | E4: =C4*D4 -> 684.174 | F4: =C4+E4 -> 5245.334 | G4: stick 20 ft | H4: =ROUNDUP(F4/Inputs!$B$10,0) -> 263 | I4: familias_out.json '6" stud (all gauges)' (canon.py on 4_canon/takeoff_canon.json)
A5: 3-5/8" metal stud (LF of material) | B5: LF | C5: 5847.9 | D5: =Inputs!$B$5 -> 0.15 | E5: =C5*D5 -> 877.185 | F5: =C5+E5 -> 6725.085 | G5: stick 20 ft | H5: =ROUNDUP(F5/Inputs!$B$10,0) -> 337 | I5: familias_out.json '3-5/8" stud (all gauges)' (canon.py on 4_canon/takeoff_canon.json)
A6: 1-5/8" metal stud (LF of material) | B6: LF | C6: 4020.86 | D6: =Inputs!$B$5 -> 0.15 | E6: =C6*D6 -> 603.129 | F6: =C6+E6 -> 4623.989 | G6: stick 20 ft | H6: =ROUNDUP(F6/Inputs!$B$10,0) -> 232 | I6: familias_out.json '1-5/8" stud' (canon.py on 4_canon/takeoff_canon.json)
A7: 6" parapet infill stud (LF of material) | B7: LF | C7: 985.53 | D7: =Inputs!$B$5 -> 0.15 | E7: =C7*D7 -> 147.8295 | F7: =C7+E7 -> 1133.3595 | G7: stick 20 ft | H7: =ROUNDUP(F7/Inputs!$B$10,0) -> 57 | I7: familias_out.json '6" parapet stud' (canon.py on 4_canon/takeoff_canon.json)
A8: Track, ceilings / soffits / canopy | B8: LF | C8: 948.41 | D8: =Inputs!$B$5 -> 0.15 | E8: =C8*D8 -> 142.2615 | F8: =C8+E8 -> 1090.6715 | G8: run 10 ft | H8: =ROUNDUP(F8/Inputs!$B$11,0) -> 110 | I8: familias_out.json 'ceiling / soffit track' (canon.py on 4_canon/takeoff_canon.json)
A9: Bracing 1-1/2" C.R. channel @ 48" O.C. | B9: LF | C9: 2466.65 | D9: =Inputs!$B$5 -> 0.15 | E9: =C9*D9 -> 369.9975 | F9: =C9+E9 -> 2836.6475 | G9: C.R. channel 16 ft | H9: =ROUNDUP(F9/Inputs!$B$16,0) -> 178 | I9: familias_out.json 'bracing C.R. channel' (canon.py on 4_canon/takeoff_canon.json)
A10: Purlin, top track to deck | B10: LF | C10: 272.55 | D10: =Inputs!$B$5 -> 0.15 | E10: =C10*D10 -> 40.8825 | F10: =C10+E10 -> 313.4325 | G10: run 10 ft | H10: =ROUNDUP(F10/Inputs!$B$11,0) -> 32 | I10: familias_out.json 'purlin (track to deck)' (canon.py on 4_canon/takeoff_canon.json)
A11: Header / metal stud box beam | B11: LF | C11: 815.27 | D11: =Inputs!$B$5 -> 0.15 | E11: =C11*D11 -> 122.2905 | F11: =C11+E11 -> 937.5605 | G11: stick 20 ft | H11: =ROUNDUP(F11/Inputs!$B$10,0) -> 47 | I11: familias_out.json 'header / box beam' (canon.py on 4_canon/takeoff_canon.json)
A12: Sill track | B12: LF | C12: 119.12 | D12: =Inputs!$B$5 -> 0.15 | E12: =C12*D12 -> 17.868 | F12: =C12+E12 -> 136.988 | G12: run 10 ft | H12: =ROUNDUP(F12/Inputs!$B$11,0) -> 14 | I12: familias_out.json 'sill track' (canon.py on 4_canon/takeoff_canon.json)
A13: Furring channel (ceilings) | B13: LF | C13: 807.65 | D13: =Inputs!$B$5 -> 0.15 | E13: =C13*D13 -> 121.1475 | F13: =C13+E13 -> 928.7975 | G13: hat channel 12 ft | H13: =ROUNDUP(F13/Inputs!$B$17,0) -> 78 | I13: familias_out.json 'furring channel' (canon.py on 4_canon/takeoff_canon.json)
A14: Carrying channel (ceilings) | B14: LF | C14: 315.98 | D14: =Inputs!$B$5 -> 0.15 | E14: =C14*D14 -> 47.397 | F14: =C14+E14 -> 363.377 | G14: C.R. channel 16 ft | H14: =ROUNDUP(F14/Inputs!$B$16,0) -> 23 | I14: familias_out.json 'carrying channel' (canon.py on 4_canon/takeoff_canon.json)
A15: Hanger wire | B15: LF | C15: 533.62 | D15: =Inputs!$B$5 -> 0.15 | E15: =C15*D15 -> 80.043 | F15: =C15+E15 -> 613.663 | G15: continuous coil (LF) | H15: =ROUNDUP(F15,0) -> 614 | I15: familias_out.json 'hanger wire' (canon.py on 4_canon/takeoff_canon.json)
A16: 5/8" gypsum board, regular | B16: SF | C16: 17713.32 | D16: =Inputs!$B$6 -> 0.06 | E16: =C16*D16 -> 1062.7992 | F16: =C16+E16 -> 18776.119 | G16: 4x12 ft sheet | H16: =ROUNDUP(F16/Inputs!$B$9,0) -> 392 | I16: familias_out.json '5/8" gyp board regular (walls + ceilings)' (canon.py on 4_canon/takeoff_canon.json)
A17: 5/8" gypsum board, MOISTURE RESISTANT | B17: SF | C17: 258.87 | D17: =Inputs!$B$6 -> 0.06 | E17: =C17*D17 -> 15.5322 | F17: =C17+E17 -> 274.4022 | G17: 4x12 ft sheet | H17: =ROUNDUP(F17/Inputs!$B$9,0) -> 6 | I17: familias_out.json '5/8" gyp MOISTURE RESISTANT' (canon.py on 4_canon/takeoff_canon.json)
A18: Ballistic panel 3/8" UL752 | B18: SF | C18: 93.89 | D18: =Inputs!$B$6 -> 0.06 | E18: =C18*D18 -> 5.6334 | F18: =C18+E18 -> 99.5234 | G18: 4x8 ft sheet | H18: =ROUNDUP(F18/32,0) -> 4 | I18: familias_out.json 'ballistic panel' (canon.py on 4_canon/takeoff_canon.json)
A19: 3/8" gypsum board | B19: SF | C19: 63.83 | D19: =Inputs!$B$6 -> 0.06 | E19: =C19*D19 -> 3.8298 | F19: =C19+E19 -> 67.6598 | G19: 4x12 ft sheet | H19: =ROUNDUP(F19/Inputs!$B$9,0) -> 2 | I19: familias_out.json '3/8" gyp board' (canon.py on 4_canon/takeoff_canon.json)
A20: 5/8" glass mat sheathing (exterior face of the stud) | B20: SF | C20: 478.79 | D20: =Inputs!$B$6 -> 0.06 | E20: =C20*D20 -> 28.7274 | F20: =C20+E20 -> 507.5174 | G20: 4x12 ft sheet | H20: =ROUNDUP(F20/Inputs!$B$9,0) -> 11 | I20: familias_out.json '5/8" glass mat sheathing' (canon.py on 4_canon/takeoff_canon.json)
A21: 5/8" EXTERIOR gypsum sheathing | B21: SF | C21: 933.99 | D21: =Inputs!$B$6 -> 0.06 | E21: =C21*D21 -> 56.0394 | F21: =C21+E21 -> 990.0294 | G21: 4x12 ft sheet | H21: =ROUNDUP(F21/Inputs!$B$9,0) -> 21 | I21: familias_out.json '5/8" EXTERIOR gyp sheathing' (canon.py on 4_canon/takeoff_canon.json)
A22: Blocking FRT / 2X FRT wood | B22: LF | C22: 1057.82 | D22: =Inputs!$B$6 -> 0.06 | E22: =C22*D22 -> 63.4692 | F22: =C22+E22 -> 1121.2892 | G22: stick 16 ft | H22: =ROUNDUP(F22/16,0) -> 71 | I22: familias_out.json 'FRT blocking' (canon.py on 4_canon/takeoff_canon.json)
A23: Stud blocking at edge of gypboard (structural detail) | B23: LF | C23: 622.67 | D23: =Inputs!$B$5 -> 0.15 | E23: =C23*D23 -> 93.4005 | F23: =C23+E23 -> 716.0705 | G23: stick 20 ft | H23: =ROUNDUP(F23/Inputs!$B$10,0) -> 36 | I23: familias_out.json metal_blocking_by_origin 'metal stud blocking (362CR / STUD BLOCKING)' (edge)
A24: Metal stud blocking at wall-mounted items (notes) | B24: LF | C24: 108.95 | D24: =Inputs!$B$5 -> 0.15 | E24: =C24*D24 -> 16.3425 | F24: =C24+E24 -> 125.2925 | G24: stick 20 ft | H24: =ROUNDUP(F24/Inputs!$B$10,0) -> 7 | I24: familias_out.json metal_blocking_by_origin 'metal stud blocking (362CR / STUD BLOCKING)' (items)
A25: METAL trim - corner bead, casing bead, shadow molding, gypsum edge trim | B25: LF | C25: 1422.39 | D25: =Inputs!$B$5 -> 0.15 | E25: =C25*D25 -> 213.3585 | F25: =C25+E25 -> 1635.7485 | G25: trim stick 10 ft | H25: =ROUNDUP(F25/Inputs!$B$18,0) -> 164 | I25: familias_out.json 'metal trim (corner bead, casing, shadow molding)' (canon.py on 4_canon/takeoff_canon.json)
A26: Cement board (substrate under the FRP cove base band) | B26: SF | C26: 31.37 | D26: =Inputs!$B$6 -> 0.06 | E26: =C26*D26 -> 1.8822 | F26: =C26+E26 -> 33.2522 | G26: 4x8 ft sheet | H26: =ROUNDUP(F26/32,0) -> 2 | I26: familias_out.json 'cement board' (canon.py on 4_canon/takeoff_canon.json)
A27: FRP panels | B27: SF | C27: 329.74 | D27: =Inputs!$B$6 -> 0.06 | E27: =C27*D27 -> 19.7844 | F27: =C27+E27 -> 349.5244 | G27: 4x8 ft sheet | H27: =ROUNDUP(F27/32,0) -> 11 | I27: familias_out.json 'FRP' (canon.py on 4_canon/takeoff_canon.json)
A28: Acoustical sealant | B28: LF | C28: 1141.84 | D28: =Inputs!$B$6 -> 0.06 | E28: =C28*D28 -> 68.5104 | F28: =C28+E28 -> 1210.3504 | G28: tube (25 LF per tube) | H28: =ROUNDUP(F28/Inputs!$B$15,0) -> 49 | I28: familias_out.json 'acoustical sealant' (canon.py on 4_canon/takeoff_canon.json)
A29: framed openings MEP | B29: LF | C29: 956.63 | D29: =Inputs!$B$5 -> 0.15 | E29: =C29*D29 -> 143.4945 | F29: =C29+E29 -> 1100.1245 | G29: stick 20 ft | H29: =ROUNDUP(F29/Inputs!$B$10,0) -> 56 | I29: framed_openings_out.json 'framed openings MEP' (framed_openings.py)
A30: Bottom track 6" | B30: LF | C30: 298.3 | D30: =Inputs!$B$5 -> 0.15 | E30: =C30*D30 -> 44.745 | F30: =C30+E30 -> 343.045 | G30: run 10 ft | H30: =ROUNDUP(F30/Inputs!$B$11,0) -> 35 | I30: familias_out.json track_by_element 'bottom track (all)' (R73.3)
A31: Parapet bottom track | B31: LF | C31: 269.38 | D31: =Inputs!$B$5 -> 0.15 | E31: =C31*D31 -> 40.407 | F31: =C31+E31 -> 309.787 | G31: run 10 ft | H31: =ROUNDUP(F31/Inputs!$B$11,0) -> 31 | I31: familias_out.json track_by_element 'bottom track (all)' (R73.3)
A32: Bottom track - other framing (not a partition type, see source) | B32: LF | C32: 66.17 | D32: =Inputs!$B$5 -> 0.15 | E32: =C32*D32 -> 9.9255 | F32: =C32+E32 -> 76.0955 | G32: run 10 ft | H32: =ROUNDUP(F32/Inputs!$B$11,0) -> 8 | I32: familias_out.json track_by_element 'bottom track (all)' (R73.3)
A33: Bottom track 3-5/8" | B33: LF | C33: 248.19 | D33: =Inputs!$B$5 -> 0.15 | E33: =C33*D33 -> 37.2285 | F33: =C33+E33 -> 285.4185 | G33: run 10 ft | H33: =ROUNDUP(F33/Inputs!$B$11,0) -> 29 | I33: familias_out.json track_by_element 'bottom track (all)' (R73.3)
A34: Bottom track - roof step and heads (vestibule / bulkhead) | B34: LF | C34: 176.84 | D34: =Inputs!$B$5 -> 0.15 | E34: =C34*D34 -> 26.526 | F34: =C34+E34 -> 203.366 | G34: run 10 ft | H34: =ROUNDUP(F34/Inputs!$B$11,0) -> 21 | I34: familias_out.json track_by_element 'bottom track (all)' (R73.3)
A35: Bottom track 1-5/8" | B35: LF | C35: 291.42 | D35: =Inputs!$B$5 -> 0.15 | E35: =C35*D35 -> 43.713 | F35: =C35+E35 -> 335.133 | G35: run 10 ft | H35: =ROUNDUP(F35/Inputs!$B$11,0) -> 34 | I35: familias_out.json track_by_element 'bottom track (all)' (R73.3)
A36: Top / deflection track 6" | B36: LF | C36: 298.3 | D36: =Inputs!$B$5 -> 0.15 | E36: =C36*D36 -> 44.745 | F36: =C36+E36 -> 343.045 | G36: run 10 ft | H36: =ROUNDUP(F36/Inputs!$B$11,0) -> 35 | I36: familias_out.json track_by_element 'top / deflection track (all)' (R73.3)
A37: Parapet top track | B37: LF | C37: 269.38 | D37: =Inputs!$B$5 -> 0.15 | E37: =C37*D37 -> 40.407 | F37: =C37+E37 -> 309.787 | G37: run 10 ft | H37: =ROUNDUP(F37/Inputs!$B$11,0) -> 31 | I37: familias_out.json track_by_element 'top / deflection track (all)' (R73.3)
A38: Top / deflection track - other framing (not a partition type, see source) | B38: LF | C38: 66.17 | D38: =Inputs!$B$5 -> 0.15 | E38: =C38*D38 -> 9.9255 | F38: =C38+E38 -> 76.0955 | G38: run 10 ft | H38: =ROUNDUP(F38/Inputs!$B$11,0) -> 8 | I38: familias_out.json track_by_element 'top / deflection track (all)' (R73.3)
A39: Top / deflection track 3-5/8" | B39: LF | C39: 248.19 | D39: =Inputs!$B$5 -> 0.15 | E39: =C39*D39 -> 37.2285 | F39: =C39+E39 -> 285.4185 | G39: run 10 ft | H39: =ROUNDUP(F39/Inputs!$B$11,0) -> 29 | I39: familias_out.json track_by_element 'top / deflection track (all)' (R73.3)
A40: Top track - roof step and heads (vestibule / bulkhead) | B40: LF | C40: 176.84 | D40: =Inputs!$B$5 -> 0.15 | E40: =C40*D40 -> 26.526 | F40: =C40+E40 -> 203.366 | G40: run 10 ft | H40: =ROUNDUP(F40/Inputs!$B$11,0) -> 21 | I40: familias_out.json track_by_element 'top / deflection track (all)' (R73.3)
...

Sheet Pending Items
A1: RFI | B1: Question / condition | C1: Delta of each alternative
A2: RFI-ACC-additional-head-track | B2: additional head track: openings with their own box (openings_extra) > 4'-0": do they also take the additional head track of 2/S5.20? | C2: 106.3 lf
A3: RFI-ACC-stud-reinforcement-mep | B3: stud reinforcement MEP: plates at double-row stud walls: one per cut row (R72.9) vs one per crossing | C3: -9 pcs
A4: RFI-ACC-stud-reinforcement-mep-2 | B4: stud reinforcement MEP: crossings read by hand (not found by mep.cruces): confirm each one on the M / P sheets (R73.5) | C4: 35 pcs
A5: RFI-ACC-stud-reinforcement-mep-3 | B5: stud reinforcement MEP: duct / fire damper openings listed outside the registered MEP sweep (R73.5) | C5: 6 pcs
A6: RFI-ACC-extra-framing-atm | B6: extra framing ATM: ATM-DU: ATM recess not fully dimensioned (width CRITERION, sistered height DERIVED, furring rows CRITERION) | C6: -39.5 lf
A7: RFI-ACC-gypsum-board-jamb-return | B7: gypsum board jamb return: jamb return width not dimensioned | C7: -40.29 sf
A8: RFI-ACC-expansion-anchors | B8: expansion anchors: untagged parts of piers / boxes (AE-41, AE-42) without anchorage in the schedule (R72.8) | C8: 9.91 pcs
A9: RFI-ACC-slab-pins | B9: slab pins: pin spacing: 12" (interior anchorage) vs 16" (fastener schedule) vs 24" (type K box) | C9: 16in: -133.2 pcs; 24in: -266.4 pcs
A10: RFI-ACC-deflection-clips | B10: deflection clips: deflection clips: the general note asks for them at non-load-bearing walls and the partition details draw a slip / deflection track (R73.6) | C10: 534 pcs
A11: A_CEIL-RFI-01 | B11: Suspended GWB ceiling framing (Vestibule 100, 24 HR Vestibule 101, Waiting 104, Restrooms 113/114) [A04.01, A09.33] | C11: carrying E-W instead of N-S: furring -39.2 LF, carrying +6.7 LF, hangers +0 PCS (N-S: furring 807.6 / carrying 316.0 LF / 113 hangers; E-W: 768.4 / 322.7 / 113)
A12: A_CEIL-RFI-02 | B12: B.O.D. of the zone between grids E and B [S2.20, H/A09.23, J/A09.23] | C12: if the E-B zone were at 13'-0 5/8": transition vertical studs -2.323 ft each (AC-07..09 are in F-B), CSR soffit sides north part 7.375 -> 5.052 ft (AC-10, AC-12)
... A103: DOCS-RFI-04 | B103: A05.01 key note 4 'tile into niche under printer cabinet millwork': read as floor tile [A05.01 key note 4; docs/04_conditional_notes.md] Carried: no cement board at the niche. | C103: + niche wall area SF cement board (not dimensioned; small)

Sheet Review Items
A1: # | B1: Item | C1: Sheet + detail | D1: Image
A2: 1 | B2: Piers NW (AE-41, A2-20): two readings differ; carried the larger (CONC-RFI-01, CONC-RFI-04) | C2: 1/A09.25 | D2: /home/user/boa24a/work/etapas/3_revision/img_resolucion/res_26_33_34_pier_NW.png
A3: 2 | B3: Piers NE (AE-42, A2-21): two readings differ; carried the larger (CONC-RFI-02, CONC-RFI-03) | C3: 2/A09.25 | D3: /home/user/boa24a/work/etapas/3_revision/img_resolucion/res_27_33_pier_NE.png
A4: 3 | B4: B2K tag (PC0011) not in the partition schedule: carried as B2 + ballistic + 3/8" (RFI-C07) | C4: A02.01; A12.01 | D4: /home/user/boa24a/work/etapas/3_revision/img_resolucion/res_11_B2K.png
A5: 4 | B5: A1K stud spacing @ 16" vs @ 24" (RFI-C02) | C5: 4/A12.01; 7/S5.20 | D5: /home/user/boa24a/work/etapas/2_lectura/A/img/A_CONST/det4_A1201.png
A6: 5 | B6: Office front run ends: wall-to-wall carried vs jamb-to-jamb (RFI-OPEN-04, A3-RFI-02) | C6: 8/A12.01; 9/A12.01; 10/A12.01 | D6: /home/user/boa24a/work/etapas/2_lectura/A/img/A_INT_F/office_fronts_runs.png
A7: 6 | B7: ATM extra framing: single source 61.92 LF, criterion (RFI-ACC-05) | C7: 5/A08.11; 6/A08.11 | D7: /home/user/boa24a/work/etapas/2_lectura/A/img/A_ACC/atm_6_A08.11.png
A8: 7 | B8: Exterior studs interrupted at canopy beams? carried continuous (RFI-AE-02, about -189 LF 6" stud) | C8: D/A09.22; H/A09.23; S2.20 | D8: /home/user/boa24a/work/adversarial/img/APLICA/ADV1-2_D-A0922_zoom.png
A9: 8 | B9: Board to deck vs stop under beam (RFI-ADV-01, -225.66 SF if stops) | C9: 8/A12.01; 9/A12.01 | D9: /home/user/boa24a/work/adversarial/img/APLICA/ADV1-1_9-A1201_board_to_deck.png
A10: 9 | B10: Corner bead at corners hidden by casework (RFI-ADV-03, about -46.74 LF) | C10: A02.01; A04.01 | D10: /home/user/boa24a/work/adversarial/img/APLICA/F2_corners_calling_cubes.png
A11: 10 | B11: Deflection clips per S1.11 note 2 (+534 pcs) vs slip track per 8,9/A12.01 (against R73.6); see review folder file adversarial_contra_regla.md | C11: S1.11; 8/A12.01 | D11: /home/user/boa24a/work/adversarial/img/S111_LGSF_note2_deflection_clips.png
A12: 11 | B12: 2X wood blocking per 3/P00.01 carried as metal (REG-RFI-01; gate rule 54.3) | C12: 3/P00.01 | D12: /home/user/boa24a/work/adversarial/img/APLICA/ADV3-F7_3-P0001_2X_blocking.png
A13: 12 | B13: Bulkhead transition trim: 4 pieces carried; alt. 2 LF per LF = -154.05 LF (A_CEIL-RFI-04) | C13: 8/A09.33 | D13: /home/user/boa24a/work/adversarial/img/F4_bulkhead_8_A0933.png
... A15: 14 | B15: Tool proposals (no tool modified): header LF from schedule; fos_chain with unequal faces; see review folder files propuesta_*.md | C15: 7/S5.20; A02.01 | D15: /home/user/boa24a/work/etapas/2_lectura/A/img/A_CONST/det4_A1201.png

Sheet Scope Checklist
A1: Scope ID | B1: Scope | C1: Status | D1: Note (quantity, NOT APPLICABLE + sheet, or RFI)
A2: ALC-01 | B2: Interior partition framing (studs + tracks) | C2: QUANTIFIED | D2: 3-5/8" / 6" / 1-5/8" studs and bottom / top track from canon.py (types A1, A1K, A5, B, B2, B2K, C1, F, G, G1; 3/A12.01, 4/A12.01, 1/A12.01, 5/A12.01, 6/A12.01, 12/A12.01)
A3: ALC-02 | B3: Exterior wall framing (CFMF) | C3: QUANTIFIED | D3: 6" CFMF exterior walls, one per axis (C/A09.21, D/A09.22, F/A09.22, H/A09.23; S1.11)
A4: ALC-03 | B4: Parapet framing | C4: QUANTIFIED | D4: 6" parapet infill bay by bay between HSS posts (11/S5.10, A02.02, E3)
A5: ALC-04 | B5: Top / deflection and bottom track | C5: QUANTIFIED | D5: Bottom and top / slip track by stud size and element (track_by_element, canon.py; 1/A12.01, 3/A12.01, 10/S5.10)
A6: ALC-05 | B6: Headers, sills and jambs at openings | C6: QUANTIFIED | D6: Header / box beam by pieces and sill track (headers.py; 7/S5.20, 2/S5.20, 11/A09.27, 8/A12.01, 9/A12.01)
A7: ALC-06 | B7: Bracing / bridging | C7: QUANTIFIED | D7: 1-1/2" C.R. channel bracing @ 48" (F/1/S5.20), corridas.py
A8: ALC-07 | B8: Gypsum board on walls (layers per type) | C8: QUANTIFIED | D8: 5/8" gypsum board face by face (board_caras.py; A12.01 type details)
A9: ALC-08 | B9: Moisture / abuse / special board at wet zones | C9: QUANTIFIED | D9: 5/8" MR board behind toilets and lavatories only, chase faces (F/A08.01 note F, A08.01)
A10: ALC-09 | B10: Exterior gypsum / glass mat sheathing | C10: QUANTIFIED | D10: 5/8" glass mat sheathing (5/A09.26, 7/A09.26) and 5/8" exterior gypsum sheathing at parapets (4/A09.26)
A11: ALC-10 | B11: FRT plywood sheathing / substrate | C11: QUANTIFIED | D11: FRT plywood by material and use (nailbase, canopy, backboards, type F public side; A09.26, A09.27, 12/A12.01, A11.03)
A12: ALC-11 | B12: Gypsum board ceilings | C12: QUANTIFIED | D12: Suspended GWB ceilings room by room (A04.01 RCP; legend NEW SUSPENDED GYPSUM WALL BOARD)
... A26: ALC-X25 | B26: batt insulation | C26: NOT APPLICABLE | D26: EXCLUDED (estimator criterion: no insulation)

Sheet _reglas
A1: reglas.py compuerta OK
A2: {"canon": "e7cd2f8abb47215f7561cb9a415f28c1f33fca8a57ca9d204c7e8c0b117c3d69", "evidencias": "08f9a091cd35722af4dee9c7cac662c91ef3c3b0b1a76b6cecc1fb010b71e5dc", "familias_out": "a9b7b5657b359ee4df34d8f14f253ca16b0e346b61da00e9a262d7690b0e8f26", "reglas": "28a2ca4a03e7a9b91a037023d0edd1e9d6699793a03b78fcb116fb62e917daa4", "version": "v73"}
