Workbook

Sheet Takeoff
A1: Wall # | B1: Partition / Scope | C1: Location | D1: Length (LF) | E1: Stud Height (FT) | F1: Layers (total both faces) | G1: 6" Metal Stud (LF) | H1: 3-5/8" Metal Stud (LF) | I1: 1-5/8" Metal Stud (LF) | J1: Stud designation | K1: O.C. (in) | L1: Stud pcs | M1: Side 1 room | N1: Side 1 board height (FT) | O1: Side 1 layers | P1: Side 2 room | Q1: Side 2 board height (FT) | R1: Side 2 layers | S1: Openings deduction (SF per face) | T1: 5/8" Gyp Board (SF) | U1: 3/8" Gyp Board (SF) | V1: 3/8" UL752 Fiberglass (SF) | W1: 3/4" FRT Plywood (SF) | X1: FRP-1 (SF) | Y1: FRP-2 (SF) | Z1: Durock (SF) | AA1: Demolition (SF) | AB1: Bottom Track (LF) | AC1: Top Track (LF) | AD1: Top track condition | AE1: Bracing C.R. channel (LF) | AF1: Clips (ea) | AG1: Header (LF) | AH1: Insulation (SF) | AI1: Acoustical sealant (LF) | AJ1: Blocking | AK1: Labor (Hrs) | AL1: Status | AM1: Detail sequence (plan -> detail -> schedule) | AN1: Seal
A2: 8 | B2: A1 - 3-5/8" MST @ 16" O.C. (362S137-33) - board per face, see Side 1 / Side 2 (1 instance) | C2: Corridor 111 east / Break Room 118, Electrical 120, NER 121 west | D2: 20.93 | E2: 13.052 | F2: 2 | H2: 304.8 | J2: 362S137-33 | K2: 16 | L2: 25 | M2: Corridor 111 | N2: 9 | O2: 1 | P2: Break Room 118 | Q2: 9 | R2: 1 | S2: 23.89 | T2: 399.48 | AB2: 20.93 | AC2: 20.93 | AD2: CONTINUOUS SLIP TRACK per 3/A12.01 | AE2: 62.79 | AF2: 150 | AG2: 4.33 | AH2: 249.25 | AI2: 41.86 | AJ2: PENDING (see Blocking sheet) | AL2: [DERIVADO] vector A02.01 | AM2: A02.01 (tags A1 @1213,1406 and @1220,1515) -> 3/A12.01 -> 7/S5.20 -> S2.20 B.O.D. -> A04.01 ceiling -> A00.30 HEAD 10/A12.02, JAMB 11/A12.02 | AN2: d67b0b4d817598c1
A3: 1 | B3: A1 - 3-5/8" MST @ 16" O.C. (362S137-33) - board per face, see Side 1 / Side 2 (1 instance) | C3: Calling Cubes 122 north / Waiting 104 | D3: 17.02 | E3: 15.375 | F3: =ROUND(((O3)+(R3))*1,2) -> 2 | H3: 230.63 | J3: 362S137-33 | K3: 16 | L3: 15 | M3: Calling Cubes 122 | N3: 9 | O3: 1 | P3: Waiting 104 | Q3: 11.5 | R3: 1 | S3: 0 | T3: =D3*N3*O3-S3*O3+D3*Q3*R3-S3*R3 -> 348.91 | AB3: 17.02 | AC3: 17.02 | AD3: CONTINUOUS SLIP TRACK per 3/A12.01 | AE3: 51.06 | AF3: 90 | AH3: 261.68 | AI3: 34.04 | AJ3: PENDING (see Blocking sheet) | AL3: [DERIVADO] vector A02.01 | AM3: A02.01 (tag A1 @1382,996) -> 3/A12.01 -> 7/S5.20 -> S2.20 B.O.D. -> A04.01 ceiling | AN3: c0fa7673fe7ef80d
A4: 5 | B4: A1 - 3-5/8" MST @ 16" O.C. (362S137-33) - board per face, see Side 1 / Side 2 (1 instance) | C4: Calling Cubes 122 south / Break Room 118 | D4: 15.23 | E4: 13.052 | F4: =ROUND(((O4)+(R4))*1,2) -> 2 | H4: 182.73 | J4: 362S137-33 | K4: 16 | L4: 14 | M4: Calling Cubes 122 | N4: 9 | O4: 1 | P4: Break Room 118 | Q4: 9 | R4: 1 | S4: 0 | T4: =D4*N4*O4-S4*O4+D4*Q4*R4-S4*R4 -> 274.14 | AB4: 15.23 | AC4: 15.23 | AD4: CONTINUOUS SLIP TRACK per 3/A12.01 | AE4: 45.69 | AF4: 84 | AH4: 198.83 | AI4: 30.46 | AJ4: PENDING (see Blocking sheet) | AL4: [DERIVADO] vector A02.01 | AM4: A02.01 (tag A1 @1376,1297) -> 3/A12.01 -> 7/S5.20 -> S2.20 B.O.D. -> A04.01 ceiling | AN4: 34d325ae99bba374
A5: 9 | B5: A1 - 3-5/8" MST @ 16" O.C. (362S137-33) - board per face, see Side 1 / Side 2 (1 instance) | C5: Work Room 119 north / Cash Window 116 & Break Room | D5: 11.67 | E5: 13.052 | F5: =ROUND(((O5)+(R5))*1,2) -> 2 | H5: 213.43 | J5: 362S137-33 | K5: 16 | L5: 18 | M5: Work Room 119 | N5: 9 | O5: 1 | P5: Cash Window 116 | Q5: 9.5 | R5: 1 | S5: 23.89 | T5: =D5*N5*O5-S5*O5+D5*Q5*R5-S5*R5 -> 168.115 | AB5: 11.67 | AC5: 11.67 | AD5: CONTINUOUS SLIP TRACK per 3/A12.01 | AE5: 35.01 | AF5: 108 | AG5: 4.33 | AH5: 128.39 | AI5: 23.34 | AJ5: PENDING (see Blocking sheet) | AL5: [DERIVADO] vector A02.01 | AM5: A02.01 (tag A1 @1740,1472) -> 3/A12.01 -> 7/S5.20 -> S2.20 B.O.D. -> A04.01 ceiling -> A00.30 HEAD 10/A12.02, JAMB 11/A12.02 | AN5: 1a56c960b1d3effc
A6: 4 | B6: A1 - 3-5/8" MST @ 16" O.C. (362S137-33) - board per face, see Side 1 / Side 2 (1 instance) | C6: Corridor 111 north (door 111) | D6: 5.59 | E6: 15.375 | F6: =ROUND(((O6)+(R6))*1,2) -> 2 | H6: 190.75 | J6: 362S137-33 | K6: 16 | L6: 14 | M6: Corridor 111 | N6: 9 | O6: 1 | P6: Central Zone 103 | Q6: 12 | R6: 1 | S6: 27.22 | T6: =D6*N6*O6-S6*O6+D6*Q6*R6-S6*R6 -> 62.95 | AB6: 5.59 | AC6: 5.59 | AD6: CONTINUOUS SLIP TRACK per 3/A12.01 | AE6: 16.77 | AF6: 84 | AG6: 4.33 | AH6: 58.67 | AI6: 11.18 | AJ6: PENDING (see Blocking sheet) | AL6: [DERIVADO] vector A02.01 | AM6: A02.01 (tag A1 @1147,1254) -> 3/A12.01 -> 7/S5.20 -> S2.20 B.O.D. -> A04.01 ceiling -> A00.30 HEAD 10/A12.02, JAMB 11/A12.02 | AN6: 56e6e995594b5b5c
A7: 2 | B7: A1 - 3-5/8" MST @ 16" O.C. (362S137-33) - board per face, see Side 1 / Side 2 (1 instance) | C7: MW01 alcove east (Calling Cubes 122) | D7: 3.13 | E7: 15.375 | F7: =ROUND(((O7)+(R7))*1,2) -> 2 | H7: 76.88 | J7: 362S137-33 | K7: 16 | L7: 5 | M7: Calling Cubes 122 | N7: 9 | O7: 1 | P7: MW01 alcove | Q7: 9 | R7: 1 | S7: 0 | T7: =D7*N7*O7-S7*O7+D7*Q7*R7-S7*R7 -> 56.34 | AB7: 3.13 | AC7: 3.13 | AD7: CONTINUOUS SLIP TRACK per 3/A12.01 | AE7: 9.39 | AF7: 30 | AH7: 48.07 | AI7: 6.26 | AJ7: PENDING (see Blocking sheet) | AL7: [DERIVADO] vector A02.01 | AM7: A02.01 (tag A1 @1299,1000) -> 3/A12.01 -> 7/S5.20 -> S2.20 B.O.D. -> A04.01 ceiling | AN7: a434297db62f6466
A8: 3 | B8: A1 - 3-5/8" MST @ 16" O.C. (362S137-33) - board per face, see Side 1 / Side 2 (1 instance) | C8: MW01 alcove south (Calling Cubes 122) | D8: 2.02 | E8: 15.375 | F8: =ROUND(((O8)+(R8))*1,2) -> 2 | H8: 61.5 | J8: 362S137-33 | K8: 16 | L8: 4 | M8: Calling Cubes 122 | N8: 9 | O8: 1 | P8: MW01 alcove | Q8: 9 | R8: 1 | S8: 0 | T8: =D8*N8*O8-S8*O8+D8*Q8*R8-S8*R8 -> 36.36 | AB8: 2.02 | AC8: 2.02 | AD8: CONTINUOUS SLIP TRACK per 3/A12.01 | AE8: 6.06 | AF8: 24 | AH8: 31.06 | AI8: 4.04 | AJ8: PENDING (see Blocking sheet) | AL8: [DERIVADO] vector A02.01 | AM8: A02.01 (tag A1 @1246,1063) -> 3/A12.01 -> 7/S5.20 -> S2.20 B.O.D. -> A04.01 ceiling | AN8: e21a491f82924ae8
A9: 6 | B9: A1 - 3-5/8" MST @ 16" O.C. (362S137-33) - board per face, see Side 1 / Side 2 (1 instance) | C9: jog SE of Calling Cubes 122 (vertical) | D9: 1.73 | E9: 13.052 | F9: =ROUND(((O9)+(R9))*1,2) -> 2 | H9: 52.21 | J9: 362S137-33 | K9: 16 | L9: 4 | M9: Break Room 118 | N9: 9 | O9: 1 | P9: Central Zone 103 | Q9: 9.5 | R9: 1 | S9: 0 | T9: =D9*N9*O9-S9*O9+D9*Q9*R9-S9*R9 -> 32.005 | AB9: 1.73 | AC9: 1.73 | AD9: CONTINUOUS SLIP TRACK per 3/A12.01 | AE9: 5.19 | AF9: 24 | AH9: 22.62 | AI9: 3.46 | AJ9: PENDING (see Blocking sheet) | AL9: [DERIVADO] vector A02.01 | AM9: A02.01 (tag A1 @1508,1343) -> 3/A12.01 -> 7/S5.20 -> S2.20 B.O.D. -> A04.01 ceiling | AN9: e58a73e29e60d087
A10: 7 | B10: A1 - 3-5/8" MST @ 16" O.C. (362S137-33) - board per face, see Side 1 / Side 2 (1 instance) | C10: jog SE of Calling Cubes 122 (horizontal) | D10: 1.3 | E10: 13.052 | F10: =ROUND(((O10)+(R10))*1,2) -> 2 | H10: 39.16 | J10: 362S137-33 | K10: 16 | L10: 3 | M10: Break Room 118 | N10: 9 | O10: 1 | P10: Central Zone 103 | Q10: 9.5 | R10: 1 | S10: 0 | T10: =D10*N10*O10-S10*O10+D10*Q10*R10-S10*R10 -> 24.05 | AB10: 1.3 | AC10: 1.3 | AD10: CONTINUOUS SLIP TRACK per 3/A12.01 | AE10: 3.9 | AF10: 18 | AH10: 16.97 | AI10: 2.6 | AJ10: PENDING (see Blocking sheet) | AL10: [DERIVADO] vector A02.01 | AM10: A02.01 (tag A1 @1540,1335) -> 3/A12.01 -> 7/S5.20 -> S2.20 B.O.D. -> A04.01 ceiling | AN10: fc92c8164bc5f2ef
A11: 10 | B11: A1K - 3-5/8" 14 GA MST @ 24" O.C. (362S137-68) - board per face, see Side 1 / Side 2 (1 instance) | C11: Teller line west (Cash Window 116 / customer side) | D11: 12.01 | E11: 15.375 | F11: 2 | H11: 131.41 | J11: 362S137-68 | K11: 24 | L11: 9 | M11: Cash Window 116 (teller side) | N11: 15.375 | O11: 1 | P11: Central Zone 103 (customer side) | Q11: 15.375 | R11: 1 | S11: 0 | T11: 344.04 | U11: 88.57 | V11: 96.08 | AB11: 12.01 | AC11: 12.01 | AD11: CONTINUOUS SLIP TRACK per 4/A12.01 | AE11: 36.03 | AF11: 54 | AH11: 172.02 | AI11: 48.04 | AJ11: PENDING (see Blocking sheet) | AL11: [DERIVADO] vector A02.01 | AM11: A02.01 (tags A1K @1659,1150 and @1662,1332) -> 4/A12.01 -> 7/S5.20 -> S2.20 B.O.D. -> A04.01 ceiling | AN11: d49b7c0ce1434ab5
A12: 13 | B12: A1K - 3-5/8" 14 GA MST @ 24" O.C. (362S137-68) - board per face, see Side 1 / Side 2 (1 instance) | C12: Future FCAM north | D12: 5.65 | E12: 13.052 | F12: =ROUND(((O12)+(R12))*1,2) -> 2 | H12: 65.26 | J12: 362S137-68 | K12: 24 | L12: 5 | M12: Future FCAM | N12: 13.052 | O12: 1 | P12: Central Zone 103 | Q12: 13.052 | R12: 1 | S12: 0 | T12: =D12*N12*O12-S12*O12+D12*Q12*R12-S12*R12 -> 147.4876 | U12: 28.54 | V12: 45.2 | AB12: 5.65 | AC12: 5.65 | AD12: CONTINUOUS SLIP TRACK per 4/A12.01 | AE12: 16.95 | AF12: 30 | AH12: 73.79 | AI12: 22.6 | AJ12: PENDING (see Blocking sheet) | AL12: [DERIVADO] vector A02.01 | AM12: A02.01 (tag A1K @1644,1335) -> 4/A12.01 -> 7/S5.20 -> S2.20 B.O.D. -> A04.01 ceiling | AN12: c32dac1b6b7f6a0e
A13: 11 | B13: A1K - 3-5/8" 14 GA MST @ 24" O.C. (362S137-68) - board per face, see Side 1 / Side 2 (1 instance) | C13: Teller line north cap | D13: 2.98 | E13: 15.375 | F13: =ROUND(((O13)+(R13))*1,2) -> 2 | H13: 61.5 | J13: 362S137-68 | K13: 24 | L13: 4 | M13: Cash Window 116 | N13: 15.375 | O13: 1 | P13: Office 108 side | Q13: 15.375 | R13: 1 | S13: 0 | T13: =D13*N13*O13-S13*O13+D13*Q13*R13-S13*R13 -> 91.635 | U13: 21.98 | V13: 23.84 | AB13: 2.98 | AC13: 2.98 | AD13: CONTINUOUS SLIP TRACK per 4/A12.01 | AE13: 8.94 | AF13: 24 | AH13: 45.82 | AI13: 11.92 | AJ13: PENDING (see Blocking sheet) | AL13: [DERIVADO] vector A02.01 | AM13: A02.01 (hatch KEVLAR legend A02.01 (no own tag)) -> 4/A12.01 -> 7/S5.20 -> S2.20 B.O.D. -> A04.01 ceiling | AN13: b8f5af71bcddbc9c
A14: 12 | B14: A1K - 3-5/8" 14 GA MST @ 24" O.C. (362S137-68) - board per face, see Side 1 / Side 2 (1 instance) | C14: Teller line south cap | D14: 2.98 | E14: 13.052 | F14: =ROUND(((O14)+(R14))*1,2) -> 2 | H14: 52.21 | J14: 362S137-68 | K14: 24 | L14: 4 | M14: Cash Window 116 | N14: 13.052 | O14: 1 | P14: Future FCAM | Q14: 13.052 | R14: 1 | S14: 0 | T14: =D14*N14*O14-S14*O14+D14*Q14*R14-S14*R14 -> 77.78992 | U14: 15.05 | V14: 23.84 | AB14: 2.98 | AC14: 2.98 | AD14: CONTINUOUS SLIP TRACK per 4/A12.01 | AE14: 8.94 | AF14: 24 | AH14: 38.89 | AI14: 11.92 | AJ14: PENDING (see Blocking sheet) | AL14: [DERIVADO] vector A02.01 | AM14: A02.01 (hatch KEVLAR legend A02.01 (no own tag)) -> 4/A12.01 -> 7/S5.20 -> S2.20 B.O.D. -> A04.01 ceiling | AN14: 3e5fa2f93e7f3207
A15: 15 | B15: A5 - 6" MST @ 16" O.C. (600S137-33) - board per face, see Side 1 / Side 2 (1 instance) | C15: Calling Cubes 122 east / Central Zone 103 | D15: 19.41 | E15: 15.375 | F15: 2 | G15: 267.46 | J15: 600S137-33 | K15: 16 | L15: 18 | M15: Calling Cubes 122 | N15: 9 | O15: 1 | P15: Central Zone 103 | Q15: 9.5 | R15: 1 | S15: 0 | T15: 359.09 | AB15: 19.41 | AC15: 19.41 | AD15: CONTINUOUS SLIP TRACK per 3/A12.01 | AE15: 58.23 | AF15: 108 | AH15: 288.35 | AI15: 38.82 | AJ15: PENDING (see Blocking sheet) | AL15: [DERIVADO] vector A02.01 | AM15: A02.01 (tag A5 @1543,1118) -> 3/A12.01 -> 7/S5.20 -> S2.20 B.O.D. -> A04.01 ceiling | AN15: 1573b37c962264a2
A16: 14 | B16: A5 - 6" MST @ 16" O.C. (600S137-33) - board per face, see Side 1 / Side 2 (1 instance) | C16: Calling Cubes 122 west / Central Zone & Corridor 111 (door 122) | D16: 19 | E16: 15.375 | F16: 2 | G16: 340.53 | J16: 600S137-33 | K16: 16 | L16: 24 | M16: Calling Cubes 122 | N16: 9 | O16: 1 | P16: Central Zone 103 / Corridor 111 | Q16: 12 | R16: 1 | S16: 23.89 | T16: 351.22 | AB16: 19 | AC16: 19 | AD16: CONTINUOUS SLIP TRACK per 3/A12.01 | AE16: 57 | AF16: 144 | AG16: 4.33 | AH16: 259.16 | AI16: 38 | AJ16: PENDING (see Blocking sheet) | AL16: [DERIVADO] vector A02.01 | AM16: A02.01 (tags A5 @1209,1129 and @1264,1240) -> 3/A12.01 -> 7/S5.20 -> S2.20 B.O.D. -> A04.01 ceiling -> A00.30 HEAD 10/A12.02, JAMB 11/A12.02 | AN16: 449509c616dd77f5
A17: 16 | B17: A5 - 6" MST @ 16" O.C. (600S137-33) - board per face, see Side 1 / Side 2 (1 instance) | C17: Future FCAM west / Break Room 118 | D17: 3.71 | E17: 13.052 | F17: =ROUND(((O17)+(R17))*1,2) -> 2 | G17: 65.26 | J17: 600S137-33 | K17: 16 | L17: 5 | M17: Future FCAM | N17: 9.5 | O17: 1 | P17: Break Room 118 | Q17: 9 | R17: 1 | S17: 0 | T17: =D17*N17*O17-S17*O17+D17*Q17*R17-S17*R17 -> 68.635 | AB17: 3.71 | AC17: 3.71 | AD17: CONTINUOUS SLIP TRACK per 3/A12.01 | AE17: 11.13 | AF17: 30 | AH17: 48.47 | AI17: 7.42 | AJ17: PENDING (see Blocking sheet) | AL17: [DERIVADO] vector A02.01 | AM17: A02.01 (tag A5 @1650,1410) -> 3/A12.01 -> 7/S5.20 -> S2.20 B.O.D. -> A04.01 ceiling | AN17: fb8ae23bcf90dd29
A18: 19 | B18: B - 3-5/8" MST @ 16" O.C. (362S137-33) - board per face, see Side 1 / Side 2 (1 instance) | C18: Electrical 120 & NER 121 east / Break Room 118 | D18: 14.15 | E18: 13.052 | F18: =ROUND(((O18)+(R18))*1,2) -> 2 | H18: 309.4 | J18: 362S137-33 | K18: 16 | L18: 27 | M18: Electrical 120 / NER 121 | N18: 13.052 | O18: 1 | P18: Break Room 118 | Q18: 13.052 | R18: 1 | S18: 47.78 | T18: =D18*N18*O18-S18*O18+D18*Q18*R18-S18*R18 -> 273.8116 | AB18: 14.15 | AC18: 14.15 | AD18: CONTINUOUS SLIP TRACK per 1/A12.01 | AE18: 42.45 | AF18: 162 | AG18: 8.67 | AH18: 136.87 | AI18: 56.6 | AJ18: PENDING (see Blocking sheet) | AL18: [DERIVADO] vector A02.01 | AM18: A02.01 (tag B @1400,1584) -> 1/A12.01 -> 7/S5.20 -> S2.20 B.O.D. -> A04.01 ceiling -> A00.30 HEAD 10/A12.02, JAMB 11/A12.02 | AN18: 2381d0116a0ab104
A19: 22 | B19: B - 3-5/8" MST @ 16" O.C. (362S137-33) - board per face, see Side 1 / Side 2 (1 instance) | C19: Janitor Closet 112 & Storage 117 / Wellness 115 | D19: 11.73 | E19: 13.052 | F19: =ROUND(((O19)+(R19))*1,2) -> 2 | H19: 143.57 | J19: 362S137-33 | K19: 16 | L19: 11 | M19: Janitor Closet 112 / Storage 117 | N19: 13.052 | O19: 1 | P19: Wellness 115 | Q19: 13.052 | R19: 1 | S19: 0 | T19: =D19*N19*O19-S19*O19+D19*Q19*R19-S19*R19 -> 306.19992 | AB19: 11.73 | AC19: 11.73 | AD19: CONTINUOUS SLIP TRACK per 1/A12.01 | AE19: 35.19 | AF19: 66 | AH19: 153.14 | AI19: 46.92 | AJ19: PENDING (see Blocking sheet) | AL19: [DERIVADO] vector A02.01 | AM19: A02.01 (tags B @944,1567 and @1101,1607) -> 1/A12.01 -> 7/S5.20 -> S2.20 B.O.D. -> A04.01 ceiling | AN19: 3f44e25de778249d
A20: 20 | B20: B - 3-5/8" MST @ 16" O.C. (362S137-33) - board per face, see Side 1 / Side 2 (1 instance) | C20: Mens Restroom 113 south / Janitor Closet 112 & Storage 117 north | D20: 11.73 | E20: 13.052 | F20: =ROUND(((O20)+(R20))*1,2) -> 2 | H20: 213.43 | J20: 362S137-33 | K20: 16 | L20: 18 | M20: Mens Restroom 113 | N20: 13.052 | O20: 1 | P20: Janitor Closet 112 / Storage 117 | Q20: 13.052 | R20: 1 | S20: 23.89 | T20: =D20*N20*O20-S20*O20+D20*Q20*R20-S20*R20 -> 258.41992 | AB20: 11.73 | AC20: 11.73 | AD20: CONTINUOUS SLIP TRACK per 1/A12.01 | AE20: 35.19 | AF20: 108 | AG20: 4.33 | AH20: 129.26 | AI20: 46.92 | AJ20: PENDING (see Blocking sheet) | AL20: [DERIVADO] vector A02.01 | AM20: A02.01 (tag B @1052,1497) -> 1/A12.01 -> 7/S5.20 -> S2.20 B.O.D. -> A04.01 ceiling -> A00.30 HEAD 10/A12.02, JAMB 11/A12.02 | AN20: 90cb13724e02a18e
A21: 17 | B21: B - 3-5/8" MST @ 16" O.C. (362S137-33) - board per face, see Side 1 / Side 2 (1 instance) | C21: Electrical 120 north / Break Room 118 | D21: 9.58 | E21: 13.052 | F21: =ROUND(((O21)+(R21))*1,2) -> 2 | H21: 130.52 | J21: 362S137-33 | K21: 16 | L21: 10 | M21: Electrical 120 | N21: 13.052 | O21: 1 | P21: Break Room 118 | Q21: 13.052 | R21: 1 | S21: 0 | T21: =D21*N21*O21-S21*O21+D21*Q21*R21-S21*R21 -> 250.07632 | AB21: 9.58 | AC21: 9.58 | AD21: CONTINUOUS SLIP TRACK per 1/A12.01 | AE21: 28.74 | AF21: 60 | AH21: 125.04 | AI21: 38.32 | AJ21: PENDING (see Blocking sheet) | AL21: [DERIVADO] vector A02.01 | AM21: A02.01 (tag B @1380,1457) -> 1/A12.01 -> 7/S5.20 -> S2.20 B.O.D. -> A04.01 ceiling | AN21: 5d100aa0ef19de8d
A22: 18 | B22: B - 3-5/8" MST @ 16" O.C. (362S137-33) - board per face, see Side 1 / Side 2 (1 instance) | C22: Electrical 120 / NER 121 | D22: 9.58 | E22: 13.052 | F22: =ROUND(((O22)+(R22))*1,2) -> 2 | H22: 130.52 | J22: 362S137-33 | K22: 16 | L22: 10 | M22: Electrical 120 | N22: 13.052 | O22: 1 | P22: NER 121 | Q22: 13.052 | R22: 1 | S22: 0 | T22: =D22*N22*O22-S22*O22+D22*Q22*R22-S22*R22 -> 250.07632 | AB22: 9.58 | AC22: 9.58 | AD22: CONTINUOUS SLIP TRACK per 1/A12.01 | AE22: 28.74 | AF22: 60 | AH22: 125.04 | AI22: 38.32 | AJ22: PENDING (see Blocking sheet) | AL22: [DERIVADO] vector A02.01 | AM22: A02.01 (tag B @1383,1572) -> 1/A12.01 -> 7/S5.20 -> S2.20 B.O.D. -> A04.01 ceiling | AN22: 0da09bcddeb876a5
A23: 21 | B23: B - 3-5/8" MST @ 16" O.C. (362S137-33) - board per face, see Side 1 / Side 2 (1 instance) | C23: Janitor Closet 112 / Storage 117 | D23: 3.5 | E23: 13.052 | F23: =ROUND(((O23)+(R23))*1,2) -> 2 | H23: 65.26 | J23: 362S137-33 | K23: 16 | L23: 5 | M23: Janitor Closet 112 | N23: 13.052 | O23: 1 | P23: Storage 117 | Q23: 13.052 | R23: 1 | S23: 0 | T23: =D23*N23*O23-S23*O23+D23*Q23*R23-S23*R23 -> 91.364 | AB23: 3.5 | AC23: 3.5 | AD23: CONTINUOUS SLIP TRACK per 1/A12.01 | AE23: 10.5 | AF23: 30 | AH23: 45.68 | AI23: 14 | AJ23: PENDING (see Blocking sheet) | AL23: [DERIVADO] vector A02.01 | AM23: A02.01 (tag B @1048,1532) -> 1/A12.01 -> 7/S5.20 -> S2.20 B.O.D. -> A04.01 ceiling | AN23: a3d71077804295b1
A24: 23 | B24: B2 - 6" MST @ 16" O.C. (600S137-33) - board per face, see Side 1 / Side 2 (1 instance) | C24: Corridor 111 west / Restrooms 114 & 113, Storage 117, Wellness 115 east (incl. drinking fountain alcove) | D24: 29.19 | E24: 15.375 | F24: 2 | G24: 677.77 | J24: 600S137-33 | K24: 16 | L24: 53 | M24: Corridor 111 | N24: 15.375 | O24: 1 | P24: Restrooms / Storage / Wellness | Q24: 15.375 | R24: 1 | S24: 95.55 | T24: 573.56 | AB24: 29.19 | AC24: 29.19 | AD24: CONTINUOUS SLIP TRACK per 1/A12.01 | AE24: 87.57 | AF24: 318 | AG24: 17.33 | AH24: 286.78 | AI24: 116.76 | AJ24: PENDING (see Blocking sheet) | AL24: [DERIVADO] vector A02.01 | AM24: A02.01 (tags B2 @1146,1314 @1154,1438 @1152,1597) -> 1/A12.01 -> 7/S5.20 -> S2.20 B.O.D. -> A04.01 ceiling -> A00.30 HEAD 10/A12.02, JAMB 11/A12.02 | AN24: 458761b4503a992b
A25: 25 | B25: B2 - 6" MST @ 16" O.C. (600S137-33) - board per face, see Side 1 / Side 2 (1 instance) | C25: Break Room 118 / Work Room 119 (door 116) | D25: 15.07 | E25: 13.052 | F25: =ROUND(((O25)+(R25))*1,2) -> 2 | G25: 252.59 | J25: 600S137-33 | K25: 16 | L25: 21 | M25: Break Room 118 | N25: 13.052 | O25: 1 | P25: Work Room 119 / FCAM | Q25: 13.052 | R25: 1 | S25: 23.89 | T25: =D25*N25*O25-S25*O25+D25*Q25*R25-S25*R25 -> 345.60728 | AB25: 15.07 | AC25: 15.07 | AD25: CONTINUOUS SLIP TRACK per 1/A12.01 | AE25: 45.21 | AF25: 126 | AG25: 4.33 | AH25: 172.85 | AI25: 60.28 | AJ25: PENDING (see Blocking sheet) | AL25: [DERIVADO] vector A02.01 | AM25: A02.01 (tags B2 @1603,1493 and @1652,1622) -> 1/A12.01 -> 7/S5.20 -> S2.20 B.O.D. -> A04.01 ceiling -> A00.30 HEAD 10/A12.02, JAMB 11/A12.02 | AN25: cb2d3f1223928700
A26: 24 | B26: B2 - 6" MST @ 16" O.C. (600S137-33) - board per face, see Side 1 / Side 2 (1 instance) | C26: ATM Room 102 east / 24 HR Vestibule & Central Zone (door 102) | D26: 6.64 | E26: 15.375 | F26: =ROUND(((O26)+(R26))*1,2) -> 2 | G26: 190.75 | J26: 600S137-33 | K26: 16 | L26: 14 | M26: ATM Room 102 | N26: 15.375 | O26: 1 | P26: Central Zone 103 | Q26: 15.375 | R26: 1 | S26: 31.3 | T26: =D26*N26*O26-S26*O26+D26*Q26*R26-S26*R26 -> 141.58 | AB26: 6.64 | AC26: 6.64 | AD26: CONTINUOUS SLIP TRACK per 1/A12.01 | AE26: 19.92 | AF26: 84 | AG26: 4.83 | AH26: 70.77 | AI26: 26.56 | AJ26: PENDING (see Blocking sheet) | AL26: [DERIVADO] vector A02.01 | AM26: A02.01 (tag B2 @1110,746) -> 1/A12.01 -> 7/S5.20 -> S2.20 B.O.D. -> A04.01 ceiling -> A00.30 HEAD 10/A12.02, JAMB 11/A12.02 | AN26: 60a2d1639746e592
A27: 26 | B27: B2K - 6" 14 GA MST @ 24" O.C. (600S137-68) - board per face, see Side 1 / Side 2 (1 instance) | C27: Teller line NW corner (Office 108 / Cash Window) | D27: 2.21 | E27: 15.375 | F27: =ROUND(((O27)+(R27))*1,2) -> 2 | G27: 61.5 | J27: 600S137-68 | K27: 24 | L27: 4 | M27: Office 108 side | N27: 15.375 | O27: 1 | P27: Cash Window 116 | Q27: 15.375 | R27: 1 | S27: 0 | T27: =D27*N27*O27-S27*O27+D27*Q27*R27-S27*R27 -> 67.9575 | U27: 16.3 | V27: 17.68 | AB27: 2.21 | AC27: 2.21 | AD27: CONTINUOUS SLIP TRACK per 4/A12.01 | AE27: 6.63 | AF27: 24 | AH27: 33.93 | AI27: 8.84 | AJ27: PENDING (see Blocking sheet) | AL27: [DERIVADO] vector A02.01 | AM27: A02.01 (tag B2K @1637,1136) -> 4/A12.01 -> 7/S5.20 -> S2.20 B.O.D. -> A04.01 ceiling | AN27: d1261f240244c6f3
A28: 28 | B28: C1 - 3-5/8" furring MST @ 16" O.C. (362S137-33) - board per face, see Side 1 / Side 2 (1 instance) | C28: Plumbing chase - Mens Restroom 113 face | D28: 10.03 | E28: 13.052 | F28: =O28 -> 1 | H28: 130.52 | J28: 362S137-33 | K28: 16 | L28: 10 | M28: Mens Restroom 113 | N28: 9 | O28: 1 | S28: 0 | T28: =D28*N28*O28-S28*O28 -> 90.27 | AB28: 10.03 | AC28: 10.03 | AD28: CONTINUOUS SLIP TRACK per 6/A12.01 | AE28: 30.09 | AF28: 60 | AH28: 130.9 | AI28: 20.06 | AJ28: PENDING (see Blocking sheet) | AL28: [DERIVADO] vector A02.01 | AM28: A02.01 (tag C1 @1004,1400) -> 6/A12.01 -> 7/S5.20 -> S2.20 B.O.D. -> A04.01 ceiling | AN28: a26e1d399994acda
A29: 27 | B29: C1 - 3-5/8" furring MST @ 16" O.C. (362S137-33) - board per face, see Side 1 / Side 2 (1 instance) | C29: Plumbing chase - Womens Restroom 114 face | D29: 10.03 | E29: 13.052 | F29: =O29 -> 1 | H29: 130.52 | J29: 362S137-33 | K29: 16 | L29: 10 | M29: Womens Restroom 114 | N29: 9 | O29: 1 | S29: 0 | T29: =D29*N29*O29-S29*O29 -> 90.27 | AB29: 10.03 | AC29: 10.03 | AD29: CONTINUOUS SLIP TRACK per 6/A12.01 | AE29: 30.09 | AF29: 60 | AH29: 130.9 | AI29: 20.06 | AJ29: PENDING (see Blocking sheet) | AL29: [DERIVADO] vector A02.01 | AM29: A02.01 (tag C1 @1005,1342) -> 6/A12.01 -> 7/S5.20 -> S2.20 B.O.D. -> A04.01 ceiling | AN29: 840b092a020d88ff
A30: 29 | B30: C1 - 3-5/8" furring MST @ 16" O.C. (362S137-33) - board per face, see Side 1 / Side 2 (1 instance) | C30: Display monitor furring - Waiting 104 face of wall 1 (keynote 7) | D30: 9.29 | E30: 15.375 | F30: =O30 -> 1 | H30: 138.38 | J30: 362S137-33 | K30: 16 | L30: 9 | M30: Waiting 104 | N30: 11.5 | O30: 1 | S30: 0 | T30: =D30*N30*O30-S30*O30 -> 106.835 | AB30: 9.29 | AC30: 9.29 | AD30: CONTINUOUS SLIP TRACK per 6/A12.01 | AE30: 27.87 | AF30: 54 | AH30: 142.89 | AI30: 18.58 | AJ30: PENDING (see Blocking sheet) | AL30: [DERIVADO] vector A02.01 | AM30: A02.01 (tag C1 @1304,943) -> 6/A12.01 -> 7/S5.20 -> S2.20 B.O.D. -> A04.01 ceiling | AN30: b32b408f4cb23acc
A31: 30 | B31: F - 3-5/8" MST @ 16" O.C. (362S137-33) - board per face, see Side 1 / Side 2 (1 instance) | C31: ATM wall (inclined 30 deg) 24 HR Vestibule 101 / ATM Room 102 | D31: 16.92 | E31: 15.375 | F31: =ROUND(((O31)+(R31))*1,2) -> 2 | H31: 317.5 | J31: 362S137-33 | K31: 16 | L31: 23 | M31: 24 HR Vestibule 101 | N31: 10 | O31: 1 | P31: ATM Room 102 | Q31: 9 | R31: 1 | S31: 6.05 | T31: =D31*N31*O31-S31*O31+D31*Q31*R31-S31*R31 -> 309.38 | W31: 260.15 | AB31: 16.92 | AC31: 16.92 | AD31: CONTINUOUS SLIP TRACK per 12/A12.01 | AE31: 50.76 | AF31: 138 | AG31: 3.25 | AH31: 260.15 | AI31: 33.84 | AJ31: PENDING (see Blocking sheet) | AL31: [DERIVADO] vector A02.01 | AM31: A02.01 (tag F @1073,672) -> 12/A12.01 -> 7/S5.20 -> S2.20 B.O.D. -> A04.01 ceiling -> A00.30 HEAD 10/A12.02, JAMB 11/A12.02 | AN31: 2703fea400bb2cd3
A32: 32 | B32: G - 1-5/8" double row MST @ 16" O.C. (162S125-33 (DERIVED)) - board per face, see Side 1 / Side 2 (1 instance) | C32: Office 107 / Office 108 | D32: 11.77 | E32: 15.375 | F32: =ROUND(((O32)+(R32))*1,2) -> 4 | I32: 338.25 | J32: 162S125-33 (DERIVED) | K32: 16 | L32: 22 | M32: Office 107 | N32: 15.375 | O32: 2 | P32: Office 108 | Q32: 15.375 | R32: 2 | S32: 0 | T32: =D32*N32*O32-S32*O32+D32*Q32*R32-S32*R32 -> 723.855 | AB32: 23.54 | AC32: 23.54 | AD32: CONTINUOUS SLIP TRACK per 5/A12.01 | AE32: 70.62 | AF32: 132 | AH32: 180.91 | AI32: 47.08 | AJ32: PENDING (see Blocking sheet) | AL32: [DERIVADO] vector A02.01 | AM32: A02.01 (tag G @1716,937) -> 5/A12.01 -> 7/S5.20 -> S2.20 B.O.D. -> A04.01 ceiling | AN32: 85ea94924962db6a
A33: 31 | B33: G - 1-5/8" double row MST @ 16" O.C. (162S125-33 (DERIVED)) - board per face, see Side 1 / Side 2 (1 instance) | C33: Office 106 / Office 107 | D33: 11.77 | E33: 15.375 | F33: =ROUND(((O33)+(R33))*1,2) -> 4 | I33: 338.25 | J33: 162S125-33 (DERIVED) | K33: 16 | L33: 22 | M33: Office 106 | N33: 15.375 | O33: 2 | P33: Office 107 | Q33: 15.375 | R33: 2 | S33: 0 | T33: =D33*N33*O33-S33*O33+D33*Q33*R33-S33*R33 -> 723.855 | AB33: 23.54 | AC33: 23.54 | AD33: CONTINUOUS SLIP TRACK per 5/A12.01 | AE33: 70.62 | AF33: 132 | AH33: 180.91 | AI33: 47.08 | AJ33: PENDING (see Blocking sheet) | AL33: [DERIVADO] vector A02.01 | AM33: A02.01 (tag G @1713,742) -> 5/A12.01 -> 7/S5.20 -> S2.20 B.O.D. -> A04.01 ceiling | AN33: dfca61ea510ec211
A34: 40 | B34: G - 1-5/8" double row MST @ 16" O.C. (162S125-33 (DERIVED)) - board per face, see Side 1 / Side 2 (1 instance) | C34: Office 110 / Womens Restroom 114 | D34: 11.63 | E34: 15.375 | F34: =ROUND(((O34)+(R34))*1,2) -> 4 | I34: 338.25 | J34: 162S125-33 (DERIVED) | K34: 16 | L34: 22 | M34: Office 110 | N34: 15.375 | O34: 2 | P34: Womens Restroom 114 | Q34: 15.375 | R34: 2 | S34: 0 | T34: =D34*N34*O34-S34*O34+D34*Q34*R34-S34*R34 -> 715.245 | AB34: 23.26 | AC34: 23.26 | AD34: CONTINUOUS SLIP TRACK per 5/A12.01 | AE34: 69.78 | AF34: 132 | AH34: 178.76 | AI34: 46.52 | AJ34: PENDING (see Blocking sheet) | AL34: [DERIVADO] vector A02.01 | AM34: A02.01 (tag G @1010,1211) -> 5/A12.01 -> 7/S5.20 -> S2.20 B.O.D. -> A04.01 ceiling | AN34: 95c0914f7f854aa7
A35: 38 | B35: G - 1-5/8" double row MST @ 16" O.C. (162S125-33 (DERIVED)) - board per face, see Side 1 / Side 2 (1 instance) | C35: ATM Room 102 / Office 109 | D35: 11.63 | E35: 15.375 | F35: =ROUND(((O35)+(R35))*1,2) -> 4 | I35: 338.25 | J35: 162S125-33 (DERIVED) | K35: 16 | L35: 22 | M35: ATM Room 102 | N35: 15.375 | O35: 2 | P35: Office 109 | Q35: 15.375 | R35: 2 | S35: 0 | T35: =D35*N35*O35-S35*O35+D35*Q35*R35-S35*R35 -> 715.245 | AB35: 23.26 | AC35: 23.26 | AD35: CONTINUOUS SLIP TRACK per 5/A12.01 | AE35: 69.78 | AF35: 132 | AH35: 178.76 | AI35: 46.52 | AJ35: PENDING (see Blocking sheet) | AL35: [DERIVADO] vector A02.01 | AM35: A02.01 (tag G @1052,818) -> 5/A12.01 -> 7/S5.20 -> S2.20 B.O.D. -> A04.01 ceiling | AN35: d1b5c3aba3cc8c73
A36: 39 | B36: G - 1-5/8" double row MST @ 16" O.C. (162S125-33 (DERIVED)) - board per face, see Side 1 / Side 2 (1 instance) | C36: Office 109 / Office 110 | D36: 11.63 | E36: 15.375 | F36: =ROUND(((O36)+(R36))*1,2) -> 4 | I36: 338.25 | J36: 162S125-33 (DERIVED) | K36: 16 | L36: 22 | M36: Office 109 | N36: 15.375 | O36: 2 | P36: Office 110 | Q36: 15.375 | R36: 2 | S36: 0 | T36: =D36*N36*O36-S36*O36+D36*Q36*R36-S36*R36 -> 715.245 | AB36: 23.26 | AC36: 23.26 | AD36: CONTINUOUS SLIP TRACK per 5/A12.01 | AE36: 69.78 | AF36: 132 | AH36: 178.76 | AI36: 46.52 | AJ36: PENDING (see Blocking sheet) | AL36: [DERIVADO] vector A02.01 | AM36: A02.01 (tag G @1053,1049) -> 5/A12.01 -> 7/S5.20 -> S2.20 B.O.D. -> A04.01 ceiling | AN36: 90c02d1bb0f0e82e
A37: 33 | B37: G - 1-5/8" double row MST @ 16" O.C. (162S125-33 (DERIVED)) - board per face, see Side 1 / Side 2 (1 instance) | C37: Office 108 / Cash Window 116 | D37: 7.09 | E37: 15.375 | F37: =ROUND(((O37)+(R37))*1,2) -> 4 | I37: 246 | J37: 162S125-33 (DERIVED) | K37: 16 | L37: 16 | M37: Office 108 | N37: 15.375 | O37: 2 | P37: Cash Window 116 | Q37: 15.375 | R37: 2 | S37: 0 | T37: =D37*N37*O37-S37*O37+D37*Q37*R37-S37*R37 -> 436.035 | AB37: 14.18 | AC37: 14.18 | AD37: CONTINUOUS SLIP TRACK per 5/A12.01 | AE37: 42.54 | AF37: 96 | AH37: 109.06 | AI37: 28.36 | AJ37: PENDING (see Blocking sheet) | AL37: [DERIVADO] vector A02.01 | AM37: A02.01 (tag G @1766,1129) -> 5/A12.01 -> 7/S5.20 -> S2.20 B.O.D. -> A04.01 ceiling | AN37: 79103f4c2266d860
A38: 35 | B38: G - 1-5/8" double row MST @ 16" O.C. (162S125-33 (DERIVED)) - board per face, see Side 1 / Side 2 (1 instance) | C38: pier between office fronts 105/106 | D38: 3.47 | E38: 15.375 | F38: =ROUND(((O38)+(R38))*1,2) -> 4 | I38: 153.75 | J38: 162S125-33 (DERIVED) | K38: 16 | L38: 10 | M38: Office 105/106 | N38: 15.375 | O38: 2 | P38: Central Zone 103 | Q38: 15.375 | R38: 2 | S38: 0 | T38: =D38*N38*O38-S38*O38+D38*Q38*R38-S38*R38 -> 213.405 | AB38: 6.94 | AC38: 6.94 | AD38: CONTINUOUS SLIP TRACK per 5/A12.01 | AE38: 20.82 | AF38: 60 | AH38: 53.3 | AI38: 13.88 | AJ38: PENDING (see Blocking sheet) | AL38: [DERIVADO] vector A02.01 | AM38: A02.01 (tag G @1602,546) -> 5/A12.01 -> 7/S5.20 -> S2.20 B.O.D. -> A04.01 ceiling | AN38: cae17a4876408c84
A39: 36 | B39: G - 1-5/8" double row MST @ 16" O.C. (162S125-33 (DERIVED)) - board per face, see Side 1 / Side 2 (1 instance) | C39: pier between office fronts 106/107 | D39: 3.26 | E39: 15.375 | F39: =ROUND(((O39)+(R39))*1,2) -> 4 | I39: 153.75 | J39: 162S125-33 (DERIVED) | K39: 16 | L39: 10 | M39: Office 106/107 | N39: 15.375 | O39: 2 | P39: Central Zone 103 | Q39: 15.375 | R39: 2 | S39: 0 | T39: =D39*N39*O39-S39*O39+D39*Q39*R39-S39*R39 -> 200.49 | AB39: 6.52 | AC39: 6.52 | AD39: CONTINUOUS SLIP TRACK per 5/A12.01 | AE39: 19.56 | AF39: 60 | AH39: 50.05 | AI39: 13.04 | AJ39: PENDING (see Blocking sheet) | AL39: [DERIVADO] vector A02.01 | AM39: A02.01 (tag G @1605,749) -> 5/A12.01 -> 7/S5.20 -> S2.20 B.O.D. -> A04.01 ceiling | AN39: dd057e416849fff8
A40: 37 | B40: G - 1-5/8" double row MST @ 16" O.C. (162S125-33 (DERIVED)) - board per face, see Side 1 / Side 2 (1 instance) | C40: pier between office fronts 107/108 | D40: 3.25 | E40: 15.375 | F40: =ROUND(((O40)+(R40))*1,2) -> 4 | I40: 153.75 | J40: 162S125-33 (DERIVED) | K40: 16 | L40: 10 | M40: Office 107/108 | N40: 15.375 | O40: 2 | P40: Central Zone 103 | Q40: 15.375 | R40: 2 | S40: 0 | T40: =D40*N40*O40-S40*O40+D40*Q40*R40-S40*R40 -> 199.875 | AB40: 6.5 | AC40: 6.5 | AD40: CONTINUOUS SLIP TRACK per 5/A12.01 | AE40: 19.5 | AF40: 60 | AH40: 49.99 | AI40: 13 | AJ40: PENDING (see Blocking sheet) | AL40: [DERIVADO] vector A02.01 | AM40: A02.01 (tag G @1602,940) -> 5/A12.01 -> 7/S5.20 -> S2.20 B.O.D. -> A04.01 ceiling | AN40: 0ebe6d3c4508cb16
...

Sheet Exterior
A1: Closure | B1: Facade / segment (axis kept separate) | C1: Length (LF) | D1: Stud height (FT) | E1: 6" Metal Stud 600S137-33 (LF) | F1: Parapet stud 600S162-54 (LF) | G1: Stud pcs | H1: Bottom track (LF) | I1: Top / deflection track (LF) | J1: Header (LF) | K1: Sill track (LF) | L1: Bracing (LF) | M1: Clips (ea) | N1: 5/8" Gyp Board interior face (SF) | O1: 5/8" Glass Mat Sheathing (SF) | P1: 5/8" Exterior Gypsum Sheathing - parapet (SF) | Q1: ALT: 5/8" FRT ply + 2 1/2" polyiso (SF) - not in base | R1: Box beam over storefront (LF) | S1: 3/4" FRT plywood at opening (LF) | T1: Gyp jamb return (LF) | U1: Sealant (LF) | V1: Detail sequence | W1: Seal
A2: X45_EXT-E | B2: East facade grid 8, interior face x=1843.08 (offices 105-108, cash window, work room) | C2: 75.33 | D2: 15.375 | E2: 1483.49 | G2: 131 | H2: 75.33 | I2: 75.33 | J2: 36 | K2: 32 | L2: 225.99 | M2: 786 | N2: 1036.56 | O2: 1036.56 | Q2: 1036.56 | U2: 75.33 | V2: A02.01 plan face -> C/A09.21 WALL SECTION -> 5/A09.26 SECTION DETAIL @ ACM BASE -> 7/S5.20 METAL STUD SCHEDULE -> S2.20 B.O.D. | W2: c51aeb1bbc1b4523
A3: X47_EXT-S | B3: South facade grid A, interior face y=1693.44 (wellness, NER, break, work room) | C3: 51.73 | D3: 13.052 | E3: 601.99 | G3: 48 | H3: 51.73 | I3: 51.73 | J3: 4.33 | L3: 155.19 | M3: 288 | N3: 648 | O3: 648 | Q3: 648 | U3: 51.73 | V3: A02.01 plan face -> C/A09.21 WALL SECTION -> 5/A09.26 SECTION DETAIL @ ACM BASE -> 7/S5.20 METAL STUD SCHEDULE -> S2.20 B.O.D. | W3: 56d6250c0df3c737
A4: X48_EXT-W1 | B4: West facade grid 1, interior face x=911.88 (offices 109/110, restrooms, janitor, wellness) | C4: 47.41 | D4: 15.375 | E4: 850.36 | G4: 74 | H4: 47.41 | I4: 47.41 | J4: 18 | K4: 16 | L4: 142.23 | M4: 444 | N4: 639.29 | O4: 639.29 | Q4: 639.29 | U4: 47.41 | V4: A02.01 plan face -> C/A09.21 WALL SECTION -> 5/A09.26 SECTION DETAIL @ ACM BASE -> 7/S5.20 METAL STUD SCHEDULE -> S2.20 B.O.D. | W4: d5847a382bbdaba4
A5: X50_EXT-W2 | B5: West facade grid 1 north, interior face x=841.56 (24 HR vestibule 101 / ATM room 102, Day 1 ATM) | C5: 21.42 | D5: 15.375 | E5: 379.16 | G5: 27 | H5: 21.42 | I5: 21.42 | J5: 3.18 | K5: 2.18 | L5: 64.26 | M5: 162 | N5: 323.69 | O5: 323.69 | Q5: 323.69 | U5: 21.42 | V5: A02.01 plan face -> C/A09.21 WALL SECTION -> 5/A09.26 SECTION DETAIL @ ACM BASE -> 7/S5.20 METAL STUD SCHEDULE -> S2.20 B.O.D. | W5: 64bdc98b68e72143
A6: X51_EXT-W3 | B6: West facade jog south of ATM room, y=840.72 from x 841.56 to 911.88 | C6: 3.91 | D6: 15.375 | E6: 76.88 | G6: 5 | H6: 3.91 | I6: 3.91 | L6: 11.73 | M6: 30 | N6: 60.07 | O6: 60.07 | Q6: 60.07 | U6: 3.91 | V6: A02.01 plan face -> C/A09.21 WALL SECTION -> 5/A09.26 SECTION DETAIL @ ACM BASE -> 7/S5.20 METAL STUD SCHEDULE -> S2.20 B.O.D. | W6: 393d2e8f17c63e31
A7: X52_EXT-N1 | B7: North facade grid G/F east part, interior face y=337.44 (office 105 + NE pier) | C7: 12.64 | D7: 15.375 | E7: 184.5 | G7: 12 | H7: 12.64 | I7: 12.64 | L7: 37.92 | M7: 72 | N7: 194.31 | O7: 194.31 | Q7: 194.31 | U7: 12.64 | V7: A02.01 plan face -> C/A09.21 WALL SECTION -> 5/A09.26 SECTION DETAIL @ ACM BASE -> 7/S5.20 METAL STUD SCHEDULE -> S2.20 B.O.D. | W7: 3ade2cb2b104d9ea
A8: X53_SFband | B8: North storefront head band, Central Zone 103 (26.68 ft storefront 1135.4->1615.6 A02.01) | C8: 26.68 | D8: 6.88 | E8: 144.48 | G8: 21 | H8: 26.68 | I8: 26.68 | L8: 26.68 | M8: 42 | N8: 183.56 | O8: 183.56 | R8: 26.68 | S8: 26.68 | T8: 26.68 | U8: 26.68 | V8: A02.01 storefront (Div 08) -> A09.01 elevation T/GLAZING 8-6 -> A/A09.21 SECTION A @ ENTRANCE DOOR -> 11/A09.27 storefront head | W8: 67827df3e54a04c5
A9: X54_SFband | B9: North storefront head band, Vestibule 100 (841.6->1126.4 A02.01, incl. C1 columns) | C9: 15.82 | D9: 6.88 | E9: 82.56 | G9: 12 | H9: 15.82 | I9: 15.82 | L9: 15.82 | M9: 24 | N9: 108.84 | O9: 108.84 | R9: 15.82 | S9: 15.82 | T9: 15.82 | U9: 15.82 | V9: A02.01 storefront (Div 08) -> A09.01 elevation T/GLAZING 8-6 -> A/A09.21 SECTION A @ ENTRANCE DOOR -> 11/A09.27 storefront head | W9: 3f117f156f6fe858
A10: X55_SFband | B10: West storefront head band, Vestibule 100 (x~832, 318.6->454.4 A02.01) | C10: 7.54 | D10: 6.88 | E10: 41.28 | G10: 6 | H10: 7.54 | I10: 7.54 | L10: 7.54 | M10: 12 | N10: 51.88 | O10: 51.88 | R10: 7.54 | S10: 7.54 | T10: 7.54 | U10: 7.54 | V10: A02.01 storefront (Div 08) -> A09.01 elevation T/GLAZING 8-6 -> A/A09.21 SECTION A @ ENTRANCE DOOR -> 11/A09.27 storefront head | W10: 7417b96c54632d83
A11: X56_parapet | B11: Parapet infill above B.O.D., E-HI 50.50 + N1 12.64 + N2 26.68 + W1-HI 22.58 + W2 21.42 + W3 3.91 | C11: 137.73 | D11: 2.04 | F11: 326.4 | G11: 160 | H11: 137.73 | I11: 137.73 | P11: 280.97 | Q11: 280.97 | V11: S2.20 6/S5.10 & 10/S5.10 burbujas -> 6/S5.10 SECTION AT PERIMETER -> 11/S5.10 PARAPET INFILL FRAMING -> C/A09.21 T/STUD LP | W11: 2b33264997a757ad
A12: X57_parapet | B12: Parapet infill above B.O.D., E-LO 24.84 + S 51.73 + W1-LO 24.84 | C12: 101.41 | D12: 4.37 | F12: 520.03 | G12: 119 | H12: 101.41 | I12: 101.41 | L12: 101.41 | M12: 238 | P12: 443.16 | Q12: 443.16 | V12: S2.20 6/S5.10 & 10/S5.10 burbujas -> 6/S5.10 SECTION AT PERIMETER -> 11/S5.10 PARAPET INFILL FRAMING -> C/A09.21 T/STUD LP | W12: 7ac1e1ac8bc480a2
A13: X58_parapet | B13: Parapet infill above B.O.D., N3 15.82 + W4 7.54 (T.O. PARAPET 2 20 ft grids 2-4 A09.01) | C13: 23.36 | D13: 4.29 | F13: 120.12 | G13: 28 | H13: 23.36 | I13: 23.36 | L13: 23.36 | M13: 56 | P13: 100.21 | Q13: 100.21 | V13: S2.20 6/S5.10 & 10/S5.10 burbujas -> 6/S5.10 SECTION AT PERIMETER -> 11/S5.10 PARAPET INFILL FRAMING -> C/A09.21 T/STUD LP | W13: 595fdb38d54331c5
B14: TOTALS - EXTERIOR (each facade stays on its own row above) | C14: =SUM(C2:C13) -> 524.98 | E14: =SUM(E2:E13) -> 3844.7 | F14: =SUM(F2:F13) -> 966.55 | G14: =SUM(G2:G13) -> 643 | H14: =SUM(H2:H13) -> 524.98 | I14: =SUM(I2:I13) -> 524.98 | J14: =SUM(J2:J13) -> 61.51 | K14: =SUM(K2:K13) -> 50.18 | L14: =SUM(L2:L13) -> 812.13 | ... U14: =SUM(U2:U13) -> 262.48

Sheet Opening Bands
A1: Closure | B1: Opening / band | C1: Length = opening width (LF) | D1: Band height (FT) | E1: 1-5/8" Metal Stud (LF) | F1: Stud pcs | G1: Bottom track on box beam (LF) | H1: Top slip track (LF) | I1: Box beam 2-362CSJ20 (LF) | J1: 5/8" Gyp Board (SF) 2 layers x 2 faces | K1: 3/4" FRT plywood blocking (LF) | L1: Corner bead (LF) | M1: Shadow molding (LF) | N1: Insulation (SF) | O1: Sealant (LF) | P1: Sill band (lower) | Q1: Detail sequence | R1: Seal
A2: BH_105 | B2: Office bulkhead over office front DFC-1A, Office 105 / Central Zone 103 | C2: 7.5 | D2: 7.38 | E2: 118 | F2: 16 | G2: 15 | H2: 15 | I2: 7.5 | J2: 221.26 | K2: 7.5 | L2: 15 | M2: 7.5 | N2: 55.31 | O2: 30 | P2: 0 - office front DFC-1A installs on structural slab (9/A12.01), no sill band | Q2: A02.01 DFC-1A office front + note E (office front by bank vendor) -> 8/A12.01 OFFICE BULKHEAD DETAIL @ DOOR -> 9/A12.01 OFFICE BULKHEAD DETAIL @ GLASS PANEL -> 2/A11.04 office front height | R2: 35d0b2d27e682e3a
A3: BH_106 | B3: Office bulkhead over office front DFC-1A, Office 106 / Central Zone 103 | C3: 7.5 | D3: 7.38 | E3: 118 | F3: 16 | G3: 15 | H3: 15 | I3: 7.5 | J3: 221.26 | K3: 7.5 | L3: 15 | M3: 7.5 | N3: 55.31 | O3: 30 | P3: 0 - office front DFC-1A installs on structural slab (9/A12.01), no sill band | Q3: A02.01 DFC-1A office front + note E (office front by bank vendor) -> 8/A12.01 OFFICE BULKHEAD DETAIL @ DOOR -> 9/A12.01 OFFICE BULKHEAD DETAIL @ GLASS PANEL -> 2/A11.04 office front height | R3: 3ab0d73d20ded81e
A4: BH_107 | B4: Office bulkhead over office front DFC-1A, Office 107 / Central Zone 103 | C4: 7.5 | D4: 7.38 | E4: 118 | F4: 16 | G4: 15 | H4: 15 | I4: 7.5 | J4: 221.26 | K4: 7.5 | L4: 15 | M4: 7.5 | N4: 55.31 | O4: 30 | P4: 0 - office front DFC-1A installs on structural slab (9/A12.01), no sill band | Q4: A02.01 DFC-1A office front + note E (office front by bank vendor) -> 8/A12.01 OFFICE BULKHEAD DETAIL @ DOOR -> 9/A12.01 OFFICE BULKHEAD DETAIL @ GLASS PANEL -> 2/A11.04 office front height | R4: ba867ca02ffed8b6
A5: BH_108 | B5: Office bulkhead over office front DFC-1A, Office 108 / Central Zone 103 | C5: 7.5 | D5: 7.38 | E5: 118 | F5: 16 | G5: 15 | H5: 15 | I5: 7.5 | J5: 221.26 | K5: 7.5 | L5: 15 | M5: 7.5 | N5: 55.31 | O5: 30 | P5: 0 - office front DFC-1A installs on structural slab (9/A12.01), no sill band | Q5: A02.01 DFC-1A office front + note E (office front by bank vendor) -> 8/A12.01 OFFICE BULKHEAD DETAIL @ DOOR -> 9/A12.01 OFFICE BULKHEAD DETAIL @ GLASS PANEL -> 2/A11.04 office front height | R5: e5cbc3f44add6d0f
A6: BH_109 | B6: Office bulkhead over office front DFC-1A, Office 109 / Central Zone 103 | C6: 7.5 | D6: 7.38 | E6: 118 | F6: 16 | G6: 15 | H6: 15 | I6: 7.5 | J6: 221.26 | K6: 7.5 | L6: 15 | M6: 7.5 | N6: 55.31 | O6: 30 | P6: 0 - office front DFC-1A installs on structural slab (9/A12.01), no sill band | Q6: A02.01 DFC-1A office front + note E (office front by bank vendor) -> 8/A12.01 OFFICE BULKHEAD DETAIL @ DOOR -> 9/A12.01 OFFICE BULKHEAD DETAIL @ GLASS PANEL -> 2/A11.04 office front height | R6: 66ce7f3cedd8c7ab
A7: BH_110 | B7: Office bulkhead over office front DFC-1A, Office 110 / Central Zone 103 | C7: 7.5 | D7: 7.38 | E7: 118 | F7: 16 | G7: 15 | H7: 15 | I7: 7.5 | J7: 221.26 | K7: 7.5 | L7: 15 | M7: 7.5 | N7: 55.31 | O7: 30 | P7: 0 - office front DFC-1A installs on structural slab (9/A12.01), no sill band | Q7: A02.01 DFC-1A office front + note E (office front by bank vendor) -> 8/A12.01 OFFICE BULKHEAD DETAIL @ DOOR -> 9/A12.01 OFFICE BULKHEAD DETAIL @ GLASS PANEL -> 2/A11.04 office front height | R7: 2aa750f74f13cc3b
B8: TOTALS - OFFICE BULKHEADS | C8: =SUM(C2:C7) -> 45 | E8: =SUM(E2:E7) -> 708 | F8: =SUM(F2:F7) -> 96 | G8: =SUM(G2:G7) -> 90 | H8: =SUM(H2:H7) -> 90 | I8: =SUM(I2:I7) -> 45 | J8: =SUM(J2:J7) -> 1327.56 | K8: =SUM(K2:K7) -> 45 | L8: =SUM(L2:L7) -> 90 | ... O8: =SUM(O2:O7) -> 180
B10: Exterior opening bands: storefront head bands are closures X53-X55 (sheet Exterior); window head/sill cripples are inside X45/X48 (B/GLAZING 6'-6", T/GLAZING 8'-6"); Day 1 ATM band PENDING (RFI-19); interior storefront 101 / coiling grille 103 band PENDING (RFI-20).

Sheet Ceilings GWB
A1: ID | B1: Room | C1: Ceiling tag | D1: Height A.F.F. (FT) | E1: Area (SF) | F1: Area derivation | G1: Transition / edge (LF) | H1: Suspension | I1: Seal
A2: CEIL-1 | B2: Vestibule 100 + 24 HR Vestibule 101 | C2: GB 10'-0" | D2: 10 | E2: 271.22 | F2: Vestibule 100 rectangle: x 841.60-1126.40, y 331.10-460.40 A04.01/A02.01: 284.80 x 129.30 pt / 324 = 113.65 | 24 HR Vestibule 101 polygon: x 841.56-1130.28 between storefront y 460.40 and F wall north face y=553.80+tan30*(x-841.44): width 288.72 x mean depth 176.83 pt / 324 = 157.57 | H2: PENDING RFI-11: GB ceiling suspension system (carrying/furring channel or drywall grid) not detailed in A09.33 / no spec book | I2: 341d6f2afbffa8b6
A3: CEIL-2 | B3: Waiting 104 | C3: GB 11'-0" | D3: 11 | E3: 510.8 | F3: Waiting 104: A04.01 boundary lines x 1223.88 & 1530.36, y 427.44-967.44: 306.48 x 540.00 pt / 324 (540 pt = 30'-0" printed A04.01) = 510.8 | G3: 77.03 | H3: PENDING RFI-11: GB ceiling suspension system (carrying/furring channel or drywall grid) not detailed in A09.33 / no spec book | I3: 14c469c07c1c1c93
A4: CEIL-3 | B4: Womens Restroom 114 | C4: GB 8'-6" | D4: 8.5 | E4: 82.36 | F4: Womens Restroom 114: x 911.88-1123.08, y 1236.36-1362.72 (A02.01 faces): 11.73 x 7.02 ft = 82.36 | H4: PENDING RFI-11: GB ceiling suspension system (carrying/furring channel or drywall grid) not detailed in A09.33 / no spec book | I4: a2026b0fb0a58199
A5: CEIL-4 | B5: Mens Restroom 113 | C5: GB 8'-6" | D5: 8.5 | E5: 82.36 | F5: Mens Restroom 113: x 911.88-1123.08, y 1382.16-1508.52: 11.73 x 7.02 ft = 82.36 | H5: PENDING RFI-11: GB ceiling suspension system (carrying/furring channel or drywall grid) not detailed in A09.33 / no spec book | I5: b25a0e8001600121
B6: TOTAL GWB CEILINGS | E6: =SUM(E2:E5) -> 946.74 | G6: =SUM(G2:G5) -> 77.03
B8: ACT ceilings (Div 09 51 00, not ours): ACT-4 / ACT-5 per A04.01 - listed for reference only. Open to structure: Janitor 112, Storage 117, Electrical 120, NER 121 (A04.01 key note 1).

Sheet Soffits
A1: ID | B1: Soffit | C1: Tag | D1: Height (FT) | E1: Bottom (SF) | F1: Vertical face (SF) | G1: Edge trim (LF) | H1: Framing | I1: Seal
A2: SOFF-1 | B2: CSR soffit over teller line, Cash Window 116 | C2: GB 8'-0" | D2: 8 | E2: 35.79 | F2: 12.01 | G2: 12.01 | H2: 3 5/8" CFMF @ 16" O.C. (10/A09.33) - piece count PENDING (RFI-23) | I2: c22edd66ddd140d2
A3: S-canopy | B3: Exterior canopy soffit (EPS-1 ACM / PT-4 stucco soffit band, A04.01 top band) | C3: - | D3: 10'-6" B/CANOPY | E3: PENDING | F3: PENDING | G3: PENDING | H3: canopy framing per 3/A09.26 and D/A09.22 not quantified - RFI-21

Sheet MEP crossings
A1: # | B1: Wall | C1: Duct (label read on M01.01) | D1: Treatment
A2: 1 | B2: wall 5 A1 | C2: 10"ø R-1B | D2: framed opening: head + sill track 5.0 LF, 2 jamb studs (6/S5.20, 9/S5.20)
A3: 2 | B3: wall 9 A1 | C3: 8"ø | D3: framed opening: head + sill track 5.0 LF, 2 jamb studs (6/S5.20, 9/S5.20)
A4: 3 | B4: wall 9 A1 | C4: S-1A duct (size not legible in crop) | D4: framed opening: head + sill track 5.0 LF, 2 jamb studs (6/S5.20, 9/S5.20)
A5: 4 | B5: wall 15 A5 | C5: duct (size not legible) | D5: framed opening: head + sill track 5.0 LF, 2 jamb studs (6/S5.20, 9/S5.20)
A6: 5 | B6: wall 16 A5 | C6: 14"x12" | D6: framed opening: head + sill track 5.0 LF, 2 jamb studs (6/S5.20, 9/S5.20)
A7: 6 | B7: wall 21 B | C7: 8"x8" | D7: framed opening: head + sill track 5.0 LF, 2 jamb studs (6/S5.20, 9/S5.20)
A8: 7 | B8: wall 23 B2 | C8: 12"x10" | D8: framed opening: head + sill track 5.0 LF, 2 jamb studs (6/S5.20, 9/S5.20)
A9: 8 | B9: wall 23 B2 | C9: 10"x10" | D9: framed opening: head + sill track 5.0 LF, 2 jamb studs (6/S5.20, 9/S5.20)
A10: 9 | B10: wall 23 B2 | C10: 8"x8" | D10: framed opening: head + sill track 5.0 LF, 2 jamb studs (6/S5.20, 9/S5.20)
A11: 10 | B11: wall 23 B2 | C11: 8"ø | D11: framed opening: head + sill track 5.0 LF, 2 jamb studs (6/S5.20, 9/S5.20)
A12: 11 | B12: wall 32 G | C12: 8"x10" | D12: framed opening: head + sill track 5.0 LF, 2 jamb studs (6/S5.20, 9/S5.20)
A13: 12 | B13: wall 32 G | C13: 10"ø | D13: framed opening: head + sill track 5.0 LF, 2 jamb studs (6/S5.20, 9/S5.20)
... A20: 19 | B20: wall 43 G1 | C20: 12"x10" (same run as #7?) | D20: framed opening: head + sill track 5.0 LF, 2 jamb studs (6/S5.20, 9/S5.20)
B22: TOTAL framed openings | C22: 19 | D22: track 95.0 LF, jamb studs 38 ea
B23: Registration | C23: M01.01 offset dx=-571.92 dy=21.84 voted with mep.registro (vy=124 >=25) and verified on F wall diagonal (1413.36,531.96) -> A02.01 (841.44,553.80)
B24: Excluded | C24: #0 wall 1: duct runs alongside, not through (crop #0) -> not counted; wall 43 single lw1.56 line = door frame, not duct
B25: Pending | C25: P01.01/P01.02 (plumbing) NOT registered: mep.registro votes vx=1 vy=3 <25 -> no geometric crossing; restroom chase C1 carries piping (RFI-16). E02.x not crossed (conduit in walls normally by electrician).

Sheet Blocking
A1: Item | B1: Derivation | C1: Qty | D1: Unit | E1: Status | F1: Source / RFI
A2: Wall stops (A00.30 sheet note D "PROVIDE BLOCKING AT EACH WALL STOP") | B2: doors 111(04A),113(08),114(08),115(16),116(11),117(10),118A(11B),118B(11),119(12) = 9 hardware groups listing 1 EA WALL STOP WS407CCV (A00.30 HARDWARE GROUPS); 2'-0" per stop (stop not located on plan) | C2: 18 | D2: LF | E2: DERIVADO | F2: A00.30 note D + hardware groups
A3: Mens Restroom 113 toilet accessories (FRT blocking, A08.01 sheet note E) | B3: TA-3 42" grab bar 4.5 + TA-4 36" grab bar 4.0 + TA-5 18" grab bar 2.5 + TA-7 mirror 2 runs x 2.0 + TA-8 soap 2.0 + TA-10 TP 2.0 + TA-16 baby changing 2 x 3.0 + TA-17 seat cover 2.0 + coat hook 2.0 | C3: 29 | D3: LF | E3: DERIVADO | F3: A08.01 TOILET ACCESSORY LEGENDS + note E
A4: Womens Restroom 114 toilet accessories (FRT blocking, A08.01 sheet note E) | B4: same as 113 + TA-9 sanitary napkin 2.0 | C4: 31 | D4: LF | E4: DERIVADO | F4: A08.01 TOILET ACCESSORY LEGENDS + note E
A5: Janitor Closet 112 utility hook TA-6 | B5: 1 x 2.0 | C5: 2 | D5: LF | E5: DERIVADO | F5: A08.01 TA-6
A6: Wellness 115 mirror TA-19 | B6: 2 runs x 2.0 | C6: 4 | D6: LF | E6: DERIVADO | F6: A08.01 TA-19
A7: 85" display monitor, key note 7 A02.01 ("PROVIDE BLOCKING IN WALL AS REQUIRED") | B7: 2 runs x 10'-0" recess width printed A02.01 (C1 #29 zone) | C7: 20 | D7: LF | E7: DERIVADO | F7: A02.01 key note 7
A8: Lockers, key note 5 A02.01 | B8: locker bank width not dimensioned | C8: PENDING | D8: LF | E8: PENDIENTE | F8: RFI-12
A9: Roof hatch & ladder, RCP key note 9 / A09.30 | B9: ladder bracket blocking - detail 9/A09.30 not quantified | C9: PENDING | D9: LF | E9: PENDIENTE | F9: RFI-13
A10: Millwork MW01, MW05, MW06A, MW07, MW08, MW11, MW12, MW13, MW18, MW21 (A12.03-A12.06, A02.01 note C) | B10: base = 1 run, upper = 2 runs; millwork details not opened in this unattended run | C10: PENDING | D10: LF | E10: PENDIENTE | F10: RFI-INT-01
A11: 3/4" FRT plywood backboard Electrical 120 / NER 121, key note 6 A02.01 (A11.03) | B11: area per A11.03 elevations not measured; normally Div 06 | C11: PENDING | D11: SF | E11: PENDIENTE | F11: RFI-14
A12: TOTAL quantified FRT blocking | C12: =SUM(C2:C11) -> 104 | D12: LF | F12: FRT blocking per A08.01 note E; 2x lumber vs 20 GA steel blocking not specified -> RFI-15

Sheet Wet Zones
A1: Item | B1: Derivation | C1: Qty | D1: Unit | E1: Status
A2: 5/8" moisture resistant gypsum board (RECLASSIFIED from regular, not added) - C1 chase face Womens 114 (toilet + lavatory wall) | B2: A08.01 sheet note F "USE MOISTURE RESISTANT GYPSUM BOARD BEHIND TOILET AND LAVATORY": toilet tank and lavatory both on the chase face (A02.01/A08.01 plan) = W27 BOARD 90.27 SF | C2: 90.27 | D2: SF | E2: DERIVADO
A3: 5/8" moisture resistant gypsum board (RECLASSIFIED) - C1 chase face Mens 113 | B3: idem = W28 BOARD 90.27 SF | C3: 90.27 | D3: SF | E3: DERIVADO
A4: FRP-1 restroom walls Womens 114 | B4: A08.01 "5'-0\" TO TOP OF FRP" over ceramic tile cove base (3/A08.01): band 5.0 - 0.5 cove (RFI-24, cove height not dimensioned) = 4.5 ft x perimeter 2x(11.73+7.02) - door 3.33 = 34.17 LF | C4: 153.75 | D4: SF | E4: DERIVADO
A5: FRP-1 restroom walls Mens 113 | B5: idem | C5: 153.75 | D5: SF | E5: DERIVADO
A6: FRP-2 mop sink Janitor 112 (A05.01 key note 6 "FRP FROM FLOOR TO 4'-0\" AFF, WIDTH TO MATCH WIDTH OF MOP SINK AT BOTH SIDES") | B6: height 4'-0" printed; mop sink width not dimensioned -> 24 in assumed both sides = 2 x 2.0 x 4.0 (RFI-25) | C6: 16 | D6: SF | E6: DERIVADO
A7: Break Room 118 sink (MW08) | B7: no FRP / W.R. note on A05.01 for 118 -> RFI-INT-01 + alternate, not quantified | C7: PENDING | D7: SF | E7: PENDIENTE
A8: Census | B8: 4 rooms with plumbing fixtures (A02.01 / A08.01 / P01.01): Womens 114, Mens 113, Janitor 112 (mop sink), Break Room 118 (MW08 sink). Resolved: 3 quantified, 1 RFI (118).

Sheet Purchase Summary
A1: Material | B1: Family | C1: Unit | D1: NET | E1: Waste % | F1: WASTE | G1: BUY | H1: Stock / unit | I1: Purchase units | J1: Source
A2: 3-5/8" metal stud 362S137-33 | B2: METAL | C2: LF | D2: =SUMIFS(Takeoff!H2:H45,Takeoff!J2:J45,"362S137-33") -> 3061.71 | E2: =Inputs!B2 -> 0.15 | F2: =ROUND(D2*E2,2) -> 459.26 | G2: =D2+F2 -> 3520.97 | H2: =Inputs!B6 -> 20 | I2: =ROUNDUP(G2/H2,0) -> 177 | J2: Takeoff col H (A1,B,C1,F)
A3: 3-5/8" metal stud 14 GA 362S137-68 | B3: METAL | C3: LF | D3: =SUMIFS(Takeoff!H2:H45,Takeoff!J2:J45,"362S137-68") -> 310.38 | E3: =Inputs!B2 -> 0.15 | F3: =ROUND(D3*E3,2) -> 46.56 | G3: =D3+F3 -> 356.94 | H3: =Inputs!B6 -> 20 | I3: =ROUNDUP(G3/H3,0) -> 18 | J3: Takeoff col H (A1K, 4/A12.01)
A4: 6" metal stud 600S137-33 (interior) | B4: METAL | C4: LF | D4: =SUMIFS(Takeoff!G2:G45,Takeoff!J2:J45,"600S137-33") -> 1794.36 | E4: =Inputs!B2 -> 0.15 | F4: =ROUND(D4*E4,2) -> 269.15 | G4: =D4+F4 -> 2063.51 | H4: =Inputs!B6 -> 20 | I4: =ROUNDUP(G4/H4,0) -> 104 | J4: Takeoff col G (A5,B2)
A5: 6" metal stud 14 GA 600S137-68 | B5: METAL | C5: LF | D5: =SUMIFS(Takeoff!G2:G45,Takeoff!J2:J45,"600S137-68") -> 61.5 | E5: =Inputs!B2 -> 0.15 | F5: =ROUND(D5*E5,2) -> 9.23 | G5: =D5+F5 -> 70.73 | H5: =Inputs!B6 -> 20 | I5: =ROUNDUP(G5/H5,0) -> 4 | J5: Takeoff col G (B2K)
A6: 1-5/8" metal stud (G/G1 double row + bulkheads) | B6: METAL | C6: LF | D6: =Takeoff!I46+'Opening Bands'!E8 -> 3998.25 | E6: =Inputs!B2 -> 0.15 | F6: =ROUND(D6*E6,2) -> 599.74 | G6: =D6+F6 -> 4597.99 | H6: =Inputs!B6 -> 20 | I6: =ROUNDUP(G6/H6,0) -> 230 | J6: Takeoff col I + Opening Bands col E
A7: 6" metal stud 600S137-33 (exterior + storefront bands) | B7: METAL | C7: LF | D7: =Exterior!E14 -> 3844.7 | E7: =Inputs!B2 -> 0.15 | F7: =ROUND(D7*E7,2) -> 576.71 | G7: =D7+F7 -> 4421.41 | H7: =Inputs!B6 -> 20 | I7: =ROUNDUP(G7/H7,0) -> 222 | J7: Exterior col E
A8: 6" parapet stud 600S162-54 | B8: METAL | C8: LF | D8: =Exterior!F14 -> 966.55 | E8: =Inputs!B2 -> 0.15 | F8: =ROUND(D8*E8,2) -> 144.98 | G8: =D8+F8 -> 1111.53 | H8: =Inputs!B6 -> 20 | I8: =ROUNDUP(G8/H8,0) -> 56 | J8: Exterior col F (11/S5.10)
A9: Bottom track - interior (all sizes; split by stud size in Takeoff) | B9: METAL | C9: LF | D9: =Takeoff!AB46+'Opening Bands'!G8 -> 590.45 | E9: =Inputs!B2 -> 0.15 | F9: =ROUND(D9*E9,2) -> 88.57 | G9: =D9+F9 -> 679.02 | H9: =Inputs!B7 -> 10 | I9: =ROUNDUP(G9/H9,0) -> 68 | J9: Takeoff col AB + bulkheads
A10: Top slip track - interior | B10: METAL | C10: LF | D10: =Takeoff!AC46+'Opening Bands'!H8 -> 590.45 | E10: =Inputs!B2 -> 0.15 | F10: =ROUND(D10*E10,2) -> 88.57 | G10: =D10+F10 -> 679.02 | H10: =Inputs!B7 -> 10 | I10: =ROUNDUP(G10/H10,0) -> 68 | J10: Takeoff col AC + bulkheads
A11: Bottom track exterior 600T125-33 / parapet 600T125-54 | B11: METAL | C11: LF | D11: =Exterior!H14 -> 524.98 | E11: =Inputs!B2 -> 0.15 | F11: =ROUND(D11*E11,2) -> 78.75 | G11: =D11+F11 -> 603.73 | H11: =Inputs!B7 -> 10 | I11: =ROUNDUP(G11/H11,0) -> 61 | J11: Exterior col H
A12: Top deflection track exterior 600T200-97 / parapet 600T125-54 | B12: METAL | C12: LF | D12: =Exterior!I14 -> 524.98 | E12: =Inputs!B2 -> 0.15 | F12: =ROUND(D12*E12,2) -> 78.75 | G12: =D12+F12 -> 603.73 | H12: =Inputs!B7 -> 10 | I12: =ROUNDUP(G12/H12,0) -> 61 | J12: Exterior col I
A13: Header (track headers / CSJ) + box beams | B13: METAL | C13: LF | D13: =Takeoff!AG46+Exterior!J14+Exterior!R14+'Opening Bands'!I8 -> 216.61 | E13: =Inputs!B2 -> 0.15 | F13: =ROUND(D13*E13,2) -> 32.49 | G13: =D13+F13 -> 249.1 | H13: =Inputs!B7 -> 10 | I13: =ROUNDUP(G13/H13,0) -> 25 | J13: Takeoff AG + Exterior J,R + bulkhead box beam
A14: Sill track exterior windows | B14: METAL | C14: LF | D14: =Exterior!K14 -> 50.18 | E14: =Inputs!B2 -> 0.15 | F14: =ROUND(D14*E14,2) -> 7.53 | G14: =D14+F14 -> 57.71 | H14: =Inputs!B7 -> 10 | I14: =ROUNDUP(G14/H14,0) -> 6 | J14: Exterior col K
A15: 1 1/2" C.R. channel bracing | B15: METAL | C15: LF | D15: =Takeoff!AE46+Exterior!L14 -> 2313.48 | E15: =Inputs!B2 -> 0.15 | F15: =ROUND(D15*E15,2) -> 347.02 | G15: =D15+F15 -> 2660.5 | H15: =Inputs!B8 -> 16 | I15: =ROUNDUP(G15/H15,0) -> 167 | J15: F/1/S5.20
A16: Clips at bracing | B16: METAL | C16: EA | D16: =Takeoff!AF46+Exterior!M14 -> 5814 | E16: =Inputs!B2 -> 0.15 | F16: =ROUND(D16*E16,2) -> 872.1 | G16: =D16+F16 -> 6686.1 | J16: F/1/S5.20
A17: MEP framed openings track | B17: METAL | C17: LF | D17: 95 | E17: =Inputs!B2 -> 0.15 | F17: =ROUND(D17*E17,2) -> 14.25 | G17: =D17+F17 -> 109.25 | H17: =Inputs!B7 -> 10 | I17: =ROUNDUP(G17/H17,0) -> 11 | J17: MEP crossings sheet
A18: 5/8" gypsum board regular (walls) | B18: NOT METAL | C18: SF | D18: =Takeoff!T46+'Opening Bands'!J8+Exterior!N14-'Wet Zones'!C2-'Wet Zones'!C3 -> 16431.405 | E18: =Inputs!B3 -> 0.06 | F18: =ROUND(D18*E18,2) -> 985.88 | G18: =D18+F18 -> 17417.285 | H18: =Inputs!B12 -> 48 | I18: =ROUNDUP(G18/H18,0) -> 363 | J18: Takeoff T + bulkheads + exterior interior face - MR reclassified
A19: 5/8" moisture resistant gypsum board (reclassified, A08.01 note F) | B19: NOT METAL | C19: SF | D19: ='Wet Zones'!C2+'Wet Zones'!C3 -> 180.54 | E19: =Inputs!B3 -> 0.06 | F19: =ROUND(D19*E19,2) -> 10.83 | G19: =D19+F19 -> 191.37 | H19: =Inputs!B12 -> 48 | I19: =ROUNDUP(G19/H19,0) -> 4 | J19: Wet Zones
A20: FRP-1 restroom wall panels + PVC trims | B20: NOT METAL | C20: SF | D20: ='Wet Zones'!C4+'Wet Zones'!C5 -> 307.5 | E20: =Inputs!B3 -> 0.06 | F20: =ROUND(D20*E20,2) -> 18.45 | G20: =D20+F20 -> 325.95 | J20: A08.01, 3/A08.01
A21: FRP-2 mop sink | B21: NOT METAL | C21: SF | D21: ='Wet Zones'!C6 -> 16 | E21: =Inputs!B3 -> 0.06 | F21: =ROUND(D21*E21,2) -> 0.96 | G21: =D21+F21 -> 16.96 | J21: A05.01 key note 6
A22: 5/8" gypsum board (ceilings + CSR soffit) | B22: NOT METAL | C22: SF | D22: ='Ceilings GWB'!E6+Soffits!E2+Soffits!F2 -> 994.54 | E22: =Inputs!B3 -> 0.06 | F22: =ROUND(D22*E22,2) -> 59.67 | G22: =D22+F22 -> 1054.21 | H22: =Inputs!B12 -> 48 | I22: =ROUNDUP(G22/H22,0) -> 22 | J22: Ceilings GWB + Soffits
A23: 3/8" gypsum board (A1K/B2K customer side) | B23: NOT METAL | C23: SF | D23: =Takeoff!U46 -> 170.44 | E23: =Inputs!B3 -> 0.06 | F23: =ROUND(D23*E23,2) -> 10.23 | G23: =D23+F23 -> 180.67 | H23: =Inputs!B12 -> 48 | I23: =ROUNDUP(G23/H23,0) -> 4 | J23: 4/A12.01
A24: 3/8" UL752 Level-2 fiberglass ballistic panel | B24: NOT METAL | C24: SF | D24: =Takeoff!V46 -> 206.64 | E24: =Inputs!B3 -> 0.06 | F24: =ROUND(D24*E24,2) -> 12.4 | G24: =D24+F24 -> 219.04 | J24: 4/A12.01
A25: 5/8" glass mat sheathing (exterior face) | B25: NOT METAL | C25: SF | D25: =Exterior!O14 -> 3246.2 | E25: =Inputs!B3 -> 0.06 | F25: =ROUND(D25*E25,2) -> 194.77 | G25: =D25+F25 -> 3440.97 | H25: =Inputs!B12 -> 48 | I25: =ROUNDUP(G25/H25,0) -> 72 | J25: 5/A09.26, 9/A09.27
A26: 5/8" exterior gypsum sheathing (parapet roof side) | B26: NOT METAL | C26: SF | D26: =Exterior!P14 -> 824.34 | E26: =Inputs!B3 -> 0.06 | F26: =ROUND(D26*E26,2) -> 49.46 | G26: =D26+F26 -> 873.8 | H26: =Inputs!B12 -> 48 | I26: =ROUNDUP(G26/H26,0) -> 19 | J26: C/A09.21
A27: 3/4" FRT plywood (F wall public side) | B27: NOT METAL | C27: SF | D27: =Takeoff!W46 -> 260.15 | E27: =Inputs!B3 -> 0.06 | F27: =ROUND(D27*E27,2) -> 15.61 | G27: =D27+F27 -> 275.76 | J27: 12/A12.01
A28: 3/4" FRT plywood strips (bulkheads + storefront heads) | B28: NOT METAL | C28: LF | D28: ='Opening Bands'!K8+Exterior!S14 -> 95.04 | E28: =Inputs!B3 -> 0.06 | F28: =ROUND(D28*E28,2) -> 5.7 | G28: =D28+F28 -> 100.74 | J28: 8/A12.01, 11/A09.27
A29: Corner bead | B29: METAL | C29: LF | D29: ='Opening Bands'!L8+Soffits!G2 -> 102.01 | E29: =Inputs!B2 -> 0.15 | F29: =ROUND(D29*E29,2) -> 15.3 | G29: =D29+F29 -> 117.31 | H29: =Inputs!B9 -> 10 | I29: =ROUNDUP(G29/H29,0) -> 12 | J29: 8/A12.01, 10/A09.33
A30: Shadow molding | B30: METAL | C30: LF | D30: ='Opening Bands'!M8 -> 45 | E30: =Inputs!B2 -> 0.15 | F30: =ROUND(D30*E30,2) -> 6.75 | G30: =D30+F30 -> 51.75 | H30: =Inputs!B9 -> 10 | I30: =ROUNDUP(G30/H30,0) -> 6 | J30: 8/A12.01
A31: Ceiling transition GB 11-0 to ACT 11-6 (kicker framing, 7/A09.33) | B31: METAL | C31: LF | D31: ='Ceilings GWB'!G6 -> 77.03 | E31: =Inputs!B2 -> 0.15 | F31: =ROUND(D31*E31,2) -> 11.55 | G31: =D31+F31 -> 88.58 | J31: 7/A09.33
A32: Batt insulation (interior partitions + bulkheads) | B32: NOT METAL | C32: SF | D32: =Takeoff!AH46+'Opening Bands'!N8 -> 5727.8 | E32: =Inputs!B3 -> 0.06 | F32: =ROUND(D32*E32,2) -> 343.67 | G32: =D32+F32 -> 6071.47 | J32: A12.01 schedule INSULATION YES
A33: Acoustical sealant | B33: NOT METAL | C33: LF | D33: =Takeoff!AI46+'Opening Bands'!O8+Exterior!U14 -> 1717.38 | E33: =Inputs!B3 -> 0.06 | F33: =ROUND(D33*E33,2) -> 103.04 | G33: =D33+F33 -> 1820.42 | H33: =Inputs!B10 -> 25 | I33: =ROUNDUP(G33/H33,0) -> 73 | J33: A12.01 details
A34: FRT blocking (quantified part) | B34: NOT METAL | C34: LF | D34: =Blocking!C12 -> 104 | E34: =Inputs!B3 -> 0.06 | F34: =ROUND(D34*E34,2) -> 6.24 | G34: =D34+F34 -> 110.24 | J34: Blocking sheet
A36: Fasteners, screws, joint compound, tape: yields per SF, no waste (not plan quantities). PENDING items are never in these totals - see sheet PARA REVISAR EN LA MANANA.

Sheet RFIs
A1: RFI | B1: Sheet / detail | C1: Issue | D1: Delta | E1: Image (Planos marcados/revisar)
A2: RFI-01 | B2: 5/A12.01 PARTITION G / G1 | C2: Top line of detail 5 is not labeled (no UNDERSIDE OF STRUCTURE note). Quoted: 2 layers 5/8" per face to deck (consistent with 8/A12.01 and 9/A12.01 "2 LAYERS ... TO UNDERSIDE OF DECK"). Alternate: board 6" above ceiling. | D2: -2,226.8 SF of 5/8" gypsum board if board stops 6" above ceiling | E2: R01_G_board_top_5-A12.01.png
A3: RFI-02 | B3: A02.01 G1 vs 5/A12.01 schedule | C3: G1 drawn 8.48" thick with two 2.48" studs + 1.04" gap; schedule says 1-5/8" studs, 8" thickness. 1-5/8" stud has no designation in 7/S5.20 (162S125-33 derived). Quoted 1-5/8" per schedule. | D3: same LF; price delta 1-5/8" -> 2-1/2" stud on 4 G1 walls + 6 bulkheads (~1,000 LF) | E3: R02_G1_thickness_A02.01.png
A4: RFI-03 | B4: 7/S5.20 vs 1,3,5/A12.01 | C4: CONTINUOUS SLIP TRACK required by details; 7/S5.20 names only 600T200-97 (6"). 3-5/8" and 1-5/8" slip track profiles/gauge not designated. | D4: price delta slip (2" leg) vs standard track on ~470 LF interior top track | E4: -
A5: RFI-04 | B5: A02.01 C1 tags at 4 columns + Future FCAM | C5: C1 (6/A12.01) = BLOCK PARTITION + 3-5/8" stud furring + 5/8" board; tags point to steel columns at vestibule and to FCAM element, no block drawn. Not quantified. | D5: approx +300 SF board + 30 studs if each column furred full height (4 columns x ~5 ft perimeter x 15.375 ft) | E5: R04_C1_columns.png
A6: RFI-05 | B6: A02.01 C1 restroom plumbing chase | C6: No block partition drawn in the 1'-1" chase; quoted 3-5/8" furring + 5/8" MR board each face to 6" above GB 8'-6" ceiling. | D6: +81.3 SF if board goes to deck (2 x 10.03 x 4.05) | E6: R05_C1_chase_restrooms.png
A7: RFI-06 | B7: A02.01 teller line (A1K / B2K) | C7: B2K has no row in the A12.01 schedule: derived as B2 (6") + ballistic = 7-5/8" like A5K. Teller south end shows two parallel hatched bands (#12 and #13); both quantified as A1K. | D7: -2.98 LF A1K (#12) if the south cap is millwork, not wall | E7: R03_teller_A1K_B2K.png
