Workbook

Sheet Inputs
A1: Bank of America - Broomfield, CO (CO1-111) | METAL FRAMING & DRYWALL TAKEOFF
A2: Bid set: 2025.08.26_CO1-111_Broomfield_PERMIT SET_BID SET.pdf · 2026-10-16 · Edit ONLY the yellow cells.
A3: PARAMETER | B3: VALUE | C3: NOTE / SOURCE
A4: Waste - ALL METAL, any type | B4: 0.15 | C4: Estimator standing rule.
A5: Waste - EVERYTHING THAT IS NOT METAL | B5: 0.06 | C5: Same figure as board.
A6: Board sheet width (ft) | B6: 4
A7: Board sheet length (ft) | B7: 12
A8: SF per board sheet | B8: =B6*B7 -> 48 | C8: Width x length.
A9: Stud stock length (ft) | B9: 20
A10: Track stock length (ft) | B10: 10

Sheet Partition Takeoff
A1: ORGANIZED PARTITION TAKEOFF - Bank of America - Broomfield, CO (CO1-111)
A2: Grouped by partition type. Every row cites its DETAIL/SHEET and its status.
A4: Partition / Scope | B4: Wall # | C4: Length (LF) | D4: Height (FT) | E4: Layers | F4: Stud Size | G4: Stud O.C. (in) | H4: Board (SF) | I4: Location | J4: Source (DETAIL/SHEET) | K4: Status
A5: TYPE A1
A6: A1 #1 - Calling Cubes 122 north / Waiting 104 | B6: 1 | C6: 17.02 | D6: 15.375 | E6: 2 | F6: 3-5/8" | G6: 16 | H6: 316.21 | I6: Calling Cubes 122 north / Waiting 104 | J6: F/A02.01 -> A12.01 schedule -> 3/A12.01 -> 7/S5.20 -> 1/A04.01 (ceiling per face) -> 1F/S5.20, 4/S5.20; sello eaafc2ef90bac845 | K6: [DERIVADO]
A7: A1 #2 - MW01 niche east / Calling Cubes 122 | B7: 2 | C7: 3.533 | D7: 15.375 | E7: 2 | F7: 3-5/8" | G7: 16 | H7: 86.12 | I7: MW01 niche east / Calling Cubes 122 | J7: F/A02.01 -> A12.01 schedule -> 3/A12.01 -> 7/S5.20 -> 1/A04.01 (ceiling per face) -> 1F/S5.20, 4/S5.20; sello 9f4753525c22c32a | K7: [DERIVADO]
A8: A1 #3 - MW01 niche south / Calling Cubes 122 | B8: 3 | C8: 2.427 | D8: 15.375 | E8: 2 | F8: 3-5/8" | G8: 16 | H8: 59.15 | I8: MW01 niche south / Calling Cubes 122 | J8: F/A02.01 -> A12.01 schedule -> 3/A12.01 -> 7/S5.20 -> 1/A04.01 (ceiling per face) -> 1F/S5.20, 4/S5.20; sello 475b7b151fd8d002 | K8: [DERIVADO]
A9: A1 #4 - Calling Cubes 122 south / MW21 Break 118 | B9: 4 | C9: 15.62 | D9: 13.052 | E9: 2 | F9: 3-5/8" | G9: 16 | H9: 277.68 | I9: Calling Cubes 122 south / MW21 Break 118 | J9: F/A02.01 -> A12.01 schedule -> 3/A12.01 -> 7/S5.20 -> 1/A04.01 (ceiling per face) -> 1F/S5.20, 4/S5.20; sello 613230164f94a0c9 | K9: [DERIVADO]
A10: A1 #5 - stub east of MW21 / Break 118 | B10: 5 | C10: 5.04 | D10: 13.052 | E10: 2 | F10: 3-5/8" | G10: 16 | H10: 38.8 | I10: stub east of MW21 / Break 118 | J10: F/A02.01 -> A12.01 schedule -> 3/A12.01 -> 7/S5.20 -> 1/A04.01 (ceiling per face) -> 1F/S5.20, 4/S5.20; sello 539958b075072b08 | K10: [DERIVADO]
A11: A1 #6 - stub east end of MW21 / Break 118 | B11: 6 | C11: 2.547 | D11: 13.052 | E11: 2 | F11: 3-5/8" | G11: 16 | H11: 47.11 | I11: stub east end of MW21 / Break 118 | J11: F/A02.01 -> A12.01 schedule -> 3/A12.01 -> 7/S5.20 -> 1/A04.01 (ceiling per face) -> 1F/S5.20, 4/S5.20; sello 7ba195f579067e4d | K11: [DERIVADO]
A12: A1 #7 - Corridor 111 / Electrical 120, NER 121, Break 118 | B12: 7 | C12: 20.393 | D12: 13.052 | E12: 4 | F12: 3-5/8" | G12: 16 | H12: 376.63 | I12: Corridor 111 / Electrical 120, NER 121, Break 118 | J12: F/A02.01 -> A12.01 schedule -> 3/A12.01 -> 7/S5.20 -> 1/A04.01 (ceiling per face) -> 1F/S5.20, 4/S5.20; sello 798d6dd950592d64 | K12: [DERIVADO]
A13: A1 #8 - Cash Window 116 / Work Room 119 | B13: 8 | C13: 11.667 | D13: 13.052 | E13: 2 | F13: 3-5/8" | G13: 16 | H13: 168.06 | I13: Cash Window 116 / Work Room 119 | J13: F/A02.01 -> A12.01 schedule -> 3/A12.01 -> 7/S5.20 -> 1/A04.01 (ceiling per face) -> 1F/S5.20, 4/S5.20; sello df583d67bd60ae8a | K13: [DERIVADO]
A14: A1 #48 - Corridor 111 entry from Central Zone (A1 stub + door 111) | B14: 48 | C14: 4.807 | D14: 15.375 | E14: 2 | F14: 3-5/8" | G14: 16 | H14: 46.5 | I14: Corridor 111 entry from Central Zone (A1 stub + door 111) | J14: F/A02.01 -> A12.01 schedule -> 3/A12.01 -> 7/S5.20 -> 1/A04.01 (ceiling per face) -> 1F/S5.20, 4/S5.20; sello a7a3c52427a99864 | K14: [DERIVADO]
A15: TYPE A1K
A16: A1K #9 - Teller line north end (Cash Window 116) | B16: 9 | C16: 3.413 | D16: 15.375 | E16: 2 | F16: 3-5/8" | G16: 24 | H16: 130.13 | I16: Teller line north end (Cash Window 116) | J16: F/A02.01 -> A12.01 schedule -> 4/A12.01 -> 7/S5.20 -> 1/A04.01 (ceiling per face) -> 1F/S5.20, 4/S5.20; sello 6c1128930c1220fa | K16: [DERIVADO]
A17: A1K #10 - Teller line south end (Cash Window 116) | B17: 10 | C17: 3.413 | D17: 13.052 | E17: 2 | F17: 3-5/8" | G17: 24 | H17: 106.34 | I17: Teller line south end (Cash Window 116) | J17: F/A02.01 -> A12.01 schedule -> 4/A12.01 -> 7/S5.20 -> 1/A04.01 (ceiling per face) -> 1F/S5.20, 4/S5.20; sello 23985f2a836f59d9 | K17: [DERIVADO]
A18: A1K #11 - Teller south / Future FCAM | B18: 11 | C18: 2.24 | D18: 13.052 | E18: 2 | F18: 3-5/8" | G18: 24 | H18: 69.8 | I18: Teller south / Future FCAM | J18: F/A02.01 -> A12.01 schedule -> 4/A12.01 -> 7/S5.20 -> 1/A04.01 (ceiling per face) -> 1F/S5.20, 4/S5.20; sello f1e9835deb4399eb | K18: [DERIVADO]
A19: TYPE A5
A20: A5 #12 - Calling Cubes 122 east / Central zone | B20: 12 | C20: 19.407 | D20: 15.375 | E20: 3 | F20: 6" | G20: 16 | H20: 380.21 | I20: Calling Cubes 122 east / Central zone | J20: F/A02.01 -> A12.01 schedule -> 3/A12.01 -> 7/S5.20 -> 1/A04.01 (ceiling per face) -> 1F/S5.20, 4/S5.20; sello e111a7654cf257f3 | K20: [DERIVADO]
A21: A5 #13 - Calling Cubes 122 west / Corridor-Waiting | B21: 13 | C21: 11.407 | D21: 15.375 | E21: 2 | F21: 6" | G21: 16 | H21: 239.54 | I21: Calling Cubes 122 west / Corridor-Waiting | J21: F/A02.01 -> A12.01 schedule -> 3/A12.01 -> 7/S5.20 -> 1/A04.01 (ceiling per face) -> 1F/S5.20, 4/S5.20; sello 5690b6c694a15d5c | K21: [DERIVADO]
A22: A5 #14 - Break 118 / Future FCAM - Cash Window 116 | B22: 14 | C22: 3.713 | D22: 13.052 | E22: 2 | F22: 6" | G22: 16 | H22: 68.7 | I22: Break 118 / Future FCAM - Cash Window 116 | J22: F/A02.01 -> A12.01 schedule -> 3/A12.01 -> 7/S5.20 -> 1/A04.01 (ceiling per face) -> 1F/S5.20, 4/S5.20; sello 8ce88e6c1ba3f096 | K22: [DERIVADO]
A23: A5 #58 - Corridor 111 / Calling Cubes 122 (door 122) | B23: 58 | C23: 5 | D23: 15.375 | E23: 2 | F23: 6" | G23: 16 | H23: 42.22 | I23: Corridor 111 / Calling Cubes 122 (door 122) | J23: F/A02.01 -> A12.01 schedule -> 3/A12.01 -> 7/S5.20 -> 1/A04.01 (ceiling per face) -> 1F/S5.20, 4/S5.20; sello 0dded9561ceb735d | K23: [DERIVADO]
A24: TYPE B
A25: B #15 - Men's Restroom 113 / Janitor 112, Storage 117 | B25: 15 | C25: 11.733 | D25: 13.052 | E25: 2 | F25: 3-5/8" | G25: 16 | H25: 258.52 | I25: Men's Restroom 113 / Janitor 112, Storage 117 | J25: F/A02.01 -> A12.01 schedule -> 1/A12.01 -> 7/S5.20 -> 1/A04.01 (ceiling per face) -> 1F/S5.20, 4/S5.20; sello 49e6c55b0b1022e7 | K25: [DERIVADO]
A26: B #16 - Janitor 112 / Storage 117 | B26: 16 | C26: 3.5 | D26: 13.052 | E26: 2 | F26: 3-5/8" | G26: 16 | H26: 91.36 | I26: Janitor 112 / Storage 117 | J26: F/A02.01 -> A12.01 schedule -> 1/A12.01 -> 7/S5.20 -> 1/A04.01 (ceiling per face) -> 1F/S5.20, 4/S5.20; sello 31395581ccb58bfa | K26: [DERIVADO]
A27: B #17 - Janitor 112, Storage 117 / Wellness 115 | B27: 17 | C27: 11.733 | D27: 13.052 | E27: 2 | F27: 3-5/8" | G27: 16 | H27: 306.28 | I27: Janitor 112, Storage 117 / Wellness 115 | J27: F/A02.01 -> A12.01 schedule -> 1/A12.01 -> 7/S5.20 -> 1/A04.01 (ceiling per face) -> 1F/S5.20, 4/S5.20; sello b72dd1277077447d | K27: [DERIVADO]
A28: B #18 - Corridor-Break / Electrical 120 | B28: 18 | C28: 9.58 | D28: 13.052 | E28: 2 | F28: 3-5/8" | G28: 16 | H28: 250.08 | I28: Corridor-Break / Electrical 120 | J28: F/A02.01 -> A12.01 schedule -> 1/A12.01 -> 7/S5.20 -> 1/A04.01 (ceiling per face) -> 1F/S5.20, 4/S5.20; sello fb875f11ba021d0e | K28: [DERIVADO]
A29: B #19 - Electrical 120 / NER 121 | B29: 19 | C29: 9.58 | D29: 13.052 | E29: 2 | F29: 3-5/8" | G29: 16 | H29: 250.08 | I29: Electrical 120 / NER 121 | J29: F/A02.01 -> A12.01 schedule -> 1/A12.01 -> 7/S5.20 -> 1/A04.01 (ceiling per face) -> 1F/S5.20, 4/S5.20; sello 71d120603f146ff0 | K29: [DERIVADO]
A30: B #20 - Electrical 120, NER 121 / Break 118 | B30: 20 | C30: 14.147 | D30: 13.052 | E30: 2 | F30: 3-5/8" | G30: 16 | H30: 273.74 | I30: Electrical 120, NER 121 / Break 118 | J30: F/A02.01 -> A12.01 schedule -> 1/A12.01 -> 7/S5.20 -> 1/A04.01 (ceiling per face) -> 1F/S5.20, 4/S5.20; sello e931eda939394aaa | K30: [DERIVADO]
A31: TYPE B2
A32: B2 #21 - ATM Room 102 east stub / Central zone | B32: 21 | C32: 5.813 | D32: 15.375 | E32: 2 | F32: 6" | G32: 16 | H32: 116.16 | I32: ATM Room 102 east stub / Central zone | J32: F/A02.01 -> A12.01 schedule -> 1/A12.01 -> 7/S5.20 -> 1/A04.01 (ceiling per face) -> 1F/S5.20, 4/S5.20; sello a15df8ae3175ed1c | K32: [DERIVADO]
A33: B2 #22 - Women's Restroom 114 / Corridor 111 | B33: 22 | C33: 5.94 | D33: 15.375 | E33: 2 | F33: 6" | G33: 16 | H33: 111.66 | I33: Women's Restroom 114 / Corridor 111 | J33: F/A02.01 -> A12.01 schedule -> 1/A12.01 -> 7/S5.20 -> 1/A04.01 (ceiling per face) -> 1F/S5.20, 4/S5.20; sello bd387c6ce9602787 | K33: [DERIVADO]
A34: B2 #23 - Break 118 / Work Room 119 | B34: 23 | C34: 15.073 | D34: 13.052 | E34: 2 | F34: 6" | G34: 16 | H34: 345.7 | I34: Break 118 / Work Room 119 | J34: F/A02.01 -> A12.01 schedule -> 1/A12.01 -> 7/S5.20 -> 1/A04.01 (ceiling per face) -> 1F/S5.20, 4/S5.20; sello eb6aee2b0339a317 | K34: [DERIVADO]
A35: B2 #49 - Men's 113, Storage 117, Wellness 115 / Corridor 111 | B35: 49 | C35: 15.787 | D35: 13.052 | E35: 2 | F35: 6" | G35: 16 | H35: 268.76 | I35: Men's 113, Storage 117, Wellness 115 / Corridor 111 | J35: F/A02.01 -> A12.01 schedule -> 1/A12.01 -> 7/S5.20 -> 1/A04.01 (ceiling per face) -> 1F/S5.20, 4/S5.20; sello 8b26a8dde4d11a82 | K35: [DERIVADO]
A36: TYPE B2K
A37: B2K #24 - Teller line NW corner / Office 108 | B37: 24 | C37: 1.773 | D37: 15.375 | E37: 2 | F37: 6" | G37: 16 | H37: 54.54 | I37: Teller line NW corner / Office 108 | J37: F/A02.01 -> A12.01 schedule -> 1/A12.01, 4/A12.01 -> 7/S5.20 -> 1/A04.01 (ceiling per face) -> 1F/S5.20, 4/S5.20; sello 706f0f7a8d621caa | K37: [DERIVADO]
A38: TYPE C1
A39: C1 #25 - Vestibule 100 NW column enclosure | B39: 25 | C39: 4.513 | D39: 15.375 | E39: 1 | F39: 3-5/8" | G39: 16 | H39: 69.39 | I39: Vestibule 100 NW column enclosure | J39: F/A02.01 -> A12.01 schedule -> 6/A12.01 -> 7/S5.20 -> 1/A04.01 (ceiling per face) -> 1F/S5.20, 4/S5.20; sello 57a235800a5ff14d | K39: [DERIVADO]
A40: C1 #26 - Vestibule 100 NE column enclosure | B40: 26 | C40: 6.533 | D40: 15.375 | E40: 1 | F40: 3-5/8" | G40: 16 | H40: 100.44 | I40: Vestibule 100 NE column enclosure | J40: F/A02.01 -> A12.01 schedule -> 6/A12.01 -> 7/S5.20 -> 1/A04.01 (ceiling per face) -> 1F/S5.20, 4/S5.20; sello e533563ffbfaaefd | K40: [DERIVADO]
A41: C1 #27 - Vestibule 100/101 column enclosure at storefront | B41: 27 | C41: 4 | D41: 15.375 | E41: 1 | F41: 3-5/8" | G41: 16 | H41: 61.5 | I41: Vestibule 100/101 column enclosure at storefront | J41: F/A02.01 -> A12.01 schedule -> 6/A12.01 -> 7/S5.20 -> 1/A04.01 (ceiling per face) -> 1F/S5.20, 4/S5.20; sello 4fe8a47d7aaaee3f | K41: [DERIVADO]
...

Sheet Material Summary
A1: MATERIAL SUMMARY - NET / WASTE / PURCHASE
A2: Waste lives HERE, in its own column, never inside the net quantity.
A3: Material | B3: Unit | C3: Net | D3: Waste % | E3: Waste | F3: Purchase | G3: Selling unit | H3: Pieces to buy | I3: Where it comes from
A4: 1-5/8" metal stud 162S125-33 | B4: LF | C4: 4152.21 | D4: =Inputs!$B$4 -> 0.15 | E4: =C4*D4 -> 622.8315 | F4: =C4+E4 -> 4775.0415 | G4: stick 20 ft | H4: =ROUNDUP(ROUNDUP(F4/15.375,0)/MAX(1,INT(20/15.375)),0) -> 311 | I4: W34 (sello 0415275b7f812490); W35 (sello 6df133960b9316c4); W36 (sello 3edbed156226f599); W37 (sello a505f759de6cfdbb); W38 (sello e97377e6645b96bf); W39 (sello 3ad9a95b5252aa03); W40 (sello 56dbb8736e478b96); W41 (sello 919c37fc58fb63a2); W42 (sello 6384b28e5f5e9693); W43 (sello 3cabe8028dbc50dc); W44 (sello 0ecf456bb6af4ee5); W45 (sello b7172f92028b01b0); W46 (sello 17388afe50c13811); BH1 8/A12.01, 9/A12.01, 10/A12.01, 7/A11.01 (sello 5fada9d59923e331); BH2 8/A12.01, 9/A12.01, 10/A12.01, 7/A11.01 (sello a8142a2699e11f2a); BH3 8/A12.01, 9/A12.01, 10/A12.01, 7/A11.01 (sello d87b1e6f7bbf1c0d); BH4 8/A12.01, 9/A12.01, 10/A12.01, 7/A11.01 (sello 2e9b177c7f808cd0); BH5 8/A12.01, 9/A12.01, 10/A12.01, 7/A11.01 (sello 2888c9bb97475122); BH6 8/A12.01, 9/A12.01, 10/A12.01, 7/A11.01 (sello 9c4f596ee2d8fbc5)
A5: 2-1/2" metal stud 250S137-33 (coiling grille head) | B5: LF | C5: 22 | D5: =Inputs!$B$4 -> 0.15 | E5: =C5*D5 -> 3.3 | F5: =C5+E5 -> 25.3 | G5: stick 20 ft | H5: =ROUNDUP(ROUNDUP(F5/2,0)/MAX(1,INT(20/2)),0) -> 2 | I5: GH103 1/A08.21, 4/A08.21, 3/A08.21 (sello a498466f0e66eeb1)
A6: 3-5/8" metal stud 362S137-33 | B6: LF | C6: 3888.34 | D6: =Inputs!$B$4 -> 0.15 | E6: =C6*D6 -> 583.251 | F6: =C6+E6 -> 4471.591 | G6: stick 20 ft | H6: =ROUNDUP(ROUNDUP(F6/15.375,0)/MAX(1,INT(20/15.375)),0) -> 291 | I6: W01 (sello eaafc2ef90bac845); W02 (sello 9f4753525c22c32a); W03 (sello 475b7b151fd8d002); W04 (sello 613230164f94a0c9); W05 (sello 539958b075072b08); W06 (sello 7ba195f579067e4d); W07 (sello 798d6dd950592d64); W08 (sello df583d67bd60ae8a); W15 (sello 49e6c55b0b1022e7); W16 (sello 31395581ccb58bfa); W17 (sello b72dd1277077447d); W18 (sello fb875f11ba021d0e); W19 (sello 71d120603f146ff0); W20 (sello e931eda939394aaa); W25 (sello 57a235800a5ff14d); W26 (sello e533563ffbfaaefd); W27 (sello 4fe8a47d7aaaee3f); W28 (sello a829e562b511a00c); W29 (sello 8f08cc6c045843f4); W30 (sello 409e9d801492e757); W31 (sello 0a5e3858851c46b3); W32 (sello 42f590d4f79cecd1); W33 (sello d606d41102057f66); W47 (sello aead7879caa50888); W48 (sello a7a3c52427a99864); BHV81 5/A12.10, 3/A12.10 (sello 7f43d1e07fb2b936); BHV82 5/A12.10, 3/A12.10 (sello 04e84caf2300fa39); RS83 4/A02.02, 9/S5.10
A7: 3-5/8" metal stud 362S137-33 (canopy fascia) | B7: LF | C7: 391.85 | D7: =Inputs!$B$4 -> 0.15 | E7: =C7*D7 -> 58.7775 | F7: =C7+E7 -> 450.6275 | G7: stick 20 ft | H7: =ROUNDUP(ROUNDUP(F7/1.979,0)/MAX(1,INT(20/1.979)),0) -> 23 | I7: CN-1 (sello a8765ca9f1397fc9); CN-1B (sello e373d15c6e2f9ebe); CN-2 (sello 5f8d0eb619987491); CN-3 (sello 69099a160c7dc19a); CN-4 (sello 598aef3c0725e90d); CN-4B (sello 6f92dd49cd34b7c5)
A8: 3-5/8" metal stud 362S137-33 (canopy soffit joists) | B8: LF | C8: 465.57 | D8: =Inputs!$B$4 -> 0.15 | E8: =C8*D8 -> 69.8355 | F8: =C8+E8 -> 535.4055 | G8: stick 20 ft | H8: =ROUNDUP(ROUNDUP(F8/4.646,0)/MAX(1,INT(20/4.646)),0) -> 29 | I8: CN-1 (sello a8765ca9f1397fc9); CN-1B (sello e373d15c6e2f9ebe); CN-2 (sello 5f8d0eb619987491); CN-3 (sello 69099a160c7dc19a); CN-4B (sello 6f92dd49cd34b7c5)
A9: 3-5/8" metal stud 362S137-33 (column wraps) | B9: LF | C9: 294 | D9: =Inputs!$B$4 -> 0.15 | E9: =C9*D9 -> 44.1 | F9: =C9+E9 -> 338.1 | G9: stick 20 ft | H9: =ROUNDUP(ROUNDUP(F9/10.5,0)/MAX(1,INT(20/10.5)),0) -> 33 | I9: CW-1 (sello a16969c530582c69)
A10: 3-5/8" metal stud 362S137-33 (drive-thru canopy joists) | B10: LF | C10: 749.92 | D10: =Inputs!$B$4 -> 0.15 | E10: =C10*D10 -> 112.488 | F10: =C10+E10 -> 862.408 | G10: stick 20 ft | H10: =ROUNDUP(ROUNDUP(F10/17.44,0)/MAX(1,INT(20/17.44)),0) -> 50 | I10: CN-4 (sello 598aef3c0725e90d)
A11: 3-5/8" metal stud 362S137-33 (kickers) | B11: LF | C11: 87.5 | D11: =Inputs!$B$4 -> 0.15 | E11: =C11*D11 -> 13.125 | F11: =C11+E11 -> 100.625 | G11: stick 20 ft | H11: =ROUNDUP(ROUNDUP(F11/4.375,0)/MAX(1,INT(20/4.375)),0) -> 6 | I11: SF-2 (sello b9fe88d224404405)
A12: 3-5/8" metal stud 362S137-33 (soffit joists) | B12: LF | C12: 37.59 | D12: =Inputs!$B$4 -> 0.15 | E12: =C12*D12 -> 5.6385 | F12: =C12+E12 -> 43.2285 | G12: stick 20 ft | H12: =ROUNDUP(ROUNDUP(F12/3.417,0)/MAX(1,INT(20/3.417)),0) -> 3 | I12: SF-1 (sello 841bfbe7ee0d91c0)
A13: 3-5/8" metal stud 362S137-33 (soffit verticals) | B13: LF | C13: 139.02 | D13: =Inputs!$B$4 -> 0.15 | E13: =C13*D13 -> 20.853 | F13: =C13+E13 -> 159.873 | G13: stick 20 ft | H13: =ROUNDUP(ROUNDUP(F13/7.375,0)/MAX(1,INT(20/7.375)),0) -> 11 | I13: SF-1 (sello 841bfbe7ee0d91c0)
A14: 3-5/8" metal stud 362S137-68 (14 ga) | B14: LF | C14: 178.97 | D14: =Inputs!$B$4 -> 0.15 | E14: =C14*D14 -> 26.8455 | F14: =C14+E14 -> 205.8155 | G14: stick 20 ft | H14: =ROUNDUP(ROUNDUP(F14/15.375,0)/MAX(1,INT(20/15.375)),0) -> 14 | I14: W09 (sello 6c1128930c1220fa); W10 (sello 23985f2a836f59d9); W11 (sello f1e9835deb4399eb)
A15: 6" exterior metal stud 600S162-54 | B15: LF | C15: 3468.1 | D15: =Inputs!$B$4 -> 0.15 | E15: =C15*D15 -> 520.215 | F15: =C15+E15 -> 3988.315 | G15: stick 20 ft | H15: =ROUNDUP(ROUNDUP(F15/15.375,0)/MAX(1,INT(20/15.375)),0) -> 260 | I15: X50 A/A09.21, 10/S5.10, 7/S5.20, S1.11 (sello 7a368938c344de59); X51 A/A09.21, 10/S5.10, 7/S5.20, S1.11 (sello ddda050dbada1fcb); X52 A/A09.21, 10/S5.10, 7/S5.20, S1.11 (sello a4ed33b922045ffc); X53 A/A09.21, 10/S5.10, 7/S5.20, S1.11 (sello 0d29c5e92275da5a); X54 A/A09.21, 10/S5.10, 7/S5.20, S1.11 (sello 80541f27438743cb); X55 A/A09.21, 10/S5.10, 7/S5.20, S1.11 (sello 43e7fb033c07e815); X56 A/A09.21, 10/S5.10, 7/S5.20, S1.11 (sello 761bf7a4b9a2ae3f); X57 A/A09.21, 10/S5.10, 7/S5.20, S1.11 (sello d41c64258f8eae3c); PIER (sello 8a36add33cc3bcd7)
A16: 6" metal stud 600S137-33 (interior) | B16: LF | C16: 1554.87 | D16: =Inputs!$B$4 -> 0.15 | E16: =C16*D16 -> 233.2305 | F16: =C16+E16 -> 1788.1005 | G16: stick 20 ft | H16: =ROUNDUP(ROUNDUP(F16/15.375,0)/MAX(1,INT(20/15.375)),0) -> 117 | I16: W12 (sello e111a7654cf257f3); W13 (sello 5690b6c694a15d5c); W14 (sello 8ce88e6c1ba3f096); W21 (sello a15df8ae3175ed1c); W22 (sello bd387c6ce9602787); W23 (sello eb6aee2b0339a317); W24 (sello 706f0f7a8d621caa); W49 (sello 8b26a8dde4d11a82); W58 (sello 0dded9561ceb735d)
A17: 6" parapet stud 600S162-54 | B17: LF | C17: 1083.42 | D17: =Inputs!$B$4 -> 0.15 | E17: =C17*D17 -> 162.513 | F17: =C17+E17 -> 1245.933 | G17: stick 20 ft | H17: =ROUNDUP(ROUNDUP(F17/4.886,0)/MAX(1,INT(20/4.886)),0) -> 64 | I17: P60 11/S5.10, 10/S5.10, 4/A09.26 (sello ce7a35893f4d8ccf); P61 11/S5.10, 10/S5.10, 4/A09.26 (sello eb883f858a48152d); P62 11/S5.10, 10/S5.10, 4/A09.26 (sello fcaef94066b5e61a); P63 11/S5.10, 10/S5.10, 4/A09.26 (sello df01618e7ff94d20); P64 11/S5.10, 10/S5.10, 4/A09.26 (sello 3368c2c4e067ba1e); P66 11/S5.10, 10/S5.10, 4/A09.26 (sello 681834f651ce6ce4); P65 11/S5.10, 10/S5.10, 4/A09.26 (sello fa213fd3aa0c82ef)
A18: Access panel 2x2 locking (Vestibule 100) | B18: EA | C18: 1 | D18: 0 | E18: =C18*D18 -> 0 | F18: =C18+E18 -> 1 | G18: EA | H18: =ROUNDUP(F18,0) -> 1 | I18: FO-CEIL (sello 0c36aea1c4b7b5d1)
A19: Additional head track (2/S5.20) | B19: LF | C19: 56 | D19: =Inputs!$B$4 -> 0.15 | E19: =C19*D19 -> 8.4 | F19: =C19+E19 -> 64.4 | G19: piece 10 ft | H19: =ROUNDUP(F19/10,0) -> 7 | I19: X51 A/A09.21, 10/S5.10, 7/S5.20, S1.11 (sello ddda050dbada1fcb); X53 A/A09.21, 10/S5.10, 7/S5.20, S1.11 (sello 0d29c5e92275da5a)
A20: Bottom track 162T125-33 | B20: LF | C20: 295.11 | D20: =Inputs!$B$4 -> 0.15 | E20: =C20*D20 -> 44.2665 | F20: =C20+E20 -> 339.3765 | G20: piece 10 ft | H20: =ROUNDUP(F20/10,0) -> 34 | I20: W34 (sello 0415275b7f812490); W35 (sello 6df133960b9316c4); W36 (sello 3edbed156226f599); W37 (sello a505f759de6cfdbb); W38 (sello e97377e6645b96bf); W39 (sello 3ad9a95b5252aa03); W40 (sello 56dbb8736e478b96); W41 (sello 919c37fc58fb63a2); W42 (sello 6384b28e5f5e9693); W43 (sello 3cabe8028dbc50dc); W44 (sello 0ecf456bb6af4ee5); W45 (sello b7172f92028b01b0); W46 (sello 17388afe50c13811); BH1 8/A12.01, 9/A12.01, 10/A12.01, 7/A11.01 (sello 5fada9d59923e331); BH2 8/A12.01, 9/A12.01, 10/A12.01, 7/A11.01 (sello a8142a2699e11f2a); BH3 8/A12.01, 9/A12.01, 10/A12.01, 7/A11.01 (sello d87b1e6f7bbf1c0d); BH4 8/A12.01, 9/A12.01, 10/A12.01, 7/A11.01 (sello 2e9b177c7f808cd0); BH5 8/A12.01, 9/A12.01, 10/A12.01, 7/A11.01 (sello 2888c9bb97475122); BH6 8/A12.01, 9/A12.01, 10/A12.01, 7/A11.01 (sello 9c4f596ee2d8fbc5)
A21: Bottom track 250T125-33 (framed head) | B21: LF | C21: 13.33 | D21: =Inputs!$B$4 -> 0.15 | E21: =C21*D21 -> 1.9995 | F21: =C21+E21 -> 15.3295 | G21: piece 10 ft | H21: =ROUNDUP(F21/10,0) -> 2 | I21: GH103 1/A08.21, 4/A08.21, 3/A08.21 (sello a498466f0e66eeb1)
A22: Bottom track 362T125-33 | B22: LF | C22: 400.97 | D22: =Inputs!$B$4 -> 0.15 | E22: =C22*D22 -> 60.1455 | F22: =C22+E22 -> 461.1155 | G22: piece 10 ft | H22: =ROUNDUP(F22/10,0) -> 47 | I22: W01 (sello eaafc2ef90bac845); W02 (sello 9f4753525c22c32a); W03 (sello 475b7b151fd8d002); W04 (sello 613230164f94a0c9); W05 (sello 539958b075072b08); W06 (sello 7ba195f579067e4d); W07 (sello 798d6dd950592d64); W08 (sello df583d67bd60ae8a); W15 (sello 49e6c55b0b1022e7); W16 (sello 31395581ccb58bfa); W17 (sello b72dd1277077447d); W18 (sello fb875f11ba021d0e); W19 (sello 71d120603f146ff0); W20 (sello e931eda939394aaa); W25 (sello 57a235800a5ff14d); W26 (sello e533563ffbfaaefd); W27 (sello 4fe8a47d7aaaee3f); W28 (sello a829e562b511a00c); W29 (sello 8f08cc6c045843f4); W30 (sello 409e9d801492e757); W31 (sello 0a5e3858851c46b3); W32 (sello 42f590d4f79cecd1); W33 (sello d606d41102057f66); W47 (sello aead7879caa50888); W48 (sello a7a3c52427a99864); BHV81 5/A12.10, 3/A12.10 (sello 7f43d1e07fb2b936); BHV82 5/A12.10, 3/A12.10 (sello 04e84caf2300fa39); RS83 4/A02.02, 9/S5.10
A23: Bottom track 362T125-33 (column wraps) | B23: LF | C23: 19.33 | D23: =Inputs!$B$4 -> 0.15 | E23: =C23*D23 -> 2.8995 | F23: =C23+E23 -> 22.2295 | G23: piece 10 ft | H23: =ROUNDUP(F23/10,0) -> 3 | I23: CW-1 (sello a16969c530582c69)
A24: Bottom track 362T125-68 | B24: LF | C24: 9.07 | D24: =Inputs!$B$4 -> 0.15 | E24: =C24*D24 -> 1.3605 | F24: =C24+E24 -> 10.4305 | G24: piece 10 ft | H24: =ROUNDUP(F24/10,0) -> 2 | I24: W09 (sello 6c1128930c1220fa); W10 (sello 23985f2a836f59d9); W11 (sello f1e9835deb4399eb)
A25: Bottom track 600T125-33 | B25: LF | C25: 83.91 | D25: =Inputs!$B$4 -> 0.15 | E25: =C25*D25 -> 12.5865 | F25: =C25+E25 -> 96.4965 | G25: piece 10 ft | H25: =ROUNDUP(F25/10,0) -> 10 | I25: W12 (sello e111a7654cf257f3); W13 (sello 5690b6c694a15d5c); W14 (sello 8ce88e6c1ba3f096); W21 (sello a15df8ae3175ed1c); W22 (sello bd387c6ce9602787); W23 (sello eb6aee2b0339a317); W24 (sello 706f0f7a8d621caa); W49 (sello 8b26a8dde4d11a82); W58 (sello 0dded9561ceb735d)
A26: Bottom track 600T125-33 (exterior) | B26: LF | C26: 264.59 | D26: =Inputs!$B$4 -> 0.15 | E26: =C26*D26 -> 39.6885 | F26: =C26+E26 -> 304.2785 | G26: piece 10 ft | H26: =ROUNDUP(F26/10,0) -> 31 | I26: X50 A/A09.21, 10/S5.10, 7/S5.20, S1.11 (sello 7a368938c344de59); X51 A/A09.21, 10/S5.10, 7/S5.20, S1.11 (sello ddda050dbada1fcb); X52 A/A09.21, 10/S5.10, 7/S5.20, S1.11 (sello a4ed33b922045ffc); X53 A/A09.21, 10/S5.10, 7/S5.20, S1.11 (sello 0d29c5e92275da5a); X54 A/A09.21, 10/S5.10, 7/S5.20, S1.11 (sello 80541f27438743cb); X55 A/A09.21, 10/S5.10, 7/S5.20, S1.11 (sello 43e7fb033c07e815); X56 A/A09.21, 10/S5.10, 7/S5.20, S1.11 (sello 761bf7a4b9a2ae3f); X57 A/A09.21, 10/S5.10, 7/S5.20, S1.11 (sello d41c64258f8eae3c); PIER (sello 8a36add33cc3bcd7)
A27: Bottom track 600T125-54 (parapet) | B27: LF | C27: 274.88 | D27: =Inputs!$B$4 -> 0.15 | E27: =C27*D27 -> 41.232 | F27: =C27+E27 -> 316.112 | G27: piece 10 ft | H27: =ROUNDUP(F27/10,0) -> 32 | I27: P60 11/S5.10, 10/S5.10, 4/A09.26 (sello ce7a35893f4d8ccf); P61 11/S5.10, 10/S5.10, 4/A09.26 (sello eb883f858a48152d); P62 11/S5.10, 10/S5.10, 4/A09.26 (sello fcaef94066b5e61a); P63 11/S5.10, 10/S5.10, 4/A09.26 (sello df01618e7ff94d20); P64 11/S5.10, 10/S5.10, 4/A09.26 (sello 3368c2c4e067ba1e); P66 11/S5.10, 10/S5.10, 4/A09.26 (sello 681834f651ce6ce4); P65 11/S5.10, 10/S5.10, 4/A09.26 (sello fa213fd3aa0c82ef)
A28: Bracing 1-1/2" C.R. channel @48" O.C. | B28: LF | C28: 2625.86 | D28: =Inputs!$B$4 -> 0.15 | E28: =C28*D28 -> 393.879 | F28: =C28+E28 -> 3019.739 | G28: piece 16 ft | H28: =ROUNDUP(F28/16,0) -> 189 | I28: W01 (sello eaafc2ef90bac845); W02 (sello 9f4753525c22c32a); W03 (sello 475b7b151fd8d002); W04 (sello 613230164f94a0c9); W05 (sello 539958b075072b08); W06 (sello 7ba195f579067e4d); W07 (sello 798d6dd950592d64); W08 (sello df583d67bd60ae8a); W09 (sello 6c1128930c1220fa); W10 (sello 23985f2a836f59d9); W11 (sello f1e9835deb4399eb); W12 (sello e111a7654cf257f3); W13 (sello 5690b6c694a15d5c); W14 (sello 8ce88e6c1ba3f096); W15 (sello 49e6c55b0b1022e7); W16 (sello 31395581ccb58bfa); W17 (sello b72dd1277077447d); W18 (sello fb875f11ba021d0e); W19 (sello 71d120603f146ff0); W20 (sello e931eda939394aaa); W21 (sello a15df8ae3175ed1c); W22 (sello bd387c6ce9602787); W23 (sello eb6aee2b0339a317); W24 (sello 706f0f7a8d621caa); W25 (sello 57a235800a5ff14d); W26 (sello e533563ffbfaaefd); W27 (sello 4fe8a47d7aaaee3f); W28 (sello a829e562b511a00c); W29 (sello 8f08cc6c045843f4); W
A29: Carrying channel 1-1/2" (ceiling) | B29: LF | C29: 235.63 | D29: =Inputs!$B$4 -> 0.15 | E29: =C29*D29 -> 35.3445 | F29: =C29+E29 -> 270.9745 | G29: piece 16 ft | H29: =ROUNDUP(F29/16,0) -> 17 | I29: CL-1 (sello 54c7bb57a60fc2f4); CL-2 (sello 7fef7d2f15e67f43); CL-3 (sello f6dcbd4b47aeb450); CL-4 (sello 921a70bcdd966b87); CL-5 (sello 03184344c59009ca)
A30: Ceiling / soffit track (CSR soffit) | B30: LF | C30: 48.08 | D30: =Inputs!$B$4 -> 0.15 | E30: =C30*D30 -> 7.212 | F30: =C30+E30 -> 55.292 | G30: piece 10 ft | H30: =ROUNDUP(F30/10,0) -> 6 | I30: SF-1 (sello 841bfbe7ee0d91c0)
A31: Ceiling / soffit track (canopy fascia top & bottom) | B31: LF | C31: 496.12 | D31: =Inputs!$B$4 -> 0.15 | E31: =C31*D31 -> 74.418 | F31: =C31+E31 -> 570.538 | G31: piece 10 ft | H31: =ROUNDUP(F31/10,0) -> 58 | I31: CN-1 (sello a8765ca9f1397fc9); CN-1B (sello e373d15c6e2f9ebe); CN-2 (sello 5f8d0eb619987491); CN-3 (sello 69099a160c7dc19a); CN-4 (sello 598aef3c0725e90d); CN-4B (sello 6f92dd49cd34b7c5)
A32: Ceiling / soffit track (canopy joists both ends) | B32: LF | C32: 426.36 | D32: =Inputs!$B$4 -> 0.15 | E32: =C32*D32 -> 63.954 | F32: =C32+E32 -> 490.314 | G32: piece 10 ft | H32: =ROUNDUP(F32/10,0) -> 50 | I32: CN-1 (sello a8765ca9f1397fc9); CN-1B (sello e373d15c6e2f9ebe); CN-2 (sello 5f8d0eb619987491); CN-3 (sello 69099a160c7dc19a); CN-4 (sello 598aef3c0725e90d); CN-4B (sello 6f92dd49cd34b7c5)
A33: Ceiling / soffit track (transition) | B33: LF | C33: 77.1 | D33: =Inputs!$B$4 -> 0.15 | E33: =C33*D33 -> 11.565 | F33: =C33+E33 -> 88.665 | G33: piece 10 ft | H33: =ROUNDUP(F33/10,0) -> 9 | I33: SF-2 (sello b9fe88d224404405)
A34: Ceiling track (perimeter, ceiling) | B34: LF | C34: 200.04 | D34: =Inputs!$B$4 -> 0.15 | E34: =C34*D34 -> 30.006 | F34: =C34+E34 -> 230.046 | G34: piece 10 ft | H34: =ROUNDUP(F34/10,0) -> 24 | I34: CL-1 (sello 54c7bb57a60fc2f4); CL-2 (sello 7fef7d2f15e67f43); CL-3 (sello f6dcbd4b47aeb450); CL-4 (sello 921a70bcdd966b87); CL-5 (sello 03184344c59009ca)
A35: Deflection clip (exterior / roof step) | B35: EA | C35: 233 | D35: 0.15 | E35: =C35*D35 -> 34.95 | F35: =C35+E35 -> 267.95 | G35: EA | H35: =ROUNDUP(F35,0) -> 268 | I35: X50 A/A09.21, 10/S5.10, 7/S5.20, S1.11 (sello 7a368938c344de59); X51 A/A09.21, 10/S5.10, 7/S5.20, S1.11 (sello ddda050dbada1fcb); X52 A/A09.21, 10/S5.10, 7/S5.20, S1.11 (sello a4ed33b922045ffc); X53 A/A09.21, 10/S5.10, 7/S5.20, S1.11 (sello 0d29c5e92275da5a); X54 A/A09.21, 10/S5.10, 7/S5.20, S1.11 (sello 80541f27438743cb); X55 A/A09.21, 10/S5.10, 7/S5.20, S1.11 (sello 43e7fb033c07e815); RS83 4/A02.02, 9/S5.10 (sello 1792966c34716cb0); PIER (sello 8a36add33cc3bcd7)
A36: Framed opening - access panel 2x2 (ceiling) | B36: LF | C36: 8 | D36: =Inputs!$B$4 -> 0.15 | E36: =C36*D36 -> 1.2 | F36: =C36+E36 -> 9.2 | G36: LF | H36: =ROUNDUP(F36,0) -> 10 | I36: FO-CEIL (sello 0c36aea1c4b7b5d1)
A37: Framed opening - recessed downlight R-14A/AE | B37: LF | C37: 28.03 | D37: =Inputs!$B$4 -> 0.15 | E37: =C37*D37 -> 4.2045 | F37: =C37+E37 -> 32.2345 | G37: LF | H37: =ROUNDUP(F37,0) -> 33 | I37: FO-CEIL (sello 0c36aea1c4b7b5d1)
A38: Framed opening - recessed fixture R-11A (CSR soffit) | B38: LF | C38: 16 | D38: =Inputs!$B$4 -> 0.15 | E38: =C38*D38 -> 2.4 | F38: =C38+E38 -> 18.4 | G38: LF | H38: =ROUNDUP(F38,0) -> 19 | I38: SF-1 (sello 841bfbe7ee0d91c0)
A39: Framed opening - recessed fixture R-11C Waiting | B39: LF | C39: 96 | D39: =Inputs!$B$4 -> 0.15 | E39: =C39*D39 -> 14.4 | F39: =C39+E39 -> 110.4 | G39: LF | H39: =ROUNDUP(F39,0) -> 111 | I39: FO-CEIL (sello 0c36aea1c4b7b5d1)
A40: Framed opening - recessed fixture canopy UU | B40: LF | C40: 694.75 | D40: =Inputs!$B$4 -> 0.15 | E40: =C40*D40 -> 104.2125 | F40: =C40+E40 -> 798.9625 | G40: LF | H40: =ROUNDUP(F40,0) -> 799 | I40: FO-CAN (sello 999cbf35b51b6275)
...

Sheet Pending Items
A1: RFI | B1: Question / condition | C1: Delta of each alternative
A2: RFI-01 | B2: Exterior stud: S1.11 note 5 calls 600S162-54 @ 16" O.C. (@ 12" O.C. within 6 ft of corners) and 11/S5.10 parapet 600S162-54; 7/S5.20 METAL STUD PROPERTIES lists 600S137-33 @ 16" O.C. for exterior walls. Which governs? | C2: Take-off carries 600S162-54 (more material, 56.2). If 600S137-33 @16": same LF minus ~2 studs per building corner end (about -11 studs, ~-165 LF) and lighter gauge (54 -> 33 mil).
A3: RFI-02 | B3: Interior slip track designation is not scheduled (1/A12.01, 3/A12.01 'CONTINUOUS SLIP TRACK'). 7/S5.20 names only 600T200-97 top track. Confirm 362T200-33 / 162T200-33 for 3-5/8" and 1-5/8" walls. | C3: No LF change; price change per LF of deep-leg track vs 1-1/4" leg.
A4: RFI-03 | B4: Type G/G1 1-5/8" studs have no SSMA designation or gauge (5/A12.01, 7/S5.20). Derived 162S125-33. | C4: Gauge only.
A5: RFI-04 | B5: Tag B2K (A02.01) has no row in the partition schedule (A12.01). Derived B2 + 3/8" UL752 fiberglass to 8'-0" (family K delta 4/A12.01); measured 7.68" vs A5K 7 5/8". | C5: 1.77 LF wall; ballistic panel 14 SF.
A6: RFI-05 | B6: Untagged office-front stubs #45 (6.16" thick) and #46 (8.48" thick) classified by measured thickness as G/G1 (rule 55.4) instead of note A 'A1'. Tag G1 drawn 8.48" vs schedule 8". | C6: If A1: -2 rows of 1-5/8" studs and -2 layers board each side; about -150 SF board on 6.15 LF of wall.
A7: RFI-06 | B7: Exterior elevation titles (A09.01 elev 1 'SOUTH' at grid G/F) contradict the north arrow on A02.01. Take-off names facades by grid lines only. | C7: No quantity change.
A8: RFI-07 | B8: Parapet roof-side face: wall sections A09.21-A09.23 say '5/8" EXTERIOR GYPSUM SHEATHING'; 4/A09.26 says '5/8" DENS DECK OR EQUAL' under membrane. Carried as exterior gypsum sheathing (53.5). | C8: ~928 SF either way (material swap, roofer vs framer).
A9: RFI-08 | B9: S2.20 canopy 'B.O.D. EL. 111' - 9"' conflicts with FF EL. 100'-0" (S2.10). Low roof slopes from 13'-0 5/8" (grid B) to 12'-6 3/8" (grid A): studs carried at the high end 13.052 ft except the grid A exterior face (12.531). | C9: Using 12'-6 3/8" for all low-zone interior walls: about -0.52 ft per stud on ~40 interior walls south of grid B (approx -350 LF stud, -400 SF board).
A10: RFI-09 | B10: Drive-up ATM sill height and box beam size not printed on 5/A08.11, 6/A08.11 (used 2'-8 1/8"). | C10: Cripples +/- 1 ft x 1 pc.
A11: RFI-10 | B11: Width of 3/4" FRT plywood strip at storefront/window/door perimeters not dimensioned (2/A09.26, 10/A09.27, 11/A09.27, 3/A09.25, 4/A09.25). Carried as LF. | C11: LF fixed; SF depends on width.
A12: RFI-11 | B12: Vestibule bulkheads 5/A12.10 'METAL STUD FRAMING & BOX HEADER AS NEEDED': stud size not given (carried 3-5/8" @16"). | C12: Size only.
... A49: CLAR-06 | B49: Low roof south of grid B slopes 13'-0 5/8" to 12'-6 3/8" (S2.20): studs carried at the high end (protocol); exterior grid A face at 12.531; parapets low zone at average (55.3). | C49: see RFI-08

Sheet PARA REVISAR EN LA MANANA
A1: # | B1: Punto | C1: Hoja + detalle | D1: Imagen
A2: 1 | B2: PUNTO DE REVISION barrido por tag tipo A1: confirmar que la lista de ubicaciones esta completa (modo sin preguntas) | C2: F/A02.01 | D2: 01_PLANO_A1.jpg
A3: 2 | B3: PUNTO DE REVISION barrido por tag tipo A1K: confirmar que la lista de ubicaciones esta completa (modo sin preguntas) | C3: F/A02.01 | D3: 02_PLANO_A1K.jpg
A4: 3 | B4: PUNTO DE REVISION barrido por tag tipo A5: confirmar que la lista de ubicaciones esta completa (modo sin preguntas) | C4: F/A02.01 | D4: 03_PLANO_A5.jpg
A5: 4 | B5: PUNTO DE REVISION barrido por tag tipo B: confirmar que la lista de ubicaciones esta completa (modo sin preguntas) | C5: F/A02.01 | D5: 04_PLANO_B.jpg
A6: 5 | B6: PUNTO DE REVISION barrido por tag tipo B2: confirmar que la lista de ubicaciones esta completa (modo sin preguntas) | C6: F/A02.01 | D6: 05_PLANO_B2.jpg
A7: 6 | B7: PUNTO DE REVISION barrido por tag tipo B2K: confirmar que la lista de ubicaciones esta completa (modo sin preguntas) | C7: F/A02.01 | D7: 06_PLANO_B2K.jpg
A8: 7 | B8: PUNTO DE REVISION barrido por tag tipo C1: confirmar que la lista de ubicaciones esta completa (modo sin preguntas) | C8: F/A02.01 | D8: 07_PLANO_C1.jpg
A9: 8 | B9: PUNTO DE REVISION barrido por tag tipo F: confirmar que la lista de ubicaciones esta completa (modo sin preguntas) | C9: F/A02.01 | D9: 08_PLANO_F.jpg
A10: 9 | B10: PUNTO DE REVISION barrido por tag tipo G: confirmar que la lista de ubicaciones esta completa (modo sin preguntas) | C10: F/A02.01 | D10: 09_PLANO_G.jpg
A11: 10 | B11: PUNTO DE REVISION barrido por tag tipo G1: confirmar que la lista de ubicaciones esta completa (modo sin preguntas) | C11: F/A02.01 | D11: 10_PLANO_G1.jpg
A12: 11 | B12: RFI-01: Exterior stud: S1.11 note 5 calls 600S162-54 @ 16" O.C. (@ 12" O.C. within 6 ft of corners) and 11/S5.10 parapet 600S162-54; 7/S5.20 METAL STUD PROPERTIES lists 600S137-33 @ 16" O.C. for exterior walls. Which governs? | delta: Take-off carries 600S162-54 (more material, 56.2). If 600S137-33 @16": same LF minus ~2 studs per building corner end (about -11 studs, ~-165 LF) and lighter gauge (54 -> 33 mil). | C12: ver RFI
A13: 12 | B13: RFI-02: Interior slip track designation is not scheduled (1/A12.01, 3/A12.01 'CONTINUOUS SLIP TRACK'). 7/S5.20 names only 600T200-97 top track. Confirm 362T200-33 / 162T200-33 for 3-5/8" and 1-5/8" walls. | delta: No LF change; price change per LF of deep-leg track vs 1-1/4" leg. | C13: ver RFI
A14: 13 | B14: RFI-03: Type G/G1 1-5/8" studs have no SSMA designation or gauge (5/A12.01, 7/S5.20). Derived 162S125-33. | delta: Gauge only. | C14: ver RFI
A15: 14 | B15: RFI-04: Tag B2K (A02.01) has no row in the partition schedule (A12.01). Derived B2 + 3/8" UL752 fiberglass to 8'-0" (family K delta 4/A12.01); measured 7.68" vs A5K 7 5/8". | delta: 1.77 LF wall; ballistic panel 14 SF. | C15: ver RFI
A16: 15 | B16: RFI-05: Untagged office-front stubs #45 (6.16" thick) and #46 (8.48" thick) classified by measured thickness as G/G1 (rule 55.4) instead of note A 'A1'. Tag G1 drawn 8.48" vs schedule 8". | delta: If A1: -2 rows of 1-5/8" studs and -2 layers board each side; about -150 SF board on 6.15 LF of wall. | C16: ver RFI
A17: 16 | B17: RFI-06: Exterior elevation titles (A09.01 elev 1 'SOUTH' at grid G/F) contradict the north arrow on A02.01. Take-off names facades by grid lines only. | delta: No quantity change. | C17: ver RFI
A18: 17 | B18: RFI-07: Parapet roof-side face: wall sections A09.21-A09.23 say '5/8" EXTERIOR GYPSUM SHEATHING'; 4/A09.26 says '5/8" DENS DECK OR EQUAL' under membrane. Carried as exterior gypsum sheathing (53.5). | delta: ~928 SF either way (material swap, roofer vs framer). | C18: ver RFI
A19: 18 | B19: RFI-08: S2.20 canopy 'B.O.D. EL. 111' - 9"' conflicts with FF EL. 100'-0" (S2.10). Low roof slopes from 13'-0 5/8" (grid B) to 12'-6 3/8" (grid A): studs carried at the high end 13.052 ft except the grid A exterior face (12.531). | delta: Using 12'-6 3/8" for all low-zone interior walls: about -0.52 ft per stud on ~40 interior walls south of grid B (approx -350 LF stud, -400 SF board). | C19: ver RFI
A20: 19 | B20: RFI-09: Drive-up ATM sill height and box beam size not printed on 5/A08.11, 6/A08.11 (used 2'-8 1/8"). | delta: Cripples +/- 1 ft x 1 pc. | C20: ver RFI
A21: 20 | B21: RFI-10: Width of 3/4" FRT plywood strip at storefront/window/door perimeters not dimensioned (2/A09.26, 10/A09.27, 11/A09.27, 3/A09.25, 4/A09.25). Carried as LF. | delta: LF fixed; SF depends on width. | C21: ver RFI
A22: 21 | B22: RFI-11: Vestibule bulkheads 5/A12.10 'METAL STUD FRAMING & BOX HEADER AS NEEDED': stud size not given (carried 3-5/8" @16"). | delta: Size only. | C22: ver RFI
A23: 22 | B23: RFI-12: GWB ceiling framing: A09.33 shows 12 ga hanger wire (3/A09.33) and 3-5/8" metal stud framing @16" only around trimless fixtures and bulkheads (6/A09.33, 8/A09.33); no carrying/furring channel is detailed. Carried ASTM C754: 7/8" furring @16", 1-1/2" CRC @48", 12 ga hangers @48" O.C., perimeter track. | delta: If 362S137-33 joists @16" replace furring: -703 LF furring, +703 LF 3-5/8" stud (938 SF of GWB ceilings). | C23: ver RFI
... A59: 58 | B59: CLAR-06: Low roof south of grid B slopes 13'-0 5/8" to 12'-6 3/8" (S2.20): studs carried at the high end (protocol); exterior grid A face at 12.531; parapets low zone at average (55.3). | delta: see RFI-08 | C59: ver RFI
A60: 59 | B60: Untagged walls: only #45, #46 (office front stubs) and #47 (drinking fountain alcove back wall) found by graphic sweep; confirm no other untagged A1 wall. | C60: F/A02.01 | D60: 11_PLANO_EXTERIORES.jpg
A61: 60 | B61: Wall lengths are vector run lengths end-cap to end-cap (union of faces), not center-to-center; delta +0.2 to +0.8 ft per wall end against a perpendicular wall. | C61: F/A02.01
A62: 61 | B62: Doors 102, 116, 118A, 118B, 122 lie between two runs; each was loaded to one run (rule 29); door 111 is in its own A1 run #48 - see cierres. | C62: F/A02.01
A63: 62 | B63: Adversarial review applied: 4 reviewers (interior, exterior, ceilings/blocking, completeness); corrections listed in Back-check/ADVERSARIAL_LOG.md. | C63: Back-check
A64: 63 | B64: Hollow metal frame R.O. taken as 3'-4" (60 pt measured between jambs, rule 55.4) for 3'-0" doors. | C64: 10/A12.02
A65: 64 | B65: MEP crossing: only fire dampers (M01.01) quantified as wall openings; ducts above ceilings through deck-high walls not individually crossed (registro2/mep tools not run) - review. | C65: M01.01
A66: 65 | B66: Grid B (S2.20) location vs walls #12, #22, #58: quantities ALREADY use zone-weighted height (15.375 north / 13.052 south of B) in stud and board; Partition Takeoff Height column shows 15.375 only as label. Confirm grid B line only - do NOT lower these walls again (would double-deduct). Delta ~0. | C66: S2.20 / F/A02.01 | D66: 05_PLANO_B2.jpg

Sheet Alcances
A1: ALC | B1: Alcance | C1: Estado | D1: Nota (cantidad, NO APLICA + hoja, o RFI)
A2: ALC-01 | B2: Interior partition framing (studs + tracks) | C2: CUANTIFICADO | D2: Material Summary 3-5/8", 6", 1-5/8" studs + tracks; 47 interior walls sealed (closer.py); 3/A12.01
A3: ALC-02 | B3: Exterior wall framing (CFMF) | C3: CUANTIFICADO | D3: 6" exterior metal stud 600S162-54, X50-X57; A/A09.21
A4: ALC-03 | B4: Parapet framing | C4: CUANTIFICADO | D4: 6" parapet stud 600S162-54, P60-P65; 11/S5.10
A5: ALC-04 | B5: Top / deflection and bottom track | C5: CUANTIFICADO | D5: bottom / top / deflection track rows by size; 10/S5.10, 7/S5.20
A6: ALC-05 | B6: Headers, sills and jambs at openings | C6: CUANTIFICADO | D6: headers, sill track, additional head track; 9/S5.20, 2/S5.20
A7: ALC-06 | B7: Bracing / bridging | C7: CUANTIFICADO | D7: 1-1/2" C.R. channel @48"; 1F/S5.20
A8: ALC-07 | B8: Gypsum board on walls (layers per type) | C8: CUANTIFICADO | D8: 5/8" gypsum board regular by face; A12.01
A9: ALC-08 | B9: Moisture / abuse / special board at wet zones | C9: CUANTIFICADO | D9: 5/8" moisture resistant gypsum board at chase + urinal chase; sheet note F A08.01
A10: ALC-09 | B10: Exterior gypsum / glass mat sheathing | C10: CUANTIFICADO | D10: glass mat base band + canopy band; exterior gypsum sheathing parapet; A09.26
A11: ALC-10 | B11: FRT plywood sheathing / substrate | C11: CUANTIFICADO | D11: 5/8" FRT plywood bonded polyiso exterior, canopy FRT plywood, 3/4" FRT plywood; A09.21
A12: ALC-11 | B12: Gypsum board ceilings | C12: CUANTIFICADO | D12: CL-1..CL-5 GWB ceilings; 1/A04.01
... A25: ALC-24 | B25: Finish level (Level 4 / Level 5) | C25: CUANTIFICADO | D25: Level 5 finish SF at WC-18 / WC-22 (A00.40); Level 4 elsewhere (A05.01 no spec, assumed)
