Workbook

Sheet Inputs
A1: Bank of America - Broomfield, CO (CO1-111) | METAL FRAMING & DRYWALL TAKEOFF
A2: Bid set: 2025.08.26_CO1-111_Broomfield_PERMIT SET_BID SET.pdf · 2026-10-19 · Edit ONLY the yellow cells.
A4: PARAMETER | B4: VALUE | C4: NOTE / SOURCE
A5: Waste - ALL METAL, any type | B5: 0.15 | C5: Estimator standing rule: 15% on everything that is metal.
A6: Waste - EVERYTHING THAT IS NOT METAL | B6: 0.06 | C6: Estimator standing rule: same figure as board.
A7: Board sheet width (ft) | B7: 4 | C7: Sheet size is a parameter; buy the size that wastes least.
A8: Board sheet length (ft) | B8: 12 | C8: Change it and every sheet count re-rounds.
A9: SF per board sheet | B9: =B7*B8 -> 48 | C9: Width x length.
A10: Stud stock length (ft) | B10: 20 | C10: Stud, header, framed opening and stud blocking: sticks.
A11: Track stock length (ft) | B11: 10 | C11: Track, sill track and purlin: runs.
A12: Floor plan scale (pt/ft) | B12: 18 | C12: Project value (canon constants).
A13: B.O. Deck (ft) | B13: 15.375 | C13: Project value (canon constants).
A14: T.O. Parapet (ft) | B14: 19.667 | C14: Project value (canon constants).
A15: Sealant coverage (LF per tube) | B15: 25 | C15: Sealant yield per tube - set your supplier's figure.
A16: C.R. channel stock length (ft) | B16: 16 | C16: 1-1/2" cold-rolled channel (bracing, carrying channel).
A17: Hat / furring channel stock (ft) | B17: 12 | C17: 7/8" hat furring channel.
A18: Trim stick length (ft) | B18: 10 | C18: Corner bead, casing bead, shadow molding, PVC trim.
A19: Hanger wire purchase | B19: continuous coil (LF) | C19: Bought by LF from a continuous coil; the hanger count goes on its own PCS row.
A20: Drywall screws per SF of board | B20: 1.2 | C20: YIELD (GA-216 field / perimeter spacing).
A21: Framing screws per stud piece | B21: 4 | C21: YIELD: 2 per stud-to-track connection, each end.
A22: Power-driven pin spacing (ft) | B22: 1 | C22: YIELD: bottom track on slab, interior walls.
A23: Joint compound (lb per SF) | B23: 0.072 | C23: YIELD: 72 lb per 1,000 SF, level 4 (estimator criterion).
A24: Joint tape (LF per SF) | B24: 0.37 | C24: YIELD: 370 LF per 1,000 SF.
A25: Expansion anchor spacing (ft) | B25: 0.6667 | C25: YIELD: exterior bottom track on slab.

Sheet Partition Takeoff
A1: ORGANIZED PARTITION TAKEOFF - Bank of America - Broomfield, CO (CO1-111)
A2: Grouped by partition type. Every row cites its DETAIL/SHEET and its status.
A4: Partition / Scope | B4: Wall # | C4: Length (LF) | D4: Height (FT) | E4: Layers | F4: Stud Size | G4: Stud O.C. (in) | H4: Board (SF) | I4: Location | J4: Source (DETAIL/SHEET) | K4: Status
A5: TYPE EXT-6CFMF
A6: EXT-6CFMF #AEXT-01 - West exterior wall on grid 2, from the south end of SF-W1 (24 HR vestibule 101) to the jog at grid D (ATM room 102); exterior = drive-thru lane | B6: AEXT-01 | C6: 21.889 | D6: 14.358 | E6: 1 | F6: 6" | G6: 16 | H6: 330.79 | I6: West exterior wall on grid 2, from the south end of SF-W1 (24 HR vestibule 101) to the jog at grid D (ATM room 102); exterior = drive-thru lane | J6: A/A09.21 | K6: [DERIVED]
A7: EXT-6CFMF #AEXT-02 - Exterior jog wall on grid D between grid 2 and grid 3 (south wall of ATM room 102; faces south to the drive-thru canopy) | B7: AEXT-02 | C7: 3.353 | D7: 14.358 | E7: 1 | F7: 6" | G7: 16 | H7: 51.55 | I7: Exterior jog wall on grid D between grid 2 and grid 3 (south wall of ATM room 102; faces south to the drive-thru canopy) | J7: A/A09.21 | K7: [DERIVED]
A8: EXT-6CFMF #AEXT-03+AEXT-04 - West exterior wall on grid 3, grid D to grid B (offices 109, 110, women's 114) + West exterior wall on grid 3, grid B to grid A (women's 114, plumbing chase, men's 113, janitor 112, wellness 115) | B8: AEXT-03+AEXT-04 | C8: 48.811 | D8: 13.067 | E8: 1 | F8: 6" | G8: 16 | H8: 658.68 | I8: West exterior wall on grid 3, grid D to grid B (offices 109, 110, women's 114) + West exterior wall on grid 3, grid B to grid A (women's 114, plumbing chase, men's 113, janitor 112, wellness 115) | J8: A/A09.21 | K8: [DERIVED]
A9: EXT-6CFMF #AEXT-05+AEXT-06 - South exterior wall on grid A, grid 3 to grid 6 (wellness 115, corridor 111 with HM door 123, NER 121, break room 118 west part) + South exterior wall on grid A, grid 6 to grid 8 (break room 118 east part, work room 119) | B9: AEXT-05+AEXT-06 | C9: 51.733 | D9: 11.17 | E9: 1 | F9: 6" | G9: 16 | H9: 621.04 | I9: South exterior wall on grid A, grid 3 to grid 6 (wellness 115, corridor 111 with HM door 123, NER 121, break room 118 west part) + South exterior wall on grid A, grid 6 to grid 8 (break room 118 east part, work room 119) | J9: A/A09.21 | K9: [DERIVED]
A10: EXT-6CFMF #AEXT-07+AEXT-08 - East exterior wall on grid 8, grid F to grid B (offices 105-108 with clerestory windows W-E1..W-E4, cash window 116 north part) + East exterior wall on grid 8, grid B to grid A (cash window 116 south part, work room 119) | B10: AEXT-07+AEXT-08 | C10: 77.189 | D10: 13.542 | E10: 1 | F10: 6" | G10: 16 | H10: 1063 | I10: East exterior wall on grid 8, grid F to grid B (offices 105-108 with clerestory windows W-E1..W-E4, cash window 116 north part) + East exterior wall on grid 8, grid B to grid A (cash window 116 south part, work room 119) | J10: A/A09.21 | K10: [DERIVED]
A11: EXT-6CFMF #AEXT-09 - North exterior wall on grid F over office 105 (grid 7 to grid 8); west end = SF-N2 storefront jamb | B11: AEXT-09 | C11: 12.639 | D11: 14.358 | E11: 1 | F11: 6" | G11: 16 | H11: 194.32 | I11: North exterior wall on grid F over office 105 (grid 7 to grid 8); west end = SF-N2 storefront jamb | J11: A/A09.21 | K11: [DERIVED]
A12: EXT-6CFMF #AEXT-16 - NW storefront pier at grid 2 / G (vestibule 100): exterior 6" CFMF L (north + west faces) | B12: AEXT-16 | C12: 3.375 | D12: 14.358 | E12: 0 | F12: 6" | G12: 16 | H12: 0 | I12: NW storefront pier at grid 2 / G (vestibule 100): exterior 6" CFMF L (north + west faces) | J12: 1/A09.25 | K12: [DERIVED]
A13: EXT-6CFMF #AEXT-17 - NE storefront pier at grid 4 / G-F (vestibule 100 / central zone 103): exterior 6" CFMF L (north + east faces) | B13: AEXT-17 | C13: 2.896 | D13: 14.358 | E13: 0 | F13: 6" | G13: 16 | H13: 0 | I13: NE storefront pier at grid 4 / G-F (vestibule 100 / central zone 103): exterior 6" CFMF L (north + east faces) | J13: 2/A09.25 | K13: [DERIVED]
A14: TYPE CANOPY-COL
A15: CANOPY-COL #AEXT-18 - Drive-thru canopy column #1 (north to south) on grid 1 (west of the ATM drive lane) | B15: AEXT-18 | C15: 5.667 | D15: 10.5 | E15: 0 | F15: 3-5/8" | G15: 16 | H15: 0 | I15: Drive-thru canopy column #1 (north to south) on grid 1 (west of the ATM drive lane) | J15: 5/A09.25 | K15: [DERIVED]
A16: CANOPY-COL #AEXT-19 - Drive-thru canopy column #2 (north to south) on grid 1 (west of the ATM drive lane) | B16: AEXT-19 | C16: 5.667 | D16: 10.5 | E16: 0 | F16: 3-5/8" | G16: 16 | H16: 0 | I16: Drive-thru canopy column #2 (north to south) on grid 1 (west of the ATM drive lane) | J16: 5/A09.25 | K16: [DERIVED]
A17: CANOPY-COL #AEXT-20 - Drive-thru canopy column #3 (north to south) on grid 1 (west of the ATM drive lane) | B17: AEXT-20 | C17: 5.667 | D17: 10.5 | E17: 0 | F17: 3-5/8" | G17: 16 | H17: 0 | I17: Drive-thru canopy column #3 (north to south) on grid 1 (west of the ATM drive lane) | J17: 5/A09.25 | K17: [DERIVED]
A18: CANOPY-COL #AEXT-21 - Drive-thru canopy column #4 (north to south) on grid 1 (west of the ATM drive lane) | B18: AEXT-21 | C18: 5.667 | D18: 10.5 | E18: 0 | F18: 3-5/8" | G18: 16 | H18: 0 | I18: Drive-thru canopy column #4 (north to south) on grid 1 (west of the ATM drive lane) | J18: 5/A09.25 | K18: [DERIVED]
A19: TYPE EXT-PARAPET
A20: EXT-PARAPET #AEXT-27 - tower (parapet 2) west run on grid 2, G to D | B20: AEXT-27 | C20: 29 | D20: 4.292 | E20: 0 | F20: 6" parapet | G20: 16 | H20: 0 | I20: tower (parapet 2) west run on grid 2, G to D | J20: 11/S5.10 | K20: [DERIVED]
A21: EXT-PARAPET #AEXT-28 - tower (parapet 2) jog run on grid D, grid 2 to grid 3 | B21: AEXT-28 | C21: 3.867 | D21: 4.292 | E21: 0 | F21: 6" parapet | G21: 16 | H21: 0 | I21: tower (parapet 2) jog run on grid D, grid 2 to grid 3 | J21: 11/S5.10 | K21: [DERIVED]
A22: EXT-PARAPET #AEXT-29+AEXT-30 - parapet 1 on grid 3, D to B (high deck) + parapet 1 on grid 3, B to A (sloped low deck) | B22: AEXT-29+AEXT-30 | C22: 47.927 | D22: 3.406 | E22: 0 | F22: 6" parapet | G22: 16 | H22: 0 | I22: parapet 1 on grid 3, D to B (high deck) + parapet 1 on grid 3, B to A (sloped low deck) | J22: 11/S5.10 | K22: [DERIVED]
A23: EXT-PARAPET #AEXT-31 - parapet 1 on grid A, grid 3 to grid 8 (eave) | B23: AEXT-31 | C23: 52.333 | D23: 4.886 | E23: 0 | F23: 6" parapet | G23: 16 | H23: 0 | I23: parapet 1 on grid A, grid 3 to grid 8 (eave) | J23: 11/S5.10 | K23: [DERIVED]
A24: EXT-PARAPET #AEXT-33+AEXT-32 - parapet 1 on grid 8, F to B (high deck) + parapet 1 on grid 8, B to A (sloped low deck) | B24: AEXT-33+AEXT-32 | C24: 75.933 | D24: 2.899 | E24: 0 | F24: 6" parapet | G24: 16 | H24: 0 | I24: parapet 1 on grid 8, F to B (high deck) + parapet 1 on grid 8, B to A (sloped low deck) | J24: 11/S5.10 | K24: [DERIVED]
A25: EXT-PARAPET #AEXT-34 - parapet 1 on grid F, grid 4 return to grid 8 | B25: AEXT-34 | C25: 40 | D25: 2.042 | E25: 0 | F25: 6" parapet | G25: 16 | H25: 0 | I25: parapet 1 on grid F, grid 4 return to grid 8 | J25: 11/S5.10 | K25: [DERIVED]
A26: EXT-PARAPET #AEXT-35 - tower (parapet 2) north run on grid G, grid 2 to grid 4 | B26: AEXT-35 | C26: 16.686 | D26: 4.292 | E26: 0 | F26: 6" parapet | G26: 16 | H26: 0 | I26: tower (parapet 2) north run on grid G, grid 2 to grid 4 | J26: 11/S5.10 | K26: [DERIVED]
A27: EXT-PARAPET #AEXT-36 - tower (parapet 2) east return on grid 4 (free end on the roof, A02.02 key note 10 ACM coping) | B27: AEXT-36 | C27: 4.092 | D27: 4.292 | E27: 0 | F27: 6" parapet | G27: 16 | H27: 0 | I27: tower (parapet 2) east return on grid 4 (free end on the roof, A02.02 key note 10 ACM coping) | J27: 11/S5.10 | K27: [DERIVED]
A28: TYPE A1
A29: A1 #AI1-01 - Calling Cubes 122 north wall / Waiting 104 (grid 5-6, between C.5 and C, y 971 pt) | B29: AI1-01 | C29: 17.02 | D29: 15.375 | E29: 1.98 | F29: 3-5/8" | G29: 16 | H29: 361.95 | I29: Calling Cubes 122 north wall / Waiting 104 (grid 5-6, between C.5 and C, y 971 pt) | J29: 3/A12.01 | K29: [DERIVED]
A30: A1 #AI1-02 - MW01 printer closet east wall / Calling Cubes 122 (grid 5-6) | B30: AI1-02 | C30: 3.533 | D30: 15.375 | E30: 1.9 | F30: 3-5/8" | G30: 16 | H30: 80.69 | I30: MW01 printer closet east wall / Calling Cubes 122 (grid 5-6) | J30: 3/A12.01 | K30: [DERIVED]
A31: A1 #AI1-03 - MW01 printer closet south wall / MW07 millwork in Calling Cubes 122 | B31: AI1-03 | C31: 2.02 | D31: 15.375 | E31: 2 | F31: 3-5/8" | G31: 16 | H31: 49.24 | I31: MW01 printer closet south wall / MW07 millwork in Calling Cubes 122 | J31: 3/A12.01 | K31: [DERIVED]
A32: A1 #AI1-07 - Corridor 111 north wall (door 111) / Central Zone 103 strip, between grid 4 and 5 just north of grid B | B32: AI1-07 | C32: 5.587 | D32: 15.375 | E32: 1.89 | F32: 3-5/8" | G32: 16 | H32: 55.84 | I32: Corridor 111 north wall (door 111) / Central Zone 103 strip, between grid 4 and 5 just north of grid B | J32: 3/A12.01 | K32: [DERIVED]
A33: A1 #AI1-10 - Calling Cubes 122 south wall / Break Room 118 (MW21), grid 5-6 south of grid B | B33: AI1-10 | C33: 15.812 | D33: 13.052 | E33: 1.98 | F33: 3-5/8" | G33: 16 | H33: 281.14 | I33: Calling Cubes 122 south wall / Break Room 118 (MW21), grid 5-6 south of grid B | J33: 3/A12.01 | K33: [DERIVED]
A34: A1 #AI1-11 - Short N-S wall at MW21 east end, Break Room 118 / CSR customer queue (grid 6) | B34: AI1-11 | C34: 1.733 | D34: 11.91 | E34: 1.8 | F34: 3-5/8" | G34: 16 | H34: 28.88 | I34: Short N-S wall at MW21 east end, Break Room 118 / CSR customer queue (grid 6) | J34: 3/A12.01 | K34: [DERIVED]
A35: A1 #AI1-12 - Break Room 118 north wall (door 118A) / CSR customer queue, grid 6-7 | B35: AI1-12 | C35: 5.5 | D35: 13.052 | E35: 1.93 | F35: 3-5/8" | G35: 16 | H35: 43.44 | I35: Break Room 118 north wall (door 118A) / CSR customer queue, grid 6-7 | J35: 3/A12.01 | K35: [CONFIRMED]
A36: A1 #AI1-14 - Work Room 119 north wall (door 119) / Cash Window 116, grid 7-8 | B36: AI1-14 | C36: 11.667 | D36: 13.052 | E36: 2 | F36: 3-5/8" | G36: 16 | H36: 168.06 | I36: Work Room 119 north wall (door 119) / Cash Window 116, grid 7-8 | J36: 3/A12.01 | K36: [CONFIRMED]
A37: A1 #AI1-15 - Corridor 111 east wall on grid 5 (door 118B; Electrical 120 and NER 121 west wall, FD-1/FD-2) | B37: AI1-15 | C37: 20.521 | D37: 11.91 | E37: 1.94 | F37: 3-5/8" | G37: 16 | H37: 363.7 | I37: Corridor 111 east wall on grid 5 (door 118B; Electrical 120 and NER 121 west wall, FD-1/FD-2) | J37: 3/A12.01 | K37: [DERIVED]
A38: A1 #RES-01+RES-01N+RES-01S - Drinking-fountain alcove on grid 4, Corridor 111 (between women's 114 and men's 113 B2 walls) | B38: RES-01+RES-01N+RES-01S | C38: 7.487 | D38: 13.052 | E38: 2 | F38: 3-5/8" | G38: 16 | H38: 134.76 | I38: Drinking-fountain alcove on grid 4, Corridor 111 (between women's 114 and men's 113 B2 walls) | J38: 3/A12.01 | K38: [DERIVED]
A39: TYPE A5
A40: A5 #AI1-04 - Calling Cubes 122 west wall (upper) / Central Zone 103 strip east of office front grid 4 (FEC-1 on W face) | B40: AI1-04 | C40: 11 | D40: 15.375 | E40: 1.97 | F40: 6" | G40: 16 | H40: 227.82 | I40: Calling Cubes 122 west wall (upper) / Central Zone 103 strip east of office front grid 4 (FEC-1 on W face) | J40: 3/A12.01 | K40: [DERIVED]
A41: A5 #AI1-05+AI1-06 - Calling Cubes 122 west wall (lower line, north of grid B) / Corridor 111 + Calling Cubes 122 west wall (lower line, south of grid B, door 122) / Corridor 111 | B41: AI1-05+AI1-06 | C41: 4.875 | D41: 12.587 | E41: 1.93 | F41: 6" | G41: 16 | H41: 36.8 | I41: Calling Cubes 122 west wall (lower line, north of grid B) / Corridor 111 + Calling Cubes 122 west wall (lower line, south of grid B, door 122) / Corridor 111 | J41: 3/A12.01 | K41: [DERIVED]
...

Sheet Material Summary
A1: MATERIAL SUMMARY - NET / WASTE / PURCHASE
A2: Waste lives HERE, in its own column, applied ONCE: Pieces = ROUNDUP(Net x (1 + waste) / stock). Every stock length, coverage and yield is an Inputs cell.
A3: Material | B3: Unit | C3: Net | D3: Waste % | E3: Waste | F3: Purchase | G3: Selling unit | H3: Pieces to buy | I3: Where it comes from | J3: Yield check (live formula)
A4: 6" metal stud 600S162-54 / 600S137-33 (exterior CFMF, A5 / B2 / B2K interior) | B4: LF | C4: 4587.69 | D4: =Inputs!$B$5 -> 0.15 | E4: =C4*D4 -> 688.1535 | F4: =C4+E4 -> 5275.8435 | G4: stick 20 ft | H4: =ROUNDUP(F4/Inputs!$B$10,0) -> 264 | I4: familias_out.json '6" stud (all gauges)'; S1.11 note 5, 7/S5.20, 1/A12.01, 4/A12.01
A5: 3-5/8" metal stud 362S137-33 (A1, A1K, B, C1, ceilings, soffits, canopy) | B5: LF | C5: 6879.25 | D5: =Inputs!$B$5 -> 0.15 | E5: =C5*D5 -> 1031.8875 | F5: =C5+E5 -> 7911.1375 | G5: stick 20 ft | H5: =ROUNDUP(F5/Inputs!$B$10,0) -> 396 | I5: familias_out.json '3-5/8" stud (all gauges)'; 7/S5.20, 3/A12.01, 6/A12.01, 7/A09.26
A6: 1-5/8" metal stud (G / G1 double row) | B6: LF | C6: 3983.76 | D6: =Inputs!$B$5 -> 0.15 | E6: =C6*D6 -> 597.564 | F6: =C6+E6 -> 4581.324 | G6: stick 20 ft | H6: =ROUNDUP(F6/Inputs!$B$10,0) -> 230 | I6: familias_out.json '1-5/8" stud'; 5/A12.01, 10/A12.01
A7: 6" parapet stud 600S162-54 (parapet infill, bay by bay) | B7: LF | C7: 1001.58 | D7: =Inputs!$B$5 -> 0.15 | E7: =C7*D7 -> 150.237 | F7: =C7+E7 -> 1151.817 | G7: stick 20 ft | H7: =ROUNDUP(F7/Inputs!$B$10,0) -> 58 | I7: familias_out.json '6" parapet stud'; 11/S5.10, 6/S5.10
A8: Ceiling / soffit track 3-5/8" (ceiling perimeter, soffits, transitions, canopy joists, fascia) | B8: LF | C8: 1254.43 | D8: =Inputs!$B$5 -> 0.15 | E8: =C8*D8 -> 188.1645 | F8: =C8+E8 -> 1442.5945 | G8: stick 20 ft | H8: =ROUNDUP(F8/Inputs!$B$10,0) -> 73 | I8: familias_out.json 'ceiling / soffit track'; 7/A09.33, 8/A09.33, 10/A09.33, 7/A09.26
A9: Bracing 1-1/2" C.R. channel @ 48" O.C. | B9: LF | C9: 2463.62 | D9: =Inputs!$B$5 -> 0.15 | E9: =C9*D9 -> 369.543 | F9: =C9+E9 -> 2833.163 | G9: C.R. channel 16 ft | H9: =ROUNDUP(F9/Inputs!$B$16,0) -> 178 | I9: familias_out.json 'bracing C.R. channel'; F/1/S5.20
A10: Purlin 1x1x1 16 ga (top track to deck parallel to flute) | B10: LF | C10: 202.03 | D10: =Inputs!$B$5 -> 0.15 | E10: =C10*D10 -> 30.3045 | F10: =C10+E10 -> 232.3345 | G10: run 10 ft | H10: =ROUNDUP(F10/Inputs!$B$11,0) -> 24 | I10: familias_out.json 'purlin (track to deck)'; 10/A09.33, 8/A09.33
A11: Header / box beam (metal stud, by pieces) | B11: LF | C11: 792.29 | D11: =Inputs!$B$5 -> 0.15 | E11: =C11*D11 -> 118.8435 | F11: =C11+E11 -> 911.1335 | G11: stick 20 ft | H11: =ROUNDUP(F11/Inputs!$B$10,0) -> 46 | I11: familias_out.json 'header / box beam'; 7/S5.20, 2/S5.20, 11/A09.27, 6/A08.11, 4/A08.21, 8/A12.01, 4/A12.10
A12: Sill track (double over 4'-0") | B12: LF | C12: 119.12 | D12: =Inputs!$B$5 -> 0.15 | E12: =C12*D12 -> 17.868 | F12: =C12+E12 -> 136.988 | G12: run 10 ft | H12: =ROUNDUP(F12/Inputs!$B$11,0) -> 14 | I12: familias_out.json 'sill track'; 2/S5.20
A13: Furring channel 7/8" (suspended GWB ceilings) | B13: LF | C13: 777.07 | D13: =Inputs!$B$5 -> 0.15 | E13: =C13*D13 -> 116.5605 | F13: =C13+E13 -> 893.6305 | G13: hat channel 12 ft | H13: =ROUNDUP(F13/Inputs!$B$17,0) -> 75 | I13: familias_out.json 'furring channel'; A04.01; RFI-ARCP-03
A14: Carrying channel 1-1/2" C.R. (suspended GWB ceilings) | B14: LF | C14: 324.17 | D14: =Inputs!$B$5 -> 0.15 | E14: =C14*D14 -> 48.6255 | F14: =C14+E14 -> 372.7955 | G14: C.R. channel 16 ft | H14: =ROUNDUP(F14/Inputs!$B$16,0) -> 24 | I14: familias_out.json 'carrying channel'; A04.01; RFI-ARCP-03
A15: Hanger wire 12 ga (height per room) | B15: LF | C15: 533.62 | D15: =Inputs!$B$5 -> 0.15 | E15: =C15*D15 -> 80.043 | F15: =C15+E15 -> 613.663 | G15: continuous coil (LF) | H15: =ROUNDUP(F15,0) -> 614 | I15: familias_out.json 'hanger wire'; A04.01, S2.20
A16: 5/8" gypsum board regular (walls + ceilings) | B16: SF | C16: 17713.32 | D16: =Inputs!$B$6 -> 0.06 | E16: =C16*D16 -> 1062.7992 | F16: =C16+E16 -> 18776.119 | G16: 4x12 sheet | H16: =ROUNDUP(F16/Inputs!$B$9,0) -> 392 | I16: familias_out.json '5/8" gyp board regular (walls + ceilings)'; A12.01, A04.01
A17: 5/8" moisture resistant gypsum board (behind toilet / lavatory) | B17: SF | C17: 261.74 | D17: =Inputs!$B$6 -> 0.06 | E17: =C17*D17 -> 15.7044 | F17: =C17+E17 -> 277.4444 | G17: 4x12 sheet | H17: =ROUNDUP(F17/Inputs!$B$9,0) -> 6 | I17: familias_out.json '5/8" gyp MOISTURE RESISTANT'; note F/A08.01
A18: Ballistic panel 3/8" UL752 Level 2 fiberglass (customer side to 8'-0") | B18: SF | C18: 82.32 | D18: =Inputs!$B$6 -> 0.06 | E18: =C18*D18 -> 4.9392 | F18: =C18+E18 -> 87.2592 | G18: 4x8 sheet | H18: =ROUNDUP(F18/32,0) -> 3 | I18: familias_out.json 'ballistic panel'; 4/A12.01
A19: 3/8" gypsum board (above the ballistic panel to structure) | B19: SF | C19: 63.92 | D19: =Inputs!$B$6 -> 0.06 | E19: =C19*D19 -> 3.8352 | F19: =C19+E19 -> 67.7552 | G19: 4x8 sheet | H19: =ROUNDUP(F19/32,0) -> 3 | I19: familias_out.json '3/8" gyp board'; 4/A12.01
A20: 5/8" glass mat sheathing (base and canopy bands) | B20: SF | C20: 477.95 | D20: =Inputs!$B$6 -> 0.06 | E20: =C20*D20 -> 28.677 | F20: =C20+E20 -> 506.627 | G20: 4x8 sheet | H20: =ROUNDUP(F20/32,0) -> 16 | I20: familias_out.json '5/8" glass mat sheathing'; 5/A09.26, 9/A09.27, 7/A09.26, 3/A09.26
A21: 5/8" exterior gypsum sheathing (parapet roof side) | B21: SF | C21: 935.76 | D21: =Inputs!$B$6 -> 0.06 | E21: =C21*D21 -> 56.1456 | F21: =C21+E21 -> 991.9056 | G21: 4x8 sheet | H21: =ROUNDUP(F21/32,0) -> 31 | I21: familias_out.json '5/8" EXTERIOR gyp sheathing'; A/A09.21, 4/A09.26; RFI-FAC-8
A22: FRT blocking (labeled FRT / FRTW / plywood) | B22: LF | C22: 1049.55 | D22: =Inputs!$B$6 -> 0.06 | E22: =C22*D22 -> 62.973 | F22: =C22+E22 -> 1112.523 | H22: =ROUNDUP(F22,0) -> 1113 | I22: familias_out.json 'FRT blocking'; 4/A09.26, 8/A12.01, 13/A12.02, 3/A08.21
A23: Metal stud blocking 362CR / stud blocking | B23: LF | C23: 722.33 | D23: =Inputs!$B$5 -> 0.15 | E23: =C23*D23 -> 108.3495 | F23: =C23+E23 -> 830.6795 | G23: stick 20 ft | H23: =ROUNDUP(F23/Inputs!$B$10,0) -> 42 | I23: familias_out.json 'metal stud blocking (362CR / STUD BLOCKING)'; 4/S5.20, note C/A02.01
A24: Metal trim - corner bead, casing bead, shadow molding, edge trim | B24: LF | C24: 1107.75 | D24: =Inputs!$B$5 -> 0.15 | E24: =C24*D24 -> 166.1625 | F24: =C24+E24 -> 1273.9125 | G24: trim stick 10 ft | H24: =ROUNDUP(F24/Inputs!$B$18,0) -> 128 | I24: familias_out.json 'metal trim (corner bead, casing, shadow molding)'; 7/A09.33, 8/A09.33, 9/A12.01, 10/A12.01
A25: Cement board (tile cove base) | B25: SF | C25: 31.8 | D25: =Inputs!$B$6 -> 0.06 | E25: =C25*D25 -> 1.908 | F25: =C25+E25 -> 33.708 | G25: 3x5 sheet | H25: =ROUNDUP(F25/15,0) -> 3 | I25: familias_out.json 'cement board'; A08.01
A26: FRP panel (restrooms to 5'-0", mop sink) | B26: SF | C26: 334 | D26: =Inputs!$B$6 -> 0.06 | E26: =C26*D26 -> 20.04 | F26: =C26+E26 -> 354.04 | G26: 4x10 sheet | H26: =ROUNDUP(F26/40,0) -> 9 | I26: familias_out.json 'FRP'; A/A08.01, 8/A08.01, 5/A08.01
A27: Acoustical sealant (partition top / bottom beads per type detail) | B27: LF | C27: 1173.93 | D27: =Inputs!$B$6 -> 0.06 | E27: =C27*D27 -> 70.4358 | F27: =C27+E27 -> 1244.3658 | G27: tube (25 LF per tube) | H27: =ROUNDUP(F27/Inputs!$B$15,0) -> 50 | I27: familias_out.json 'acoustical sealant'; A12.01 details
A28: Framed openings MEP (recessed fixtures, slot diffusers, access panel) - 3-5/8" stud | B28: LF | C28: 940.27 | D28: =Inputs!$B$5 -> 0.15 | E28: =C28*D28 -> 141.0405 | F28: =C28+E28 -> 1081.3105 | G28: stick 20 ft | H28: =ROUNDUP(F28/Inputs!$B$10,0) -> 55 | I28: framed_openings_out.json 'framed openings MEP'; E02.01, E00.01, M01.01, A04.01
A29: Bottom track 6" 54 mil 600T125-54 (exterior CFMF) | B29: LF | C29: 215.61 | D29: =Inputs!$B$5 -> 0.15 | E29: =C29*D29 -> 32.3415 | F29: =C29+E29 -> 247.9515 | G29: stick 20 ft | H29: =ROUNDUP(F29/Inputs!$B$10,0) -> 13 | I29: track_por_tamano.py (familias_out.json bottom / top family 1393.33 LF) walls 6" 54 mil
A30: Bottom track 6" 600T125-33 (B2, gauge per 7/S5.20) | B30: LF | C30: 44.67 | D30: =Inputs!$B$5 -> 0.15 | E30: =C30*D30 -> 6.7005 | F30: =C30+E30 -> 51.3705 | G30: run 10 ft | H30: =ROUNDUP(F30/Inputs!$B$11,0) -> 6 | I30: track_por_tamano.py (familias_out.json bottom / top family 1393.33 LF) walls 6"
A31: Bottom track 3-5/8" 362T125-33 (A1, B, C1) | B31: LF | C31: 147.06 | D31: =Inputs!$B$5 -> 0.15 | E31: =C31*D31 -> 22.059 | F31: =C31+E31 -> 169.119 | G31: run 10 ft | H31: =ROUNDUP(F31/Inputs!$B$11,0) -> 17 | I31: track_por_tamano.py (familias_out.json bottom / top family 1393.33 LF) walls 3-5/8"
A32: Bottom track 3-5/8" 33 mil 362T125-33 (A1, A5 group) | B32: LF | C32: 90.88 | D32: =Inputs!$B$5 -> 0.15 | E32: =C32*D32 -> 13.632 | F32: =C32+E32 -> 104.512 | G32: run 10 ft | H32: =ROUNDUP(F32/Inputs!$B$11,0) -> 11 | I32: track_por_tamano.py (familias_out.json bottom / top family 1393.33 LF) walls 3-5/8" 33 mil
A33: Bottom track 6" 33 mil 600T125-33 (A5) | B33: LF | C33: 42.23 | D33: =Inputs!$B$5 -> 0.15 | E33: =C33*D33 -> 6.3345 | F33: =C33+E33 -> 48.5645 | G33: run 10 ft | H33: =ROUNDUP(F33/Inputs!$B$11,0) -> 5 | I33: track_por_tamano.py (familias_out.json bottom / top family 1393.33 LF) walls 6" 33 mil
A34: Bottom track 3-5/8" 14 GA 362T 14 ga (A1K, 4/A12.01) | B34: LF | C34: 8.6 | D34: =Inputs!$B$5 -> 0.15 | E34: =C34*D34 -> 1.29 | F34: =C34+E34 -> 9.89 | G34: run 10 ft | H34: =ROUNDUP(F34/Inputs!$B$11,0) -> 1 | I34: track_por_tamano.py (familias_out.json bottom / top family 1393.33 LF) walls 3-5/8" 14 GA
A35: Bottom track 6" 14 GA 600T 14 ga (B2K, 4/A12.01) | B35: LF | C35: 2.21 | D35: =Inputs!$B$5 -> 0.15 | E35: =C35*D35 -> 0.3315 | F35: =C35+E35 -> 2.5415 | G35: run 10 ft | H35: =ROUNDUP(F35/Inputs!$B$11,0) -> 1 | I35: track_por_tamano.py (familias_out.json bottom / top family 1393.33 LF) walls 6" 14 GA
A36: Bottom track 1-5/8" 162T (G / G1 double row) | B36: LF | C36: 291.43 | D36: =Inputs!$B$5 -> 0.15 | E36: =C36*D36 -> 43.7145 | F36: =C36+E36 -> 335.1445 | G36: run 10 ft | H36: =ROUNDUP(F36/Inputs!$B$11,0) -> 34 | I36: track_por_tamano.py (familias_out.json bottom / top family 1393.33 LF) walls 1-5/8"
A37: Bottom track 2-1/2" - grille head | B37: LF | C37: 13.33 | D37: =Inputs!$B$5 -> 0.15 | E37: =C37*D37 -> 1.9995 | F37: =C37+E37 -> 15.3295 | G37: run 10 ft | H37: =ROUNDUP(F37/Inputs!$B$11,0) -> 2 | I37: corridas_out.json element grille_head (4/A08.21)
A38: Bottom track 6" 54 mil - parapet | B38: LF | C38: 269.84 | D38: =Inputs!$B$5 -> 0.15 | E38: =C38*D38 -> 40.476 | F38: =C38+E38 -> 310.316 | G38: run 10 ft | H38: =ROUNDUP(F38/Inputs!$B$11,0) -> 32 | I38: corridas_out.json element parapet (11/S5.10)
A39: Bottom track 3-5/8" - roof step | B39: LF | C39: 154.77 | D39: =Inputs!$B$5 -> 0.15 | E39: =C39*D39 -> 23.2155 | F39: =C39+E39 -> 177.9855 | G39: run 10 ft | H39: =ROUNDUP(F39/Inputs!$B$11,0) -> 18 | I39: corridas_out.json element roof_step (4/A02.02)
A40: Bottom track 6" - storefront cripples | B40: LF | C40: 90.62 | D40: =Inputs!$B$5 -> 0.15 | E40: =C40*D40 -> 13.593 | F40: =C40+E40 -> 104.213 | G40: run 10 ft | H40: =ROUNDUP(F40/Inputs!$B$11,0) -> 11 | I40: corridas_out.json element storefront_cripples (2/A09.26)
...

Sheet Pending Items
A1: RFI | B1: Question / condition | C1: Delta of each alternative
A2: RFI-ACC-additional-head-track | B2: additional head track: openings with their own box (openings_extra) > 4'-0": do they also take the additional head track of 2/S5.20? | C2: 100.55 lf
A3: RFI-ACC-gypsum-board-jamb-return | B3: gypsum board jamb return: jamb return width not dimensioned | C3: -40.29 sf
A4: RFI-ACC-slab-pins | B4: slab pins: pin spacing: 12" (interior anchorage) vs 16" (fastener schedule) vs 24" (type K box) | C4: 16in: -132.7 pcs; 24in: -265.4 pcs
A5: RFI-ACC-extra-framing-atm | B5: extra framing ATM: 6/A08.11 does not dimension the sistered stud count nor the furring rows; furring under the fiber cement panel taken as cladding (excluded) | C5: +2.208 LF per furring row; +6.0 LF per extra sistered stud
A6: RFI-ACC-access-panel | B6: access panel: M00.01 general note 16 and P00.01 require access panels for dampers / valves requiring access above ceilings; none is located over a GB ceiling on the M/P plans (only A04.01 key note 4) | C6: +1 pcs per device found above GB ceilings (vestibules 100/101, waiting 104, restrooms 113/114, CSR soffit)
A7: RFI-ACC-level-5-finish | B7: Level 5 finish: A05.01 key note 9 asks Level 5 for wallcovering WC-20, but no WC-20 tag exists on A05.01 nor a WC-20 row in the A00.40 legend | C7: + L x (H - base) of the WC-20 wall if it exists (unknown)
A8: RFI-ACC-pvc-trim-at-frp | B8: PVC trim at FRP: restrooms 113/114 taken as rectangles; the chase-end hand dryer niche (TA-13) may add 2 inside + 2 outside corners per room; mop sink width from the plumbing model (TSH-24), not printed on A08.01 | C8: +2 x 5.0 = +10 LF per room if the niche is lined with FRP
A9: RFI-ACC-2-1-2-cfmf-coiling-grill | B9: 2-1/2" CFMF coiling grille head: A00.30 door 103 HEIGHT 13'-6 1/2" vs 4/A08.21: framed head taken = 6" + 1'-6" between the two box beams; the 2'-4 1/2" link above is the vendor spool zone | C9: if the 2'-4 1/2" zone were framed: +11 studs x 2.375 = +26.1 LF
A10: RFI-01 | B10: Elevation titles A09.01 'SOUTH' / A09.02 'NORTH' are transposed against the A02.01 north arrow (R71.1); facade letters follow the arrow. | C10: n/a: no quantity delta
A11: RFI-02 | B11: Storefront heads SF-N1 / SF-N2 / SF-W1 carry HSS9x5x5/8 lintels (S2.20, 2/A09.26 STEEL HEADER FRAMING) -> 0 metal stud header (E16). Is a CFS box required under the HSS? | C11: +197.24 LF 6" box header (55.58 + 110.33 + 31.33)
A12: RFI-03 | B12: Interior HM door R.O. = 3'-4" sits exactly on the SINGLE / DOUBLE TRACK boundary of 7/S5.20. | C12: +60.67 LF 18 ga track if DOUBLE
... A56: RFI-40 | B56: Parapet grid G and grid 4 return: reading A 16.686 / 4.092 ft vs reading B 16.20 / 3.927 ft (A kept, more material); the return may stop at grid F. | C56: -0.65 LF parapet run (-2.9 LF more if the return stops at F)

Sheet Review Items
A1: # | B1: Item | C1: Sheet + detail | D1: Image
A2: 1 | B2: Tag inventory (Stage 1): 49 partition tags counted on A02.01 (A1 10, A1K 3, A5 4, B 6, B2 6, C1 8, F 1, G 9, G1 2) + B2K (out of schedule) + PA0034 'B' accepted; please confirm the list (inventario.md, one circled image per tag). | C2: A02.01 | D2: 1_inventario/recortes/OVERVIEW_A02.01_p24.png
A3: 2 | B3: Double reading: 49 walls matched, 15 differed, 13 only in A, 11 only in B; 35 decided with image, 4 parapet items left to the estimator (see resolucion.md). | C3: A02.01 | D3: 3_revision/img
A4: 3 | B4: Parapet grid G and grid 4 return lengths: estimator to choose A or B (RFI-40). | C4: 11/S5.10 | D4: 3_revision/img/R32_parapet_BEXT-16_A02.01_p24.png
A5: 4 | B5: Drinking-fountain alcove walls (RES-01, 7.487 LF A1 untagged) were missed by both readings and added at Stage 3. | C5: 3/A12.01 | D5: 3_revision/img
A6: 5 | B6: Exterior corners closed on the reading A band thickness (vertical walls own the corners, R70.2): exterior LF 215.61 vs reading B 189.29 + piers. | C6: A/A09.21 | D6: 4_canon/conciliacion_log.md
A7: 6 | B7: Face segments short at T-joints were extended behind the abutting partitions (board continuous to deck); 23 walls (conciliacion_log.md). | C7: A/A09.21 | D7: 4_canon/conciliacion_log.md
A8: 7 | B8: C1 monitor furring end returns (2 x 0.667 ft x 15.375 ft) are carried as RES-04 / RES-05 records; board_caras takes faces only on sides A/B (tool gap proposal in PARA REVISAR). | C8: 6/A12.01 | D8: 3_revision/img
A9: 8 | B9: Walls partly under a beam (AI2-11, AI2-12, AI3-06, AI3-14) keep the deck height; split at the beam end if wanted. | C9: S2.20 | D9: 2_lectura/trabajo_A/ANODOS/img
A10: 9 | B10: Grille head bottom soffit board (11.1 SF, 4/A08.21) and the 5" bottom return of 7/A09.33 transitions are not in the faces model (tool gap). | C10: 4/A08.21 | D10: 2_lectura/trabajo_A/AACC1/img
A11: 11 | B11: Adversarial back-check: 11 findings accepted and applied (ADV1-F1/F2, ADV2-F1/F2, ADV3-G1/G2/G4/G6), 6 left as RFIs (RFI-41 to RFI-47), 1 rejected as against a rule (ADV2-F3 west glass mat, canon v63 rule; RFI-16 stays). See Back-check folder. | C11: A02.02 | D11: backcheck/img
A12: 10 | B12: MEP registration: mep.py registro fails on P01.01 / P01.02 (offset MediaBox) and E02.01 (thin background); the sweep used in-run scripts with the same rules (tool gap proposal). | C12: M01.01 | D12: 2_lectura/trabajo_A/AACC2/img

Sheet Scope Checklist
A1: Scope ID | B1: Scope | C1: Status | D1: Note (quantity, NOT APPLICABLE + sheet, or RFI)
A2: ALC-01 | B2: Interior partition framing (studs + tracks) | C2: QUANTIFIED | D2: Material Summary studs / tracks; A12.01, 7/S5.20
A3: ALC-02 | B3: Exterior wall framing (CFMF) | C3: QUANTIFIED | D3: EXT-6CFMF; A/A09.21, S1.11, 10/S5.10
A4: ALC-03 | B4: Parapet framing | C4: QUANTIFIED | D4: 6" parapet stud; 11/S5.10
A5: ALC-04 | B5: Top / deflection and bottom track | C5: QUANTIFIED | D5: track rows by stud size (R71.8)
A6: ALC-05 | B6: Headers, sills and jambs at openings | C6: QUANTIFIED | D6: header / box beam, sill track; 7/S5.20, 2/S5.20
A7: ALC-06 | B7: Bracing / bridging | C7: QUANTIFIED | D7: 1-1/2" C.R. channel; F/1/S5.20
A8: ALC-07 | B8: Gypsum board on walls (layers per type) | C8: QUANTIFIED | D8: 5/8" board; A12.01
A9: ALC-08 | B9: Moisture / abuse / special board at wet zones | C9: QUANTIFIED | D9: 5/8" MR behind toilet / lavatory; note F/A08.01
A10: ALC-09 | B10: Exterior gypsum / glass mat sheathing | C10: QUANTIFIED | D10: glass mat + exterior gyp sheathing; 5/A09.26, A/A09.21
A11: ALC-10 | B11: FRT plywood sheathing / substrate | C11: QUANTIFIED | D11: FRT plywood by material; 2/A09.26, 10/A09.27
A12: ALC-11 | B12: Gypsum board ceilings | C12: QUANTIFIED | D12: 5/8" board on GWB ceilings; A04.01
... A26: ALC-X25 | B26: batt insulation | C26: NOT APPLICABLE | D26: EXCLUDED (estimator criterion: no insulation)
