Workbook

Sheet Inputs
A1: Bank of America CO1-111 Broomfield, CO | METAL FRAMING & DRYWALL TAKEOFF
A2: Bid set: 2025.08.26_CO1-111_Broomfield_PERMIT SET_BID SET.pdf · 2026-10-21 · Edit ONLY the yellow cells.
A4: PARAMETER | B4: VALUE | C4: NOTE / SOURCE
A5: Waste - ALL METAL, any type | B5: 0.15 | C5: Estimator standing rule: 15% on everything that is metal.
A6: Waste - EVERYTHING THAT IS NOT METAL | B6: 0.06 | C6: Estimator standing rule: same figure as board.
A7: Board sheet width (ft) | B7: 4 | C7: Sheet size is a parameter; buy the size that wastes least.
A8: Board sheet length (ft) | B8: 12 | C8: Change it and every sheet count re-rounds.
A9: SF per board sheet | B9: =B7*B8 -> 48 | C9: Width x length.
A10: Stud stock length (ft) | B10: 20 | C10: Stud, header, framed opening and stud blocking: sticks.
A11: Track stock length (ft) | B11: 10 | C11: Track, sill track and purlin: runs.
A12: Floor plan scale (pt/ft) | B12: n/a | C12: Project value (canon constants).
A13: B.O. Deck (ft) | B13: n/a | C13: Project value (canon constants).
A14: T.O. Parapet (ft) | B14: n/a | C14: Project value (canon constants).
A15: Sealant coverage (LF per tube) | B15: 25 | C15: Sealant yield per tube - set your supplier's figure.
A16: C.R. channel stock length (ft) | B16: 16 | C16: 1-1/2" cold-rolled channel (bracing, carrying channel).
A17: Hat / furring channel stock (ft) | B17: 12 | C17: 7/8" hat furring channel.
A18: Trim stick length (ft) | B18: 10 | C18: Corner bead, casing bead, shadow molding, PVC trim.
A19: Hanger wire purchase | B19: continuous coil (LF) | C19: Bought by LF from a continuous coil; the hanger count goes on its own PCS row.
A20: Drywall screws per SF of board | B20: 1.2 | C20: YIELD (GA-216 field / perimeter spacing).
A21: Framing screws per stud piece | B21: 4 | C21: YIELD: 2 per stud-to-track connection, each end.
A22: Power-driven pin spacing (ft) | B22: 1 | C22: YIELD: bottom track on slab, interior walls.
A23: Joint compound (lb per SF) | B23: 0.072 | C23: YIELD: 72 lb per 1,000 SF, level 4 (estimator criterion).
A24: Joint tape (LF per SF) | B24: 0.37 | C24: YIELD: 370 LF per 1,000 SF.
A25: Expansion anchor spacing (ft) | B25: 0.6667 | C25: YIELD: exterior bottom track on slab.

Sheet Partition Takeoff
A1: ORGANIZED PARTITION TAKEOFF - Bank of America CO1-111 Broomfield, CO
A2: Grouped by partition type. Every row cites its DETAIL/SHEET and its status.
A4: Partition / Scope | B4: Wall # | C4: Length (LF) | D4: Height (FT) | E4: Layers | F4: Stud Size | G4: Stud O.C. (in) | H4: Board (SF) | I4: Location | J4: Source (DETAIL/SHEET) | K4: Status
A5: TYPE EXT-6CFMF
A6: EXT-6CFMF #A-EXT-UP-N-F47+A-EXT-N-F+A-EXT-UP-N-F78 - North facade grid F from pier G/4 to the NE corner (over storefront SF-F-4/8 and Office 105 wall A-EXT-N-F): infill row above the canopy beam up to the roof beam + North exterior wall, grid F between 7 and 8 (Office 105), from storefront SF-F-4/8 east jamb to the NE corner | B6: A-EXT-UP-N-F47+A-EXT-N-F+A-EXT-UP-N-F78 | C6: 53.458 | D6: 4.216 | E6: 0.25 | F6: 6" | G6: 16 | H6: 209.2 | I6: North facade grid F from pier G/4 to the NE corner (over storefront SF-F-4/8 and Office 105 wall A-EXT-N-F): infill row above the canopy beam up to the roof beam + North exterior wall, grid F between 7 and 8 (Office 105), from storefront SF-F-4/8 east jamb to the NE corner | J6: C/A09.21 | K6: [DERIVED]
A7: EXT-6CFMF #A-EXT-E-8+A-EXT-UP-E-8 - East exterior wall, grid 8 from the NE corner (inside face of A-EXT-N-F) to the SE corner (inside face of A-EXT-S-A); Offices 105-108, Cash Window 116, Future FCAM, Work Room 119 + East facade grid 8 from the NE corner (inside face of A-EXT-UP-N-F) to grid B.2 (end of the canopy): infill row above the canopy beam up to the W12x19 (HI) roof beam; Offices 105-108, Cash Window 116 | B7: A-EXT-E-8+A-EXT-UP-E-8 | C7: 122.17 | D7: 7.987 | E7: 0.62 | F7: 6" | G7: 16 | H7: 1030.2 | I7: East exterior wall, grid 8 from the NE corner (inside face of A-EXT-N-F) to the SE corner (inside face of A-EXT-S-A); Offices 105-108, Cash Window 116, Future FCAM, Work Room 119 + East facade grid 8 from the NE corner (inside face of A-EXT-UP-N-F) to grid B.2 (end of the canopy): infill row above the canopy beam up to the W12x19 (HI) roof beam; Offices 105-108, Cash Window 116 | J7: D/A09.22 | K7: [DERIVED]
A8: EXT-6CFMF #A-EXT-S-A - South exterior wall, grid A from the SW corner (exterior face of A-EXT-W-3) to the SE corner (exterior face of A-EXT-E-8); Wellness 115, Corridor 111 (door 123), NER 121, Break Room 118, Work Room 119 | B8: A-EXT-S-A | C8: 53.667 | D8: 11.172 | E8: 1 | F8: 6" | G8: 16 | H8: 645.3 | I8: South exterior wall, grid A from the SW corner (exterior face of A-EXT-W-3) to the SE corner (exterior face of A-EXT-E-8); Wellness 115, Corridor 111 (door 123), NER 121, Break Room 118, Work Room 119 | J8: F/A09.22 | K8: [DERIVED]
A9: EXT-6CFMF #A-EXT-UP-W-3+A-EXT-W-3 - West facade grid 3 from the D-line return to grid B (Offices 109-110, Restroom 114 north part): infill row above the W16x26 (CANOPY) up to the W12x19 (HI) + West exterior wall (lower), grid 3 from the D-line return (exterior face of A-EXT-S-D23) to the SW corner (inside face of A-EXT-S-A); Offices 109-110, Restrooms 114 / 113, Janitor 112, Wellness 115 | B9: A-EXT-UP-W-3+A-EXT-W-3 | C9: 69.058 | D9: 8.462 | E9: 0.68 | F9: 6" | G9: 16 | H9: 625.76 | I9: West facade grid 3 from the D-line return to grid B (Offices 109-110, Restroom 114 north part): infill row above the W16x26 (CANOPY) up to the W12x19 (HI) + West exterior wall (lower), grid 3 from the D-line return (exterior face of A-EXT-S-D23) to the SW corner (inside face of A-EXT-S-A); Offices 109-110, Restrooms 114 / 113, Janitor 112, Wellness 115 | J9: H/A09.23 | K9: [DERIVED]
A10: EXT-6CFMF #A-EXT-S-D23+A-EXT-UP-S-D23 - Exterior return wall facing south under the drive-up canopy, grid D between 2 and 3 (ATM Room 102 behind) + Return wall facing south on grid D between 2 and 3 (ATM Room 102 behind): infill row above the W12x19 (CANOPY) up to the W12x19 (HI) | B10: A-EXT-S-D23+A-EXT-UP-S-D23 | C10: 7.813 | D10: 6.671 | E10: 0.5 | F10: 6" | G10: 16 | H10: 60.07 | I10: Exterior return wall facing south under the drive-up canopy, grid D between 2 and 3 (ATM Room 102 behind) + Return wall facing south on grid D between 2 and 3 (ATM Room 102 behind): infill row above the W12x19 (CANOPY) up to the W12x19 (HI) | J10: J/A09.23 | K10: [DERIVED]
A11: EXT-6CFMF #A-EXT-UP-W-2SF+A-EXT-UP-W-2S+A-EXT-W-2+A-EXT-W-2M - West facade grid 2 from the NW corner (inside face of A-EXT-UP-N-G) to the D-line return: infill row above the canopy beams (W16x26 G-E, W12x19 E-D) up to the W12x19 (HI); Vestibule 100, 24 HR Vestibule 101, ATM Room 102 + West exterior wall (upper), grid 2 from the vestibule storefront SF-2-F/E.4 south jamb to the D-line return; 24 HR Vestibule 101 and ATM Room 102 (drive-up ATM) | B11: A-EXT-UP-W-2SF+A-EXT-UP-W-2S+A-EXT-W-2+A-EXT-W-2M | C11: 66.817 | D11: 4.421 | E11: 0.33 | F11: 6" | G11: 16 | H11: 330.84 | I11: West facade grid 2 from the NW corner (inside face of A-EXT-UP-N-G) to the D-line return: infill row above the canopy beams (W16x26 G-E, W12x19 E-D) up to the W12x19 (HI); Vestibule 100, 24 HR Vestibule 101, ATM Room 102 + West exterior wall (upper), grid 2 from the vestibule storefront SF-2-F/E.4 south jamb to the D-line return; 24 HR Vestibule 101 and ATM Room 102 (drive-up ATM) | J11: J/A09.23 | K11: [DERIVED]
A12: EXT-6CFMF #A-EXT-UP-N-G - North facade grid G between piers G/2 and G/4 (Vestibule 100 entrance): infill row above the W12x19 (CANOPY) up to the W12x19 (HI) roof beam, over the entrance storefront SF-F-2/4 and both piers | B12: A-EXT-UP-N-G | C12: 17.688 | D12: 2.41 | E12: 0 | F12: 6" | G12: 16 | H12: 0 | I12: North facade grid G between piers G/2 and G/4 (Vestibule 100 entrance): infill row above the W12x19 (CANOPY) up to the W12x19 (HI) roof beam, over the entrance storefront SF-F-2/4 and both piers | J12: A/A09.21 | K12: [DERIVED]
A13: TYPE CANOPY-COL
A14: CANOPY-COL #A-EXT-CCOL-1 - Drive-up canopy column 1 of 4 on grid 1 (from north), A02.01 bubble 5/A09.25 | B14: A-EXT-CCOL-1 | C14: 5.667 | D14: 10.5 | E14: 0 | F14: 3-5/8" | G14: 16 | H14: 0 | I14: Drive-up canopy column 1 of 4 on grid 1 (from north), A02.01 bubble 5/A09.25 | J14: 5/A09.25 | K14: [DERIVED]
A15: CANOPY-COL #A-EXT-CCOL-2 - Drive-up canopy column 2 of 4 on grid 1 (from north), A02.01 bubble 5/A09.25 | B15: A-EXT-CCOL-2 | C15: 5.667 | D15: 10.5 | E15: 0 | F15: 3-5/8" | G15: 16 | H15: 0 | I15: Drive-up canopy column 2 of 4 on grid 1 (from north), A02.01 bubble 5/A09.25 | J15: 5/A09.25 | K15: [DERIVED]
A16: CANOPY-COL #A-EXT-CCOL-3 - Drive-up canopy column 3 of 4 on grid 1 (from north), A02.01 bubble 5/A09.25 | B16: A-EXT-CCOL-3 | C16: 5.667 | D16: 10.5 | E16: 0 | F16: 3-5/8" | G16: 16 | H16: 0 | I16: Drive-up canopy column 3 of 4 on grid 1 (from north), A02.01 bubble 5/A09.25 | J16: 5/A09.25 | K16: [DERIVED]
A17: CANOPY-COL #A-EXT-CCOL-4 - Drive-up canopy column 4 of 4 on grid 1 (from north), A02.01 bubble 5/A09.25 | B17: A-EXT-CCOL-4 | C17: 5.667 | D17: 10.5 | E17: 0 | F17: 3-5/8" | G17: 16 | H17: 0 | I17: Drive-up canopy column 4 of 4 on grid 1 (from north), A02.01 bubble 5/A09.25 | J17: 5/A09.25 | K17: [DERIVED]
A18: TYPE G
A19: G #A-N-G-01 - Office 105 front, north stub (office front line at grid 7, east side of Central Zone 103) | B19: A-N-G-01 | C19: 2.42 | D19: 14.383 | E19: 4.42 | F19: 1-5/8" | G19: 16 | H19: 147.43 | I19: Office 105 front, north stub (office front line at grid 7, east side of Central Zone 103) | J19: 5/A12.01 | K19: [DERIVED]
A20: G #A-N-G-02 - Office front stub between Office 105 and Office 106 | B20: A-N-G-02 | C20: 3.467 | D20: 14.383 | E20: 4.59 | F20: 1-5/8" | G20: 16 | H20: 215.88 | I20: Office front stub between Office 105 and Office 106 | J20: 5/A12.01 | K20: [DERIVED]
A21: G #A-N-G-03 - Office front stub between Office 106 and Office 107 | B21: A-N-G-03 | C21: 3.253 | D21: 14.225 | E21: 4.63 | F21: 1-5/8" | G21: 16 | H21: 201.52 | I21: Office front stub between Office 106 and Office 107 | J21: 5/A12.01 | K21: [DERIVED]
A22: G #A-N-G-05 - Office front stub between Office 107 and Office 108 | B22: A-N-G-05 | C22: 3.253 | D22: 14.225 | E22: 4.63 | F22: 1-5/8" | G22: 16 | H22: 201.52 | I22: Office front stub between Office 107 and Office 108 | J22: 5/A12.01 | K22: [DERIVED]
A23: G #A-N-G-04 - Demising wall Office 106 / Office 107 | B23: A-N-G-04 | C23: 11.771 | D23: 15.375 | E23: 4 | F23: 1-5/8" | G23: 16 | H23: 723.9 | I23: Demising wall Office 106 / Office 107 | J23: 5/A12.01 | K23: [CONFIRMED]
A24: G #A-N-G-06 - Demising wall Office 107 / Office 108 | B24: A-N-G-06 | C24: 11.771 | D24: 15.375 | E24: 4 | F24: 1-5/8" | G24: 16 | H24: 723.9 | I24: Demising wall Office 107 / Office 108 | J24: 5/A12.01 | K24: [CONFIRMED]
A25: G #A-N-G-08 - Demising wall Office 109 / Office 110 | B25: A-N-G-08 | C25: 11.625 | D25: 15.185 | E25: 4 | F25: 1-5/8" | G25: 16 | H25: 706.1 | I25: Demising wall Office 109 / Office 110 | J25: 5/A12.01 | K25: [CONFIRMED]
A26: G #A-N-G-07 - South wall of Office 108 (Office 108 / Cash Window 116 teller area) | B26: A-N-G-07 | C26: 10.073 | D26: 15.375 | E26: 4 | F26: 1-5/8" | G26: 16 | H26: 619.49 | I26: South wall of Office 108 (Office 108 / Cash Window 116 teller area) | J26: 5/A12.01 | K26: [DERIVED]
A27: G #A-N-G-09 - ATM Room 102 / Office 109 (south wall of ATM Room) | B27: A-N-G-09 | C27: 12.333 | D27: 15.375 | E27: 4 | F27: 1-5/8" | G27: 16 | H27: 758.48 | I27: ATM Room 102 / Office 109 (south wall of ATM Room) | J27: 5/A12.01 | K27: [DERIVED]
A28: G #A-S-G-01 - Women's Restroom 114 north wall / Office 6 CB 110, grid B | B28: A-S-G-01 | C28: 11.625 | D28: 15.375 | E28: 4 | F28: 1-5/8" | G28: 16 | H28: 714.94 | I28: Women's Restroom 114 north wall / Office 6 CB 110, grid B | J28: 5/A12.01 | K28: [DERIVED]
A29: TYPE G1
A30: G1 #A-N-G1-01 - Demising wall Office 105 / Office 106 | B30: A-N-G1-01 | C30: 11.771 | D30: 15.188 | E30: 4 | F30: 1-5/8" | G30: 16 | H30: 715.08 | I30: Demising wall Office 105 / Office 106 | J30: 5/A12.01 | K30: [CONFIRMED]
A31: G1 #A-N-G1-02 - Office front stub between Office 109 and Office 110 | B31: A-N-G1-02 | C31: 3.507 | D31: 15.375 | E31: 4.81 | F31: 1-5/8" | G31: 16 | H31: 238.3 | I31: Office front stub between Office 109 and Office 110 | J31: 5/A12.01 | K31: [DERIVED]
A32: G1 #A-S-G1-01 - Office 6 east office-front end stub south of DFC-1A (vendor glass), north of door 111 | B32: A-S-G1-01 | C32: 3.18 | D32: 15.375 | E32: 4 | F32: 1-5/8" | G32: 16 | H32: 195.58 | I32: Office 6 east office-front end stub south of DFC-1A (vendor glass), north of door 111 | J32: 5/A12.01 | K32: [DERIVED]
A33: TYPE B2K
A34: B2K #A-N-B2K-01 - Kevlar wall at SW corner of Office 108, west end of teller line (hatched) | B34: A-N-B2K-01 | C34: 1.773 | D34: 15.375 | E34: 2.36 | F34: 6" | G34: 24 | H34: 64.36 | I34: Kevlar wall at SW corner of Office 108, west end of teller line (hatched) | J34: 4/A12.01 | K34: [DERIVED]
A35: TYPE A1K
A36: A1K #A-N-A1K-01 - Kevlar wall north side of teller station (Cash Window 116), below Office 108 south wall (hatched) | B36: A-N-A1K-01 | C36: 3.417 | D36: 15.375 | E36: 2 | F36: 3-5/8" | G36: 24 | H36: 105.06 | I36: Kevlar wall north side of teller station (Cash Window 116), below Office 108 south wall (hatched) | J36: 4/A12.01 | K36: [CONFIRMED]
A37: A1K #A-S-A1K-01 - Cash Window 116 teller pod - lower ballistic run (customer queue / Break Room 118), west of teller counter | B37: A-S-A1K-01 | C37: 1.767 | D37: 12.922 | E37: 2 | F37: 3-5/8" | G37: 24 | H37: 45.66 | I37: Cash Window 116 teller pod - lower ballistic run (customer queue / Break Room 118), west of teller counter | J37: 4/A12.01 | K37: [DERIVED]
A38: A1K #A-S-A1K-02 - Cash Window 116 teller pod - south ballistic run behind teller workstations (C1 FCAM furring on south face) | B38: A-S-A1K-02 | C38: 3.413 | D38: 12.935 | E38: 2 | F38: 3-5/8" | G38: 24 | H38: 88.3 | I38: Cash Window 116 teller pod - south ballistic run behind teller workstations (C1 FCAM furring on south face) | J38: 4/A12.01 | K38: [DERIVED]
A39: TYPE B2
A40: B2 #A-N-B2-01 - East wall of ATM Room 102 at grid 4 / E (HSS column wrap + door 102) | B40: A-N-B2-01 | C40: 5.66 | D40: 15.375 | E40: 2 | F40: 6" | G40: 16 | H40: 111.44 | I40: East wall of ATM Room 102 at grid 4 / E (HSS column wrap + door 102) | J40: 1/A12.01 | K40: [DERIVED]
A41: B2 #A-S-B2-01a+A-S-B2-01b - Women's Restroom 114 east wall, north piece (deck break at grid B, split of A-S-B2-01b) + Women's Restroom 114 east wall at Corridor 111, door 114 | B41: A-S-B2-01a+A-S-B2-01b | C41: 5.542 | D41: 13.286 | E41: 2 | F41: 6" | G41: 16 | H41: 100.6 | I41: Women's Restroom 114 east wall, north piece (deck break at grid B, split of A-S-B2-01b) + Women's Restroom 114 east wall at Corridor 111, door 114 | J41: 1/A12.01 | K41: [DERIVED]
...

Sheet Material Summary
A1: MATERIAL SUMMARY - NET / WASTE / PURCHASE
A2: Waste lives HERE, in its own column, applied ONCE: Pieces = ROUNDUP(Net x (1 + waste) / stock). Every stock length, coverage and yield is an Inputs cell.
A3: Material | B3: Unit | C3: Net | D3: Waste % | E3: Waste | F3: Purchase | G3: Selling unit | H3: Pieces to buy | I3: Where it comes from | J3: Yield check (live formula)
A4: 6" metal stud (LF of material) | B4: LF | C4: 4363.89 | D4: =Inputs!$B$5 -> 0.15 | E4: =C4*D4 -> 654.5835 | F4: =C4+E4 -> 5018.4735 | G4: stick 20 ft | H4: =ROUNDUP(F4/Inputs!$B$10,0) -> 251 | I4: familias_out.json '6" stud (all gauges)'
A5: 3-5/8" metal stud (LF of material) | B5: LF | C5: 6625.02 | D5: =Inputs!$B$5 -> 0.15 | E5: =C5*D5 -> 993.753 | F5: =C5+E5 -> 7618.773 | G5: stick 20 ft | H5: =ROUNDUP(F5/Inputs!$B$10,0) -> 381 | I5: familias_out.json '3-5/8" stud (all gauges)'
A6: 1-5/8" metal stud (LF of material) | B6: LF | C6: 3785.8 | D6: =Inputs!$B$5 -> 0.15 | E6: =C6*D6 -> 567.87 | F6: =C6+E6 -> 4353.67 | G6: stick 20 ft | H6: =ROUNDUP(F6/Inputs!$B$10,0) -> 218 | I6: familias_out.json '1-5/8" stud'
A7: 6" parapet infill stud (LF of material) | B7: LF | C7: 1001.47 | D7: =Inputs!$B$5 -> 0.15 | E7: =C7*D7 -> 150.2205 | F7: =C7+E7 -> 1151.6905 | G7: stick 20 ft | H7: =ROUNDUP(F7/Inputs!$B$10,0) -> 58 | I7: familias_out.json '6" parapet stud'
A8: Track, ceilings / soffits / canopy | B8: LF | C8: 1231.38 | D8: =Inputs!$B$5 -> 0.15 | E8: =C8*D8 -> 184.707 | F8: =C8+E8 -> 1416.087 | G8: run 10 ft | H8: =ROUNDUP(F8/Inputs!$B$11,0) -> 142 | I8: familias_out.json 'ceiling / soffit track'
A9: Bracing 1-1/2" C.R. channel | B9: LF | C9: 2332.26 | D9: =Inputs!$B$5 -> 0.15 | E9: =C9*D9 -> 349.839 | F9: =C9+E9 -> 2682.099 | G9: C.R. channel 16 ft | H9: =ROUNDUP(F9/Inputs!$B$16,0) -> 168 | I9: familias_out.json 'bracing C.R. channel'
A10: Purlin, top track to deck | B10: LF | C10: 260.44 | D10: =Inputs!$B$5 -> 0.15 | E10: =C10*D10 -> 39.066 | F10: =C10+E10 -> 299.506 | G10: run 10 ft | H10: =ROUNDUP(F10/Inputs!$B$11,0) -> 30 | I10: familias_out.json 'purlin (track to deck)'
A11: Header / metal stud box beam | B11: LF | C11: 796.59 | D11: =Inputs!$B$5 -> 0.15 | E11: =C11*D11 -> 119.4885 | F11: =C11+E11 -> 916.0785 | G11: stick 20 ft | H11: =ROUNDUP(F11/Inputs!$B$10,0) -> 46 | I11: familias_out.json 'header / box beam'
A12: Sill track | B12: LF | C12: 119.09 | D12: =Inputs!$B$5 -> 0.15 | E12: =C12*D12 -> 17.8635 | F12: =C12+E12 -> 136.9535 | G12: run 10 ft | H12: =ROUNDUP(F12/Inputs!$B$11,0) -> 14 | I12: familias_out.json 'sill track'
A13: Furring channel (ceilings) | B13: LF | C13: 786.08 | D13: =Inputs!$B$5 -> 0.15 | E13: =C13*D13 -> 117.912 | F13: =C13+E13 -> 903.992 | G13: hat channel 12 ft | H13: =ROUNDUP(F13/Inputs!$B$17,0) -> 76 | I13: familias_out.json 'furring channel'
A14: Carrying channel (ceilings) | B14: LF | C14: 315.94 | D14: =Inputs!$B$5 -> 0.15 | E14: =C14*D14 -> 47.391 | F14: =C14+E14 -> 363.331 | G14: C.R. channel 16 ft | H14: =ROUNDUP(F14/Inputs!$B$16,0) -> 23 | I14: familias_out.json 'carrying channel'
A15: Hanger wire | B15: LF | C15: 533.63 | D15: =Inputs!$B$5 -> 0.15 | E15: =C15*D15 -> 80.0445 | F15: =C15+E15 -> 613.6745 | G15: continuous coil (LF) | H15: =ROUNDUP(F15,0) -> 614 | I15: familias_out.json 'hanger wire'
A16: 5/8" gypsum board, regular | B16: SF | C16: 17406.06 | D16: =Inputs!$B$6 -> 0.06 | E16: =C16*D16 -> 1044.3636 | F16: =C16+E16 -> 18450.424 | G16: 4x12 sheet | H16: =ROUNDUP(F16/Inputs!$B$9,0) -> 385 | I16: familias_out.json '5/8" gyp board regular (walls + ceilings)'
A17: 5/8" gypsum board, MOISTURE RESISTANT | B17: SF | C17: 258.84 | D17: =Inputs!$B$6 -> 0.06 | E17: =C17*D17 -> 15.5304 | F17: =C17+E17 -> 274.3704 | G17: 4x12 sheet | H17: =ROUNDUP(F17/Inputs!$B$9,0) -> 6 | I17: familias_out.json '5/8" gyp MOISTURE RESISTANT'
A18: Ballistic panel UL752 | B18: SF | C18: 85.74 | D18: =Inputs!$B$6 -> 0.06 | E18: =C18*D18 -> 5.1444 | F18: =C18+E18 -> 90.8844 | G18: 4x8 sheet | H18: =ROUNDUP(F18/32,0) -> 3 | I18: familias_out.json 'ballistic panel'
A19: 3/8" gypsum board | B19: SF | C19: 65.88 | D19: =Inputs!$B$6 -> 0.06 | E19: =C19*D19 -> 3.9528 | F19: =C19+E19 -> 69.8328 | G19: 4x8 sheet | H19: =ROUNDUP(F19/32,0) -> 3 | I19: familias_out.json '3/8" gyp board'
A20: 5/8" glass mat sheathing (exterior face of the stud) | B20: SF | C20: 358.87 | D20: =Inputs!$B$6 -> 0.06 | E20: =C20*D20 -> 21.5322 | F20: =C20+E20 -> 380.4022 | G20: 4x8 sheet | H20: =ROUNDUP(F20/32,0) -> 12 | I20: familias_out.json '5/8" glass mat sheathing'
A21: 5/8" EXTERIOR gypsum sheathing | B21: SF | C21: 948.41 | D21: =Inputs!$B$6 -> 0.06 | E21: =C21*D21 -> 56.9046 | F21: =C21+E21 -> 1005.3146 | G21: 4x8 sheet | H21: =ROUNDUP(F21/32,0) -> 32 | I21: familias_out.json '5/8" EXTERIOR gyp sheathing'
A22: Blocking FRT / 2X FRT wood | B22: LF | C22: 857.71 | D22: =Inputs!$B$6 -> 0.06 | E22: =C22*D22 -> 51.4626 | F22: =C22+E22 -> 909.1726 | G22: piece 16 ft | H22: =ROUNDUP(F22/16,0) -> 57 | I22: familias_out.json 'FRT blocking'
A23: METAL trim - corner bead, casing bead, shadow molding, gypsum edge trim | B23: LF | C23: 1030.72 | D23: =Inputs!$B$5 -> 0.15 | E23: =C23*D23 -> 154.608 | F23: =C23+E23 -> 1185.328 | G23: trim stick 10 ft | H23: =ROUNDUP(F23/Inputs!$B$18,0) -> 119 | I23: familias_out.json 'metal trim (corner bead, casing, shadow molding)'
A24: Cement board (substrate under the FRP cove base band) | B24: SF | C24: 33.38 | D24: =Inputs!$B$6 -> 0.06 | E24: =C24*D24 -> 2.0028 | F24: =C24+E24 -> 35.3828 | G24: 3x5 sheet | H24: =ROUNDUP(F24/15,0) -> 3 | I24: familias_out.json 'cement board'
A25: FRP panels | B25: SF | C25: 349.75 | D25: =Inputs!$B$6 -> 0.06 | E25: =C25*D25 -> 20.985 | F25: =C25+E25 -> 370.735 | G25: 4x8 sheet | H25: =ROUNDUP(F25/32,0) -> 12 | I25: familias_out.json 'FRP'
A26: Framed openings - MEP, light slots and diffusers | B26: LF | C26: 241.38 | D26: =Inputs!$B$5 -> 0.15 | E26: =C26*D26 -> 36.207 | F26: =C26+E26 -> 277.587 | G26: stick 20 ft | H26: =ROUNDUP(F26/Inputs!$B$10,0) -> 14 | I26: framed_openings_out.json 'framed openings MEP'
A27: Bottom track 6" | B27: LF | C27: 476.62 | D27: =Inputs!$B$5 -> 0.15 | E27: =C27*D27 -> 71.493 | F27: =C27+E27 -> 548.113 | G27: run 10 ft | H27: =ROUNDUP(F27/Inputs!$B$11,0) -> 55 | I27: familias_out.json track_by_element 'bottom track (all)' (R73.3)
A28: Bottom track - other framing (not a partition type, see source) | B28: LF | C28: 64.92 | D28: =Inputs!$B$5 -> 0.15 | E28: =C28*D28 -> 9.738 | F28: =C28+E28 -> 74.658 | G28: run 10 ft | H28: =ROUNDUP(F28/Inputs!$B$11,0) -> 8 | I28: familias_out.json track_by_element 'bottom track (all)' (R73.3)
A29: Bottom track 3-5/8" | B29: LF | C29: 248.52 | D29: =Inputs!$B$5 -> 0.15 | E29: =C29*D29 -> 37.278 | F29: =C29+E29 -> 285.798 | G29: run 10 ft | H29: =ROUNDUP(F29/Inputs!$B$11,0) -> 29 | I29: familias_out.json track_by_element 'bottom track (all)' (R73.3)
A30: Bottom track 1-5/8" | B30: LF | C30: 290.1 | D30: =Inputs!$B$5 -> 0.15 | E30: =C30*D30 -> 43.515 | F30: =C30+E30 -> 333.615 | G30: run 10 ft | H30: =ROUNDUP(F30/Inputs!$B$11,0) -> 34 | I30: familias_out.json track_by_element 'bottom track (all)' (R73.3)
A31: Parapet bottom track | B31: LF | C31: 269.18 | D31: =Inputs!$B$5 -> 0.15 | E31: =C31*D31 -> 40.377 | F31: =C31+E31 -> 309.557 | G31: run 10 ft | H31: =ROUNDUP(F31/Inputs!$B$11,0) -> 31 | I31: familias_out.json track_by_element 'bottom track (all)' (R73.3)
A32: Bottom track - roof step and heads (vestibule / bulkhead) | B32: LF | C32: 177.56 | D32: =Inputs!$B$5 -> 0.15 | E32: =C32*D32 -> 26.634 | F32: =C32+E32 -> 204.194 | G32: run 10 ft | H32: =ROUNDUP(F32/Inputs!$B$11,0) -> 21 | I32: familias_out.json track_by_element 'bottom track (all)' (R73.3)
A33: Top / deflection track 6" | B33: LF | C33: 476.62 | D33: =Inputs!$B$5 -> 0.15 | E33: =C33*D33 -> 71.493 | F33: =C33+E33 -> 548.113 | G33: run 10 ft | H33: =ROUNDUP(F33/Inputs!$B$11,0) -> 55 | I33: familias_out.json track_by_element 'top / deflection track (all)' (R73.3)
A34: Top / deflection track - other framing (not a partition type, see source) | B34: LF | C34: 64.92 | D34: =Inputs!$B$5 -> 0.15 | E34: =C34*D34 -> 9.738 | F34: =C34+E34 -> 74.658 | G34: run 10 ft | H34: =ROUNDUP(F34/Inputs!$B$11,0) -> 8 | I34: familias_out.json track_by_element 'top / deflection track (all)' (R73.3)
A35: Top / deflection track 3-5/8" | B35: LF | C35: 248.52 | D35: =Inputs!$B$5 -> 0.15 | E35: =C35*D35 -> 37.278 | F35: =C35+E35 -> 285.798 | G35: run 10 ft | H35: =ROUNDUP(F35/Inputs!$B$11,0) -> 29 | I35: familias_out.json track_by_element 'top / deflection track (all)' (R73.3)
A36: Top / deflection track 1-5/8" | B36: LF | C36: 290.1 | D36: =Inputs!$B$5 -> 0.15 | E36: =C36*D36 -> 43.515 | F36: =C36+E36 -> 333.615 | G36: run 10 ft | H36: =ROUNDUP(F36/Inputs!$B$11,0) -> 34 | I36: familias_out.json track_by_element 'top / deflection track (all)' (R73.3)
A37: Parapet top track | B37: LF | C37: 269.18 | D37: =Inputs!$B$5 -> 0.15 | E37: =C37*D37 -> 40.377 | F37: =C37+E37 -> 309.557 | G37: run 10 ft | H37: =ROUNDUP(F37/Inputs!$B$11,0) -> 31 | I37: familias_out.json track_by_element 'top / deflection track (all)' (R73.3)
A38: Top track - roof step and heads (vestibule / bulkhead) | B38: LF | C38: 177.56 | D38: =Inputs!$B$5 -> 0.15 | E38: =C38*D38 -> 26.634 | F38: =C38+E38 -> 204.194 | G38: run 10 ft | H38: =ROUNDUP(F38/Inputs!$B$11,0) -> 21 | I38: familias_out.json track_by_element 'top / deflection track (all)' (R73.3)
A39: 3-5/8" stud, framed soffit 9/A12.08 (LF) | B39: LF | C39: 37.58 | D39: =Inputs!$B$5 -> 0.15 | E39: =C39*D39 -> 5.637 | F39: =C39+E39 -> 43.217 | G39: stick 20 ft | H39: =ROUNDUP(F39/Inputs!$B$10,0) -> 3 | I39: familias_out.json stud_by_element '3-5/8" stud (all gauges)' (v76)
A40: 5/8" FRT plywood sheathing (canopy and soffits) | B40: SF | C40: 1941.04 | D40: =Inputs!$B$6 -> 0.06 | E40: =C40*D40 -> 116.4624 | F40: =C40+E40 -> 2057.5024 | G40: 4x12 ft sheet (Inputs) | H40: =ROUNDUP(F40/Inputs!$B$9,0) -> 43 | I40: familias_out.json FRT plywood by material; canon rows
...

Sheet Pending Items
A1: RFI | B1: Question / condition | C1: Delta of each alternative
A2: RFI-ACC-additional-head-track | B2: additional head track: openings with their own box (openings_extra) > 4'-0": do they also take the additional head track of HEAD TRACK @ NON LOAD BRG: ADD FULL LENGTH ADDL HEAD TRACK @ OPNG > 4'-0"? | C2: 100.54 lf
A3: RFI-ACC-stud-reinforcement-mep | B3: stud reinforcement MEP: plates at double-row stud walls: one per cut row (R72.9) vs one per crossing | C3: -8 pcs
A4: RFI-ACC-stud-reinforcement-mep-2 | B4: stud reinforcement MEP: crossings read by hand (not found by mep.cruces): confirm each one on the M / P sheets (R73.5) | C4: 12 pcs
A5: RFI-ACC-gypsum-board-jamb-return | B5: gypsum board jamb return: jamb return width not dimensioned | C5: -40.29 sf
A6: RFI-ACC-expansion-anchors | B6: expansion anchors: untagged parts of piers / boxes (A-EXT-PIER-G2, A-EXT-PIER-G4) without anchorage in the schedule (R72.8) | C6: 9.41 pcs
A7: RFI-ACC-slab-pins | B7: slab pins: pin spacing: 12" (interior anchorage) vs 16" (fastener schedule) vs 24" (type K box) | C7: 16in: -133.63 pcs; 24in: -267.26 pcs
A8: RFI-ACC-deflection-clips | B8: deflection clips: deflection clips: the general note asks for them at non-load-bearing walls and the partition details draw a slip / deflection track (R73.6) | C8: 773 pcs
A9: RFI-ACC-stud-reinforcement-mep-3 | B9: stud reinforcement MEP: 4 fire dampers (Electrical 120 / NER 121) sit at the wall line and are not found by mep.cruces; listed manual | C9: +4 pcs (14", 14", 12", 12" at 16" O.C. = 1 stud each)
A10: RFI-ACC-stud-reinforcement-mep-4 | B10: stud reinforcement MEP: pipes > 1 in. through stud walls read on P01.01 (registro 14 < 25 votes): 2" ST x3, 4" OD x1, 3" ST x1 | C10: +6 pcs
A11: RFI-ACC-stud-reinforcement-mep-5 | B11: stud reinforcement MEP: crossing at A5 wall of Calling Cubes 122 shows two parallel branches (12" and 10") not labeled at the crossing; confirm sizes | C11: 0 / -1 pcs if a single duct
A12: RFI-ACC-access-panel | B12: access panel: M01.01 general note 2 and M00.03 note 16 require access panels for equipment / dampers above ceilings; only one panel drawn (RCP key note 4). Fire dampers at Electrical 120 / NER 121 are above ACT (no panel); GB ceilings (Vestibules 100/101, Waiting 104, Cash Window 116, Restrooms 113/114) may need more | C12: +n pcs per equipment found above GB ceilings
... A42: RFI-26 | B42: Roof step 4/A02.02: two stacked rows bear on two decks (low and upper); purlin carried on both rows' top tracks. | C42: -38.9 LF purlin if only one row (59.1)

Sheet Review Items
A1: 19 questions in total, asked ONE at a time in this order: floor plan (partition types A-Z), then the details the floor plan calls, in order
A2: # | B2: Phase | C2: Type / order | D2: Item | E2: Sheet + detail | F2: Image
A3: 1/19 | B3: Floor plan | C3: A1 | D3: A-N-A5-01 / MW01 printer alcove: the partition above the cabinet is carried inside the A5 west wall of Calling Cubes (R77.9), wall extended 3.11 ft over the alcove opening (header single track 4.46 LF). | E3: 6/A12.03 | F3: /home/user/boa28a/work/etapas/3_revision/res_img/item10_A5_N-A5-01_south.png
A4: 2/19 | B4: Floor plan | C4: A1K | D4: A1K south run A-S-A1K-01: hatch extent 1.767 LF carried (R72.1); node-to-node reading 2.20 LF (delta +0.433 LF ballistic + framing). | E4: 4/A12.01 | F4: /home/user/boa28a/work/etapas/3_revision/res_img/item06_A1K.png
A5: 3/19 | B5: Floor plan | C5: B | D5: A-S-B-03 Wellness north wall: stops under the printed W14x22 over 5.29 ft (weighted height 12.149 ft, E26); B-01 / G-08 / G1-01 same criterion. | E5: 1/A12.01 | F5: /home/user/boa28a/work/etapas/adversarial/img_V2/V2_H1_S2.20_B03_beam.png
A6: 4/19 | B6: Floor plan | C6: B2 | D6: Drinking-fountain alcove between the restroom B2 runs: untagged A1 walls carried as a niche of the B2 line (R74.3), 7.49 LF in OTHER FRAMING 'alcove'. PT0025 run: A02.01 prints 5'-6 1/2" and A08.01 5'-5 3/4" (3/4" difference). | E6: 1/A12.01 | F6: /home/user/boa28a/work/etapas/3_revision/res_img/item08-09_A1_corner.png
A7: 5/19 | B7: Floor plan | C7: B2K | D7: B2K is not in the A12.01 schedule (RFI-07); hatch 1.773 LF carried vs 2.207 LF if the kevlar hatch runs to the G-07 start (RFI-20, +0.434 LF). | E7: 4/A12.01 | F7: /home/user/boa28a/work/etapas/3_revision/res_img/item05_B2K.png
A8: 6/19 | B8: Floor plan | C8: C1 | D8: FCAM furring C1: 2.98 LF + east return 0.58 LF measured from the outside face (R75.7) = 3.56 LF (A 2.98 / B 3.21). Storefront piers C1: interior faces only (R76.5). | E8: 6/A12.01 | F8: /home/user/boa28a/work/etapas/3_revision/res_img/item13_C1_S-C1-03.png
A9: 7/19 | B9: Floor plan | C9: EXT-6CFMF | D9: Second 6" CFMF row between the canopy beam and the roof beam on grids G, F, 8, 2, D, 3 (A09.21-A09.23 sections) + row over the grid 2 HSS: carried as stacked walls (split_of). The Partition Takeoff sheet adds their LF to EXT-6CFMF (tool gap P02, about -159.8 LF in that sheet only). | E9: J/A09.23 | F9: /home/user/boa28a/work/etapas/adversarial/img_V1/H1_A02.01_W-2_solid_454-734.png
A10: 8/19 | B10: Floor plan | C10: EXT-6CFMF | D10: Exterior LF excludes the storefront spans (R70.7) and runs node to node through the corners (resolution items 1-3, 28): N-F 13.60, W-2 21.89, S-A 53.67 LF. | E10: C/A09.21 | F10: /home/user/boa28a/work/etapas/3_revision/res_img/item03_EXT_N-F.png
A11: 9/19 | B11: Floor plan | C11: EXT-PARAPET | D11: Parapet LF measured on the stud CL along each grid run (4/A09.26) with lf_override instead of W2's exterior-wall length, because the exterior LF excludes the storefront spans; corners @16" (RFI-12). | E11: 4/A09.26 | F11: /home/user/boa28a/work/etapas/3_revision/res_img/item22_EXT-PARAPET_A-PAR-03.png
A12: 10/19 | B12: Floor plan | C12: G | D12: A-N-G-09 kept to deck although partly under W12X19 / W8X10 (RFI-17); office jamb blocking 10 ends vs corner bead 11 (RFI-19). | E12: 5/A12.01 | F12: /home/user/boa28a/work/etapas/2_lectura/A/img_T2A/A-N-G-09.png
A13: 11/19 | B13: Floor plan | C13: G1 | D13: A-S-G1-01 untagged office-front end stub typed G1 by thickness 8.47" (R74.1); alternative A1 by note A. | E13: 5/A12.01 | F13: /home/user/boa28a/work/etapas/3_revision/res_img/item04_G1_S-G1-01.png
A14: 12/19 | B14: Detail | C14: 1 | D14: Drive-up ATM recess: 2 1/2" sistered + furring printed, 3 lines each carried (28.25 LF, R79.2); full-height reading 53.67 LF (RFI-06). | E14: 6/A08.11 | F14: /home/user/boa28a/work/etapas/2_lectura/A/img_T7A/A0811_det6_DU_ATM_section.png
A15: 13/19 | B15: Detail | C15: 2 | D15: Storefront pier jamb strips 3/4" FRT plywood not measured (RFI-15, approx +24 SF). | E15: 2/A09.25 | F15: /home/user/boa28a/work/etapas/adversarial/img_V1/H4_A09.25_det2_pier_jamb_FRT.png
A16: 14/19 | B16: Detail | C16: 3 | D16: Coiling grille 103 head: head 10'-0" (2/A08.21 vector) vs 13'-6 1/2" on A00.30 (RFI-11); 2-1/2" head studs from the R79.1 chain. | E16: 4/A08.21 | F16: /home/user/boa28a/work/etapas/2_lectura/A/img_T8A/A08.21_4_grille_head.png
A17: 15/19 | B17: Detail | C17: 4 | D17: HM door R.O. convention door + 4" vs door + 2.13" measured (RFI-16, -2.34 LF header). | E17: 11/A12.02 | F17: /home/user/boa28a/work/etapas/adversarial/img_V3/A12.02_11_jamb_HM.png
A18: 16/19 | B18: Detail | C18: 5 | D18: Stud blocking at edge of gypboard: carried on faces taller than a 12 ft sheet per stud row (R78.33); two figures in RFI-14. | E18: 4/S5.20 | F18: /home/user/boa28a/work/etapas/adversarial/img_V4/S520_edge_gypboard.png
A19: 17/19 | B19: Detail | C19: 6 | D19: Drive-up canopy band does not label glass mat (RFI-13, +109.9 SF). | E19: 15/A09.27 | F19: /home/user/boa28a/work/etapas/2_lectura/A/img_T5A/DET_15_A09.27_drive_up_canopy_band.png
A20: 18/19 | B20: Detail | C20: 7 | D20: Roof step: purlin on both rows bearing on two decks (RFI-26). | E20: 4/A02.02 | F20: /home/user/boa28a/work/etapas/2_lectura/A/img_T5A/DET_4_A02.02_roof_step.png
A21: 19/19 | B21: Detail | C21: 8 | D21: CSR soffit framed (9/A12.08 + 10/A09.33): corner bead and FRTW blocking at both drop edges added after the adversarial check (24.04 LF each). | E21: 10/A09.33 | F21: /home/user/boa28a/work/etapas/adversarial/img_V4/A0933_det10_CSR_cornerbead_FRTW.png

Sheet Scope Checklist
A1: Scope ID | B1: Scope | C1: Status | D1: Note (quantity, NOT APPLICABLE + sheet, or RFI)
A2: ALC-01 | B2: Interior partition framing (studs + tracks) | C2: QUANTIFIED | D2: Material Summary: 3-5/8", 6", 1-5/8" metal stud + bottom / top track by size (familias_out.json); A12.01, 7/S5.20
A3: ALC-02 | B3: Exterior wall framing (CFMF) | C3: QUANTIFIED | D3: EXT-6CFMF walls + upper infill rows + storefront cripples (6" metal stud family); A09.21-A09.23, S1.11, S2.20
A4: ALC-03 | B4: Parapet framing | C4: QUANTIFIED | D4: 6" parapet infill stud, bay by bay (E3); 4/A09.26, 11/S5.10
A5: ALC-04 | B5: Top / deflection and bottom track | C5: QUANTIFIED | D5: Bottom track / Top deflection track rows by stud size and element (R71.8, R73.3); A12.01, S5.10
A6: ALC-05 | B6: Headers, sills and jambs at openings | C6: QUANTIFIED | D6: Header / box beam by pieces (E1/E2) + sill track (E18); 7/S5.20, 2/S5.20, A00.30
A7: ALC-06 | B7: Bracing / bridging | C7: QUANTIFIED | D7: Bracing C.R. channel rows = ROUNDUP(H x 12 / 48) - 1 (53.4); S1.11, S5.20
A8: ALC-07 | B8: Gypsum board on walls (layers per type) | C8: QUANTIFIED | D8: 5/8" gypsum board regular, face by face (board_caras); A12.01
A9: ALC-08 | B9: Moisture / abuse / special board at wet zones | C9: QUANTIFIED | D9: 5/8" MOISTURE RESISTANT behind toilet and lavatory only (A08.01 note F)
A10: ALC-09 | B10: Exterior gypsum / glass mat sheathing | C10: QUANTIFIED | D10: 5/8" glass mat sheathing (base strip + canopy band) and 5/8" EXTERIOR gypsum sheathing (parapet roof side); A09.26, A09.27
A11: ALC-10 | B11: FRT plywood sheathing / substrate | C11: QUANTIFIED | D11: FRT plywood by material and use (nailbase, substrate, column wrap, opening substrate, backboards); A09.21, A11.03, A12.01
A12: ALC-11 | B12: Gypsum board ceilings | C12: QUANTIFIED | D12: Suspended GWB ceilings in 5 rooms + CSR framed soffit (A04.01, A9.22 bubbles / A09.33)
... A26: ALC-X25 | B26: batt insulation | C26: NOT APPLICABLE | D26: EXCLUDED (estimator criterion: no insulation)

Sheet _reglas
A1: reglas.py compuerta OK
A2: {"canon": "f9cf4c3d0c7b720e4e4390a17becad4c10cbb7055a1180cb1a5d17e427f01b2c", "evidencias": "b24aea026497f3d78ef21f1d3a6f59511673c702f7e178a4feb3055ff17d5c0b", "familias_out": "c00653f3bf0ad35ca7cd6f58a769f31de349e5c69a13419c7d86cf7ece8f1d61", "reglas": "765fa0be283da1e3f849c9ab1f1f94e210282701890f84fb96862890f4435793", "version": "v73"}
