Workbook

Sheet Takeoff
A1: Bank of America - Broomfield, CO (CO1-111) - Organized Partition Takeoff Estimator - Div. 05 / Div. 09
A2: Bid set: 2025.08.26_CO1-111_Broomfield_PERMIT SET_BID SET.pdf (94 pages, rev. IF Permit 08/26/2025). Net quantities; waste in its own cells below. Status: [CONFIRMADO]/[DERIVADO]/[PENDIENTE].
A4: Partition / Scope | B4: Detail sequence (plan -> detail -> detail of detail -> schedule) | C4: Status / derivation | D4: Length (LF) | E4: Height (FT) | F4: Layers | G4: Stud O.C. (in) | H4: Stud rows | I4: Extra studs (ea) | J4: Side 1 board height (FT) | K4: Side 1 layers | L4: Side 2 board height (FT) | M4: Side 2 layers | N4: Openings deduct (SF per face) | O4: 6" Metal Stud (LF) | P4: 3-5/8" Metal Stud (LF) | Q4: 1-5/8" Metal Stud (LF) | R4: 2-1/2" Metal Stud (LF) | S4: 6" parapet stud (LF) | T4: Bottom track (LF) | U4: Top / deflection track (LF) | V4: Header / box beam (LF) | W4: Sill track (LF) | X4: Bracing C.R. channel 1-1/2" (LF) | Y4: 5/8" Gyp Board regular (SF) | Z4: 5/8" Gyp MOISTURE RESISTANT (SF) | AA4: 3/8" Gyp Board (SF) | AB4: 5/8" EXTERIOR gyp sheathing (SF) | AC4: 5/8" glass mat sheathing (SF) | AD4: FRT plywood (SF) | AE4: Ballistic panel 3/8" UL752 fiberglass (SF) | AF4: FRP-1 (SF) | AG4: Durock / cement board (SF) | AH4: Batt insulation (SF) | AI4: FRT blocking (LF) | AJ4: Metal trim - corner bead / casing / shadow molding (LF) | AK4: Acoustical sealant (LF) | AL4: Furring channel 7/8" (LF) | AM4: Carrying channel 1-1/2" (LF) | AN4: Hanger wire 12 GA (LF) | AO4: Track de ceilings / soffits (LF) | AP4: Framed openings MEP / recessed (EA) | AQ4: Level 5 finish (SF) | AR4: Demolition (SF) | AS4: Labor (Hrs) | AT4: Notes / RFI
A5: TYPE / SCOPE: A1
A6: W-06 A1 - Corridor 111 east / Electrical 120 + NER 121 west. side 1 (111): 1 layer 5/8" GWB to 9.0 ft | side 2 (120): 1 layer 5/8" GWB to 13.052 ft (ceiling + 6", 3/A12.01; open-to-structure face to deck) | B6: A02.01 -> 3/A12.01 (A1 & A5) -> S5.20 METAL STUD PROPERTIES (362S137-33 @16") -> A04.01 (ceiling per face) | zone LOW (S2.20 B.O.D. 13'-0 5/8" high end) | C6: [DERIVADO] L = vector faces A02.01 (band 119-121; tags A1@1214,1406 + A1@1220,1515) / 18 pt/ft; H = 13.052 = 13'-0 5/8" - 0'-0" | D6: 17.06 | E6: 13.052 | F6: 2 | G6: 16 | H6: 1 | I6: 2 | J6: 9 | K6: 1 | L6: 13.052 | M6: 1 | N6: 0 | P6: =(ROUNDUP(D6*12/G6,0)+1+I6)*E6*H6 -> 208.832 | T6: =(D6-0)*H6 -> 17.06 | U6: =D6*H6 -> 17.06 | X6: =D6*3 -> 51.18 | Y6: =D6*(J6*K6+L6*M6)-N6*2 -> 376.20712 | AH6: =D6*E6 -> 222.66712 | AK6: =D6*2*H6 -> 34.12 | AT6: 1 1/2" C.R. channel @48" O.C. (S5.20 F. BRIDGING AND BRACING): floor(13.052/4)=3 lines
A7: W-01 A1 - Calling Cubes 122 north / Waiting 104. side 1 (122): 1 layer 5/8" GWB to 9.0 ft | side 2 (104): 1 layer 5/8" GWB to 11.5 ft (ceiling + 6", 3/A12.01; open-to-structure face to deck) | B7: A02.01 -> 3/A12.01 (A1 & A5) -> S5.20 METAL STUD PROPERTIES (362S137-33 @16") -> A04.01 (ceiling per face) | zone HI (S2.20 B.O.D. 15'-4 1/2") | C7: [DERIVADO] L = vector faces A02.01 (band 31-34; tag A1@1383,996) / 18 pt/ft; H = 15.375 = 15'-4 1/2" - 0'-0" | D7: 16.42 | E7: 15.375 | F7: 2 | G7: 16 | H7: 1 | I7: 2 | J7: 9 | K7: 1 | L7: 11.5 | M7: 1 | N7: 0 | P7: =(ROUNDUP(D7*12/G7,0)+1+I7)*E7*H7 -> 246 | T7: =(D7-0)*H7 -> 16.42 | U7: =D7*H7 -> 16.42 | X7: =D7*3 -> 49.26 | Y7: =D7*(J7*K7+L7*M7)-N7*2 -> 336.61 | AH7: =D7*E7 -> 252.4575 | AK7: =D7*2*H7 -> 32.84 | AT7: 1 1/2" C.R. channel @48" O.C. (S5.20 F. BRIDGING AND BRACING): floor(15.375/4)=3 lines
A8: W-05 A1 - Calling Cubes 122 south / Break Room 118 north. side 1 (122): 1 layer 5/8" GWB to 9.0 ft | side 2 (118): 1 layer 5/8" GWB to 9.0 ft (ceiling + 6", 3/A12.01; open-to-structure face to deck) | B8: A02.01 -> 3/A12.01 (A1 & A5) -> S5.20 METAL STUD PROPERTIES (362S137-33 @16") -> A04.01 (ceiling per face) | zone LOW (S2.20 B.O.D. 13'-0 5/8" high end) | C8: [DERIVADO] L = vector faces A02.01 (band 50; tag A1@1376,1296) / 18 pt/ft; H = 13.052 = 13'-0 5/8" - 0'-0" | D8: 15.23 | E8: 13.052 | F8: 2 | G8: 16 | H8: 1 | I8: 2 | J8: 9 | K8: 1 | L8: 9 | M8: 1 | N8: 0 | P8: =(ROUNDUP(D8*12/G8,0)+1+I8)*E8*H8 -> 195.78 | T8: =(D8-0)*H8 -> 15.23 | U8: =D8*H8 -> 15.23 | X8: =D8*3 -> 45.69 | Y8: =D8*(J8*K8+L8*M8)-N8*2 -> 274.14 | AH8: =D8*E8 -> 198.78196 | AK8: =D8*2*H8 -> 30.46 | AT8: 1 1/2" C.R. channel @48" O.C. (S5.20 F. BRIDGING AND BRACING): floor(13.052/4)=3 lines
A9: W-09 A1 - Work Room 119 north / Cash Window 116. side 1 (116): 1 layer 5/8" GWB to 9.5 ft | side 2 (119): 1 layer 5/8" GWB to 9.0 ft (ceiling + 6", 3/A12.01; open-to-structure face to deck) | B9: A02.01 -> 3/A12.01 (A1 & A5) -> S5.20 METAL STUD PROPERTIES (362S137-33 @16") -> A04.01 (ceiling per face) | zone LOW (S2.20 B.O.D. 13'-0 5/8" high end) | C9: [DERIVADO] L = vector faces A02.01 (band 62; tag A1@1740,1471) / 18 pt/ft; H = 13.052 = 13'-0 5/8" - 0'-0" | D9: 8.17 | E9: 13.052 | F9: 2 | G9: 16 | H9: 1 | I9: 2 | J9: 9.5 | K9: 1 | L9: 9 | M9: 1 | N9: 0 | P9: =(ROUNDUP(D9*12/G9,0)+1+I9)*E9*H9 -> 130.52 | T9: =(D9-0)*H9 -> 8.17 | U9: =D9*H9 -> 8.17 | X9: =D9*3 -> 24.51 | Y9: =D9*(J9*K9+L9*M9)-N9*2 -> 151.145 | AH9: =D9*E9 -> 106.63484 | AK9: =D9*2*H9 -> 16.34 | AT9: 1 1/2" C.R. channel @48" O.C. (S5.20 F. BRIDGING AND BRACING): floor(13.052/4)=3 lines
A10: W-07 A1 - Break Room 118 north / FCAM (door 118A). side 1 (STRIP): 1 layer 5/8" GWB to 9.5 ft | side 2 (118): 1 layer 5/8" GWB to 9.0 ft (ceiling + 6", 3/A12.01; open-to-structure face to deck) | B10: A02.01 -> 3/A12.01 (A1 & A5) -> S5.20 METAL STUD PROPERTIES (362S137-33 @16") -> A04.01 (ceiling per face) | zone LOW (S2.20 B.O.D. 13'-0 5/8" high end) | C10: [DERIVADO] L = vector faces A02.01 (band 54,55; tag A1@1540,1335) / 18 pt/ft; H = 13.052 = 13'-0 5/8" - 0'-0" | D10: 5.11 | E10: 13.052 | F10: 2 | G10: 16 | H10: 1 | I10: 6 | J10: 9.5 | K10: 1 | L10: 9 | M10: 1 | N10: 24 | P10: =(ROUNDUP(D10*12/G10,0)+1+I10)*E10*H10 -> 143.572 | T10: =(D10-3)*H10 -> 2.11 | U10: =D10*H10 -> 5.11 | X10: =D10*3 -> 15.33 | Y10: =D10*(J10*K10+L10*M10)-N10*2 -> 46.535 | AH10: =D10*E10 -> 66.69572 | AK10: =D10*2*H10 -> 10.22 | AT10: 1 1/2" C.R. channel @48" O.C. (S5.20 F. BRIDGING AND BRACING): floor(13.052/4)=3 lines
A11: W-04 A1 - Corridor 111 north end (door 111). side 1 (111): 1 layer 5/8" GWB to 9.0 ft | side 2 (103): 1 layer 5/8" GWB to 12.0 ft (ceiling + 6", 3/A12.01; open-to-structure face to deck) | B11: A02.01 -> 3/A12.01 (A1 & A5) -> S5.20 METAL STUD PROPERTIES (362S137-33 @16") -> A04.01 (ceiling per face) | zone HI (S2.20 B.O.D. 15'-4 1/2") | C11: [DERIVADO] L = vector faces A02.01 (band 45,46; tag A1@1147,1253) / 18 pt/ft; H = 15.375 = 15'-4 1/2" - 0'-0" | D11: 5 | E11: 15.375 | F11: 2 | G11: 16 | H11: 1 | I11: 6 | J11: 9 | K11: 1 | L11: 12 | M11: 1 | N11: 24 | P11: =(ROUNDUP(D11*12/G11,0)+1+I11)*E11*H11 -> 169.125 | T11: =(D11-3)*H11 -> 2 | U11: =D11*H11 -> 5 | X11: =D11*3 -> 15 | Y11: =D11*(J11*K11+L11*M11)-N11*2 -> 57 | AH11: =D11*E11 -> 76.875 | AK11: =D11*2*H11 -> 10 | AT11: 1 1/2" C.R. channel @48" O.C. (S5.20 F. BRIDGING AND BRACING): floor(15.375/4)=3 lines
A12: W-02 A1 - MW01 printer recess - east side. side 1 (122): 1 layer 5/8" GWB to 9.0 ft | side 2 (103): 1 layer 5/8" GWB to 12.0 ft (ceiling + 6", 3/A12.01; open-to-structure face to deck) | B12: A02.01 -> 3/A12.01 (A1 & A5) -> S5.20 METAL STUD PROPERTIES (362S137-33 @16") -> A04.01 (ceiling per face) | zone HI (S2.20 B.O.D. 15'-4 1/2") | C12: [DERIVADO] L = vector faces A02.01 (lw1.2 faces x1271.16/1278.48; tag A1@1299,1000) / 18 pt/ft; H = 15.375 = 15'-4 1/2" - 0'-0" | D12: 3.12 | E12: 15.375 | F12: 2 | G12: 16 | H12: 1 | I12: 2 | J12: 9 | K12: 1 | L12: 12 | M12: 1 | N12: 0 | P12: =(ROUNDUP(D12*12/G12,0)+1+I12)*E12*H12 -> 92.25 | T12: =(D12-0)*H12 -> 3.12 | U12: =D12*H12 -> 3.12 | X12: =D12*3 -> 9.36 | Y12: =D12*(J12*K12+L12*M12)-N12*2 -> 65.52 | AH12: =D12*E12 -> 47.97 | AK12: =D12*2*H12 -> 6.24 | AT12: 1 1/2" C.R. channel @48" O.C. (S5.20 F. BRIDGING AND BRACING): floor(15.375/4)=3 lines
A13: W-03 A1 - MW01 printer recess - south side. side 1 (122): 1 layer 5/8" GWB to 9.0 ft | side 2 (103): 1 layer 5/8" GWB to 12.0 ft (ceiling + 6", 3/A12.01; open-to-structure face to deck) | B13: A02.01 -> 3/A12.01 (A1 & A5) -> S5.20 METAL STUD PROPERTIES (362S137-33 @16") -> A04.01 (ceiling per face) | zone HI (S2.20 B.O.D. 15'-4 1/2") | C13: [DERIVADO] L = vector faces A02.01 (band 36; tag A1@1246,1063) / 18 pt/ft; H = 15.375 = 15'-4 1/2" - 0'-0" | D13: 2.02 | E13: 15.375 | F13: 2 | G13: 16 | H13: 1 | I13: 2 | J13: 9 | K13: 1 | L13: 12 | M13: 1 | N13: 0 | P13: =(ROUNDUP(D13*12/G13,0)+1+I13)*E13*H13 -> 76.875 | T13: =(D13-0)*H13 -> 2.02 | U13: =D13*H13 -> 2.02 | X13: =D13*3 -> 6.06 | Y13: =D13*(J13*K13+L13*M13)-N13*2 -> 42.42 | AH13: =D13*E13 -> 31.0575 | AK13: =D13*2*H13 -> 4.04 | AT13: 1 1/2" C.R. channel @48" O.C. (S5.20 F. BRIDGING AND BRACING): floor(15.375/4)=3 lines
A14: W-08 A1 - Calling Cubes east line - stub to Break Room. side 1 (118): 1 layer 5/8" GWB to 9.0 ft | side 2 (STRIP): 1 layer 5/8" GWB to 9.5 ft (ceiling + 6", 3/A12.01; open-to-structure face to deck) | B14: A02.01 -> 3/A12.01 (A1 & A5) -> S5.20 METAL STUD PROPERTIES (362S137-33 @16") -> A04.01 (ceiling per face) | zone LOW (S2.20 B.O.D. 13'-0 5/8" high end) | C14: [DERIVADO] L = vector faces A02.01 (band 129; tag A1@1508,1342) / 18 pt/ft; H = 13.052 = 13'-0 5/8" - 0'-0" | D14: 1.73 | E14: 13.052 | F14: 2 | G14: 16 | H14: 1 | I14: 2 | J14: 9 | K14: 1 | L14: 9.5 | M14: 1 | N14: 0 | P14: =(ROUNDUP(D14*12/G14,0)+1+I14)*E14*H14 -> 65.26 | T14: =(D14-0)*H14 -> 1.73 | U14: =D14*H14 -> 1.73 | X14: =D14*3 -> 5.19 | Y14: =D14*(J14*K14+L14*M14)-N14*2 -> 32.005 | AH14: =D14*E14 -> 22.57996 | AK14: =D14*2*H14 -> 3.46 | AT14: 1 1/2" C.R. channel @48" O.C. (S5.20 F. BRIDGING AND BRACING): floor(13.052/4)=3 lines
A15: TYPE / SCOPE: A5
A16: W-13 A5 - Calling Cubes 122 east / Central Zone - HI zone part (north of grid B). side 1 (122): 1 layer 5/8" GWB to 9.0 ft | side 2 (103): 1 layer 5/8" GWB to 12.0 ft (ceiling + 6", 3/A12.01; open-to-structure face to deck) | B16: A02.01 -> 3/A12.01 (A1 & A5) -> S5.20 METAL STUD PROPERTIES (600S137-33) -> A04.01 (ceiling per face) | zone HI (S2.20 B.O.D. 15'-4 1/2") | C16: [DERIVADO] L = vector faces A02.01 (band 128; tag A5@1544,1118) / 18 pt/ft; H = 15.375 = 15'-4 1/2" - 0'-0" | D16: 14.98 | E16: 15.375 | F16: 2 | G16: 16 | H16: 1 | I16: 2 | J16: 9 | K16: 1 | L16: 12 | M16: 1 | N16: 0 | O16: =(ROUNDUP(D16*12/G16,0)+1+I16)*E16*H16 -> 230.625 | T16: =(D16-0)*H16 -> 14.98 | U16: =D16*H16 -> 14.98 | X16: =D16*3 -> 44.94 | Y16: =D16*(J16*K16+L16*M16)-N16*2 -> 314.58 | AH16: =D16*E16 -> 230.3175 | AK16: =D16*2*H16 -> 29.96 | AT16: 1 1/2" C.R. channel @48" O.C. (S5.20 F. BRIDGING AND BRACING): floor(15.375/4)=3 lines
A17: W-11 A5 - Calling Cubes 122 west / Office 5-6 corridor side. side 1 (103): 1 layer 5/8" GWB to 12.0 ft | side 2 (122): 1 layer 5/8" GWB to 9.0 ft (ceiling + 6", 3/A12.01; open-to-structure face to deck) | B17: A02.01 -> 3/A12.01 (A1 & A5) -> S5.20 METAL STUD PROPERTIES (600S137-33) -> A04.01 (ceiling per face) | zone HI (S2.20 B.O.D. 15'-4 1/2") | C17: [DERIVADO] L = vector faces A02.01 (band 115-117; tag A5@1209,1128) / 18 pt/ft; H = 15.375 = 15'-4 1/2" - 0'-0" | D17: 10.59 | E17: 15.375 | F17: 2 | G17: 16 | H17: 1 | I17: 2 | J17: 12 | K17: 1 | L17: 9 | M17: 1 | N17: 0 | O17: =(ROUNDUP(D17*12/G17,0)+1+I17)*E17*H17 -> 169.125 | T17: =(D17-0)*H17 -> 10.59 | U17: =D17*H17 -> 10.59 | X17: =D17*3 -> 31.77 | Y17: =D17*(J17*K17+L17*M17)-N17*2 -> 222.39 | AH17: =D17*E17 -> 162.82125 | AK17: =D17*2*H17 -> 21.18 | AT17: 1 1/2" C.R. channel @48" O.C. (S5.20 F. BRIDGING AND BRACING): floor(15.375/4)=3 lines
A18: W-13B A5 - Calling Cubes 122 east / Central strip - LOW zone part (south of grid B). side 1 (122): 1 layer 5/8" GWB to 9.0 ft | side 2 (STRIP): 1 layer 5/8" GWB to 9.5 ft (ceiling + 6", 3/A12.01; open-to-structure face to deck) | B18: A02.01 -> 3/A12.01 (A1 & A5) -> S5.20 METAL STUD PROPERTIES (600S137-33) -> A04.01 (ceiling per face) | zone LOW (S2.20 B.O.D. 13'-0 5/8" high end) | C18: [DERIVADO] L = vector faces A02.01 (band 128 split at grid B y1244.4) / 18 pt/ft; H = 13.052 = 13'-0 5/8" - 0'-0" | D18: 4.02 | E18: 13.052 | F18: 2 | G18: 16 | H18: 1 | I18: 2 | J18: 9 | K18: 1 | L18: 9.5 | M18: 1 | N18: 0 | O18: =(ROUNDUP(D18*12/G18,0)+1+I18)*E18*H18 -> 91.364 | T18: =(D18-0)*H18 -> 4.02 | U18: =D18*H18 -> 4.02 | X18: =D18*3 -> 12.06 | Y18: =D18*(J18*K18+L18*M18)-N18*2 -> 74.37 | AH18: =D18*E18 -> 52.46904 | AK18: =D18*2*H18 -> 8.04 | AT18: 1 1/2" C.R. channel @48" O.C. (S5.20 F. BRIDGING AND BRACING): floor(13.052/4)=3 lines
A19: W-14 A5 - Break Room 118 east / Cash Window - FCAM (south to door 116). side 1 (118): 1 layer 5/8" GWB to 9.0 ft | side 2 (116): 1 layer 5/8" GWB to 9.5 ft (ceiling + 6", 3/A12.01; open-to-structure face to deck) | B19: A02.01 -> 3/A12.01 (A1 & A5) -> S5.20 METAL STUD PROPERTIES (600S137-33) -> A04.01 (ceiling per face) | zone LOW (S2.20 B.O.D. 13'-0 5/8" high end) | C19: [DERIVADO] L = vector faces A02.01 (band 139; tag A5@1650,1409) / 18 pt/ft; H = 13.052 = 13'-0 5/8" - 0'-0" | D19: 3.28 | E19: 13.052 | F19: 2 | G19: 16 | H19: 1 | I19: 2 | J19: 9 | K19: 1 | L19: 9.5 | M19: 1 | N19: 0 | O19: =(ROUNDUP(D19*12/G19,0)+1+I19)*E19*H19 -> 78.312 | T19: =(D19-0)*H19 -> 3.28 | U19: =D19*H19 -> 3.28 | X19: =D19*3 -> 9.84 | Y19: =D19*(J19*K19+L19*M19)-N19*2 -> 60.68 | AH19: =D19*E19 -> 42.81056 | AK19: =D19*2*H19 -> 6.56 | AT19: 1 1/2" C.R. channel @48" O.C. (S5.20 F. BRIDGING AND BRACING): floor(13.052/4)=3 lines
A20: W-12 A5 - Corridor 111 east - stub north of door 122. side 1 (111): 1 layer 5/8" GWB to 9.0 ft | side 2 (122): 1 layer 5/8" GWB to 9.0 ft (ceiling + 6", 3/A12.01; open-to-structure face to deck) | B20: A02.01 -> 3/A12.01 (A1 & A5) -> S5.20 METAL STUD PROPERTIES (600S137-33) -> A04.01 (ceiling per face) | zone LOW (S2.20 B.O.D. 13'-0 5/8" high end) | C20: [DERIVADO] L = vector faces A02.01 (band 118; tag A5@1264,1240) / 18 pt/ft; H = 13.052 = 13'-0 5/8" - 0'-0" | D20: 0.97 | E20: 13.052 | F20: 2 | G20: 16 | H20: 1 | I20: 2 | J20: 9 | K20: 1 | L20: 9 | M20: 1 | N20: 0 | O20: =(ROUNDUP(D20*12/G20,0)+1+I20)*E20*H20 -> 52.208 | T20: =(D20-0)*H20 -> 0.97 | U20: =D20*H20 -> 0.97 | X20: =D20*3 -> 2.91 | Y20: =D20*(J20*K20+L20*M20)-N20*2 -> 17.46 | AH20: =D20*E20 -> 12.66044 | AK20: =D20*2*H20 -> 1.94 | AT20: 1 1/2" C.R. channel @48" O.C. (S5.20 F. BRIDGING AND BRACING): floor(13.052/4)=3 lines
A21: TYPE / SCOPE: B
A22: W-23 B - Electrical 120 + NER 121 east / Break Room (doors 120,121). each side: 1 layer 5/8" GWB full height to underside of structure (1/A12.01) | B22: A02.01 -> 1/A12.01 (B, B2) -> S5.20 METAL STUD PROPERTIES (362S137-33 @16") -> S2.20 (B.O.D.) | zone LOW (S2.20 B.O.D. 13'-0 5/8" high end) | C22: [DERIVADO] L = vector faces A02.01 (band 123-126; tag B@1401,1583) / 18 pt/ft; H = 13.052 = 13'-0 5/8" - 0'-0" | D22: 13.74 | E22: 13.052 | F22: 2 | G22: 16 | H22: 1 | I22: 10 | J22: 13.052 | K22: 1 | L22: 13.052 | M22: 1 | N22: 42 | P22: =(ROUNDUP(D22*12/G22,0)+1+I22)*E22*H22 -> 287.144 | T22: =(D22-6)*H22 -> 7.74 | U22: =D22*H22 -> 13.74 | X22: =D22*3 -> 41.22 | Y22: =D22*(J22*K22+L22*M22)-N22*2 -> 274.66896 | AH22: =D22*E22 -> 179.33448 | AK22: =D22*4 -> 54.96 | AT22: 1 1/2" C.R. channel @48" O.C. (S5.20 F. BRIDGING AND BRACING): floor(13.052/4)=3 lines
A23: W-24 B - Janitor 112 + Storage 117 south / Wellness 115 north. each side: 1 layer 5/8" GWB full height to underside of structure (1/A12.01) | B23: A02.01 -> 1/A12.01 (B, B2) -> S5.20 METAL STUD PROPERTIES (362S137-33 @16") -> S2.20 (B.O.D.) | zone LOW (S2.20 B.O.D. 13'-0 5/8" high end) | C23: [DERIVADO] L = vector faces A02.01 (band 65-67; tag B@1102,1607) / 18 pt/ft; H = 13.052 = 13'-0 5/8" - 0'-0" | D23: 11.73 | E23: 13.052 | F23: 2 | G23: 16 | H23: 1 | I23: 2 | J23: 13.052 | K23: 1 | L23: 13.052 | M23: 1 | N23: 0 | P23: =(ROUNDUP(D23*12/G23,0)+1+I23)*E23*H23 -> 156.624 | T23: =(D23-0)*H23 -> 11.73 | U23: =D23*H23 -> 11.73 | X23: =D23*3 -> 35.19 | Y23: =D23*(J23*K23+L23*M23)-N23*2 -> 306.19992 | AH23: =D23*E23 -> 153.09996 | AK23: =D23*4 -> 46.92 | AT23: 1 1/2" C.R. channel @48" O.C. (S5.20 F. BRIDGING AND BRACING): floor(13.052/4)=3 lines
A24: W-26 B - Men's RR 113 south / Janitor 112 north (door 112). each side: 1 layer 5/8" GWB full height to underside of structure (1/A12.01) | B24: A02.01 -> 1/A12.01 (B, B2) -> S5.20 METAL STUD PROPERTIES (362S137-33 @16") -> S2.20 (B.O.D.) | zone LOW (S2.20 B.O.D. 13'-0 5/8" high end) | C24: [DERIVADO] L = vector faces A02.01 (lw1.2 faces y1508.52/1515.84; tag B@1052,1497) / 18 pt/ft; H = 13.052 = 13'-0 5/8" - 0'-0" | D24: 11.73 | E24: 13.052 | F24: 2 | G24: 16 | H24: 1 | I24: 6 | J24: 13.052 | K24: 1 | L24: 13.052 | M24: 1 | N24: 21 | P24: =(ROUNDUP(D24*12/G24,0)+1+I24)*E24*H24 -> 208.832 | T24: =(D24-3)*H24 -> 8.73 | U24: =D24*H24 -> 11.73 | X24: =D24*3 -> 35.19 | Y24: =D24*(J24*K24+L24*M24)-N24*2 -> 264.19992 | AH24: =D24*E24 -> 153.09996 | AK24: =D24*4 -> 46.92 | AT24: 1 1/2" C.R. channel @48" O.C. (S5.20 F. BRIDGING AND BRACING): floor(13.052/4)=3 lines
A25: W-21 B - Electrical 120 north / Break Room. each side: 1 layer 5/8" GWB full height to underside of structure (1/A12.01) | B25: A02.01 -> 1/A12.01 (B, B2) -> S5.20 METAL STUD PROPERTIES (362S137-33 @16") -> S2.20 (B.O.D.) | zone LOW (S2.20 B.O.D. 13'-0 5/8" high end) | C25: [DERIVADO] L = vector faces A02.01 (band 60,61; tag B@1381,1457) / 18 pt/ft; H = 13.052 = 13'-0 5/8" - 0'-0" | D25: 9.58 | E25: 13.052 | F25: 2 | G25: 16 | H25: 1 | I25: 2 | J25: 13.052 | K25: 1 | L25: 13.052 | M25: 1 | N25: 0 | P25: =(ROUNDUP(D25*12/G25,0)+1+I25)*E25*H25 -> 143.572 | T25: =(D25-0)*H25 -> 9.58 | U25: =D25*H25 -> 9.58 | X25: =D25*3 -> 28.74 | Y25: =D25*(J25*K25+L25*M25)-N25*2 -> 250.07632 | AH25: =D25*E25 -> 125.03816 | AK25: =D25*4 -> 38.32 | AT25: 1 1/2" C.R. channel @48" O.C. (S5.20 F. BRIDGING AND BRACING): floor(13.052/4)=3 lines
A26: W-22 B - Electrical 120 / NER 121. each side: 1 layer 5/8" GWB full height to underside of structure (1/A12.01) | B26: A02.01 -> 1/A12.01 (B, B2) -> S5.20 METAL STUD PROPERTIES (362S137-33 @16") -> S2.20 (B.O.D.) | zone LOW (S2.20 B.O.D. 13'-0 5/8" high end) | C26: [DERIVADO] L = vector faces A02.01 (band 64; tag B@1384,1572) / 18 pt/ft; H = 13.052 = 13'-0 5/8" - 0'-0" | D26: 9.58 | E26: 13.052 | F26: 2 | G26: 16 | H26: 1 | I26: 2 | J26: 13.052 | K26: 1 | L26: 13.052 | M26: 1 | N26: 0 | P26: =(ROUNDUP(D26*12/G26,0)+1+I26)*E26*H26 -> 143.572 | T26: =(D26-0)*H26 -> 9.58 | U26: =D26*H26 -> 9.58 | X26: =D26*3 -> 28.74 | Y26: =D26*(J26*K26+L26*M26)-N26*2 -> 250.07632 | AH26: =D26*E26 -> 125.03816 | AK26: =D26*4 -> 38.32 | AT26: 1 1/2" C.R. channel @48" O.C. (S5.20 F. BRIDGING AND BRACING): floor(13.052/4)=3 lines
A27: W-37 B - Drinking fountain alcove - back wall (restroom chase side). each side: 1 layer 5/8" GWB full height to underside of structure (1/A12.01) | B27: A02.01 -> 1/A12.01 (B, B2) -> S5.20 METAL STUD PROPERTIES (362S137-33 @16") -> S2.20 (B.O.D.) | zone LOW (S2.20 B.O.D. 13'-0 5/8" high end) | C27: [DERIVADO] L = vector faces A02.01 (lw1.2 x1092.36/1099.68; thickness 4.88 in) / 18 pt/ft; H = 13.052 = 13'-0 5/8" - 0'-0" | D27: 4.89 | E27: 13.052 | F27: 2 | G27: 16 | H27: 1 | I27: 2 | J27: 13.052 | K27: 1 | L27: 13.052 | M27: 1 | N27: 0 | P27: =(ROUNDUP(D27*12/G27,0)+1+I27)*E27*H27 -> 91.364 | T27: =(D27-0)*H27 -> 4.89 | U27: =D27*H27 -> 4.89 | X27: =D27*3 -> 14.67 | Y27: =D27*(J27*K27+L27*M27)-N27*2 -> 127.64856 | AH27: =D27*E27 -> 63.82428 | AK27: =D27*4 -> 19.56 | AT27: 1 1/2" C.R. channel @48" O.C. (S5.20 F. BRIDGING AND BRACING): floor(13.052/4)=3 lines
A28: W-25 B - Janitor 112 / Storage 117 (MW06A-MW05). each side: 1 layer 5/8" GWB full height to underside of structure (1/A12.01) | B28: A02.01 -> 1/A12.01 (B, B2) -> S5.20 METAL STUD PROPERTIES (362S137-33 @16") -> S2.20 (B.O.D.) | zone LOW (S2.20 B.O.D. 13'-0 5/8" high end) | C28: [DERIVADO] L = vector faces A02.01 (band 95; tag B@1048,1532) / 18 pt/ft; H = 13.052 = 13'-0 5/8" - 0'-0" | D28: 3.5 | E28: 13.052 | F28: 2 | G28: 16 | H28: 1 | I28: 2 | J28: 13.052 | K28: 1 | L28: 13.052 | M28: 1 | N28: 0 | P28: =(ROUNDUP(D28*12/G28,0)+1+I28)*E28*H28 -> 78.312 | T28: =(D28-0)*H28 -> 3.5 | U28: =D28*H28 -> 3.5 | X28: =D28*3 -> 10.5 | Y28: =D28*(J28*K28+L28*M28)-N28*2 -> 91.364 | AH28: =D28*E28 -> 45.682 | AK28: =D28*4 -> 14 | AT28: 1 1/2" C.R. channel @48" O.C. (S5.20 F. BRIDGING AND BRACING): floor(13.052/4)=3 lines
A29: W-38 B - Drinking fountain alcove - north return. each side: 1 layer 5/8" GWB full height to underside of structure (1/A12.01) | B29: A02.01 -> 1/A12.01 (B, B2) -> S5.20 METAL STUD PROPERTIES (362S137-33 @16") -> S2.20 (B.O.D.) | zone LOW (S2.20 B.O.D. 13'-0 5/8" high end) | C29: [DERIVADO] L = vector faces A02.01 (lw1.2 y1328.64/1335.96) / 18 pt/ft; H = 13.052 = 13'-0 5/8" - 0'-0" | D29: 1.9 | E29: 13.052 | F29: 2 | G29: 16 | H29: 1 | I29: 2 | J29: 13.052 | K29: 1 | L29: 13.052 | M29: 1 | N29: 0 | P29: =(ROUNDUP(D29*12/G29,0)+1+I29)*E29*H29 -> 65.26 | T29: =(D29-0)*H29 -> 1.9 | U29: =D29*H29 -> 1.9 | X29: =D29*3 -> 5.7 | Y29: =D29*(J29*K29+L29*M29)-N29*2 -> 49.5976 | AH29: =D29*E29 -> 24.7988 | AK29: =D29*4 -> 7.6 | AT29: 1 1/2" C.R. channel @48" O.C. (S5.20 F. BRIDGING AND BRACING): floor(13.052/4)=3 lines
A30: W-39 B - Drinking fountain alcove - south return. each side: 1 layer 5/8" GWB full height to underside of structure (1/A12.01) | B30: A02.01 -> 1/A12.01 (B, B2) -> S5.20 METAL STUD PROPERTIES (362S137-33 @16") -> S2.20 (B.O.D.) | zone LOW (S2.20 B.O.D. 13'-0 5/8" high end) | C30: [DERIVADO] L = vector faces A02.01 (lw1.2 y1409.28/1416.6) / 18 pt/ft; H = 13.052 = 13'-0 5/8" - 0'-0" | D30: 1.9 | E30: 13.052 | F30: 2 | G30: 16 | H30: 1 | I30: 2 | J30: 13.052 | K30: 1 | L30: 13.052 | M30: 1 | N30: 0 | P30: =(ROUNDUP(D30*12/G30,0)+1+I30)*E30*H30 -> 65.26 | T30: =(D30-0)*H30 -> 1.9 | U30: =D30*H30 -> 1.9 | X30: =D30*3 -> 5.7 | Y30: =D30*(J30*K30+L30*M30)-N30*2 -> 49.5976 | AH30: =D30*E30 -> 24.7988 | AK30: =D30*4 -> 7.6 | AT30: 1 1/2" C.R. channel @48" O.C. (S5.20 F. BRIDGING AND BRACING): floor(13.052/4)=3 lines
A31: TYPE / SCOPE: B2
A32: W-36 B2 - Break Room 118 east / Work Room 119 west. each side: 1 layer 5/8" GWB full height to underside of structure (1/A12.01) | B32: A02.01 -> 1/A12.01 (B, B2) -> S5.20 METAL STUD PROPERTIES (600S137-33 @16") -> S2.20 (B.O.D.) | zone LOW (S2.20 B.O.D. 13'-0 5/8" high end) | C32: [DERIVADO] L = vector faces A02.01 (band 140-143; tags B2@1603,1493 + B2@1652,1622) / 18 pt/ft; H = 13.052 = 13'-0 5/8" - 0'-0" | D32: 11.74 | E32: 13.052 | F32: 2 | G32: 16 | H32: 1 | I32: 2 | J32: 13.052 | K32: 1 | L32: 13.052 | M32: 1 | N32: 0 | O32: =(ROUNDUP(D32*12/G32,0)+1+I32)*E32*H32 -> 156.624 | T32: =(D32-0)*H32 -> 11.74 | U32: =D32*H32 -> 11.74 | X32: =D32*3 -> 35.22 | Y32: =D32*(J32*K32+L32*M32)-N32*2 -> 306.46096 | AH32: =D32*E32 -> 153.23048 | AK32: =D32*4 -> 46.96 | AT32: 1 1/2" C.R. channel @48" O.C. (S5.20 F. BRIDGING AND BRACING): floor(13.052/4)=3 lines
A33: W-35 B2 - Wellness 115 east / Corridor (door 115). each side: 1 layer 5/8" GWB full height to underside of structure (1/A12.01) | B33: A02.01 -> 1/A12.01 (B, B2) -> S5.20 METAL STUD PROPERTIES (600S137-33 @16") -> S2.20 (B.O.D.) | zone LOW (S2.20 B.O.D. 13'-0 5/8" high end) | C33: [DERIVADO] L = vector faces A02.01 (band 107,108; tag B2@1153,1596) / 18 pt/ft; H = 13.052 = 13'-0 5/8" - 0'-0" | D33: 5.96 | E33: 13.052 | F33: 2 | G33: 16 | H33: 1 | I33: 6 | J33: 13.052 | K33: 1 | L33: 13.052 | M33: 1 | N33: 21 | O33: =(ROUNDUP(D33*12/G33,0)+1+I33)*E33*H33 -> 156.624 | T33: =(D33-3)*H33 -> 2.96 | U33: =D33*H33 -> 5.96 | X33: =D33*3 -> 17.88 | Y33: =D33*(J33*K33+L33*M33)-N33*2 -> 113.57984 | AH33: =D33*E33 -> 77.78992 | AK33: =D33*4 -> 23.84 | AT33: 1 1/2" C.R. channel @48" O.C. (S5.20 F. BRIDGING AND BRACING): floor(13.052/4)=3 lines
A34: W-31 B2 - ATM Room 102 east / Central Zone (door 102). each side: 1 layer 5/8" GWB full height to underside of structure (1/A12.01) | B34: A02.01 -> 1/A12.01 (B, B2) -> S5.20 METAL STUD PROPERTIES (600S137-33 @16") -> S2.20 (B.O.D.) | zone HI (S2.20 B.O.D. 15'-4 1/2") | C34: [DERIVADO] L = vector faces A02.01 (band 103,104; tag B2@1110,745) / 18 pt/ft; H = 15.375 = 15'-4 1/2" - 0'-0" | D34: 5.66 | E34: 15.375 | F34: 2 | G34: 16 | H34: 1 | I34: 6 | J34: 15.375 | K34: 1 | L34: 15.375 | M34: 1 | N34: 28 | O34: =(ROUNDUP(D34*12/G34,0)+1+I34)*E34*H34 -> 184.5 | T34: =(D34-3.5)*H34 -> 2.16 | U34: =D34*H34 -> 5.66 | X34: =D34*3 -> 16.98 | Y34: =D34*(J34*K34+L34*M34)-N34*2 -> 118.045 | AH34: =D34*E34 -> 87.0225 | AK34: =D34*4 -> 22.64 | AT34: 1 1/2" C.R. channel @48" O.C. (S5.20 F. BRIDGING AND BRACING): floor(15.375/4)=3 lines
A35: W-32 B2 - Women's RR 114 east / Corridor - north of fountain alcove. each side: 1 layer 5/8" GWB full height to underside of structure (1/A12.01) | B35: A02.01 -> 1/A12.01 (B, B2) -> S5.20 METAL STUD PROPERTIES (600S137-33 @16") -> S2.20 (B.O.D.) | zone LOW (S2.20 B.O.D. 13'-0 5/8" high end) | C35: [DERIVADO] L = vector faces A02.01 (lw1.2 x1123.08/1133.88; tag B2@1146,1313) / 18 pt/ft; H = 13.052 = 13'-0 5/8" - 0'-0" | D35: 1.82 | E35: 13.052 | F35: 2 | G35: 16 | H35: 1 | I35: 2 | J35: 13.052 | K35: 1 | L35: 13.052 | M35: 1 | N35: 0 | O35: =(ROUNDUP(D35*12/G35,0)+1+I35)*E35*H35 -> 65.26 | T35: =(D35-0)*H35 -> 1.82 | U35: =D35*H35 -> 1.82 | X35: =D35*3 -> 5.46 | Y35: =D35*(J35*K35+L35*M35)-N35*2 -> 47.50928 | AH35: =D35*E35 -> 23.75464 | AK35: =D35*4 -> 7.28 | AT35: 1 1/2" C.R. channel @48" O.C. (S5.20 F. BRIDGING AND BRACING): floor(13.052/4)=3 lines
A36: W-33 B2 - Men's RR 113 east / Corridor - south of fountain alcove. each side: 1 layer 5/8" GWB full height to underside of structure (1/A12.01) | B36: A02.01 -> 1/A12.01 (B, B2) -> S5.20 METAL STUD PROPERTIES (600S137-33 @16") -> S2.20 (B.O.D.) | zone LOW (S2.20 B.O.D. 13'-0 5/8" high end) | C36: [DERIVADO] L = vector faces A02.01 (band 105; tag B2@1155,1438) / 18 pt/ft; H = 13.052 = 13'-0 5/8" - 0'-0" | D36: 1.8 | E36: 13.052 | F36: 2 | G36: 16 | H36: 1 | I36: 2 | J36: 13.052 | K36: 1 | L36: 13.052 | M36: 1 | N36: 0 | O36: =(ROUNDUP(D36*12/G36,0)+1+I36)*E36*H36 -> 65.26 | T36: =(D36-0)*H36 -> 1.8 | U36: =D36*H36 -> 1.8 | X36: =D36*3 -> 5.4 | Y36: =D36*(J36*K36+L36*M36)-N36*2 -> 46.9872 | AH36: =D36*E36 -> 23.4936 | AK36: =D36*4 -> 7.2 | AT36: 1 1/2" C.R. channel @48" O.C. (S5.20 F. BRIDGING AND BRACING): floor(13.052/4)=3 lines
A37: W-34 B2 - Men's RR 113 / Corridor - south of door 113. each side: 1 layer 5/8" GWB full height to underside of structure (1/A12.01) | B37: A02.01 -> 1/A12.01 (B, B2) -> S5.20 METAL STUD PROPERTIES (600S137-33 @16") -> S2.20 (B.O.D.) | zone LOW (S2.20 B.O.D. 13'-0 5/8" high end) | C37: [DERIVADO] L = vector faces A02.01 (lw1.2 x1123.08/1133.88 y1501.68-1517.52) / 18 pt/ft; H = 13.052 = 13'-0 5/8" - 0'-0" | D37: 0.88 | E37: 13.052 | F37: 2 | G37: 16 | H37: 1 | I37: 2 | J37: 13.052 | K37: 1 | L37: 13.052 | M37: 1 | N37: 0 | O37: =(ROUNDUP(D37*12/G37,0)+1+I37)*E37*H37 -> 52.208 | T37: =(D37-0)*H37 -> 0.88 | U37: =D37*H37 -> 0.88 | X37: =D37*3 -> 2.64 | Y37: =D37*(J37*K37+L37*M37)-N37*2 -> 22.97152 | AH37: =D37*E37 -> 11.48576 | AK37: =D37*4 -> 3.52 | AT37: 1 1/2" C.R. channel @48" O.C. (S5.20 F. BRIDGING AND BRACING): floor(13.052/4)=3 lines
A38: TYPE / SCOPE: B2K
A39: W-41 B2K - Cash Window 116 north-west stub (teller line). teller side: 3/8" UL752 fiberglass to 8'-0" + 5/8" GWB | other side 5/8" GWB, full height (derived from 1/A12.01 + 4/A12.01) | B39: A02.01 (tag B2K) -> 1/A12.01 (B2) + 4/A12.01 (K = 3/8" UL752 fiberglass) -> S2.20 (B.O.D.) [type not in schedule, derived] | zone HI (S2.20 B.O.D. 15'-4 1/2") | C39: [DERIVADO] L = vector faces A02.01 (band 41 (7.67 in); tag B2K@1637,1137) / 18 pt/ft; H = 15.375 = 15'-4 1/2" - 0'-0" | D39: 1.26 | E39: 15.375 | F39: 2 | G39: 16 | H39: 1 | I39: 2 | J39: 15.375 | K39: 1 | L39: 15.375 | M39: 1 | N39: 0 | O39: =(ROUNDUP(D39*12/G39,0)+1+I39)*E39*H39 -> 61.5 | T39: =(D39-0)*H39 -> 1.26 | U39: =D39*H39 -> 1.26 | X39: =D39*3 -> 3.78 | Y39: =D39*(J39*K39+L39*M39)-N39*2 -> 38.745 | AE39: =D39*8 -> 10.08 | AH39: =D39*E39 -> 19.3725 | AK39: =D39*4 -> 5.04 | AT39: 1 1/2" C.R. channel @48" O.C. (S5.20 F. BRIDGING AND BRACING): floor(15.375/4)=3 lines
A40: TYPE / SCOPE: A1K
A41: W-52 A1K - Cash Window 116 south / FCAM. teller side: 5/8" GWB over 3/8" UL752 fiberglass to 8'-0", 3/8" GWB 8'-0" to structure | customer side: 5/8" GWB to structure (4/A12.01) | B41: A02.01 -> 4/A12.01 (A1K & A5K, WALL CONSTRUCTION SHALL INCLUDE: 14 GA @24") -> A12.08 (CSR line) -> S2.20 | zone LOW (S2.20 B.O.D. 13'-0 5/8" high end) | C41: [DERIVADO] L = vector faces A02.01 (band 51 (5.27 in); tags A1K@1663,1331 + A1K@1644,1335) / 18 pt/ft; H = 13.052 = 13'-0 5/8" - 0'-0" | D41: 2.62 | E41: 13.052 | F41: 2 | G41: 24 | H41: 1 | I41: 2 | J41: 13.052 | K41: 1 | L41: 13.052 | M41: 1 | N41: 0 | P41: =(ROUNDUP(D41*12/G41,0)+1+I41)*E41*H41 -> 65.26 | T41: =(D41-0)*H41 -> 2.62 | U41: =D41*H41 -> 2.62 | X41: =D41*3 -> 7.86 | Y41: =D41*(8*1+E41*1)-N41*2 -> 55.15624 | AA41: =D41*(E41-8) -> 13.23624 | AE41: =D41*8 -> 20.96 | AH41: =D41*E41 -> 34.19624 | AJ41: =D41*2 -> 5.24 | AK41: =D41*2*H41 -> 5.24 | AT41: 1 1/2" C.R. channel @48" O.C. (S5.20 F. BRIDGING AND BRACING): floor(13.052/4)=3 lines
...

Sheet Materials
A1: Material (family) | B1: Net | C1: Waste % | D1: Waste | E1: Purchase | F1: Unit | G1: Source column
A2: 6" Metal Stud (LF) | B2: =Takeoff!O146 -> 5321.172 | C2: =Takeoff!O147 -> 0.15 | D2: =Takeoff!O148 -> 798.1758 | E2: =Takeoff!O149 -> 6119.3478 | F2: LF | G2: Takeoff column O
A3: 3-5/8" Metal Stud (LF) | B3: =Takeoff!P146 -> 6154.9452 | C3: =Takeoff!P147 -> 0.15 | D3: =Takeoff!P148 -> 923.24179 | E3: =Takeoff!P149 -> 7078.187 | F3: LF | G3: Takeoff column P
A4: 1-5/8" Metal Stud (LF) | B4: =Takeoff!Q146 -> 4071.75 | C4: =Takeoff!Q147 -> 0.15 | D4: =Takeoff!Q148 -> 610.7625 | E4: =Takeoff!Q149 -> 4682.5125 | F4: LF | G4: Takeoff column Q
A5: 2-1/2" Metal Stud (LF) | B5: =Takeoff!R146 -> 18 | C5: =Takeoff!R147 -> 0.15 | D5: =Takeoff!R148 -> 2.7 | E5: =Takeoff!R149 -> 20.7 | F5: LF | G5: Takeoff column R
A6: 6" parapet stud (LF) | B6: =Takeoff!S146 -> 1036.433 | C6: =Takeoff!S147 -> 0.15 | D6: =Takeoff!S148 -> 155.46495 | E6: =Takeoff!S149 -> 1191.898 | F6: LF | G6: Takeoff column S
A7: Bottom track (LF) | B7: =Takeoff!T146 -> 1090.2 | C7: =Takeoff!T147 -> 0.15 | D7: =Takeoff!T148 -> 163.53 | E7: =Takeoff!T149 -> 1253.73 | F7: LF | G7: Takeoff column T
A8: Top / deflection track (LF) | B8: =Takeoff!U146 -> 1188.09 | C8: =Takeoff!U147 -> 0.15 | D8: =Takeoff!U148 -> 178.2135 | E8: =Takeoff!U149 -> 1366.3035 | F8: LF | G8: Takeoff column U
A9: Header / box beam (LF) | B9: =Takeoff!V146 -> 198.03 | C9: =Takeoff!V147 -> 0.15 | D9: =Takeoff!V148 -> 29.7045 | E9: =Takeoff!V149 -> 227.7345 | F9: LF | G9: Takeoff column V
A10: Sill track (LF) | B10: =Takeoff!W146 -> 58 | C10: =Takeoff!W147 -> 0.15 | D10: =Takeoff!W148 -> 8.7 | E10: =Takeoff!W149 -> 66.7 | F10: LF | G10: Takeoff column W
A11: Bracing C.R. channel 1-1/2" (LF) | B11: =Takeoff!X146 -> 1804.11 | C11: =Takeoff!X147 -> 0.15 | D11: =Takeoff!X148 -> 270.6165 | E11: =Takeoff!X149 -> 2074.7265 | F11: LF | G11: Takeoff column X
A12: 5/8" Gyp Board regular (SF) | B12: =Takeoff!Y146 -> 17207.505 | C12: =Takeoff!Y147 -> 0.06 | D12: =Takeoff!Y148 -> 1032.4503 | E12: =Takeoff!Y149 -> 18239.956 | F12: SF | G12: Takeoff column Y
A13: 5/8" Gyp MOISTURE RESISTANT (SF) | B13: =Takeoff!Z146 -> 261.82312 | C13: =Takeoff!Z147 -> 0.06 | D13: =Takeoff!Z148 -> 15.709387 | E13: =Takeoff!Z149 -> 277.53251 | F13: SF | G13: Takeoff column Z
A14: 3/8" Gyp Board (SF) | B14: =Takeoff!AA146 -> 38.05031 | C14: =Takeoff!AA147 -> 0.06 | D14: =Takeoff!AA148 -> 2.2830186 | E14: =Takeoff!AA149 -> 40.333329 | F14: SF | G14: Takeoff column AA
A15: 5/8" EXTERIOR gyp sheathing (SF) | B15: =Takeoff!AB146 -> 1107.3923 | C15: =Takeoff!AB147 -> 0.06 | D15: =Takeoff!AB148 -> 66.44354 | E15: =Takeoff!AB149 -> 1173.8359 | F15: SF | G15: Takeoff column AB
A16: 5/8" glass mat sheathing (SF) | B16: =Takeoff!AC146 -> 0 | C16: =Takeoff!AC147 -> 0.06 | D16: =Takeoff!AC148 -> 0 | E16: =Takeoff!AC149 -> 0 | F16: SF | G16: Takeoff column AC
A17: FRT plywood (SF) | B17: =Takeoff!AD146 -> 7346.0932 | C17: =Takeoff!AD147 -> 0.06 | D17: =Takeoff!AD148 -> 440.76559 | E17: =Takeoff!AD149 -> 7786.8588 | F17: SF | G17: Takeoff column AD
A18: Ballistic panel 3/8" UL752 fiberglass (SF) | B18: =Takeoff!AE146 -> 60.88 | C18: =Takeoff!AE147 -> 0.06 | D18: =Takeoff!AE148 -> 3.6528 | E18: =Takeoff!AE149 -> 64.5328 | F18: SF | G18: Takeoff column AE
A19: FRP-1 (SF) | B19: =Takeoff!AF146 -> 334.2 | C19: =Takeoff!AF147 -> 0.06 | D19: =Takeoff!AF148 -> 20.052 | E19: =Takeoff!AF149 -> 354.252 | F19: SF | G19: Takeoff column AF
A20: Durock / cement board (SF) | B20: =Takeoff!AG146 -> 0 | C20: =Takeoff!AG147 -> 0.06 | D20: =Takeoff!AG148 -> 0 | E20: =Takeoff!AG149 -> 0 | F20: SF | G20: Takeoff column AG
A21: Batt insulation (SF) | B21: =Takeoff!AH146 -> 5289.7697 | C21: =Takeoff!AH147 -> 0 | D21: =Takeoff!AH148 -> 0 | E21: =Takeoff!AH149 -> 5289.7697 | F21: SF | G21: Takeoff column AH
A22: FRT blocking (LF) | B22: =Takeoff!AI146 -> 722.25 | C22: =Takeoff!AI147 -> 0 | D22: =Takeoff!AI148 -> 0 | E22: =Takeoff!AI149 -> 722.25 | F22: LF | G22: Takeoff column AI
A23: Metal trim - corner bead / casing / shadow molding (LF) | B23: =Takeoff!AJ146 -> 1332.82 | C23: =Takeoff!AJ147 -> 0.15 | D23: =Takeoff!AJ148 -> 199.923 | E23: =Takeoff!AJ149 -> 1532.743 | F23: LF | G23: Takeoff column AJ
A24: Acoustical sealant (LF) | B24: =Takeoff!AK146 -> 1190.56 | C24: =Takeoff!AK147 -> 0 | D24: =Takeoff!AK148 -> 0 | E24: =Takeoff!AK149 -> 1190.56 | F24: LF | G24: Takeoff column AK
A25: Furring channel 7/8" (LF) | B25: =Takeoff!AL146 -> 706.2 | C25: =Takeoff!AL147 -> 0.15 | D25: =Takeoff!AL148 -> 105.93 | E25: =Takeoff!AL149 -> 812.13 | F25: LF | G25: Takeoff column AL
A26: Carrying channel 1-1/2" (LF) | B26: =Takeoff!AM146 -> 235.4 | C26: =Takeoff!AM147 -> 0.15 | D26: =Takeoff!AM148 -> 35.31 | E26: =Takeoff!AM149 -> 270.71 | F26: LF | G26: Takeoff column AM
A27: Hanger wire 12 GA (LF) | B27: =Takeoff!AN146 -> 282.27 | C27: =Takeoff!AN147 -> 0.15 | D27: =Takeoff!AN148 -> 42.3405 | E27: =Takeoff!AN149 -> 324.6105 | F27: LF | G27: Takeoff column AN
A28: Track de ceilings / soffits (LF) | B28: =Takeoff!AO146 -> 554.5 | C28: =Takeoff!AO147 -> 0.15 | D28: =Takeoff!AO148 -> 83.175 | E28: =Takeoff!AO149 -> 637.675 | F28: LF | G28: Takeoff column AO
A29: Framed openings MEP / recessed (EA) | B29: =Takeoff!AP146 -> 9 | C29: =Takeoff!AP147 -> 0 | D29: =Takeoff!AP148 -> 0 | E29: =Takeoff!AP149 -> 9 | F29: EA | G29: Takeoff column AP
A30: Level 5 finish (SF) | B30: =Takeoff!AQ146 -> 914.6 | C30: =Takeoff!AQ147 -> 0 | D30: =Takeoff!AQ148 -> 0 | E30: =Takeoff!AQ149 -> 914.6 | F30: SF | G30: Takeoff column AQ

Sheet Partition Types
A1: Type | B1: Detail | C1: Stud | D1: Spacing / gauge | E1: Side 1 (layers / board / height) | F1: Side 2 (layers / board / height) | G1: Top track condition | H1: Insulation | I1: Status
A2: A1 | B2: 3/A12.01 | C2: 3 5/8" 362S137-33 (S5.20) | D2: 16" O.C., 33 mil (20 ga) | E2: 1 layer 5/8" GWB to ceiling + 6" | F2: 1 layer 5/8" GWB to ceiling + 6" | G2: CONTINUOUS SLIP TRACK to underside of structure (3/A12.01); slip track profile not designated in S5.20 -> RFI-18 | H2: Batt (YES) | I2: [CONFIRMADO] 3/A12.01 table: 3 5/8", 5/8", 4 7/8"
A3: A5 | B3: 3/A12.01 | C3: 6" 600S137-33 | D3: 16" O.C. | E3: 1 layer 5/8" GWB to ceiling + 6" | F3: same | G3: CONTINUOUS SLIP TRACK | H3: Batt | I3: [CONFIRMADO] 3/A12.01: 6", 5/8", 7 1/4"
A4: B | B4: 1/A12.01 | C4: 3 5/8" | D4: 16" O.C. | E4: 1 layer 5/8" GWB full height to structure | F4: same | G4: CONTINUOUS SLIP TRACK | H4: Batt | I4: [CONFIRMADO] 1/A12.01: 3 5/8", 4 7/8"
A5: B2 | B5: 1/A12.01 | C5: 6" | D5: 16" O.C. | E5: 1 layer 5/8" GWB full height | F5: same | G5: CONTINUOUS SLIP TRACK | H5: Batt | I5: [CONFIRMADO] 1/A12.01: 6", 7 1/4"
A6: B2K | B6: 1/A12.01 + 4/A12.01 (derived, not in schedule) | C6: 6" | D6: 16" O.C. | E6: 3/8" UL752 fiberglass to 8'-0" + 5/8" GWB full height | F6: 5/8" GWB full height | G6: slip track | H6: Batt | I6: [DERIVADO] B2 + K (A5K delta 7 5/8" - 7 1/4" = 3/8"); measured 7.67" on A02.01 -> RFI-02
A7: A1K | B7: 4/A12.01 | C7: 3 5/8" 14 GA | D7: 24" O.C. MAX (WALL CONSTRUCTION SHALL INCLUDE) | E7: teller side: 5/8" GWB over 3/8" UL752 LEVEL-2 fiberglass to 8'-0"; 3/8" GWB 8'-0" to structure | F7: customer side: 5/8" GWB | G7: CONTINUOUS SLIP TRACK; PAF @2'-0" O.C. alternating, within 3" of track ends | H7: Batt | I7: [CONFIRMADO] 4/A12.01 note text
A8: C1 | B8: 6/A12.01 | C8: 3 5/8" | D8: 16" O.C. | E8: 1 layer 5/8" GWB (furred face) | F8: -- (block / chase side) | G8: to structure | H8: -- | I8: [CONFIRMADO] 6/A12.01
A9: F | B9: 12/A12.01 | C9: 3 5/8" | D9: 16" O.C., span floor to deck, brace as required | E9: ATM lobby: 3/4" FRT plywood to deck + 5/8" GWB | F9: ATM room: 5/8" GWB to ceiling + 6" | G9: track to deck | H9: Batt | I9: [CONFIRMADO] 12/A12.01
A10: G | B10: 5/A12.01 | C10: double row 1 5/8" + Soundguard isolator (Marinoware) | D10: 16" O.C. each row | E10: 2 layers 5/8" GWB to structure | F10: 2 layers 5/8" GWB to structure | G10: METAL STUD TRACK | H10: Batt | I10: [CONFIRMADO] 5/A12.01: 1 5/8", 6 1/8"
A11: G1 | B11: 5/A12.01 | C11: double row 1 5/8" + isolator | D11: 16" O.C. | E11: 2 layers 5/8" GWB | F11: 2 layers 5/8" GWB | G11: METAL STUD TRACK | H11: Batt | I11: [CONFIRMADO] 5/A12.01: 8"
A12: A6 / A8 / A5K | B12: 2/A12.01, 4/A12.01 | C12: -- | D12: -- | E12: -- | F12: -- | G12: -- | H12: -- | I12: NOT ON PLAN: no tag found on A02.01 (census 51 boxed tags) -> not quantified
A13: EXT 6" CFMF | B13: A09.21-A09.23, A09.26, S5.20 | C13: 6" 600S137-33 | D13: 16" O.C.; bottom 600T125-33; top 600T200-97; 1 1/2" C.R. channel @48" | E13: interior: 5/8" GWB to deck | F13: exterior: 5/8" FRT plywood bonded to 2 1/2" polyiso; parapet back 5/8" exterior gypsum sheathing | G13: top track 600T200-97 at T/STUD | H13: spray foam by others | I13: [CONFIRMADO] S5.20 METAL STUD PROPERTIES

Sheet RFIs
A1: RFI | B1: Question / condition | C1: Delta of each alternative
A2: RFI-01 | B2: Exterior elevation titles transposed: A09.01 "SOUTH ELEVATION" shows the plan-north facade (entrance, grids 8->1) and A09.02 "NORTH ELEVATION" shows plan-south (door 123). A11.04 office elevations titled SOUTH show WC-18 which A05.01 places on the plan-north wall. Take-off follows plan orientation (north arrow A02.01). | C2: No quantity change; risk of other trades mis-reading.
A3: RFI-02 | B3: Tag B2K (Cash Window NW stub) has no row in the 1/A12.01 schedule. Carried as B2 + 3/8" UL752 fiberglass panel (A5K logic), measured 7.67" in plan. | C3: If plain B2: - 10.1 SF ballistic panel.
A4: RFI-03 | B4: LOW roof zone (grids A-B) deck slopes 13'-0 5/8" to 12'-6 3/8" (S2.20). Studs carried at high end 13.052 ft. | C4: Using low end: - 126.6 LF of studs (and matching board on full-height faces).
A5: RFI-04 | B5: Office bulkheads 8,9/A12.01: "METAL STUD" double row with isolator, size not given. Carried 1 5/8" (G family). | C5: If 3 5/8": same LF moves from 1-5/8" to 3-5/8" column (535.5 LF).
A6: RFI-05 | B6: C1 tags at the 4 vestibule column/pier boxes: 6/A12.01 shows C1 as block partition furring; 1,2/A09.25 show storefront pier (3 5/8" framing, 3/4" FRT plywood, 5/8" GWB). Carried as piers (PIER row). | C6: --
A7: RFI-06 | B7: High parapet block (T.O. PARAPET 2 20'-0") extent: carried over vestibule/ATM block with east (30.36 LF) and south (17.68 LF) returns 4.29 ft high above main roof. | C7: Returns = 206 SF FRT plywood + 206 SF ext. gyp sheathing + 262 LF parapet studs.
A8: RFI-07 | B8: Drinking fountain alcove (Corridor 111) drawn 4 7/8" while adjacent tags are B2 (7 1/4"). Carried as B (3 5/8"). | C8: If B2: 8.69 LF moves from 3-5/8" to 6" studs.
A9: RFI-08 | B9: GWB ceiling suspension not specified (only "12 GAUGE HANGER WIRE" 3/A09.33). Carried 7/8" furring channel @16" on 1 1/2" CRC @48", 12 GA hanger wire @48"x48", perimeter track (ASTM C754). | C9: Alt: drywall grid (heavy duty main runner + cross tee) - removes furring/CRC.
A10: RFI-09 | B10: Blocking allowances: wall stops on all 14 wood doors (confirm per hardware group), lockers keynote 5 (location not shown), 3/4" fire rated plywood backboards (extent), equipment note C. | C10: Allowance lines BLK-WS 28 LF, BLK-LKR 12 LF, BB-NER 128 SF, BLK-EQ 40 LF.
A11: RFI-10 | B11: MEP crossings at full-height partitions and exterior walls not cross-checked geometrically (M01.01/P01.01 not registered). No framed duct openings carried. | C11: To be priced after MEP review.
A12: RFI-11 | B12: Canopy soffit sheathing: 3,7/A09.26 = 5/8" ext. grade FRT plywood; 4,5/A09.33 = "5/8" EXTERIOR SHEATHING". Carried FRT plywood. | C12: Alt 5/8" exterior gypsum sheathing on 1,443.9 SF.
... A19: RFI-18 | B19: Continuous slip track (A1, A5, B, B2, A1K, F) has no profile designation; S5.20 lists 600T200-97 top track for exterior walls only. Carried interior top track as slip track of the same stud size, 2" leg. | C19: Price delta slip track vs standard track.

Sheet Clarifications
A1: # | B1: Clarifications & Exclusions
A2: 1 | B2: Ground-up new building (A00.00: GROUND UP - NEW FINANCIAL CENTER, Type II-B, Group B, 4,260 SF). No demolition / existing walls: Demolition column = 0.
A3: 2 | B3: Excluded (other divisions / vendors): aluminum storefront & entrance doors (Div 08), Allsteel DFC-1A office fronts (bank vendor, A02.01 note E), coiling grille (vendor), airlock all-glass 24 HR vestibule (A12.10), ACM / EPS-3 / EPS-5 panels and coping (Div 07), PT-3/PT-4 stucco (Div 09 24), spray foam insulation, roofing, ACT ceilings and grid (Div 09 51), millwork, toilet partitions & accessories (Div 10), light fixtures (Div 26), signage.
A4: 3 | B4: Included: interior framing & GWB per partition types, office front bulkheads (8,9/A12.01), coiling grille head, CSR soffit, GWB ceilings with suspension, exterior 6" CFMF incl. parapets, FRT plywood/polyiso sheathing (RFI-14), parapet back exterior gypsum sheathing, canopy soffit & fascia framing + FRT plywood, canopy column wraps, storefront piers, FRT blocking, framed openings, FRP WC-3 (A00.40 "GC/GC"), batt insulation, acoustical sealant, metal trim.
A5: 4 | B5: Finish level: Level 4 assumed everywhere except Level 5 at WC-18, WC-20, WC-22 (A00.40, A05.01 keynotes 9,10).
A6: 5 | B6: Control joints: none labeled for interior GWB; stucco CJ by others (A09.31) - excluded.
A7: 6 | B7: No fire-rated assemblies: every type in 1-6/A12.01 lists FIRE RATING "--"; no fire tape carried.
A8: 7 | B8: Trade criteria not drawn: wall stop blocking 2'-0" per stop; jambs 2 studs per side (S5.20 DBL JAMB); waste metal 15%, board 6% in own cells.
A9: 8 | B9: Heights: north (HI) zone deck 15'-4 1/2", south (LOW) zone 13'-0 5/8" high end (S2.20); T/STUD 17'-5" (LP) and 19'-8" (HP) (A09.21).

Sheet Revisar en la manana
A1: # | B1: Punto (los términos del trade quedan en inglés) | C1: Referencia
A2: 1 | B2: Barrido por tag: 51 tags con caja real en A02.01 (A1 10, G 9, C1 8, B 7, B2 6, A5 4, A1K 3, G1 2, F 1, B2K 1) -> 54 walls interiores numerados W-01..W-97. Revisar la lista y los planos marcados por tipo (carpeta Planos marcados). | C2: Punto de revisión (pausa del barrido)
A3: 2 | B3: Walls sin tag (rojo en los planos): W-34, W-37, W-38, W-39 (alcove de bebederos), W-87 (stub office 1), W-97 (stub office 6), W-13B (split en grid B). Confirmar tipo. | C3: RFI-07
A4: 3 | B4: Elevaciones N/S con títulos invertidos (A09.01/A09.02 y A11.04). Se trabajó con la orientación de la planta. | C4: RFI-01
A5: 4 | B5: B2K no existe en el schedule: se derivó como B2 + 3/8" fiberglass (delta 10.1 SF ballistic panel). | C5: RFI-02
A6: 5 | B6: Zona LOW con pendiente: se usó el extremo alto 13'-0 5/8" (delta -126.6 LF stud si se usa el bajo). | C6: RFI-03
A7: 6 | B7: Bulkheads de office front: stud doble 1 5/8" supuesto (detalle no da medida). | C7: RFI-04
A8: 7 | B8: Suspensión de GWB ceilings no especificada: se usó furring channel + carrying channel + hanger wire. | C8: RFI-08
A9: 8 | B9: Cruce MEP no hecho por geometría: sin framed openings de ductos. | C9: RFI-10
A10: 9 | B10: Soffit del canopy: FRT plywood vs exterior sheathing (delta 1,443.9 SF). | C10: RFI-11
A11: 10 | B11: Allowances de blocking (wall stops, lockers, backboards, equipo). | C11: RFI-09
A12: 11 | B12: Day 1 ATM / Future ATM: aberturas no deducidas. | C12: RFI-13
... A14: 13 | B14: Herramienta alcances.py compuerta depende de eval_takeoff.py (calificador, prohibido bajarlo): la compuerta no pudo correr. Ver resumen. | C14: Falla de herramienta

Sheet Sheet map
A1: page_index (0-based) | B1: Sheet (title block, largest text)
A2: 0 | B2: SIN ROTULO
A3: 1 | B3: A00.00
A4: 2 | B4: C1.1
A5: 3 | B5: SIN ROTULO
A6: 4 | B6: SIN ROTULO
A7: 5 | B7: SIN ROTULO
A8: 6 | B8: SIN ROTULO
A9: 7 | B9: SIN ROTULO
A10: 8 | B10: SIN ROTULO
A11: 9 | B11: SIN ROTULO
A12: 10 | B12: SIN ROTULO
A13: 11 | B13: C7.2
... A95: 93 | B95: P03.01
