Workbook

Sheet Inputs
A1: Bank of America - Broomfield, CO (CO1-111) | METAL FRAMING & DRYWALL TAKEOFF
A2: Bid set: 2025.08.26_CO1-111_Broomfield_PERMIT SET_BID SET.pdf · 2026-10-15 · Edit ONLY the yellow cells.
A3: PARAMETER | B3: VALUE | C3: NOTE / SOURCE
A4: Waste - ALL METAL, any type | B4: 0.15 | C4: Estimator standing rule.
A5: Waste - EVERYTHING THAT IS NOT METAL | B5: 0.06 | C5: Same figure as board.
A6: Board sheet width (ft) | B6: 4
A7: Board sheet length (ft) | B7: 12
A8: SF per board sheet | B8: =B6*B7 -> 48 | C8: Width x length.
A9: Stud stock length (ft) | B9: 20
A10: Track stock length (ft) | B10: 10

Sheet Partition Takeoff
A1: ORGANIZED PARTITION TAKEOFF - Bank of America - Broomfield, CO (CO1-111)
A2: Grouped by partition type. Every row cites its DETAIL/SHEET and its status.
A4: Partition / Scope | B4: Wall # | C4: Length (LF) | D4: Height (FT) | E4: Layers | F4: Stud Size | G4: Stud O.C. (in) | H4: Board (SF) | I4: Location | J4: Source (DETAIL/SHEET) | K4: Status
A5: TYPE A1
A6: A1 #1 - Calling Cubes 122 north wall (incl. MW01 niche back) || 122 Calling Cubes: 1 x 5/8" GB to 9.0 ft | 104 Waiting (GB island): 1 x 5/8" GB to 11.5 ft || sello d0071506edff939d | B6: 1 | C6: 16.42 | D6: 15.375 | E6: 2 | F6: 3-5/8" | G6: 16 | H6: 336.61 | I6: Calling Cubes 122 north wall (incl. MW01 niche back) || 122 Calling Cubes: 1 x 5/8" GB to 9.0 ft | 104 Waiting (GB island): 1 x 5/8" GB to 11.5 ft || sello d0071506edff939d | J6: A02.01 -> 3/A12.01 -> 7/S5.20 -> 1/S5.20 | K6: [DERIVADO]
A7: A1 #2 - MW01 niche east wall || 122 Calling Cubes: 1 x 5/8" GB to 9.0 ft | 103 Central Zone: 1 x 5/8" GB to 12.0 ft || sello c8b927050a8b0ac4 | B7: 2 | C7: 3.53 | D7: 15.375 | E7: 2 | F7: 3-5/8" | G7: 16 | H7: 74.2 | I7: MW01 niche east wall || 122 Calling Cubes: 1 x 5/8" GB to 9.0 ft | 103 Central Zone: 1 x 5/8" GB to 12.0 ft || sello c8b927050a8b0ac4 | J7: A02.01 -> 3/A12.01 -> 7/S5.20 -> 1/S5.20 | K7: [DERIVADO]
A8: A1 #3 - MW01 niche south wall at FEC-1 || 122 Calling Cubes: 1 x 5/8" GB to 9.0 ft | 103 Central Zone: 1 x 5/8" GB to 12.0 ft || sello 5cd642dbe1dd5c6e | B8: 3 | C8: 3.03 | D8: 15.375 | E8: 2 | F8: 3-5/8" | G8: 16 | H8: 63.7 | I8: MW01 niche south wall at FEC-1 || 122 Calling Cubes: 1 x 5/8" GB to 9.0 ft | 103 Central Zone: 1 x 5/8" GB to 12.0 ft || sello 5cd642dbe1dd5c6e | J8: A02.01 -> 3/A12.01 -> 7/S5.20 -> 1/S5.20 | K8: [DERIVADO]
A9: A1 #4 - Corridor 111 stub east of Restroom 114 door || 103 Central Zone: 1 x 5/8" GB to 12.0 ft | 111 Corridor: 1 x 5/8" GB to 9.0 ft || sello 7d2691b56bc90b22 | B9: 4 | C9: 1.47 | D9: 15.375 | E9: 2 | F9: 3-5/8" | G9: 16 | H9: 30.94 | I9: Corridor 111 stub east of Restroom 114 door || 103 Central Zone: 1 x 5/8" GB to 12.0 ft | 111 Corridor: 1 x 5/8" GB to 9.0 ft || sello 7d2691b56bc90b22 | J9: A02.01 -> 3/A12.01 -> 7/S5.20 -> 1/S5.20 | K9: [DERIVADO]
A10: A1 #5 - Calling Cubes 122 south wall / Corridor 111 / Break Room 118 || 122 Calling Cubes: 1 x 5/8" GB to 9.0 ft | 118 Break Room: 1 x 5/8" GB to 9.0 ft || sello ac8dc76f483eac60 | B10: 5 | C10: 15.62 | D10: 13.052 | E10: 2 | F10: 3-5/8" | G10: 16 | H10: 281.16 | I10: Calling Cubes 122 south wall / Corridor 111 / Break Room 118 || 122 Calling Cubes: 1 x 5/8" GB to 9.0 ft | 118 Break Room: 1 x 5/8" GB to 9.0 ft || sello ac8dc76f483eac60 | J10: A02.01 -> 3/A12.01 -> 7/S5.20 -> 1/S5.20 | K10: [DERIVADO]
A11: A1 #6 - Break Room 118 north jog at door 118A (vertical) || 118 Break Room: 1 x 5/8" GB to 9.0 ft | Corridor at 116/118A (ACT-4 9 ft): 1 x 5/8" GB to 9.5 ft || sello 4cedc9b9c55fbf77 | B11: 6 | C11: 2.14 | D11: 13.052 | E11: 2 | F11: 3-5/8" | G11: 16 | H11: 39.59 | I11: Break Room 118 north jog at door 118A (vertical) || 118 Break Room: 1 x 5/8" GB to 9.0 ft | Corridor at 116/118A (ACT-4 9 ft): 1 x 5/8" GB to 9.5 ft || sello 4cedc9b9c55fbf77 | J11: A02.01 -> 3/A12.01 -> 7/S5.20 -> 1/S5.20 | K11: [DERIVADO]
A12: A1 #7 - Break Room 118 north jog at door 118A (horizontal) || 118 Break Room: 1 x 5/8" GB to 9.0 ft | Corridor at 116/118A (ACT-4 9 ft): 1 x 5/8" GB to 9.5 ft || sello 1d1fa2607700450e | B12: 7 | C12: 1.3 | D12: 13.052 | E12: 2 | F12: 3-5/8" | G12: 16 | H12: 24.05 | I12: Break Room 118 north jog at door 118A (horizontal) || 118 Break Room: 1 x 5/8" GB to 9.0 ft | Corridor at 116/118A (ACT-4 9 ft): 1 x 5/8" GB to 9.5 ft || sello 1d1fa2607700450e | J12: A02.01 -> 3/A12.01 -> 7/S5.20 -> 1/S5.20 | K12: [DERIVADO]
A13: A1 #8 - Corridor 111 east = Electrical 120 / NER 121 west wall || 111 Corridor: 1 x 5/8" GB to 9.0 ft | 120 Electrical: 1 x 5/8" GB to 13.05 ft || sello b822229dc2452645 | B13: 8 | C13: 17.06 | D13: 13.052 | E13: 2 | F13: 3-5/8" | G13: 16 | H13: 376.21 | I13: Corridor 111 east = Electrical 120 / NER 121 west wall || 111 Corridor: 1 x 5/8" GB to 9.0 ft | 120 Electrical: 1 x 5/8" GB to 13.05 ft || sello b822229dc2452645 | J13: A02.01 -> 3/A12.01 -> 7/S5.20 -> 1/S5.20 | K13: [DERIVADO]
A14: A1 #9 - Work Room 119 north wall || 119 Work Room: 1 x 5/8" GB to 9.0 ft | Corridor at 116/118A (ACT-4 9 ft): 1 x 5/8" GB to 9.5 ft || sello 36e13db3828c15d3 | B14: 9 | C14: 8.17 | D14: 13.052 | E14: 2 | F14: 3-5/8" | G14: 16 | H14: 151.09 | I14: Work Room 119 north wall || 119 Work Room: 1 x 5/8" GB to 9.0 ft | Corridor at 116/118A (ACT-4 9 ft): 1 x 5/8" GB to 9.5 ft || sello 36e13db3828c15d3 | J14: A02.01 -> 3/A12.01 -> 7/S5.20 -> 1/S5.20 | K14: [DERIVADO]
A15: A1 #10 - Men's Restroom 113 urinal wall at chase east end (untagged, note A) || 113 Men: 1 x 5/8" GB to 9.0 ft | 114 Women: 1 x 5/8" GB to 9.0 ft || sello c92485a88154cc00 | B15: 10 | C15: 4.89 | D15: 13.052 | E15: 1.63 | F15: 3-5/8" | G15: 16 | H15: 71.88 | I15: Men's Restroom 113 urinal wall at chase east end (untagged, note A) || 113 Men: 1 x 5/8" GB to 9.0 ft | 114 Women: 1 x 5/8" GB to 9.0 ft || sello c92485a88154cc00 | J15: A02.01 -> 3/A12.01 -> 7/S5.20 -> 1/S5.20 | K15: [DERIVADO]
A16: A1 #11 - Restroom 114 jog to B2 at urinal niche north (untagged) || 114 Women: 1 x 5/8" GB to 9.0 ft | 111 Corridor: 1 x 5/8" GB to 9.0 ft || sello d70ac06450239353 | B16: 11 | C16: 1.9 | D16: 13.052 | E16: 2 | F16: 3-5/8" | G16: 16 | H16: 34.2 | I16: Restroom 114 jog to B2 at urinal niche north (untagged) || 114 Women: 1 x 5/8" GB to 9.0 ft | 111 Corridor: 1 x 5/8" GB to 9.0 ft || sello d70ac06450239353 | J16: A02.01 -> 3/A12.01 -> 7/S5.20 -> 1/S5.20 | K16: [DERIVADO]
A17: A1 #12 - Restroom 113 jog to B2 at urinal niche south (untagged) || 113 Men: 1 x 5/8" GB to 9.0 ft | 111 Corridor: 1 x 5/8" GB to 9.0 ft || sello 3fff140bddcb3578 | B17: 12 | C17: 1.9 | D17: 13.052 | E17: 2 | F17: 3-5/8" | G17: 16 | H17: 34.2 | I17: Restroom 113 jog to B2 at urinal niche south (untagged) || 113 Men: 1 x 5/8" GB to 9.0 ft | 111 Corridor: 1 x 5/8" GB to 9.0 ft || sello 3fff140bddcb3578 | J17: A02.01 -> 3/A12.01 -> 7/S5.20 -> 1/S5.20 | K17: [DERIVADO]
A18: TYPE A1K
A19: A1K #13 - Cash Window 116 north (Kevlar) || 116 Cash Window (teller side): 1 x 5/8" GB to 15.38 ft | Customer side (behind G #41): 1 x 5/8" GB to 15.38 ft || sello f4be4d34b2d3145f | B19: 13 | C19: 3.41 | D19: 15.375 | E19: 2 | F19: 3-5/8" | G19: 24 | H19: 104.94 | I19: Cash Window 116 north (Kevlar) || 116 Cash Window (teller side): 1 x 5/8" GB to 15.38 ft | Customer side (behind G #41): 1 x 5/8" GB to 15.38 ft || sello f4be4d34b2d3145f | J19: A02.01 -> 4/A12.01 -> 7/S5.20 -> 1/S5.20 | K19: [DERIVADO]
A20: A1K #14 - Cash Window 116 south (Kevlar) || 116 Cash Window (teller side): 1 x 5/8" GB to 13.05 ft | Customer side (Future FCAM / 118A): 1 x 5/8" GB to 13.05 ft || sello 254a7bd2f04507c7 | B20: 14 | C20: 3.41 | D20: 13.052 | E20: 2 | F20: 3-5/8" | G20: 24 | H20: 89.1 | I20: Cash Window 116 south (Kevlar) || 116 Cash Window (teller side): 1 x 5/8" GB to 13.05 ft | Customer side (Future FCAM / 118A): 1 x 5/8" GB to 13.05 ft || sello 254a7bd2f04507c7 | J20: A02.01 -> 4/A12.01 -> 7/S5.20 -> 1/S5.20 | K20: [DERIVADO]
A21: A1K #15 - Cash Window 116 south-west leg at door 118A (Kevlar) || Corridor at 116/118A (ACT-4 9 ft) customer side N: 1 x 5/8" GB to 13.05 ft | Customer side (118A) S: 1 x 5/8" GB to 13.05 ft || sello d06eaf155297aac8 | B21: 15 | C21: 2.24 | D21: 13.052 | E21: 2 | F21: 3-5/8" | G21: 24 | H21: 58.48 | I21: Cash Window 116 south-west leg at door 118A (Kevlar) || Corridor at 116/118A (ACT-4 9 ft) customer side N: 1 x 5/8" GB to 13.05 ft | Customer side (118A) S: 1 x 5/8" GB to 13.05 ft || sello d06eaf155297aac8 | J21: A02.01 -> 4/A12.01 -> 7/S5.20 -> 1/S5.20 | K21: [DERIVADO]
A22: TYPE A5
A23: A5 #16 - Calling Cubes 122 east wall || 122 Calling Cubes: 1 x 5/8" GB to 9.0 ft | 103 Central Zone: 1 x 5/8" GB to 12.0 ft | Corridor at 116/118A (ACT-4 9 ft): 1 x 5/8" GB to 9.5 ft || sello f9cf1182ba9a23a2 | B23: 16 | C23: 19 | D23: 14.897 | E23: 2 | F23: 6" | G23: 16 | H23: 371.34 | I23: Calling Cubes 122 east wall || 122 Calling Cubes: 1 x 5/8" GB to 9.0 ft | 103 Central Zone: 1 x 5/8" GB to 12.0 ft | Corridor at 116/118A (ACT-4 9 ft): 1 x 5/8" GB to 9.5 ft || sello f9cf1182ba9a23a2 | J23: A02.01 -> 3/A12.01 -> 7/S5.20 -> 1/S5.20 | K23: [DERIVADO]
A24: A5 #17 - Calling Cubes 122 west wall at MW07 || 122 Calling Cubes: 1 x 5/8" GB to 9.0 ft | 103 Central Zone: 1 x 5/8" GB to 12.0 ft || sello 2620f487fabd6d7f | B24: 17 | C24: 10.59 | D24: 15.375 | E24: 2 | F24: 6" | G24: 16 | H24: 222.46 | I24: Calling Cubes 122 west wall at MW07 || 122 Calling Cubes: 1 x 5/8" GB to 9.0 ft | 103 Central Zone: 1 x 5/8" GB to 12.0 ft || sello 2620f487fabd6d7f | J24: A02.01 -> 3/A12.01 -> 7/S5.20 -> 1/S5.20 | K24: [DERIVADO]
A25: A5 #18 - Corridor 111 jamb wall at door 111 || 122 Calling Cubes: 1 x 5/8" GB to 9.0 ft | 111 Corridor: 1 x 5/8" GB to 9.0 ft || sello e369e8d4a29f07d4 | B25: 18 | C25: 0.97 | D25: 15.375 | E25: 2 | F25: 6" | G25: 16 | H25: 17.4 | I25: Corridor 111 jamb wall at door 111 || 122 Calling Cubes: 1 x 5/8" GB to 9.0 ft | 111 Corridor: 1 x 5/8" GB to 9.0 ft || sello e369e8d4a29f07d4 | J25: A02.01 -> 3/A12.01 -> 7/S5.20 -> 1/S5.20 | K25: [DERIVADO]
A26: A5 #19 - Break Room 118 east at Future FCAM || 118 Break Room: 1 x 5/8" GB to 9.0 ft | Corridor at 116/118A (ACT-4 9 ft): 1 x 5/8" GB to 9.5 ft || sello c54617a6c1f43042 | B26: 19 | C26: 3.28 | D26: 13.052 | E26: 2 | F26: 6" | G26: 16 | H26: 60.68 | I26: Break Room 118 east at Future FCAM || 118 Break Room: 1 x 5/8" GB to 9.0 ft | Corridor at 116/118A (ACT-4 9 ft): 1 x 5/8" GB to 9.5 ft || sello c54617a6c1f43042 | J26: A02.01 -> 3/A12.01 -> 7/S5.20 -> 1/S5.20 | K26: [DERIVADO]
A27: TYPE B
A28: B #20 - Electrical 120 north wall (FEC-2 recess) || 118 Break Room: 1 x 5/8" GB to 13.05 ft | 120 Electrical: 1 x 5/8" GB to 13.05 ft || sello 4d6091bda8059fdb | B28: 20 | C28: 9.99 | D28: 13.052 | E28: 2 | F28: 3-5/8" | G28: 16 | H28: 260.7 | I28: Electrical 120 north wall (FEC-2 recess) || 118 Break Room: 1 x 5/8" GB to 13.05 ft | 120 Electrical: 1 x 5/8" GB to 13.05 ft || sello 4d6091bda8059fdb | J28: A02.01 -> 1/A12.01 -> 7/S5.20 -> 1/S5.20 | K28: [DERIVADO]
A29: B #21 - Electrical 120 / NER 121 demising || 120 Electrical: 1 x 5/8" GB to 13.05 ft | 121 NER: 1 x 5/8" GB to 13.05 ft || sello bd64610576e40fe6 | B29: 21 | C29: 9.58 | D29: 13.052 | E29: 2 | F29: 3-5/8" | G29: 16 | H29: 250.08 | I29: Electrical 120 / NER 121 demising || 120 Electrical: 1 x 5/8" GB to 13.05 ft | 121 NER: 1 x 5/8" GB to 13.05 ft || sello bd64610576e40fe6 | J29: A02.01 -> 1/A12.01 -> 7/S5.20 -> 1/S5.20 | K29: [DERIVADO]
A30: B #22 - Electrical 120 / NER 121 east wall (doors 120,121) || 120 Electrical / 121 NER: 1 x 5/8" GB to 13.05 ft | 118 Break Room: 1 x 5/8" GB to 13.05 ft || sello 85e5b987cebcf74e | B30: 22 | C30: 13.74 | D30: 13.052 | E30: 2 | F30: 3-5/8" | G30: 16 | H30: 263.12 | I30: Electrical 120 / NER 121 east wall (doors 120,121) || 120 Electrical / 121 NER: 1 x 5/8" GB to 13.05 ft | 118 Break Room: 1 x 5/8" GB to 13.05 ft || sello 85e5b987cebcf74e | J30: A02.01 -> 1/A12.01 -> 7/S5.20 -> 1/S5.20 | K30: [DERIVADO]
A31: B #23 - Restroom 113 south / Janitor-Storage north (door 112) || 113 Men: 1 x 5/8" GB to 13.05 ft | 112 Janitor: 1 x 5/8" GB to 13.05 ft || sello a8515e3d163b67ac | B31: 23 | C31: 12.33 | D31: 13.052 | E31: 2 | F31: 3-5/8" | G31: 16 | H31: 274.16 | I31: Restroom 113 south / Janitor-Storage north (door 112) || 113 Men: 1 x 5/8" GB to 13.05 ft | 112 Janitor: 1 x 5/8" GB to 13.05 ft || sello a8515e3d163b67ac | J31: A02.01 -> 1/A12.01 -> 7/S5.20 -> 1/S5.20 | K31: [DERIVADO]
A32: B #24 - Janitor 112 / Storage 117 demising || 112 Janitor: 1 x 5/8" GB to 13.05 ft | 117 Storage: 1 x 5/8" GB to 13.05 ft || sello 1ed3f131e7a04e96 | B32: 24 | C32: 3.5 | D32: 13.052 | E32: 2 | F32: 3-5/8" | G32: 16 | H32: 91.36 | I32: Janitor 112 / Storage 117 demising || 112 Janitor: 1 x 5/8" GB to 13.05 ft | 117 Storage: 1 x 5/8" GB to 13.05 ft || sello 1ed3f131e7a04e96 | J32: A02.01 -> 1/A12.01 -> 7/S5.20 -> 1/S5.20 | K32: [DERIVADO]
A33: B #25 - Janitor 112-Storage 117 south / Wellness 115 north || 112 Janitor: 1 x 5/8" GB to 13.05 ft | 115 Wellness: 1 x 5/8" GB to 13.05 ft || sello 7fe690636750ca33 | B33: 25 | C33: 11.73 | D33: 13.052 | E33: 2 | F33: 3-5/8" | G33: 16 | H33: 306.28 | I33: Janitor 112-Storage 117 south / Wellness 115 north || 112 Janitor: 1 x 5/8" GB to 13.05 ft | 115 Wellness: 1 x 5/8" GB to 13.05 ft || sello 7fe690636750ca33 | J33: A02.01 -> 1/A12.01 -> 7/S5.20 -> 1/S5.20 | K33: [DERIVADO]
A34: TYPE B2
A35: B2 #26 - ATM Room 102 east jamb wall at door 102 || 102 ATM Room: 1 x 5/8" GB to 15.38 ft | 103 Central Zone: 1 x 5/8" GB to 15.38 ft || sello 677005bf85f414eb | B35: 26 | C35: 1.5 | D35: 15.375 | E35: 2 | F35: 6" | G35: 16 | H35: 46.12 | I35: ATM Room 102 east jamb wall at door 102 || 102 ATM Room: 1 x 5/8" GB to 15.38 ft | 103 Central Zone: 1 x 5/8" GB to 15.38 ft || sello 677005bf85f414eb | J35: A02.01 -> 1/A12.01 -> 7/S5.20 -> 1/S5.20 | K35: [DERIVADO]
A36: B2 #27 - Women's Restroom 114 east (south of door 114) || 114 Women: 1 x 5/8" GB to 13.05 ft | 111 Corridor: 1 x 5/8" GB to 13.05 ft || sello da1e7a931f0156de | B36: 27 | C36: 1.82 | D36: 13.052 | E36: 2 | F36: 6" | G36: 16 | H36: 47.5 | I36: Women's Restroom 114 east (south of door 114) || 114 Women: 1 x 5/8" GB to 13.05 ft | 111 Corridor: 1 x 5/8" GB to 13.05 ft || sello da1e7a931f0156de | J36: A02.01 -> 1/A12.01 -> 7/S5.20 -> 1/S5.20 | K36: [DERIVADO]
A37: B2 #28 - Men's Restroom 113 east (north of door 113) || 113 Men: 1 x 5/8" GB to 13.05 ft | 111 Corridor: 1 x 5/8" GB to 13.05 ft || sello 6e3cd3f0628a8276 | B37: 28 | C37: 1.8 | D37: 13.052 | E37: 2 | F37: 6" | G37: 16 | H37: 46.98 | I37: Men's Restroom 113 east (north of door 113) || 113 Men: 1 x 5/8" GB to 13.05 ft | 111 Corridor: 1 x 5/8" GB to 13.05 ft || sello 6e3cd3f0628a8276 | J37: A02.01 -> 1/A12.01 -> 7/S5.20 -> 1/S5.20 | K37: [DERIVADO]
A38: B2 #29 - Wellness 115 east (between doors 117 and 115) || 115 Wellness: 1 x 5/8" GB to 13.05 ft | 111 Corridor: 1 x 5/8" GB to 13.05 ft || sello 7bc90b2d65064489 | B38: 29 | C38: 2.69 | D38: 13.052 | E38: 2 | F38: 6" | G38: 16 | H38: 70.3 | I38: Wellness 115 east (between doors 117 and 115) || 115 Wellness: 1 x 5/8" GB to 13.05 ft | 111 Corridor: 1 x 5/8" GB to 13.05 ft || sello 7bc90b2d65064489 | J38: A02.01 -> 1/A12.01 -> 7/S5.20 -> 1/S5.20 | K38: [DERIVADO]
A39: B2 #30 - Work Room 119 west / Break Room 118 east || 119 Work Room: 1 x 5/8" GB to 13.05 ft | 118 Break Room: 1 x 5/8" GB to 13.05 ft || sello 57a022443a1f5c72 | B39: 30 | C39: 11.74 | D39: 13.052 | E39: 2 | F39: 6" | G39: 16 | H39: 306.46 | I39: Work Room 119 west / Break Room 118 east || 119 Work Room: 1 x 5/8" GB to 13.05 ft | 118 Break Room: 1 x 5/8" GB to 13.05 ft || sello 57a022443a1f5c72 | J39: A02.01 -> 1/A12.01 -> 7/S5.20 -> 1/S5.20 | K39: [DERIVADO]
A40: TYPE B2K
A41: B2K #31 - Cash Window 116 north-west corner at office front (Kevlar) || 116 Cash Window (teller side): 1 x 5/8" GB to 15.38 ft | Customer side (Office 108 front): 1 x 5/8" GB to 15.38 ft || sello 4ab59348315582d9 | B41: 31 | C41: 1.77 | D41: 15.375 | E41: 2 | F41: 6" | G41: 24 | H41: 54.52 | I41: Cash Window 116 north-west corner at office front (Kevlar) || 116 Cash Window (teller side): 1 x 5/8" GB to 15.38 ft | Customer side (Office 108 front): 1 x 5/8" GB to 15.38 ft || sello 4ab59348315582d9 | J41: A02.01 -> 4/A12.01 + 1/A12.01 -> 7/S5.20 -> 1/S5.20 | K41: [DERIVADO]
...

Sheet Material Summary
A1: MATERIAL SUMMARY - NET / WASTE / PURCHASE
A2: Waste lives HERE, in its own column, never inside the net quantity.
A3: Material | B3: Unit | C3: Net | D3: Waste % | E3: Waste | F3: Purchase | G3: Selling unit | H3: Pieces to buy | I3: Where it comes from
A4: 3-5/8" metal stud 362S137-68 (14 GA) - Kevlar A1K | B4: LF | C4: 285.7 | D4: =Inputs!$B$4 -> 0.15 | E4: =C4*D4 -> 42.855 | F4: =C4+E4 -> 328.555 | G4: stick 20 ft | H4: =ROUNDUP(F4/20,0) -> 17 | I4: 6 renglones: 4/A12.01; 6/S5.20
A5: 6" metal stud 600S137-68 (14 GA) - Kevlar B2K | B5: LF | C5: 61.5 | D5: =Inputs!$B$4 -> 0.15 | E5: =C5*D5 -> 9.225 | F5: =C5+E5 -> 70.725 | G5: stick 20 ft | H5: =ROUNDUP(F5/20,0) -> 4 | I5: 1 renglones: 4/A12.01 + 1/A12.01
A6: 6" parapet infill stud 600S162-54 @ 16" O.C. | B6: LF | C6: 1116.45 | D6: =Inputs!$B$4 -> 0.15 | E6: =C6*D6 -> 167.4675 | F6: =C6+E6 -> 1283.9175 | G6: stick 20 ft | H6: =ROUNDUP(F6/20,0) -> 65 | I6: 11 renglones: 11/S5.10
A7: 6" exterior metal stud 600S162-54 (S1.11; RFI vs 600S137-33) | B7: LF | C7: 3550.63 | D7: =Inputs!$B$4 -> 0.15 | E7: =C7*D7 -> 532.5945 | F7: =C7+E7 -> 4083.2245 | G7: stick 20 ft | H7: =ROUNDUP(F7/20,0) -> 205 | I7: 13 renglones: 1/A09.25; S1.11 note 5
A8: 6" metal stud 600S137-33 (interior A5/B2) | B8: LF | C8: 1624.26 | D8: =Inputs!$B$4 -> 0.15 | E8: =C8*D8 -> 243.639 | F8: =C8+E8 -> 1867.899 | G8: stick 20 ft | H8: =ROUNDUP(F8/20,0) -> 94 | I8: 17 renglones: 1/A12.01; 3/A12.01; 6/S5.20
A9: 1-5/8" metal stud 162S125-33 (double row G/G1, office bulkheads) | B9: LF | C9: 5259.22 | D9: =Inputs!$B$4 -> 0.15 | E9: =C9*D9 -> 788.883 | F9: =C9+E9 -> 6048.103 | G9: stick 20 ft | H9: =ROUNDUP(F9/20,0) -> 303 | I9: 29 renglones: 5/A12.01; 6/S5.20; 8/A12.01
A10: 2-1/2" metal stud (coiling grille head) 250S125-33 | B10: LF | C10: 12 | D10: =Inputs!$B$4 -> 0.15 | E10: =C10*D10 -> 1.8 | F10: =C10+E10 -> 13.8 | G10: stick 20 ft | H10: =ROUNDUP(F10/20,0) -> 1 | I10: 1 renglones: 4/A08.21
A11: 3-5/8" metal stud 362S137-33 (20 GA) | B11: LF | C11: 6751.88 | D11: =Inputs!$B$4 -> 0.15 | E11: =C11*D11 -> 1012.782 | F11: =C11+E11 -> 7764.662 | G11: stick 20 ft | H11: =ROUNDUP(F11/20,0) -> 389 | I11: 59 renglones: 1/A12.01; 12/A12.01; 3/A08.21; 3/A09.26; 3/A12.01; 4/A02.02; 4/A12.10; 5/A09.25; 6/A12.01; 6/S5.20; 8/A09.33 3 5/8" METAL STUD BRACING @ 48" O.C.; 8/A09.33 3 5/8" METAL STUD FRAMING AND TRACK @ 16" O.C.; 9/A12.08; S2.20 B.O.D. 11'-9" TYP @ CANOPY
A12: 6" parapet bottom track 600T125-54 | B12: LF | C12: 263.69 | D12: =Inputs!$B$4 -> 0.15 | E12: =C12*D12 -> 39.5535 | F12: =C12+E12 -> 303.2435 | G12: 10 ft | H12: =ROUNDUP(F12/10,0) -> 31 | I12: 11 renglones: 11/S5.10 TOP & BOT. (54.2)
A13: 6" parapet top track 600T125-54 | B13: LF | C13: 263.69 | D13: =Inputs!$B$4 -> 0.15 | E13: =C13*D13 -> 39.5535 | F13: =C13+E13 -> 303.2435 | G13: 10 ft | H13: =ROUNDUP(F13/10,0) -> 31 | I13: 11 renglones: 11/S5.10 TOP & BOT. (54.2)
A14: 6" bottom track 600T125-68 (B2K) | B14: LF | C14: 1.77 | D14: =Inputs!$B$4 -> 0.15 | E14: =C14*D14 -> 0.2655 | F14: =C14+E14 -> 2.0355 | G14: 10 ft | H14: =ROUNDUP(F14/10,0) -> 1 | I14: 1 renglones: 4/A12.01 + 1/A12.01
A15: 3-5/8" bottom track 362T125-68 (A1K) | B15: LF | C15: 9.06 | D15: =Inputs!$B$4 -> 0.15 | E15: =C15*D15 -> 1.359 | F15: =C15+E15 -> 10.419 | G15: 10 ft | H15: =ROUNDUP(F15/10,0) -> 2 | I15: 3 renglones: 4/A12.01
A16: 6" bottom track 600T125-33 | B16: LF | C16: 264.05 | D16: =Inputs!$B$4 -> 0.15 | E16: =C16*D16 -> 39.6075 | F16: =C16+E16 -> 303.6575 | G16: 10 ft | H16: =ROUNDUP(F16/10,0) -> 31 | I16: 17 renglones: 1/A12.01; 3/A12.01; 7/S5.20
A17: 6" top deflection track 600T200-97 | B17: LF | C17: 334.94 | D17: =Inputs!$B$4 -> 0.15 | E17: =C17*D17 -> 50.241 | F17: =C17+E17 -> 385.181 | G17: 10 ft | H17: =ROUNDUP(F17/10,0) -> 39 | I17: 28 renglones: 1/A12.01; 3/A12.01; 4/A12.01 + 1/A12.01; 7/S5.20
A18: 3-5/8" bottom track 362T125-33 | B18: LF | C18: 185.82 | D18: =Inputs!$B$4 -> 0.15 | E18: =C18*D18 -> 27.873 | F18: =C18+E18 -> 213.693 | G18: 10 ft | H18: =ROUNDUP(F18/10,0) -> 22 | I18: 22 renglones: 1/A12.01; 12/A12.01; 3/A12.01; 6/A12.01
A19: 3-5/8" top deflection track 362T200-97 | B19: LF | C19: 190.74 | D19: =Inputs!$B$4 -> 0.15 | E19: =C19*D19 -> 28.611 | F19: =C19+E19 -> 219.351 | G19: 10 ft | H19: =ROUNDUP(F19/10,0) -> 22 | I19: 28 renglones: 1/A12.01; 3/A12.01; 4/A12.01; 6/A12.01
A20: 3-5/8" top track 362T125-33 at deck (F) | B20: LF | C20: 17.46 | D20: =Inputs!$B$4 -> 0.15 | E20: =C20*D20 -> 2.619 | F20: =C20+E20 -> 20.079 | G20: 10 ft | H20: =ROUNDUP(F20/10,0) -> 3 | I20: 1 renglones: 12/A12.01
A21: 1-5/8" bottom track 162T125-33 | B21: LF | C21: 299.19 | D21: =Inputs!$B$4 -> 0.15 | E21: =C21*D21 -> 44.8785 | F21: =C21+E21 -> 344.0685 | G21: 10 ft | H21: =ROUNDUP(F21/10,0) -> 35 | I21: 14 renglones: 5/A12.01; 8/A12.01
A22: 1-5/8" top slip track 162T200-97 | B22: LF | C22: 299.19 | D22: =Inputs!$B$4 -> 0.15 | E22: =C22*D22 -> 44.8785 | F22: =C22+E22 -> 344.0685 | G22: 10 ft | H22: =ROUNDUP(F22/10,0) -> 35 | I22: 14 renglones: 5/A12.01; 8/A12.01 CONT. SLIP TRACK
A23: 3-5/8" track - ceilings / soffits / canopy / bulkheads | B23: LF | C23: 1703.9 | D23: =Inputs!$B$4 -> 0.15 | E23: =C23*D23 -> 255.585 | F23: =C23+E23 -> 1959.485 | G23: 10 ft | H23: =ROUNDUP(F23/10,0) -> 196 | I23: 24 renglones: 1/A09.25; 10/A09.33 CONT. TRACK; 3/A08.21; 3/A09.26; 4/A02.02; 4/A12.10; 5/A09.25; 6/A12.01; 8/A09.33; A04.01 (wall angle where GB ceiling meets wall)
A24: sill track 600T125-54 at windows / ATM | B24: LF | C24: 284.35 | D24: =Inputs!$B$4 -> 0.15 | E24: =C24*D24 -> 42.6525 | F24: =C24+E24 -> 327.0025 | G24: 10 ft | H24: =ROUNDUP(F24/10,0) -> 33 | I24: 48 renglones: 10/A09.27; 6/S5.20; A00.40 #1 KNOXBOX 3200 RECESSED MOUNT; A02.01 FEC-1, FEC-2; A08.01 A/A08.01
A25: header + sill track at ATM walk-up framed opening | B25: LF | C25: 7.17 | D25: =Inputs!$B$4 -> 0.15 | E25: =C25*D25 -> 1.0755 | F25: =C25+E25 -> 8.2455 | G25: LF | H25: =ROUNDUP(F25,0) -> 9 | I25: 1 renglones: 1/A08.11
A26: bracing 1-1/2" C.R. channel @ 48" O.C. | B26: LF | C26: 2205.72 | D26: =Inputs!$B$4 -> 0.15 | E26: =C26*D26 -> 330.858 | F26: =C26+E26 -> 2536.578 | G26: 16 ft | H26: =ROUNDUP(F26/16,0) -> 159 | I26: 66 renglones: 1/S5.20 (F)
A27: 1-1/2" carrying channel @ 48" O.C. (GB ceilings) | B27: LF | C27: 233.87 | D27: =Inputs!$B$4 -> 0.15 | E27: =C27*D27 -> 35.0805 | F27: =C27+E27 -> 268.9505 | G27: 16 ft | H27: =ROUNDUP(F27/16,0) -> 17 | I27: 5 renglones: A04.01 legend NEW SUSPENDED GYPSUM WALL BOARD CEILING
A28: 7/8" furring channel @ 16" O.C. (GB ceilings) | B28: LF | C28: 701.81 | D28: =Inputs!$B$4 -> 0.15 | E28: =C28*D28 -> 105.2715 | F28: =C28+E28 -> 807.0815 | G28: 12 ft | H28: =ROUNDUP(F28/12,0) -> 68 | I28: 5 renglones: A04.01 legend
A29: hanger wire 12 GA | B29: LF | C29: 342.27 | D29: =Inputs!$B$4 -> 0.15 | E29: =C29*D29 -> 51.3405 | F29: =C29+E29 -> 393.6105 | G29: LF | H29: =ROUNDUP(F29,0) -> 394 | I29: 5 renglones: 3/A09.33 TYPICAL 12 GAUGE HANGER WIRE
A30: 1x1x1 16 GA purlin across flutes | B30: LF | C30: 18.02 | D30: =Inputs!$B$4 -> 0.15 | E30: =C30*D30 -> 2.703 | F30: =C30+E30 -> 20.723 | G30: 10 ft | H30: =ROUNDUP(F30/10,0) -> 3 | I30: 1 renglones: 10/A09.33 ALTERNATE CEILING DETAIL
A31: framed opening for recessed fixture / access panel (metal framing) | B31: LF | C31: 847.34 | D31: =Inputs!$B$4 -> 0.15 | E31: =C31*D31 -> 127.101 | F31: =C31+E31 -> 974.441 | G31: LF | H31: =ROUNDUP(F31,0) -> 975 | I31: 11 renglones: 5/A09.33 FIXTURE LENGTH + 1/4"; 6/A09.33; A04.01; A04.01 key note 4; E00.01
A32: metal stud blocking 362CR22 (STUD BLOCKING) at edge of gypboard | B32: LF | C32: 603.56 | D32: =Inputs!$B$4 -> 0.15 | E32: =C32*D32 -> 90.534 | F32: =C32+E32 -> 694.094 | G32: 10 ft | H32: =ROUNDUP(F32/10,0) -> 70 | I32: 1 renglones: 4/S5.20 PROVIDE BLOCKING AT THE EDGE OF GYPBOARD
A33: PAFs @ 12" O.C. parapet / power driven fasteners (Kevlar track) | B33: EA | C33: 290 | D33: =Inputs!$B$4 -> 0.15 | E33: =C33*D33 -> 43.5 | F33: =C33+E33 -> 333.5 | G33: EA | H33: =ROUNDUP(F33,0) -> 334 | I33: 15 renglones: 11/S5.10; 4/A12.01
A34: joint tape & compound - Level 5 finish | B34: SF | C34: 922.49 | D34: =Inputs!$B$5 -> 0.06 | E34: =C34*D34 -> 55.3494 | F34: =C34+E34 -> 977.8394 | G34: SF | H34: =ROUNDUP(F34/Inputs!$B$8,0) -> 21 | I34: 1 renglones: A05.01 key notes 9,10
A35: joint tape & compound - Level 4 finish | B35: SF | C35: 12753.19 | D35: =Inputs!$B$5 -> 0.06 | E35: =C35*D35 -> 765.1914 | F35: =C35+E35 -> 13518.381 | G35: SF | H35: =ROUNDUP(F35/Inputs!$B$8,0) -> 282 | I35: 1 renglones: A00.40 finish legend
A36: 5/8" moisture resistant gypsum board (restroom chase) | B36: SF | C36: 261.74 | D36: =Inputs!$B$5 -> 0.06 | E36: =C36*D36 -> 15.7044 | F36: =C36+E36 -> 277.4444 | G36: 4x12 sheet | H36: =ROUNDUP(F36/Inputs!$B$8,0) -> 6 | I36: 1 renglones: F/A08.01
A37: 3/8" gypsum board (Kevlar customer side above 8'-0") | B37: SF | C37: 66.81 | D37: =Inputs!$B$5 -> 0.06 | E37: =C37*D37 -> 4.0086 | F37: =C37+E37 -> 70.8186 | G37: 4x12 sheet | H37: =ROUNDUP(F37/Inputs!$B$8,0) -> 2 | I37: 4 renglones: 4/A12.01
A38: 3/8" UL752 Level-2 fiberglass ballistic panel (Kevlar) | B38: SF | C38: 86.7 | D38: =Inputs!$B$5 -> 0.06 | E38: =C38*D38 -> 5.202 | F38: =C38+E38 -> 91.902 | G38: 4x8 panel | H38: =ROUNDUP(F38/Inputs!$B$8,0) -> 2 | I38: 4 renglones: 4/A12.01
A39: 5/8" exterior gypsum sheathing - parapet roof side | B39: SF | C39: 807.98 | D39: =Inputs!$B$5 -> 0.06 | E39: =C39*D39 -> 48.4788 | F39: =C39+E39 -> 856.4588 | G39: 4x8 sheet | H39: =ROUNDUP(F39/Inputs!$B$8,0) -> 18 | I39: 11 renglones: B/A09.21
A40: 5/8" glass mat sheathing (base band + canopy band) | B40: SF | C40: 482.1 | D40: =Inputs!$B$5 -> 0.06 | E40: =C40*D40 -> 28.926 | F40: =C40+E40 -> 511.026 | G40: 4x8 sheet | H40: =ROUNDUP(F40/Inputs!$B$8,0) -> 11 | I40: 11 renglones: 5/A09.26
...

Sheet Pending Items
A1: RFI | B1: Question / condition | C1: Delta of each alternative
A2: RFI-01 | B2: Exterior stud gauge/spacing: S1.11 note 5 = 600S162-54 @16" (@12" within 6 ft of corners) vs 7/S5.20 = 600S137-33 @16". Take-off carries S1.11 (more material, 56.2). | C2: Same LF in both; gauge 54 vs 33 mil; S5.20 option deletes ~2 studs per corner end (~16 studs x 15.4 ft = -246 LF of 12" O.C. extras).
A3: RFI-02 | B3: 10/S5.10: exterior studs end at deflection track UNDER perimeter beam; beam depth per segment not shown in the detail. Carried studs to B.O.D. (53.3 more material). | C3: Deduct beam depth (C10 ~10" to W14 ~14") x ~250 exterior studs = approx -210 to -290 LF of 600S162-54.
A4: RFI-03 | B4: Exterior elevation titles N/S are transposed: 1/A09.01 'SOUTH ELEVATION' shows the grid F/G (north, entrance) facade; 2/A09.02 'NORTH ELEVATION' shows grid A. Take-off follows the plan (north = grid F/G). | C4: No quantity change if confirmed; otherwise canopy/parapet assignments swap N/S.
A5: RFI-04 | B5: C1 (6/A12.01) board height not shown (break line). Carried to deck (53.3). | C5: To ceiling+6": #32 -33.75 SF; #33/#34 -127.9 SF MR board.
A6: RFI-05 | B6: Tag B2K on A02.01 has no row in the partition schedule. Derived as B2 (1/A12.01) + Kevlar layers (4/A12.01); measured thickness 7.68" vs A5K 7 5/8". | C6: If B2K = A5K: no change. If plain B2: -14 SF ballistic panel, studs 14 GA -> 20 GA.
A7: RFI-06 | B7: Interior slip track designation: only 600T200-97 is scheduled (7/S5.20). 362T200-97 and 162T200-97 derived. | C7: Price delta per LF of 2" flange 97 mil vs 1-1/4" 33 mil track (177 + 299 LF).
A8: RFI-07 | B8: G / G1 / office bulkhead 1-5/8" stud gauge not shown; 162S125-33 derived. | C8: 4,337 LF; heavier gauge raises price only.
A9: RFI-08 | B9: GB ceiling suspension not detailed (only 1/A09.33 for lay-in). Standard C754 system carried (1-1/2" CRC @48", 7/8" furring @16", 12 GA hangers @48"). | C9: Grid system alternative would delete 235 LF CRC + 706 LF furring channel.
A10: RFI-09 | B10: Storefront head: 2/A09.26 says STEEL HEADER FRAMING, 11/A09.27 says METAL STUD BOX BEAM OR STEEL. Carried box beam LF in base. | C10: If steel by Div 05: -49.3 LF box beam (N2 27.58, N3 13.89, W1 7.83).
A11: RFI-10 | B11: 3/4" FRT plywood strip width at window/door/storefront perimeter not dimensioned (10, 11, 14/A09.27; 1-3/A09.25). Carried 6" (stud depth). | C11: +/- per inch of width: about +/-12 SF per inch overall.
A12: RFI-11 | B12: Electrical 120 / NER 121 backboards: carried 7'-6" high from 6" AFF (5/A11.03); confirm the 8'-0" in 2-4/A11.03 is the top elevation, not the height. | C12: 8'-0" high option: +12.5 SF (120) +3.75 SF (121).
... A40: RFI-MEP1 | B40: 6/S5.20 says MAXIMUM d = 2" FOR 8 5/8" STUDS (probable typo for 3 5/8"); D13, D14, D15 duct heights not labeled on M01.01; clashes W7, W10, W15, W17, W18 (ducts riding on wall faces) and 2 x 8" branches crossing B2 line at y 1377-1405 outside measured walls. | C40: Framed opening header/sill by width carried (43 crossings, 49 openings with G double rows); heights not needed for header/sill LF. Clash walls may need offsets.

Sheet PARA REVISAR EN LA MANANA
A1: # | B1: Punto | C1: Hoja + detalle | D1: Imagen
A2: 1 | B2: Confirmar walls interiores (48) por tipo en las hojas marcadas; en especial piers G #42 (sin tag) y G1 #48 (sin tag), y walls A1 #10-12 sin tag (default nota A) | C2: A02.01; nota A/A02.01 | D2: Planos marcados/01..10_PLANO_<tipo>_*.png
A3: 2 | B3: Calibre exterior S1.11 600S162-54 vs S5.20 600S137-33 (RFI-01) | C3: S1.11 nota 5; 7/S5.20 | D3: revisar/R01_S1.11_note5_exterior_studs.png; R01b
A4: 3 | B4: Studs exteriores a B.O.D. vs bajo la viga (RFI-02) | C4: 10/S5.10 | D4: revisar/R02_10-S5.10_section_at_perimeter.png
A5: 4 | B5: Titulos N/S transpuestos en elevaciones (RFI-03) | C5: 1/A09.01; 2/A09.02 | D5: revisar/R03_1-A09.01_SOUTH_title_shows_north_facade.png
A6: 5 | B6: B2K sin fila en schedule (RFI-05) | C6: A02.01; 4/A12.01 | D6: revisar/R04_A02.01_B2K_tag.png
A7: 6 | B7: Altura de board de C1 (RFI-04) | C7: 6/A12.01 | D7: revisar/R05_6-A12.01_C1_board_height.png
A8: 7 | B8: Storefront head: steel header vs box beam (RFI-09) | C8: 2/A09.26; 11/A09.27 | D8: revisar/R06_2-A09.26_storefront_head_steel_header.png
A9: 8 | B9: Roof step grid B (RFI-15) | C9: 4/A02.02 | D9: revisar/R07_4-A02.02_roof_step.png
A10: 9 | B10: Stud blocking 362CR22 sin ubicacion (RFI-16) | C10: 4/S5.20 | D10: revisar/R08_4-S5.20_stud_blocking_NTS.png
A11: 10 | B11: Backboards FRT plywood Electrical/NER (RFI-11) | C11: 2-5/A11.03 | D11: revisar/R09_A11.03_FRT_backboards.png
A12: 11 | B12: CSR soffit = mismo elemento 9/A12.08 y 10/A09.33 (55.2); blocking plywood vs FRTW (RFI-12) | C12: 9/A12.08; 10/A09.33 | D12: revisar/R10_A12.08_CSR_line.png
A13: 12 | B13: ATM drive-up y walk-up R.O. (RFI-17) | C13: 5,6,7/A08.11 | D13: revisar/R11_A08.11_ATM.png
... A21: 20 | B21: Cruce MEP: 40 ductos + 3 tuberias (43 cruces, 49 framed openings), registro M01.01 a A02.01 con 138 pares | C21: M01.01; P01.01; 6/S5.20 | D21: /img/mep/D01..D40_*.png

Sheet Alcances
A1: ALC | B1: Alcance | C1: Estado | D1: Nota (cantidad, NO APLICA + hoja, o RFI)
A2: ALC-01 | B2: Interior partition framing (studs + tracks) | C2: CUANTIFICADO | D2: 48 walls sellados (closer.py); Material Summary studs/tracks; 1-6,12/A12.01
A3: ALC-02 | B3: Exterior wall framing (CFMF) | C3: CUANTIFICADO | D3: 11 fachadas EXT-* selladas; 6" exterior metal stud 600S162-54; C/A09.21, S1.11
A4: ALC-03 | B4: Parapet framing | C4: CUANTIFICADO | D4: 6" parapet infill stud 600S162-54 + tracks + PAFs; 11/S5.10, 4/A09.26
A5: ALC-04 | B5: Top / deflection and bottom track | C5: CUANTIFICADO | D5: bottom y top/deflection en renglones separados; 7/S5.20, 10/S5.10
A6: ALC-05 | B6: Headers, sills and jambs at openings | C6: CUANTIFICADO | D6: header / box beam, sill track, jamb studs en STUD; 9/S5.20, 10-11/A09.27
A7: ALC-06 | B7: Bracing / bridging | C7: CUANTIFICADO | D7: bracing 1-1/2" C.R. channel @48"; F/1/S5.20 (53.4)
A8: ALC-07 | B8: Gypsum board on walls (layers per type) | C8: CUANTIFICADO | D8: 5/8" gypsum board regular por face; A12.01
A9: ALC-08 | B9: Moisture / abuse / special board at wet zones | C9: CUANTIFICADO | D9: 5/8" moisture resistant gypsum board chase C1 #33/#34; F/A08.01
A10: ALC-09 | B10: Exterior gypsum / glass mat sheathing | C10: CUANTIFICADO | D10: 5/8" exterior gypsum sheathing parapet roof side + 5/8" glass mat sheathing; C/A09.21, 5/A09.26
A11: ALC-10 | B11: FRT plywood sheathing / substrate | C11: CUANTIFICADO | D11: FRT plywood bonded to polyiso, ext. grade FRT plywood canopy, 3/4" FRT plywood; C/A09.21, 3/A09.26, A11.03
A12: ALC-11 | B12: Gypsum board ceilings | C12: CUANTIFICADO | D12: CLG-01..05 (Vestibule 100, 24HR 101, Waiting 104, 113, 114); A04.01
... A25: ALC-24 | B25: Finish level (Level 4 / Level 5) | C25: CUANTIFICADO | D25: Level 5 at WC-18/20/22 (A05.01 notes 9-10, A00.40); Level 4 balance (RFI-27)
