Workbook

Sheet Inputs
A1: Bank of America - Broomfield, CO (CO1-111) | METAL FRAMING & DRYWALL TAKEOFF
A2: Bid set: 2025.08.26_CO1-111_Broomfield_PERMIT SET_BID SET.pdf · 2026-10-17 · Edit ONLY the yellow cells.
A4: PARAMETER | B4: VALUE | C4: NOTE / SOURCE
A5: Waste - ALL METAL, any type | B5: 0.15 | C5: Estimator standing rule: 15% on everything that is metal.
A6: Waste - EVERYTHING THAT IS NOT METAL | B6: 0.06 | C6: Estimator standing rule: same figure as board.
A7: Board sheet width (ft) | B7: 4 | C7: Sheet size is a parameter; buy the size that wastes least.
A8: Board sheet length (ft) | B8: 12 | C8: Change it and every sheet count re-rounds.
A9: SF per board sheet | B9: =B7*B8 -> 48 | C9: Width x length.
A10: Stud stock length (ft) | B10: 20 | C10: Stud, header, framed opening and stud blocking: sticks.
A11: Track stock length (ft) | B11: 10 | C11: Track, sill track and purlin: runs.
A12: Floor plan scale (pt/ft) | B12: 18 | C12: Project value (canon constants).
A13: B.O. Deck (ft) | B13: 15.375 | C13: Project value (canon constants).
A14: T.O. Parapet (ft) | B14: 20 | C14: Project value (canon constants).
A15: Sealant coverage (LF per tube) | B15: 25 | C15: Sealant yield per tube - set your supplier's figure.
A16: C.R. channel stock length (ft) | B16: 16 | C16: 1-1/2" cold-rolled channel (bracing, carrying channel).
A17: Hat / furring channel stock (ft) | B17: 12 | C17: 7/8" hat furring channel.
A18: Trim stick length (ft) | B18: 10 | C18: Corner bead, casing bead, shadow molding, PVC trim.
A19: Hanger wire purchase | B19: continuous coil (LF) | C19: Bought by LF from a continuous coil; the hanger count goes on its own PCS row.
A20: Drywall screws per SF of board | B20: 1.2 | C20: YIELD (GA-216 field / perimeter spacing).
A21: Framing screws per stud piece | B21: 4 | C21: YIELD: 2 per stud-to-track connection, each end.
A22: Power-driven pin spacing (ft) | B22: 1 | C22: YIELD: bottom track on slab, interior walls.
A23: Joint compound (lb per SF) | B23: 0.072 | C23: YIELD: 72 lb per 1,000 SF, level 4 (estimator criterion).
A24: Joint tape (LF per SF) | B24: 0.37 | C24: YIELD: 370 LF per 1,000 SF.
A25: Expansion anchor spacing (ft) | B25: 0.6667 | C25: YIELD: exterior bottom track on slab.

Sheet Partition Takeoff
A1: ORGANIZED PARTITION TAKEOFF - Bank of America - Broomfield, CO (CO1-111)
A2: Grouped by partition type. Every row cites its DETAIL/SHEET and its status.
A4: Partition / Scope | B4: Wall # | C4: Length (LF) | D4: Height (FT) | E4: Layers | F4: Stud Size | G4: Stud O.C. (in) | H4: Board (SF) | I4: Location | J4: Source (DETAIL/SHEET) | K4: Status
A5: TYPE G
A6: G #W001 - 103 / 105 | B6: W001 | C6: 2.42 | D6: 14.383 | E6: 4 | F6: 1-5/8" | G6: 16 | H6: 139.22 | I6: 103 / 105 | J6: 5/A12.01 | K6: [DERIVED]
A7: G #W002 - 103 / 105 / 106 / no board (abutting walls) | B7: W002 | C7: 3.467 | D7: 14.383 | E7: 8 | F7: 1-5/8" | G7: 16 | H7: 179.13 | I7: 103 / 105 / 106 / no board (abutting walls) | J7: 5/A12.01 | K7: [DERIVED]
A8: G #W003 - 103 / 106 / 107 / no board (abutting walls) | B8: W003 | C8: 3.253 | D8: 15.375 | E8: 8 | F8: 1-5/8" | G8: 16 | H8: 184.28 | I8: 103 / 106 / 107 / no board (abutting walls) | J8: 5/A12.01 | K8: [DERIVED]
A9: G #W004 - 103 / 107 / 108 / no board (abutting walls) | B9: W004 | C9: 3.253 | D9: 14.225 | E9: 8 | F9: 1-5/8" | G9: 16 | H9: 170.5 | I9: 103 / 107 / 108 / no board (abutting walls) | J9: 5/A12.01 | K9: [DERIVED]
A10: G #W007 - 106 / 107 | B10: W007 | C10: 11.771 | D10: 15.375 | E10: 4 | F10: 1-5/8" | G10: 16 | H10: 723.92 | I10: 106 / 107 | J10: 5/A12.01 | K10: [CONFIRMED]
A11: G #W008 - 107 / 108 | B11: W008 | C11: 11.771 | D11: 15.375 | E11: 4 | F11: 1-5/8" | G11: 16 | H11: 723.92 | I11: 107 / 108 | J11: 5/A12.01 | K11: [CONFIRMED]
A12: G #W009+W005 - 108 / cavity behind A1K W049 / 116 + 103 / 108 / no board (abutting walls) (incl. jog W005 0.973 LF) | B12: W009+W005 | C12: 11.046 | D12: 15.375 | E12: 6 | F12: 1-5/8" | G12: 16 | H12: 568.01 | I12: 108 / cavity behind A1K W049 / 116 + 103 / 108 / no board (abutting walls) (incl. jog W005 0.973 LF) | J12: 5/A12.01 | K12: [DERIVED]
A13: G #W010 - 102 / no board (abutting walls) / 109 | B13: W010 | C13: 12.333 | D13: 15.375 | E13: 8 | F13: 1-5/8" | G13: 16 | H13: 718.32 | I13: 102 / no board (abutting walls) / 109 | J13: 5/A12.01 | K13: [DERIVED]
A14: G #W014 - 109 / 110 | B14: W014 | C14: 10.96 | D14: 15.375 | E14: 4 | F14: 1-5/8" | G14: 16 | H14: 674.04 | I14: 109 / 110 | J14: 5/A12.01 | K14: [DERIVED]
A15: G #W015 - 110 / 114 | B15: W015 | C15: 11.625 | D15: 15.375 | E15: 4 | F15: 1-5/8" | G15: 16 | H15: 714.94 | I15: 110 / 114 | J15: 5/A12.01 | K15: [CONFIRMED]
A16: TYPE G1
A17: G1 #W006 - 105 / 106 | B17: W006 | C17: 11.771 | D17: 15.375 | E17: 4 | F17: 1-5/8" | G17: 16 | H17: 723.92 | I17: 105 / 106 | J17: 5/A12.01 | K17: [CONFIRMED]
A18: G1 #W012+W011 - 109 / 110 / no board (abutting walls) / 103 + 109 / 103 (incl. jog W011 0.333 LF) | B18: W012+W011 | C18: 3.84 | D18: 15.375 | E18: 8 | F18: 1-5/8" | G18: 16 | H18: 220.57 | I18: 109 / 110 / no board (abutting walls) / 103 + 109 / 103 (incl. jog W011 0.333 LF) | J18: 5/A12.01 | K18: [DERIVED]
A19: G1 #W013 - 110 / 114 / no board (abutting walls) / 103 / 111 | B19: W013 | C19: 3.56 | D19: 15.375 | E19: 12 | F19: 1-5/8" | G19: 16 | H19: 195.8 | I19: 110 / 114 / no board (abutting walls) / 103 / 111 | J19: 5/A12.01 | K19: [DERIVED]
A20: TYPE B2
A21: B2 #W016 - 102 / 103 | B21: W016 | C21: 5.667 | D21: 15.375 | E21: 2 | F21: 6" | G21: 16 | H21: 111.66 | I21: 102 / 103 | J21: 1/A12.01 | K21: [CONFIRMED]
A22: B2 #W023 - 114 / 111 | B22: W023 | C22: 1.413 | D22: 12.985 | E22: 2 | F22: 6" | G22: 16 | H22: 36.7 | I22: 114 / 111 | J22: 1/A12.01 | K22: [DERIVED]
A23: B2 #W024 - 113 / 117 / 115 / no board (abutting walls) / 111 | B23: W024 | C23: 15.38 | D23: 12.855 | E23: 5 | F23: 6" | G23: 16 | H23: 241.62 | I23: 113 / 117 / 115 / no board (abutting walls) / 111 | J23: 1/A12.01 | K23: [DERIVED]
A24: B2 #W043 - 118 / 116 / 119 / no board (abutting walls) | B24: W043 | C24: 11.74 | D24: 11.638 | E24: 4 | F24: 6" | G24: 16 | H24: 268.53 | I24: 118 / 116 / 119 / no board (abutting walls) | J24: 1/A12.01 | K24: [DERIVED]
A25: TYPE F
A26: F #W017 - 101 / 102 / no board (abutting walls) | B26: W017 | C26: 16.914 | D26: 15.375 | E26: 3 | F26: 3-5/8" | G26: 16 | H26: 304.46 | I26: 101 / 102 / no board (abutting walls) | J26: 12/A12.01 | K26: [DERIVED]
A27: TYPE C1
A28: C1 #W018+P001+P002 - 114 + P001 + P002 (incl. jog P001 1.0 LF) (incl. jog P002 1.0 LF) | B28: W018+P001+P002 | C28: 12.027 | D28: 13.329 | E28: 1 | F28: 3-5/8" | G28: 16 | H28: 129.55 | I28: 114 + P001 + P002 (incl. jog P001 1.0 LF) (incl. jog P002 1.0 LF) | J28: 6/A12.01 | K28: [DERIVED]
A29: C1 #W019 - 113 | B29: W019 | C29: 10.027 | D29: 12.891 | E29: 1 | F29: 3-5/8" | G29: 16 | H29: 129.26 | I29: 113 | J29: 6/A12.01 | K29: [DERIVED]
A30: C1 #W033+W034+W035 - 104 / recess cavity (in-wall box 9/A12.02) / no board (abutting walls) + 104 (incl. jog W034 0.313 LF) (incl. jog W035 0.313 LF) | B30: W033+W034+W035 | C30: 10.626 | D30: 15.375 | E30: 3 | F30: 3-5/8" | G30: 16 | H30: 163.37 | I30: 104 / recess cavity (in-wall box 9/A12.02) / no board (abutting walls) + 104 (incl. jog W034 0.313 LF) (incl. jog W035 0.313 LF) | J30: 6/A12.01 | K30: [DERIVED]
A31: C1 #W052 - 116 / FCAM recess cavity | B31: W052 | C31: 2.98 | D31: 12.92 | E31: 2 | F31: 3-5/8" | G31: 16 | H31: 38.5 | I31: 116 / FCAM recess cavity | J31: 6/A12.01 | K31: [DERIVED]
A32: TYPE A1
A33: A1 #W020 - 114 / chase cavity / 113 / no board (abutting walls) / 111 | B33: W020 | C33: 4.887 | D33: 11.814 | E33: 6 | F33: 3-5/8" | G33: 16 | H33: 64.51 | I33: 114 / chase cavity / 113 / no board (abutting walls) / 111 | J33: 3/A12.01 | K33: [DERIVED]
A34: A1 #W021 - 114 / no board (abutting walls) / 111 | B34: W021 | C34: 1.9 | D34: 12.952 | E34: 3 | F34: 3-5/8" | G34: 16 | H34: 28.8 | I34: 114 / no board (abutting walls) / 111 | J34: 3/A12.01 | K34: [DERIVED]
A35: A1 #W022 - 111 / 113 / no board (abutting walls) | B35: W022 | C35: 1.9 | D35: 12.859 | E35: 3 | F35: 3-5/8" | G35: 16 | H35: 28.8 | I35: 111 / 113 / no board (abutting walls) | J35: 3/A12.01 | K35: [DERIVED]
A36: A1 #W028 - 103 / no board (abutting walls) / 111 | B36: W028 | C36: 5.583 | D36: 15.375 | E36: 3 | F36: 3-5/8" | G36: 16 | H36: 55.81 | I36: 103 / no board (abutting walls) / 111 | J36: 3/A12.01 | K36: [CONFIRMED]
A37: A1 #W030 - 104 / MW01 printer niche (open to 103) / 122 / no board (abutting walls) | B37: W030 | C37: 17.02 | D37: 15.375 | E37: 4 | F37: 3-5/8" | G37: 16 | H37: 347.27 | I37: 104 / MW01 printer niche (open to 103) / 122 / no board (abutting walls) | J37: 3/A12.01 | K37: [DERIVED]
A38: A1 #W031 - MW01 niche / no board (abutting walls) / 122 | B38: W031 | C38: 3.533 | D38: 15.375 | E38: 3 | F38: 3-5/8" | G38: 16 | H38: 79.88 | I38: MW01 niche / no board (abutting walls) / 122 | J38: 3/A12.01 | K38: [DERIVED]
A39: A1 #W032 - MW01 niche / 122 | B39: W032 | C39: 2.02 | D39: 15.375 | E39: 2 | F39: 3-5/8" | G39: 16 | H39: 49.24 | I39: MW01 niche / 122 | J39: 3/A12.01 | K39: [DERIVED]
A40: A1 #W037 - 122 / no board (abutting walls) / 118 | B40: W037 | C40: 15.833 | D40: 12.965 | E40: 4 | F40: 3-5/8" | G40: 16 | H40: 275.94 | I40: 122 / no board (abutting walls) / 118 | J40: 3/A12.01 | K40: [DERIVED]
A41: A1 #W039 - 111 / 118 / 120 / 121 / no board (abutting walls) | B41: W039 | C41: 17.06 | D41: 11.748 | E41: 5 | F41: 3-5/8" | G41: 16 | H41: 336.39 | I41: 111 / 118 / 120 / 121 / no board (abutting walls) | J41: 3/A12.01 | K41: [DERIVED]
...

Sheet Material Summary
A1: MATERIAL SUMMARY - NET / WASTE / PURCHASE
A2: Waste lives HERE, in its own column, applied ONCE: Pieces = ROUNDUP(Net x (1 + waste) / stock). Every stock length, coverage and yield is an Inputs cell.
A3: Material | B3: Unit | C3: Net | D3: Waste % | E3: Waste | F3: Purchase | G3: Selling unit | H3: Pieces to buy | I3: Where it comes from | J3: Yield check (live formula)
A4: 6" metal stud 600S162-54 (exterior, S1.11 note 5) / 600S137-33 (interior A5, B2) / 14 GA (B2K) | B4: LF | C4: 4332.86 | D4: =Inputs!$B$5 -> 0.15 | E4: =C4*D4 -> 649.929 | F4: =C4+E4 -> 4982.789 | G4: stick 20 ft | H4: =ROUNDUP(F4/Inputs!$B$10,0) -> 250 | I4: familias_out.json '6" stud (all gauges)'; 7/S5.20; S1.11; 3/A12.01; 1/A12.01
A5: 3-5/8" metal stud 362S137-33 (A1, B, C1, F, soffits, transitions, canopy) / 14 GA (A1K) | B5: LF | C5: 6697.57 | D5: =Inputs!$B$5 -> 0.15 | E5: =C5*D5 -> 1004.6355 | F5: =C5+E5 -> 7702.2055 | G5: stick 20 ft | H5: =ROUNDUP(F5/Inputs!$B$10,0) -> 386 | I5: familias_out.json '3-5/8" stud (all gauges)'; 7/S5.20; 3/A12.01; 4/A12.01
A6: 1-5/8" metal stud, double row (G, G1, office bulkheads) | B6: LF | C6: 4001.61 | D6: =Inputs!$B$5 -> 0.15 | E6: =C6*D6 -> 600.2415 | F6: =C6+E6 -> 4601.8515 | G6: stick 20 ft | H6: =ROUNDUP(F6/Inputs!$B$10,0) -> 231 | I6: familias_out.json '1-5/8" stud'; 5/A12.01; 8/A12.01
A7: 6" parapet stud 600S162-54 @ 16" O.C. (parapet infill) | B7: LF | C7: 992.88 | D7: =Inputs!$B$5 -> 0.15 | E7: =C7*D7 -> 148.932 | F7: =C7+E7 -> 1141.812 | G7: stick 20 ft | H7: =ROUNDUP(F7/Inputs!$B$10,0) -> 58 | I7: familias_out.json '6" parapet stud'; 11/S5.10
A8: Bottom track, all walls (not deducted at doors) | B8: LF | C8: 1326.91 | D8: =Inputs!$B$5 -> 0.15 | E8: =C8*D8 -> 199.0365 | F8: =C8+E8 -> 1525.9465 | G8: run 10 ft | H8: =ROUNDUP(F8/Inputs!$B$11,0) -> 153 | I8: familias_out.json 'bottom track (all)'; 7/S5.20 600T125-33; 11/S5.10 600T125-54
A9: Top / deflection track, all walls | B9: LF | C9: 1326.91 | D9: =Inputs!$B$5 -> 0.15 | E9: =C9*D9 -> 199.0365 | F9: =C9+E9 -> 1525.9465 | G9: run 10 ft | H9: =ROUNDUP(F9/Inputs!$B$11,0) -> 153 | I9: familias_out.json 'top / deflection track (all)'; 7/S5.20 600T200-97; 3/A12.01 continuous slip track
A10: Ceiling / soffit track (ceiling perimeter, soffit sides, transitions, fascia, canopy soffit) | B10: LF | C10: 1335.15 | D10: =Inputs!$B$5 -> 0.15 | E10: =C10*D10 -> 200.2725 | F10: =C10+E10 -> 1535.4225 | G10: run 10 ft | H10: =ROUNDUP(F10/Inputs!$B$11,0) -> 154 | I10: familias_out.json 'ceiling / soffit track'; 7/A09.33; 10/A09.33; 7/A09.26
A11: Bracing - 1-1/2" C.R. channel @ 48" O.C. | B11: LF | C11: 2401.31 | D11: =Inputs!$B$5 -> 0.15 | E11: =C11*D11 -> 360.1965 | F11: =C11+E11 -> 2761.5065 | G11: C.R. channel 16 ft | H11: =ROUNDUP(F11/Inputs!$B$16,0) -> 173 | I11: familias_out.json 'bracing C.R. channel'; F/1/S5.20
A12: Purlin 1x1x1 16 GA across min. (2) flutes (top track to deck parallel to flute) | B12: LF | C12: 240.68 | D12: =Inputs!$B$5 -> 0.15 | E12: =C12*D12 -> 36.102 | F12: =C12+E12 -> 276.782 | G12: run 10 ft | H12: =ROUNDUP(F12/Inputs!$B$11,0) -> 28 | I12: familias_out.json 'purlin (track to deck)'; 10/A09.33
A13: Header / box beam (R.O. + 1'-4" x pieces) | B13: LF | C13: 818.25 | D13: =Inputs!$B$5 -> 0.15 | E13: =C13*D13 -> 122.7375 | F13: =C13+E13 -> 940.9875 | G13: stick 20 ft | H13: =ROUNDUP(F13/Inputs!$B$10,0) -> 48 | I13: familias_out.json 'header / box beam'; 7/S5.20; 11/A09.27; 8/A12.01; 4/A08.21; 4/A12.10
A14: Sill track (R.O. + 1'-4", double over 4'-0") | B14: LF | C14: 115.58 | D14: =Inputs!$B$5 -> 0.15 | E14: =C14*D14 -> 17.337 | F14: =C14+E14 -> 132.917 | G14: run 10 ft | H14: =ROUNDUP(F14/Inputs!$B$11,0) -> 14 | I14: familias_out.json 'sill track'; 2/S5.20; 9/S5.20
A15: Furring channel 7/8" hat @ 16" O.C. (GWB ceilings) | B15: LF | C15: 807.01 | D15: =Inputs!$B$5 -> 0.15 | E15: =C15*D15 -> 121.0515 | F15: =C15+E15 -> 928.0615 | G15: hat channel 12 ft | H15: =ROUNDUP(F15/Inputs!$B$17,0) -> 78 | I15: familias_out.json 'furring channel'; A04.01
A16: Carrying channel 1-1/2" C.R. @ 48" O.C. | B16: LF | C16: 315.75 | D16: =Inputs!$B$5 -> 0.15 | E16: =C16*D16 -> 47.3625 | F16: =C16+E16 -> 363.1125 | G16: C.R. channel 16 ft | H16: =ROUNDUP(F16/Inputs!$B$16,0) -> 23 | I16: familias_out.json 'carrying channel'; A04.01
A17: Hanger wire 12 ga | B17: LF | C17: 530.11 | D17: =Inputs!$B$6 -> 0.06 | E17: =C17*D17 -> 31.8066 | F17: =C17+E17 -> 561.9166 | G17: continuous coil (LF) | H17: =ROUNDUP(F17,0) -> 562 | I17: familias_out.json 'hanger wire'; A04.01; S2.20
A18: 5/8" gypsum board, regular (walls + ceilings) | B18: SF | C18: 16705.36 | D18: =Inputs!$B$6 -> 0.06 | E18: =C18*D18 -> 1002.3216 | F18: =C18+E18 -> 17707.682 | G18: 4x12 sheet | H18: =ROUNDUP(F18/Inputs!$B$9,0) -> 369 | I18: familias_out.json '5/8" gyp board regular (walls + ceilings)'; 3/A12.01; 1/A12.01; 5/A12.01; A04.01
A19: 5/8" gypsum board, moisture resistant (behind toilet and lavatory) | B19: SF | C19: 258.81 | D19: =Inputs!$B$6 -> 0.06 | E19: =C19*D19 -> 15.5286 | F19: =C19+E19 -> 274.3386 | G19: 4x12 sheet | H19: =ROUNDUP(F19/Inputs!$B$9,0) -> 6 | I19: familias_out.json '5/8" gyp MOISTURE RESISTANT'; F/A08.01
A20: 3/8" UL752 Level-2 fiberglass ballistic panel (NIJ Type II) | B20: SF | C20: 76.38 | D20: =Inputs!$B$6 -> 0.06 | E20: =C20*D20 -> 4.5828 | F20: =C20+E20 -> 80.9628 | G20: 4x8 sheet | H20: =ROUNDUP(F20/32,0) -> 3 | I20: familias_out.json 'ballistic panel'; 4/A12.01
A21: 3/8" gypsum board (above ballistic panel to structure) | B21: SF | C21: 51.68 | D21: =Inputs!$B$6 -> 0.06 | E21: =C21*D21 -> 3.1008 | F21: =C21+E21 -> 54.7808 | G21: 4x8 sheet | H21: =ROUNDUP(F21/32,0) -> 2 | I21: familias_out.json '3/8" gyp board'; 4/A12.01
A22: 5/8" glass mat sheathing (base strip and canopy band) | B22: SF | C22: 476.97 | D22: =Inputs!$B$6 -> 0.06 | E22: =C22*D22 -> 28.6182 | F22: =C22+E22 -> 505.5882 | G22: 4x8 sheet | H22: =ROUNDUP(F22/32,0) -> 16 | I22: familias_out.json '5/8" glass mat sheathing'; 5/A09.26; 9/A09.27; 7/A09.26
A23: 5/8" exterior gypsum sheathing (parapet roof side) | B23: SF | C23: 935.51 | D23: =Inputs!$B$6 -> 0.06 | E23: =C23*D23 -> 56.1306 | F23: =C23+E23 -> 991.6406 | G23: 4x8 sheet | H23: =ROUNDUP(F23/32,0) -> 31 | I23: familias_out.json '5/8" EXTERIOR gyp sheathing'; 4/A09.26; C/A09.21
A24: FRT blocking (labeled FRT / FRTW / 2X / plywood blocking) | B24: LF | C24: 941.89 | D24: =Inputs!$B$6 -> 0.06 | E24: =C24*D24 -> 56.5134 | F24: =C24+E24 -> 998.4034 | H24: =ROUNDUP(F24,0) -> 999 | I24: familias_out.json 'FRT blocking'; 4/A09.26; A08.01 note E; A00.30 note D
A25: Metal stud blocking 362CR22 (STUD BLOCKING) | B25: LF | C25: 639.26 | D25: =Inputs!$B$5 -> 0.15 | E25: =C25*D25 -> 95.889 | F25: =C25+E25 -> 735.149 | G25: stick 20 ft | H25: =ROUNDUP(F25/Inputs!$B$10,0) -> 37 | I25: familias_out.json 'metal stud blocking (362CR / STUD BLOCKING)'; 4/S5.20
A26: Metal trim - corner bead, casing bead, shadow molding, gypsum edge trim | B26: LF | C26: 1266.47 | D26: =Inputs!$B$5 -> 0.15 | E26: =C26*D26 -> 189.9705 | F26: =C26+E26 -> 1456.4405 | G26: trim stick 10 ft | H26: =ROUNDUP(F26/Inputs!$B$18,0) -> 146 | I26: familias_out.json 'metal trim (corner bead, casing, shadow molding)'; 7/A09.33; 8/A12.01; 6/A09.33
A27: Cement board at tile cove base | B27: SF | C27: 31.38 | D27: =Inputs!$B$6 -> 0.06 | E27: =C27*D27 -> 1.8828 | F27: =C27+E27 -> 33.2628 | G27: 3x5 sheet | H27: =ROUNDUP(F27/15,0) -> 3 | I27: familias_out.json 'cement board'; A08.01 CT-12C
A28: FRP panel | B28: SF | C28: 329.75 | D28: =Inputs!$B$6 -> 0.06 | E28: =C28*D28 -> 19.785 | F28: =C28+E28 -> 349.535 | G28: 4x10 sheet | H28: =ROUNDUP(F28/40,0) -> 9 | I28: familias_out.json 'FRP'; A/A08.01; A05.01 key note 6
A29: Acoustical sealant | B29: LF | C29: 1184.93 | D29: =Inputs!$B$6 -> 0.06 | E29: =C29*D29 -> 71.0958 | F29: =C29+E29 -> 1256.0258 | G29: tube (25 LF per tube) | H29: =ROUNDUP(F29/Inputs!$B$15,0) -> 51 | I29: familias_out.json 'acoustical sealant'; 1/A12.01; 3/A12.01; 4/A12.01
A30: Framed openings - recessed fixtures and air devices in GWB ceilings and canopy soffits | B30: LF | C30: 949.87 | D30: =Inputs!$B$5 -> 0.15 | E30: =C30*D30 -> 142.4805 | F30: =C30+E30 -> 1092.3505 | G30: stick 20 ft | H30: =ROUNDUP(F30/Inputs!$B$10,0) -> 55 | I30: framed_openings_out.json; E00.01; E02.01; M01.01; 6/A09.33
A31: 5/8" exterior grade FRT plywood (canopy soffits, fascia, column wraps) | B31: SF | C31: 2120.11 | D31: =Inputs!$B$6 -> 0.06 | E31: =C31*D31 -> 127.2066 | F31: =C31+E31 -> 2247.3166 | G31: 4x12 ft sheet (Inputs) | H31: =ROUNDUP(F31/Inputs!$B$9,0) -> 47 | I31: familias_out.json FRT plywood by material; 7/A09.26; 11/A09.27; 12/A12.01
A32: 5/8" FRT plywood bonded to 2-1/2" polyiso (exterior sheathing / nailbase) | B32: SF | C32: 3957.23 | D32: =Inputs!$B$6 -> 0.06 | E32: =C32*D32 -> 237.4338 | F32: =C32+E32 -> 4194.6638 | G32: 4x12 ft sheet (Inputs) | H32: =ROUNDUP(F32/Inputs!$B$9,0) -> 88 | I32: familias_out.json FRT plywood by material; 7/A09.26; 11/A09.27; 12/A12.01
A33: 3/4" FRT plywood | B33: SF | C33: 693.96 | D33: =Inputs!$B$6 -> 0.06 | E33: =C33*D33 -> 41.6376 | F33: =C33+E33 -> 735.5976 | G33: 4x12 ft sheet (Inputs) | H33: =ROUNDUP(F33/Inputs!$B$9,0) -> 16 | I33: familias_out.json FRT plywood by material; 7/A09.26; 11/A09.27; 12/A12.01
A34: 5/8" FRT plywood | B34: SF | C34: 32.62 | D34: =Inputs!$B$6 -> 0.06 | E34: =C34*D34 -> 1.9572 | F34: =C34+E34 -> 34.5772 | G34: 4x12 ft sheet (Inputs) | H34: =ROUNDUP(F34/Inputs!$B$9,0) -> 1 | I34: familias_out.json FRT plywood by material; 7/A09.26; 11/A09.27; 12/A12.01
A35: Sealant at base of gypsum (exterior, not acoustical) | B35: LF | C35: 219.61 | D35: =Inputs!$B$6 -> 0.06 | E35: =C35*D35 -> 13.1766 | F35: =C35+E35 -> 232.7866 | G35: tube (25 LF per tube) | H35: =ROUNDUP(F35/Inputs!$B$15,0) -> 10 | I35: familias_out.json acoustical sealant rows 'base of gypsum (exterior)'
A36: Hanger wire 12 ga - hanger count (one per hanger, height per room) | B36: PCS | C36: 113 | D36: 0 | E36: =C36*D36 -> 0 | F36: =C36+E36 -> 113 | H36: =ROUNDUP(F36,0) -> 113 | I36: familias_out.json hanger_pcs.total_pcs; wire bought on the LF row
A37: Additional head track at openings over 4'-0" wide | B37: LF | C37: 56 | D37: =Inputs!$B$5 -> 0.15 | E37: =C37*D37 -> 8.4 | F37: =C37+E37 -> 64.4 | G37: run 10 ft | H37: =ROUNDUP(F37/Inputs!$B$11,0) -> 7 | I37: accesorios.py [CRITERION]: HEAD TRACK @ NON LOAD BRG: ADD FULL LENGTH ADDL HEAD TRACK @ OPNG > 4'-0"; Estimator user decision #1: R.O. + 1'-4" (8" bearing each side)
A38: Stud reinforcement at MEP penetrations | B38: PCS | C38: 32 | D38: 0 | E38: =C38*D38 -> 0 | F38: =C38+E38 -> 32 | G38: each | H38: =ROUNDUP(F38,0) -> 32 | I38: accesorios.py [CRITERION]: 6/S5.20; 1/P01.01 '2" ST' solid (above ceiling, P01.01 general note 1); 6/S5.20; 1/P01.01 '2" ST 10 GPM'; 6/S5.20; 1/P01.01 '2" ST 15 GPM'; 6/S5.20; 1/P01.01 '2" ST' 'CO'; 6/S5.20; 1/P01.01 'UP TO DRAIN'; 6/S5.20; 1/P01.01 'CO'; 6/S5.20; 1/
A39: Extra framing - sistered stud and furring at the ATM recess | B39: LF | C39: 22.42 | D39: =Inputs!$B$5 -> 0.15 | E39: =C39*D39 -> 3.363 | F39: =C39+E39 -> 25.783 | G39: stick 20 ft | H39: =ROUNDUP(F39/Inputs!$B$10,0) -> 2 | I39: accesorios.py [CRITERION]: 6/A08.11; 7/A08.11
A40: 2-1/2" CFMF @ 16" O.C. at coiling grille head (4/A08.21) | B40: LF | C40: 10.43 | D40: =Inputs!$B$5 -> 0.15 | E40: =C40*D40 -> 1.5645 | F40: =C40+E40 -> 11.9945 | G40: stick 20 ft | H40: =ROUNDUP(F40/Inputs!$B$10,0) -> 1 | I40: accesorios.py [DERIVED]: 4/A08.21
...

Sheet Pending Items
A1: RFI | B1: Question / condition | C1: Delta of each alternative
A2: RFI-ACC-additional-head-track | B2: additional head track: openings with their own box (openings_extra) > 4'-0": do they also take the additional head track of 2/S5.20? | C2: 107.04 lf
A3: RFI-ACC-extra-framing-atm | B3: extra framing ATM: ATM-DU drive-up (NHA 9D TTW): ATM recess not fully dimensioned (width CONFIRMED, sistered height DERIVED, furring rows DERIVED) | C3: 8.21 lf
A4: RFI-ACC-gypsum-board-jamb-return | B4: gypsum board jamb return: jamb return width not dimensioned | C4: -54.69 sf
A5: RFI-ACC-slab-pins | B5: slab pins: pin spacing: 12" (interior anchorage) vs 16" (fastener schedule) vs 24" (type K box) | C5: 16in: -120.22 pcs; 24in: -240.45 pcs
A6: RFI-A01 | B6: Exterior stud: S1.11 note 5 calls 600S162-54 @ 16" O.C. and @ 12" O.C. within 6 ft of building corners; 7/S5.20 calls 600S137-33 @ 16" O.C. Carried S1.11 (more material). | C6: 33 mil vs 54 mil gauge; corner zones add studs at 12" O.C. within 6 ft each side (included in 6" stud LF)
A7: RFI-A02 | B7: No header schedule row for exterior non-load-bearing walls; openings 3'-4" to 4'-0": 9/S5.20 single vs 7/S5.20 double. Carried double. | C7: 1 track piece x (R.O. + 1'-4") per opening
A8: RFI-A03 | B8: S2.20 note '@ LOW ROOF' south of grid E without a B.O.D.; zone E-B carried at 15'-4 1/2". | C8: -2.32 ft per stud / hanger in zone E-B if 13'-0 5/8"
A9: RFI-A04 | B9: Canopy B.O.D. printed 111'-9" on S2.20 (typo); 11'-9" carried (T/STEEL J, H/A09.23). | C9: n/a: no partition to deck at canopy
A10: RFI-A05 | B10: Canopy beam in the exterior stud plane (C/A09.21, D/A09.22, H/A09.23, 7/S5.11): stud carried continuous to the roof beam. | C10: split stud: -1.02 to -1.31 ft per stud and +2 track lines per LF
A11: RFI-A06 | B11: Beam on grid 3 F-E has no mark on S2.20. | C11: W12: stud 14.36 ft; W16: 14.07 ft
A12: RFI-A07 | B12: Board sheet length not specified; 12 ft carried. | C12: n/a: sheet size is an Inputs parameter
... A75: RFI-ASM-02 | B75: Canopy soffit wall line measured equal to the fascia line (CS-W, CS-N); E13 asks for a separate measurement. | C75: track: wall line at corners differs by the canopy depth

Sheet Review Items
A1: # | B1: Item | C1: Sheet + detail | D1: Image
A2: 1 | B2: Confirm exterior stud gauge and 12" corner zones (RFI-A01): S1.11 vs 7/S5.20. | C2: see RFI | D2: Planos marcados
A3: 2 | B3: Confirm B.O.D. in zone E-B (RFI-A03) - drives stud and hanger heights in Waiting 104 area. | C3: see RFI | D3: Planos marcados
A4: 3 | B4: Confirm office front CONT. BOX BEAM run length per front (RFI-01). | C4: see RFI | D4: Planos marcados
A5: 4 | B5: Confirm ballistic contour faces at the teller pod (RFI-03). | C5: see RFI | D5: Planos marcados
A6: 5 | B6: Confirm C1 furring height (RFI-04) and vestibule head height / stud size (RFI-08). | C6: see RFI | D6: Planos marcados
A7: 6 | B7: Confirm canopy linear fixtures UU1-UU6 framed openings are by drywall contractor (54.1, 4,5/A09.33). | C7: see RFI | D7: Planos marcados
A8: 7 | B8: Confirm canopy beam in exterior wall plane (RFI-A05): continuous vs split stud. | C8: see RFI | D8: Planos marcados
A9: 8 | B9: Confirm Level 5 WC-20 extent (RFI-E07). | C9: see RFI | D9: Planos marcados
A10: 9 | B10: Check walls partially under beams (vigas_sobre_walls.py <70%) carried to deck (RFI-ASM-01). | C10: see RFI | D10: Planos marcados
A11: 10 | B11: W036a (A5) band touches the roof step RS bands at grid B (partition_types warning R11): the roof step is at roof level, the partition at floor level. | C11: see RFI | D11: Planos marcados
A12: 11 | B12: Exterior outside-corner trim sweep: only the trims listed in detail callouts are carried; project-wide outside corners of partitions not swept one by one. | C12: see RFI | D12: Planos marcados
A13: 12 | B13: E02.x wall-mounted electrical equipment not crossed against walls (MEP sweep covered P01.01, P01.02, M01.01, M01.02). | C13: see RFI | D13: Planos marcados

Sheet Scope Checklist
A1: Scope ID | B1: Scope | C1: Status | D1: Note (quantity, NOT APPLICABLE + sheet, or RFI)
A2: ALC-01 | B2: ALC-01 | C2: QUANTIFIED | D2: Partition Takeoff; 3-5/8" / 6" / 1-5/8" stud rows; A12.01
A3: ALC-02 | B3: ALC-02 | C3: QUANTIFIED | D3: EXT-6CFMF rows; C/A09.21, D/A09.22, H/A09.23
A4: ALC-03 | B4: ALC-03 | C4: QUANTIFIED | D4: EXT-PARAPET rows; 11/S5.10, 4/A09.26
A5: ALC-04 | B5: ALC-04 | C5: QUANTIFIED | D5: bottom and top / deflection track rows; 7/S5.20, 3/A12.01
A6: ALC-05 | B6: ALC-05 | C6: QUANTIFIED | D6: header / box beam and sill track rows; 7/S5.20, 2/S5.20
A7: ALC-06 | B7: ALC-06 | C7: QUANTIFIED | D7: bracing row; F/1/S5.20
A8: ALC-07 | B8: ALC-07 | C8: QUANTIFIED | D8: 5/8" gypsum board regular row; A12.01
A9: ALC-08 | B9: ALC-08 | C9: QUANTIFIED | D9: 5/8" moisture resistant row; F/A08.01
A10: ALC-09 | B10: ALC-09 | C10: QUANTIFIED | D10: glass mat and exterior gypsum sheathing rows; 5/A09.26, 4/A09.26
A11: ALC-10 | B11: ALC-10 | C11: QUANTIFIED | D11: FRT plywood rows by material; 7/A09.26, 11/A09.27, 12/A12.01
A12: ALC-11 | B12: ALC-11 | C12: QUANTIFIED | D12: GWB ceilings 100, 101, 104, 113, 114 in board row; A04.01
... A26: ALC-X25 | B26: batt insulation | C26: NOT APPLICABLE | D26: EXCLUDED (estimator criterion: no insulation)
