Workbook

Sheet Inputs
A1: O'Reilly Auto Parts Store - 23rd Ave., Evans, CO #1 | METAL FRAMING & DRYWALL TAKEOFF
A2: Bid set: EV1 Current Conformed Set 11-20-2025 (clean copy, 81 annotations removed) · 2026-10-31 · Edit ONLY the yellow cells.
A4: PARAMETER | B4: VALUE | C4: NOTE / SOURCE
A5: Waste - ALL METAL, any type | B5: 0.15 | C5: Estimator standing rule: 15% on everything that is metal.
A6: Waste - EVERYTHING THAT IS NOT METAL | B6: 0.06 | C6: Estimator standing rule: same figure as board.
A7: Board sheet width (ft) | B7: 4 | C7: Sheet size is a parameter; buy the size that wastes least.
A8: Board sheet length (ft) | B8: 12 | C8: Change it and every sheet count re-rounds.
A9: SF per board sheet | B9: =B7*B8 -> 48 | C9: Width x length.
A10: Stud stock length (ft) | B10: 20 | C10: Stud, header, framed opening and stud blocking: sticks.
A11: Track stock length (ft) | B11: 10 | C11: Track, sill track and purlin: runs.
A12: Floor plan scale (pt/ft) | B12: n/a | C12: Project value (not used in this take-off: heights are per wall in the Partition Takeoff).
A13: B.O. Deck (ft) | B13: n/a | C13: Project value (not used in this take-off: heights are per wall in the Partition Takeoff).
A14: T.O. Parapet (ft) | B14: n/a | C14: Project value (not used in this take-off: heights are per wall in the Partition Takeoff).
A15: Sealant coverage (LF per tube) | B15: 25 | C15: Sealant yield per tube - set your supplier's figure.
A16: C.R. channel stock length (ft) | B16: 16 | C16: 1-1/2" cold-rolled channel (bracing, carrying channel).
A17: Hat / furring channel stock (ft) | B17: 12 | C17: 7/8" hat furring channel.
A18: Trim stick length (ft) | B18: 10 | C18: Corner bead, casing bead, shadow molding, PVC trim.
A19: Hanger wire purchase | B19: continuous coil (LF) | C19: Bought by LF from a continuous coil; the hanger count goes on its own PCS row.
A20: Drywall screws per SF of board | B20: 1.2 | C20: YIELD (GA-216 field / perimeter spacing).
A21: Framing screws per stud piece | B21: 4 | C21: YIELD: 2 per stud-to-track connection, each end.
A22: Power-driven pin spacing (ft) | B22: 4 | C22: YIELD: bottom track on slab, interior walls.
A23: Joint compound (lb per SF) | B23: 0.072 | C23: YIELD: 72 lb per 1,000 SF, level 4 (estimator criterion).
A24: Joint tape (LF per SF) | B24: 0.37 | C24: YIELD: 370 LF per 1,000 SF.
A25: Expansion anchor spacing (ft) | B25: 4 | C25: YIELD: exterior bottom track on slab.
A26: 2x lumber stock length (ft) | B26: 16 | C26: 2x wood / FRT blocking: 16 ft sticks (precedent: estimator decision 2026-10-27 on a previous project; skill standing input).
A27: Drywall grid main tee length (ft) | B27: 12 | C27: USG DGLW26 main tee (manufacturer length).
A28: Drywall grid cross tee length (ft) | B28: 4 | C28: USG DGLW424 cross tee (manufacturer length).
A29: Grid channel / angle molding length (ft) | B29: 12 | C29: USG DGCM27 / DGWM24 molding (manufacturer length).
A30: FRP panel (SF per panel) | B30: 40 | C30: FRP-1 panel 4'x10' (estimator to confirm the panel size).

Sheet Partition Takeoff
A1: ORGANIZED PARTITION TAKEOFF - O'Reilly Auto Parts Store - 23rd Ave., Evans, CO #1
A2: Grouped by partition type. Every row cites its DETAIL/SHEET and its status.
A4: Partition / Scope | B4: Wall # | C4: Length (LF) | D4: Height (FT) | E4: Layers | F4: Stud Size | G4: Stud O.C. (in) | H4: Board (SF) | I4: Location | J4: Source (DETAIL/SHEET) | K4: Status
A5: TYPE S21
A6: S21 #S21-E1 - East facade (grid A) interior furring, Parts C 105, from the north furring face to office 102 west wall | B6: S21-E1 | C6: 45.346 | D6: 14.625 | E6: 1 | F6: 1-1/2" Z-furring (150ZF125-18) 18 mil (25 ga) - 150ZF125-18 | G6: 24 | H6: 663.19 | I6: East facade (grid A) interior furring, Parts C 105, from the north furring face to office 102 west wall | Board by face: A Parts Area C 105 45.35 x 14.62 ft (5/8 type X) | J6: S21/A1.1 | K6: [DERIVED]
A7: S21 #S21-E2 - East facade (grid A) interior furring, Break Area (between office 102 east wall and R.R. 103 west wall) | B7: S21-E2 | C7: 10.882 | D7: 14.625 | E7: 1 | F7: 1-1/2" Z-furring (150ZF125-18) 18 mil (25 ga) - 150ZF125-18 | G7: 24 | H7: 159.15 | I7: East facade (grid A) interior furring, Break Area (between office 102 east wall and R.R. 103 west wall) | Board by face: A Break Area (Parts C 105) 10.88 x 14.62 ft (5/8 type X) | J7: S21/A1.1 | K7: [DERIVED]
A8: S21 #S21-N - North facade (grid 1) interior furring, Parts C 105 + Parts A 100, full length between E and W furring faces | B8: S21-N | C8: 84.708 | D8: 15.511 | E8: 1 | F8: 1-1/2" Z-furring (150ZF125-18) 18 mil (25 ga) - 150ZF125-18 | G8: 24 | H8: 1313.91 | I8: North facade (grid 1) interior furring, Parts C 105 + Parts A 100, full length between E and W furring faces | Board by face: B Parts Area C 105 / Parts Area A 100 84.71 x 15.51 ft (5/8 type X) | J8: S21/A1.1 | K8: [DERIVED]
A9: S21 #S21-S - South facade (grid 4) interior furring, Parts B 101 / Parts C 105, from R.R. 104 south wall to the west furring face | B9: S21-S | C9: 75.64 | D9: 15.511 | E9: 1 | F9: 1-1/2" Z-furring (150ZF125-18) 18 mil (25 ga) - 150ZF125-18 | G9: 24 | H9: 1173.25 | I9: South facade (grid 4) interior furring, Parts B 101 / Parts C 105, from R.R. 104 south wall to the west furring face | Board by face: A Parts Area B 101 / Parts Area C 105 75.64 x 15.51 ft (5/8 type X) | J9: S21/A1.1 | K9: [DERIVED]
A10: S21 #S21-W1 - West facade (grid C) interior furring, Parts A 100, from the north furring face to the left entry pier | B10: S21-W1 | C10: 9.22 | D10: 16.396 | E10: 1 | F10: 1-1/2" Z-furring (150ZF125-18) 18 mil (25 ga) - 150ZF125-18 | G10: 24 | H10: 151.17 | I10: West facade (grid C) interior furring, Parts A 100, from the north furring face to the left entry pier | Board by face: B Parts Area A 100 9.22 x 16.4 ft (5/8 type X) | J10: S21/A1.1 | K10: [DERIVED]
A11: S21 #S21-W2 - West facade (grid C) interior furring, Parts B 101, from the right entry pier (concealed column, key note 1) to the south furring face | B11: S21-W2 | C11: 24.911 | D11: 16.396 | E11: 1 | F11: 1-1/2" Z-furring (150ZF125-18) 18 mil (25 ga) - 150ZF125-18 | G11: 24 | H11: 408.44 | I11: West facade (grid C) interior furring, Parts B 101, from the right entry pier (concealed column, key note 1) to the south furring face | Board by face: B Parts Area B 101 24.91 x 16.4 ft (5/8 type X) | J11: S21/A1.1 | K11: [DERIVED]
B12: SUBTOTAL TYPE S21 | C12: =SUM(C6:C11) -> 250.707 | H12: =SUM(H6:H11) -> 3869.11
A13: TYPE S24
A14: S24 #S24-OFF - Office 102 east-facade wall (furring + stud lining), between office west and east walls | B14: S24-OFF | C14: 11 | D14: 8.5 | E14: 1 | F14: 3-5/8" 33 mil (20 ga) - 362S162-33 | G14: 24 | H14: 93.5 | I14: Office 102 east-facade wall (furring + stud lining), between office west and east walls | J14: S24/A1.1 | K14: [CONFIRMED]
A15: S24 #S24-RR - R.R. 103 + R.R. 104 east-facade wall (one line, two S24 tags), from R.R. 103 west wall to the south-facade S24 | B15: S24-RR | C15: 16.167 | D15: 8.5 | E15: 1 | F15: 3-5/8" 33 mil (20 ga) - 362S162-33 | G15: 24 | H15: 137.42 | I15: R.R. 103 + R.R. 104 east-facade wall (one line, two S24 tags), from R.R. 103 west wall to the south-facade S24 | J15: S24/A1.1 | K15: [CONFIRMED]
A16: S24 #S24-RR104S - R.R. 104 south-facade wall (furring + stud lining), horizontal S24 tag | B16: S24-RR104S | C16: 8.5 | D16: 8.5 | E16: 1 | F16: 3-5/8" 33 mil (20 ga) - 362S162-33 | G16: 24 | H16: 72.25 | I16: R.R. 104 south-facade wall (furring + stud lining), horizontal S24 tag | J16: S24/A1.1 | K16: [CONFIRMED]
B17: SUBTOTAL TYPE S24 | C17: =SUM(C14:C16) -> 35.667 | H17: =SUM(H14:H16) -> 303.17
A18: TYPE S41
A19: S41 #S41-B-H - Showroom corner box-out at the north wall / S42 corner (key note 5), leg parallel to S42 | B19: S41-B-H | C19: 1.313 | D19: 12 | E19: 1 | F19: 3-5/8" 33 mil (20 ga) - 362S162-33 | G19: 24 | H19: 15.76 | I19: Showroom corner box-out at the north wall / S42 corner (key note 5), leg parallel to S42 | Board by face: A Parts Area A 100 1.31 x 12 ft (5/8 type X) | J19: 4/A4.2 | K19: [DERIVED]
A20: S41 #S41-B-V - Showroom corner box-out at the north wall / S42 corner (key note 5), leg parallel to the north wall | B20: S41-B-V | C20: 2.167 | D20: 12 | E20: 1 | F20: 3-5/8" 33 mil (20 ga) - 362S162-33 | G20: 24 | H20: 26 | I20: Showroom corner box-out at the north wall / S42 corner (key note 5), leg parallel to the north wall | Board by face: B Parts Area A 100 2.17 x 12 ft (5/8 type X) | J20: 4/A4.2 | K20: [CONFIRMED]
A21: S41 #S41-C-H - Showroom corner box-out at the north/west corner (key note 5), leg parallel to the west wall | B21: S41-C-H | C21: 1.313 | D21: 12 | E21: 1 | F21: 3-5/8" 33 mil (20 ga) - 362S162-33 | G21: 24 | H21: 15.76 | I21: Showroom corner box-out at the north/west corner (key note 5), leg parallel to the west wall | Board by face: B Parts Area A 100 1.31 x 12 ft (5/8 type X) | J21: 4/A4.2 | K21: [DERIVED]
A22: S41 #S41-C-V - Showroom corner box-out at the north/west corner (key note 5), leg parallel to the north wall | B22: S41-C-V | C22: 1.667 | D22: 12 | E22: 1 | F22: 3-5/8" 33 mil (20 ga) - 362S162-33 | G22: 24 | H22: 20 | I22: Showroom corner box-out at the north/west corner (key note 5), leg parallel to the north wall | Board by face: B Parts Area A 100 1.67 x 12 ft (5/8 type X) | J22: 4/A4.2 | K22: [CONFIRMED]
B23: SUBTOTAL TYPE S41 | C23: =SUM(C19:C22) -> 6.46 | H23: =SUM(H19:H22) -> 77.52
A24: TYPE S42
A25: S42 #S42-H1+S42-H2 - Parts A 100 / Parts C 105 demising wall near grid B, floor-supported full-height part (hatched), north wall to the gypsum board joint 2/A4.2 + S42 suspended header wall near grid B (non-hatched double line), joint 2/A4.2 east to the free end past the S42 vertical wall; OFCI sales counters / fixtures below (14/A4.1) | B25: S42-H1+S42-H2 | C25: 64.11 | D25: 12.461 | E25: 2 | F25: 3-5/8" 33 mil (20 ga) - 362S162-33 | G25: 24 | H25: 1415.77 | I25: Parts A 100 / Parts C 105 demising wall near grid B, floor-supported full-height part (hatched), north wall to the gypsum board joint 2/A4.2 + S42 suspended header wall near grid B (non-hatched double line), joint 2/A4.2 east to the free end past the S42 vertical wall; OFCI sales counters / fixtures below (14/A4.1) | Board by face: S42-H1 A Parts Area A 100 38.67 x 12 ft (5/8 type X); S42-H1 B Parts Area C 105 38.67 x 15.17 ft (5/8 type X); S42-H2 A Parts Area A 100 18.69 x 5.17 ft (5/8 type X); S42-H2 A Parts Area B 101 6.75 x 8.34 ft (5/8 type X); S42-H2 B Parts Area C 105 25.44 x 8.34 ft (5/8 type X) | J25: 5/A4.2; 6/A4.2 | K25: [DERIVED]
A26: S42 #S42-V1+S42-V2 - S42 suspended header wall between Parts A 100 and Parts B 101 (non-hatched double line), from S42-H2 down to the joint 2/A4.2 + S42 floor-supported full-height part (hatched) between Parts A 100 and Parts B 101, joint 2/A4.2 to the right entry pier (west facade) | B26: S42-V1+S42-V2 | C26: 58.5 | D26: 9.905 | E26: 2 | F26: 3-5/8" 33 mil (20 ga) - 362S162-33 | G26: 24 | H26: 937.52 | I26: S42 suspended header wall between Parts A 100 and Parts B 101 (non-hatched double line), from S42-H2 down to the joint 2/A4.2 + S42 floor-supported full-height part (hatched) between Parts A 100 and Parts B 101, joint 2/A4.2 to the right entry pier (west facade) | Board by face: S42-V1 A Parts Area A 100 50.33 x 5.17 ft (5/8 type X); S42-V1 B Parts Area B 101 50.33 x 8.87 ft (5/8 type X); S42-V2 A Parts Area A 100 8.17 x 12 ft (5/8 type X); S42-V2 B Parts Area B 101 8.17 x 16.31 ft (5/8 type X) | J26: 6/A4.2; 5/A4.2 | K26: [CONFIRMED]
B27: SUBTOTAL TYPE S42 | C27: =SUM(C25:C26) -> 122.61 | H27: =SUM(H25:H26) -> 2353.29
A28: TYPE S43
A29: S43 #S43-OFF-E - Office 102 east wall (Break Area side) | B29: S43-OFF-E | C29: 8.664 | D29: 8.5 | E29: 2 | F29: 3-5/8" 33 mil (20 ga) - 362S162-33 | G29: 24 | H29: 151.62 | I29: Office 102 east wall (Break Area side) | Board by face: A Office 102 8.66 x 8.5 ft (5/8 type X); B Break Area (Parts C 105) 8.66 x 9 ft (5/8 type X) | J29: S43/A1.1 | K29: [DERIVED]
A30: S43 #S43-OFF-S - Office 102 south wall with door 4 (between the office west and east walls) | B30: S43-OFF-S | C30: 11 | D30: 8.5 | E30: 2 | F30: 3-5/8" 33 mil (20 ga) - 362S162-33 | G30: 24 | H30: 192.5 | I30: Office 102 south wall with door 4 (between the office west and east walls) | Board by face: A Parts Area C 105 11 x 9 ft (5/8 type X); B Office 102 11 x 8.5 ft (5/8 type X) | J30: S43/A1.1 | K30: [CONFIRMED]
A31: S43 #S43-OFF-W - Office 102 west wall (Parts C side) | B31: S43-OFF-W | C31: 8.642 | D31: 8.5 | E31: 2 | F31: 3-5/8" 33 mil (20 ga) - 362S162-33 | G31: 24 | H31: 151.24 | I31: Office 102 west wall (Parts C side) | Board by face: A Parts Area C 105 8.64 x 9 ft (5/8 type X); B Office 102 8.64 x 8.5 ft (5/8 type X) | J31: S43/A1.1 | K31: [DERIVED]
A32: S43 #S43-RR103-W - R.R. 103 west wall (alcove / Break Area side) | B32: S43-RR103-W | C32: 9.106 | D32: 8.5 | E32: 2 | F32: 3-5/8" 33 mil (20 ga) - 362S162-33 | G32: 24 | H32: 159.35 | I32: R.R. 103 west wall (alcove / Break Area side) | Board by face: A Break Area (Parts C 105) 9.11 x 9 ft (5/8 type X); B R.R. 103 9.11 x 8.5 ft (5/8 type X WR) | J32: S43/A1.1 | K32: [DERIVED]
A33: S43 #S43-RR-S - R.R. 103 + R.R. 104 south (Parts C) wall, one line with two S43 tags, doors 5 and 6 | B33: S43-RR-S | C33: 16.167 | D33: 8.5 | E33: 2 | F33: 3-5/8" 33 mil (20 ga) - 362S162-33 | G33: 24 | H33: 282.92 | I33: R.R. 103 + R.R. 104 south (Parts C) wall, one line with two S43 tags, doors 5 and 6 | Board by face: A Parts Area C 105 16.17 x 9 ft (5/8 type X); B R.R. 103 8.08 x 8.5 ft (5/8 type X WR); B R.R. 104 8.08 x 8.5 ft (5/8 type X WR) | J33: S43/A1.1 | K33: [CONFIRMED]
B34: SUBTOTAL TYPE S43 | C34: =SUM(C29:C33) -> 53.579 | H34: =SUM(H29:H33) -> 937.63
A35: TYPE S61
A36: S61 #S61-RR - R.R. 103 / R.R. 104 common wall (6" plumbing wall) | B36: S61-RR | C36: 8.5 | D36: 8.5 | E36: 2 | F36: 6" 33 mil (20 ga) - 600S162-33 | G36: 24 | H36: 144.5 | I36: R.R. 103 / R.R. 104 common wall (6" plumbing wall) | J36: S61/A1.1 | K36: [CONFIRMED]
B37: SUBTOTAL TYPE S61 | C37: =SUM(C36:C36) -> 8.5 | H37: =SUM(H36:H36) -> 144.5
A38: TYPE EXT-8CFMF
A39: EXT-8CFMF #EXT-PIER-L-8+EXT-HEAD-8+EXT-PIER-R-8 - West facade left (north) entry pier at 1/A3.1, inner 8" stud row (7/A3.2) + West facade head wall over storefront A (18'-8" + 8'-0" vestibule + 12'-0"), inner 8" row + West facade right (south) entry pier at 2/A3.1, inner 8" stud row (7/A3.2) | B39: EXT-PIER-L-8+EXT-HEAD-8+EXT-PIER-R-8 | C39: 50.667 | D39: 12.017 | E39: 0.84 | F39: 8" 54 mil (16 ga) - 800S162-54 | G39: 16 | H39: 352.03 | I39: West facade left (north) entry pier at 1/A3.1, inner 8" stud row (7/A3.2) + West facade head wall over storefront A (18'-8" + 8'-0" vestibule + 12'-0"), inner 8" row + West facade right (south) entry pier at 2/A3.1, inner 8" stud row (7/A3.2) | Board by face: EXT-PIER-L-8 B Parts Area A 100 6 x 16.4 ft (5/8 type X); EXT-HEAD-8 B Parts Area A 100 30.67 x 5.06 ft (5/8 type X); EXT-HEAD-8 B Vestibule 100A (above the C-3 ceiling) 8 x 0 ft (5/8 type X); EXT-PIER-R-8 B Parts Area A 100 6 x 16.4 ft (5/8 type X) | J39: 1/A3.1; 3/A3.1 | K39: [CONFIRMED]
B40: SUBTOTAL TYPE EXT-8CFMF | C40: =SUM(C39:C39) -> 50.667 | H40: =SUM(H39:H39) -> 352.03
A41: TYPE EXT-6CFMF
...

Sheet Material Summary
A1: MATERIAL SUMMARY - NET / WASTE / PURCHASE
A2: Waste lives HERE, in its own column, applied ONCE: Pieces = ROUNDUP(Net x (1 + waste) / stock). Every stock length, coverage and yield is an Inputs cell.
A3: Material | B3: Unit | C3: Net | D3: Waste % | E3: Waste | F3: Purchase | G3: Selling unit | H3: Pieces to buy | I3: Where it comes from | J3: Yield check (live formula)
A4: Bottom track 3-5/8" | B4: LF | C4: 218.32 | D4: =Inputs!$B$5 -> 0.15 | E4: =C4*D4 -> 32.748 | F4: =C4+E4 -> 251.068 | G4: run 10 ft | H4: =ROUNDUP(F4/Inputs!$B$11,0) -> 26 | I4: N/SHEET: not applicable (see note) | Breakdown [DERIVED]: S24-OFF 11 + S24-RR 16.17 + S24-RR104S 8.5 + S43-OFF-W 8.64 + S43-OFF-E 8.66 + S43-OFF-S 11 + S43-RR103-W 9.11 + S43-RR-S 16.17 + S41-B-V 2.17 + S41-B-H 1.31 + S41-C-V 1.67 + S41-C-H 1.31 + S42-H1 38.67 + S42-H2 25.44 + S42-V1 50.33 + S42-V2 8.17 = 218.32 LF (wall length x rows) | Track gauge = stud gauge of each wall: 33 mil (20 ga) - 362S162-33 218.32 LF
A5: Bottom track 6" | B5: LF | C5: 95.17 | D5: =Inputs!$B$5 -> 0.15 | E5: =C5*D5 -> 14.2755 | F5: =C5+E5 -> 109.4455 | G5: run 10 ft | H5: =ROUNDUP(F5/Inputs!$B$11,0) -> 11 | I5: N/SHEET: not applicable (see note) | Breakdown [DERIVED]: S61-RR 8.5 + EXT-PIER-L-6 6 + EXT-PIER-R-6 6 + EXT-HEAD-6 38.67 + EXT-SOUTH-BAND 36 = 95.17 LF (wall length x rows) | Track gauge = stud gauge of each wall: 33 mil (20 ga) - 600S162-33 8.5 LF; 54 mil (16 ga) - 600S162-54 50.67 LF; 43 mil (18 ga) - 600S162-43 36 LF
A6: Bottom track 8" | B6: LF | C6: 50.67 | D6: =Inputs!$B$5 -> 0.15 | E6: =C6*D6 -> 7.6005 | F6: =C6+E6 -> 58.2705 | G6: run 10 ft | H6: =ROUNDUP(F6/Inputs!$B$11,0) -> 6 | I6: N/SHEET: not applicable (see note) | Breakdown [DERIVED]: EXT-PIER-L-8 6 + EXT-PIER-R-8 6 + EXT-HEAD-8 38.67 = 50.67 LF (wall length x rows) | Track gauge = stud gauge of each wall: 54 mil (16 ga) - 800S162-54 50.67 LF
A7: Bottom track - roof step and heads (vestibule / bulkhead) | B7: LF | C7: 20.57 | D7: =Inputs!$B$5 -> 0.15 | E7: =C7*D7 -> 3.0855 | F7: =C7+E7 -> 23.6555 | G7: run 10 ft | H7: =ROUNDUP(F7/Inputs!$B$11,0) -> 3 | I7: N/SHEET: not applicable (see note) | Breakdown [DERIVED]: VEST-HD-C 8.49 + VEST-HD-B2 6.04 + VEST-HD-B1 6.04 = 20.57 LF (wall length x rows) | Track gauge = stud gauge of each wall: 54 mil (16 ga) - 600S162-54 20.57 LF
A8: Top / deflection track 3-5/8" | B8: LF | C8: 171.48 | D8: =Inputs!$B$5 -> 0.15 | E8: =C8*D8 -> 25.722 | F8: =C8+E8 -> 197.202 | G8: run 10 ft | H8: =ROUNDUP(F8/Inputs!$B$11,0) -> 20 | I8: N/SHEET: not applicable (see note) | Breakdown [DERIVED]: S24-OFF 11 + S24-RR 16.17 + S24-RR104S 8.5 + S43-OFF-W 8.64 + S43-OFF-E 8.66 + S43-OFF-S 11 + S43-RR103-W 9.11 + S43-RR-S 16.17 + S41-B-V 2.17 + S41-B-H 1.31 + S41-C-V 1.67 + S41-C-H 1.31 + S42-H2 25.44 + S42-V1 50.33 = 171.48 LF (wall length x rows) | Track gauge = stud gauge of each wall: 33 mil (20 ga) - 362S162-33 171.48 LF
A9: Top / deflection track 6" | B9: LF | C9: 95.17 | D9: =Inputs!$B$5 -> 0.15 | E9: =C9*D9 -> 14.2755 | F9: =C9+E9 -> 109.4455 | G9: run 10 ft | H9: =ROUNDUP(F9/Inputs!$B$11,0) -> 11 | I9: N/SHEET: not applicable (see note) | Breakdown [DERIVED]: S61-RR 8.5 + EXT-PIER-L-6 6 + EXT-PIER-R-6 6 + EXT-HEAD-6 38.67 + EXT-SOUTH-BAND 36 = 95.17 LF (wall length x rows) | Track gauge = stud gauge of each wall: 33 mil (20 ga) - 600S162-33 8.5 LF; 54 mil (16 ga) - 600S162-54 50.67 LF; 43 mil (18 ga) - 600S162-43 36 LF
A10: Top / deflection track 8" | B10: LF | C10: 50.67 | D10: =Inputs!$B$5 -> 0.15 | E10: =C10*D10 -> 7.6005 | F10: =C10+E10 -> 58.2705 | G10: run 10 ft | H10: =ROUNDUP(F10/Inputs!$B$11,0) -> 6 | I10: N/SHEET: not applicable (see note) | Breakdown [DERIVED]: EXT-PIER-L-8 6 + EXT-PIER-R-8 6 + EXT-HEAD-8 38.67 = 50.67 LF (wall length x rows) | Track gauge = stud gauge of each wall: 54 mil (16 ga) - 800S162-54 50.67 LF
A11: Top track - roof step and heads (vestibule / bulkhead) | B11: LF | C11: 20.57 | D11: =Inputs!$B$5 -> 0.15 | E11: =C11*D11 -> 3.0855 | F11: =C11+E11 -> 23.6555 | G11: run 10 ft | H11: =ROUNDUP(F11/Inputs!$B$11,0) -> 3 | I11: N/SHEET: not applicable (see note) | Breakdown [DERIVED]: VEST-HD-C 8.49 + VEST-HD-B2 6.04 + VEST-HD-B1 6.04 = 20.57 LF (wall length x rows) | Track gauge = stud gauge of each wall: 54 mil (16 ga) - 600S162-54 20.57 LF
A12: 1-1/2" Z-furring channel (LF of material) | B12: LF | C12: 2690.71 | D12: =Inputs!$B$5 -> 0.15 | E12: =C12*D12 -> 403.6065 | F12: =C12+E12 -> 3094.3165 | G12: hat channel 12 ft | H12: =ROUNDUP(F12/Inputs!$B$17,0) -> 258 | I12: N/SHEET: not applicable (see note) | pieces ROUNDUP(L / 2) + 1: S24-OFF 11.0 -> 7, S24-RR 16.17 -> 10 (grid A, T.O. low eave 14.625 ft, 2/A3.2); S24-RR104S 8.5 -> 6 (grid 4 near grid A, 14.71 ft by the 1/4:12 slope); top of furring not printed -> eave (53.3, RFI-02); 17 x 14.625 + 6 x 14.71 = 248.63 + 88.26 = 336.89 LF
A13: 8" stud (all gauges) | B13: LF | C13: 537.32 | D13: =Inputs!$B$5 -> 0.15 | E13: =C13*D13 -> 80.598 | F13: =C13+E13 -> 617.918 | G13: stick 20 ft | H13: =ROUNDUP(F13/Inputs!$B$10,0) -> 31 | I13: N/SHEET: not applicable (see note) | Breakdown [DERIVED]: EXT-PIER-L-8 124 + EXT-PIER-R-8 124 + EXT-HEAD-8 289.32 = 537.32 LF (per wall: field + jambs + nodes + cripples x height; plus listed elements) | By gauge (stud gauge of each wall, from its type / stud schedule): 54 mil (16 ga) - 800S162-54 537.32 LF
A14: 6" metal stud (LF of material) | B14: LF | C14: 1105.09 | D14: =Inputs!$B$5 -> 0.15 | E14: =C14*D14 -> 165.7635 | F14: =C14+E14 -> 1270.8535 | G14: stick 20 ft | H14: =ROUNDUP(F14/Inputs!$B$10,0) -> 64 | I14: N/SHEET: not applicable (see note) | Breakdown [DERIVED]: S61-RR 68 + EXT-PIER-L-6 124 + EXT-PIER-R-6 124 + EXT-HEAD-6 289.32 + EXT-SOUTH-BAND 223.13 + VEST-HD-C 40.17 + VEST-HD-B2 25.11 + VEST-HD-B1 25.11 + JOISTS-OFFICE-RR 150 + JOISTS-VESTIBULE 36.25 = 1,105.09 LF (per wall: field + jambs + nodes + cripples x height; plus listed elements) | By gauge (stud gauge of each wall, from its type / stud schedule): 33 mil (20 ga) - 600S162-33 68 LF; 54 mil (16 ga) - 600S162-54 627.71 LF; 43 mil (18 ga) - 600S162-43 223.13 LF; elements (gauge in their operation) 186.25 LF
A15: 3-5/8" metal stud (LF of material) | B15: LF | C15: 2214.54 | D15: =Inputs!$B$5 -> 0.15 | E15: =C15*D15 -> 332.181 | F15: =C15+E15 -> 2546.721 | G15: stick 20 ft | H15: =ROUNDUP(F15/Inputs!$B$10,0) -> 128 | I15: N/SHEET: not applicable (see note) | Breakdown [DERIVED]: S24-OFF 76.5 + S24-RR 102 + S24-RR104S 51 + S43-OFF-W 59.5 + S43-OFF-E 59.5 + S43-OFF-S 86.33 + S43-RR103-W 59.5 + S43-RR-S 147.17 + S41-B-V 60 + S41-B-H 36 + S41-C-V 48 + S41-C-H 36 + S42-H1 333.81 + S42-H2 116.76 + S42-V1 248.25 + S42-V2 97.85 + KICK-S42-H2 56.57 + KICK-S42-V1 98.99 + STRUT-S42-HDR 75.78 + ANGLED-STRUT-S42-HDR 64 + STUD-TIES-ENTRY 238.07 + CJ-DOUBLE-STUDS 62.96 = 2,214.54 LF (per wall: field + jambs + nodes + cripples x height; plus listed elements) | By gauge (stud gauge of each wall, from its type / stud schedule): 33 mil (20 ga) - 362S162-33 1,618.17 LF; elements (gauge in their operation) 596.37 LF
A16: Bracing 1-1/2" C.R. channel @ 48" O.C. | B16: LF | C16: 839.87 | D16: =Inputs!$B$5 -> 0.15 | E16: =C16*D16 -> 125.9805 | F16: =C16+E16 -> 965.8505 | G16: C.R. channel 16 ft | H16: =ROUNDUP(F16/Inputs!$B$16,0) -> 61 | I16: N/SHEET: not applicable (see note) | Breakdown [DERIVED]: S24-OFF 22 + S24-RR 32.33 + S24-RR104S 17 + S43-OFF-W 17.28 + S43-OFF-E 17.33 + S43-OFF-S 22 + S43-RR103-W 18.21 + S43-RR-S 32.33 + S61-RR 17 + S41-B-V 4.33 + S41-B-H 2.63 + S41-C-V 3.33 + S41-C-H 2.63 + S42-H1 116 + S42-H2 50.89 + S42-V1 100.67 + S42-V2 32.67 + EXT-PIER-L-8 30 + EXT-PIER-L-6 30 + EXT-PIER-R-8 30 + EXT-PIER-R-6 30 + EXT-HEAD-8 77.33 + EXT-HEAD-6 77.33 + EXT-SOUTH-BAND 36 + VEST-HD-C 8.49 + VEST-HD-B2 6.04 + VEST-HD-B1 6.04 = 839.86 LF (rows = ROUNDUP(H x 12 / 48) - 1, x length)
A17: Header / metal stud box beam | B17: LF | C17: 56 | D17: =Inputs!$B$5 -> 0.15 | E17: =C17*D17 -> 8.4 | F17: =C17+E17 -> 64.4 | G17: stick 20 ft | H17: =ROUNDUP(F17/Inputs!$B$10,0) -> 4 | I17: N/SHEET: not applicable (see note)
A18: 5/8" glass mat sheathing (exterior face of the stud) | B18: SF | C18: 534.88 | D18: =Inputs!$B$6 -> 0.06 | E18: =C18*D18 -> 32.0928 | F18: =C18+E18 -> 566.9728 | G18: 4x12 ft sheet (Inputs) | H18: =ROUNDUP(F18/Inputs!$B$9,0) -> 12 | I18: N/SHEET: not applicable (see note) | Breakdown [DERIVED]: GLASSMAT-ENTRY 248 + GLASSMAT-SOUTH 286.88 = 534.88 SF | piers 2 x 6.0 x 20.667 = 248.0 SF (1/A3.1 key 19). Head wall over storefront A excluded: 2/A3.1 shows key 34 5/8" exterior FRT plywood sheathing on that face, not key 19 (double reading resolution R-06); 36.0 x 7.969 = 286.88 SF
A19: Blocking FRT / 2X FRT wood | B19: LF | C19: 387.75 | D19: =Inputs!$B$6 -> 0.06 | E19: =C19*D19 -> 23.265 | F19: =C19+E19 -> 411.015 | G19: 2x lumber 16 ft | H19: =ROUNDUP(F19/Inputs!$B$26,0) -> 26 | I19: N/SHEET: not applicable (see note) | Breakdown [DERIVED]: BLK-S42-HDR-NAILERS 151.55 + BLK-RR-ACCESSORIES 38 + BLK-WATER-HEATER 4 + BLK-TOP-NAILERS-FRONT 101.34 + BLK-CMU-OPENINGS 92.86 = 387.75 LF
A20: 5/8" gypsum board, Type X | B20: SF | C20: 7741.58 | D20: =Inputs!$B$6 -> 0.06 | E20: =C20*D20 -> 464.4948 | F20: =C20+E20 -> 8206.0748 | G20: 4x12 ft sheet (Inputs) | H20: =ROUNDUP(F20/Inputs!$B$9,0) -> 171 | I20: N/SHEET: not applicable (see note) | Breakdown [DERIVED]: S21-N 1,313.91 + S21-E1 663.19 + S21-E2 159.15 + S21-S 1,173.25 + S21-W1 151.17 + S21-W2 408.44 + S24-OFF 93.5 + S43-OFF-W 151.24 + S43-OFF-E 151.62 + S43-OFF-S 192.5 + S43-RR103-W 81.95 + S43-RR-S 145.5 + S41-B-V 26 + S41-B-H 15.76 + S41-C-V 20 + S41-C-H 15.76 + S42-H1 1,050.69 + S42-H2 365.08 + S42-V1 706.32 + S42-V2 231.2 + EXT-PIER-L-8 98.38 + EXT-PIER-R-8 98.38 + EXT-HEAD-8 155.27 + VEST-HD-C 42.62 + VEST-HD-B2 30.34 + VEST-HD-B1 30.34 + CLG-GWB-OFFICE-VEST 139.28 + GB-S42-HDR-UNDERSIDE 30.76 = 7,741.6 SF (faces: length x face height x layers - openings; ceilings: RCP area)
A21: 5/8" gypsum board, Type X W.R. (water resistant) | B21: SF | C21: 702.15 | D21: =Inputs!$B$6 -> 0.06 | E21: =C21*D21 -> 42.129 | F21: =C21+E21 -> 744.279 | G21: 4x12 ft sheet (Inputs) | H21: =ROUNDUP(F21/Inputs!$B$9,0) -> 16 | I21: N/SHEET: not applicable (see note) | Breakdown [DERIVED]: S24-RR 137.42 + S24-RR104S 72.25 + S43-RR103-W 77.4 + S43-RR-S 137.42 + S61-RR 144.5 + CLG-GWB-RR 133.16 = 702.15 SF (faces: length x face height x layers - openings; ceilings: RCP area)
A22: Deep-leg slotted deflection track - printed product (see Where it comes from) | B22: LF | C22: 46.83 | D22: =Inputs!$B$5 -> 0.15 | E22: =C22*D22 -> 7.0245 | F22: =C22+E22 -> 53.8545 | G22: run 10 ft | H22: =ROUNDUP(F22/Inputs!$B$11,0) -> 6 | I22: N/SHEET: not applicable (see note) | Breakdown [DERIVED]: DL-TRACK-S42 46.83 = 46.83 LF | floor-supported S42 walls to the purlins (S4.1 key plan cuts 3/S5.1, 4/S5.1): S42-H1 38.67 + S42-V2 8.17 = 46.83 LF
A23: Sheathing screws - printed product and spacing (see Where it comes from) | B23: PCS | C23: 1058 | D23: =Inputs!$B$5 -> 0.15 | E23: =C23*D23 -> 158.7 | F23: =C23+E23 -> 1216.7 | G23: piece | H23: =ROUNDUP(F23,0) -> 1217 | I23: N/SHEET: not applicable (see note) | Breakdown [DERIVED]: SHEATHING-SCREWS-EXT 1,058 = 1,058 PCS | exterior sheathing on studs @ 16" O.C.: (12/16 lines per ft) x (12/8 screws per ft) = 1.125 / SF x (glass mat 534.88 + FRT plywood 360.79 + 45.12 = 940.79 SF) = 1,058
A24: Framing clips per stud - printed product (see Where it comes from) | B24: PCS | C24: 144 | D24: =Inputs!$B$5 -> 0.15 | E24: =C24*D24 -> 21.6 | F24: =C24+E24 -> 165.6 | G24: piece | H24: =ROUNDUP(F24,0) -> 166 | I24: N/SHEET: not applicable (see note) | Breakdown [DERIVED]: FCB43.5-CLIPS 144 = 144 PCS | 1/S5.3 south panel 600S162-43: studs ROUNDUP(36.0 / 1.333) + 1 = 28 x 3 clips drawn (top / middle / bottom, @ 48") = 84; 3/S5.3 head wall: studs ROUNDUP(38.67 / 1.333) + 1 = 30 x 2 wind beams = 60; 84 + 60 = 144 clips (fasteners per clip as labelled)
A25: Metal stud blocking at wall-mounted items (notes) | B25: LF | C25: 6 | D25: =Inputs!$B$5 -> 0.15 | E25: =C25*D25 -> 0.9 | F25: =C25+E25 -> 6.9 | G25: stick 20 ft | H25: =ROUNDUP(F25/Inputs!$B$10,0) -> 1 | I25: N/SHEET: not applicable (see note) | Breakdown [DERIVED]: BLK-FIRE-EXT 6 = 6 LF | 6.0 LF
A26: METAL trim - corner bead, casing bead, shadow molding, gypsum edge trim | B26: LF | C26: 183.05 | D26: =Inputs!$B$5 -> 0.15 | E26: =C26*D26 -> 27.4575 | F26: =C26+E26 -> 210.5075 | G26: trim stick 10 ft | H26: =ROUNDUP(F26/Inputs!$B$18,0) -> 22 | I26: N/SHEET: not applicable (see note) | Breakdown [DERIVED]: Corner bead - office 102 / restrooms hard-lid top edge 54.38 + Control joint reveal DRMF-625-75 + JDM-625 at S42 joint near grid B 27.58 + Control joint reveal DRMF-625-75 + JDM-625 at S42 joint near the west wall 28.71 + jamb returns 72.38 = 183.05 LF
A27: FRT plywood substrate (5/8 in.) | B27: SF | C27: 420.25 | D27: =Inputs!$B$6 -> 0.06 | E27: =C27*D27 -> 25.215 | F27: =C27+E27 -> 445.465 | G27: 4x12 ft sheet (Inputs) | H27: =ROUNDUP(F27/Inputs!$B$9,0) -> 10 | I27: N/SHEET: not applicable (see note) | Breakdown [DERIVED]: FRT-BOX-B 7.67 + FRT-BOX-C 6.67 + FRT-EXT-HEAD-SOFFIT 45.12 + EXT-W-HEAD-FRT 360.79 = 420.25 SF (strip length x height)
A28: Additional head track at openings over 4'-0" wide | B28: LF | C28: 32.73 | D28: =Inputs!$B$5 -> 0.15 | E28: =C28*D28 -> 4.9095 | F28: =C28+E28 -> 37.6395 | G28: run 10 ft | H28: =ROUNDUP(F28/Inputs!$B$11,0) -> 4 | I28: N/SHEET: not applicable (see note) | Door 3 (S21-N): (6.0 + 2 x 0.667) x 1 = 7.33; Window D1 (S21-S): (11.365 + 2 x 0.667) x 1 = 12.7; Window D2 (S21-S): (11.365 + 2 x 0.667) x 1 = 12.7
A29: Stud reinforcement at MEP penetrations | B29: PCS | C29: 0 | D29: 0 | E29: =C29*D29 -> 0 | F29: =C29+E29 -> 0 | G29: each | H29: =ROUNDUP(F29,0) -> 0 | I29: N/SHEET: not applicable (see note) | RFI: MEP sheets excluded by the estimator 2026-10-31: no duct / pipe crossing read (RFI-08) Delta: per duct crossing: + MAX(1, ROUNDUP(width/24")) plates + 1 sleeve
A30: Extra framing - ATM recess (only what a detail prints at the recess; the wall stays in its type) | B30: LF | C30: 0 | D30: =Inputs!$B$5 -> 0.15 | E30: =C30*D30 -> 0 | F30: =C30+E30 -> 0 | G30: stick 20 ft | H30: =ROUNDUP(F30/Inputs!$B$10,0) -> 0 | I30: [DERIVED] N/SHEET: not applicable (see note) | none: No ATM / equipment recess in the set (A1.1, A4.1, A5.1 reviewed) (A1.1)
A31: 2-1/2" CFMF @ 16" O.C. at coiling grille head (detail per plans) | B31: LF | C31: 0 | D31: =Inputs!$B$5 -> 0.15 | E31: =C31*D31 -> 0 | F31: =C31+E31 -> 0 | G31: stick 20 ft | H31: =ROUNDUP(F31/Inputs!$B$10,0) -> 0 | I31: N/SHEET: not applicable (see note) | none: no parapet infill, coiling grille or duct sleeve detail in the canon
A32: Gypsum board jamb return at openings | B32: SF | C32: 18.09 | D32: =Inputs!$B$6 -> 0.06 | E32: =C32*D32 -> 1.0854 | F32: =C32+E32 -> 19.1754 | G32: 4x12 ft sheet (Inputs) | H32: =ROUNDUP(F32/Inputs!$B$9,0) -> 1 | I32: N/SHEET: not applicable (see note) | edges 36.19 LF x 0.5 ft = 18.09 SF [Window D1 18.09 [12/A5.2]; Window D2 18.09 [12/A5.2]]
A33: PVC trim - edge trim molding and inside corner molding at the FRP | B33: LF | C33: 0 | D33: =Inputs!$B$6 -> 0.06 | E33: =C33*D33 -> 0 | F33: =C33+E33 -> 0 | G33: trim stick 10 ft | H33: =ROUNDUP(F33/Inputs!$B$18,0) -> 0 | I33: [DERIVED] N/SHEET: not applicable (see note) | none: No FRP called; restrooms W-4 sanitary wall and ceiling panel system (A1.2) is a finish item - RFI-07
A34: Power-driven fasteners and duct sleeves | B34: PCS | C34: 0 | D34: 0 | E34: =C34*D34 -> 0 | F34: =C34+E34 -> 0 | G34: each | H34: =ROUNDUP(F34,0) -> 0 | I34: [DERIVED] N/SHEET: not applicable (see note) | none: no parapet infill, coiling grille or duct sleeve detail in the canon
A35: Access panel | B35: PCS | C35: 0 | D35: 0 | E35: =C35*D35 -> 0 | F35: =C35+E35 -> 0 | G35: each | H35: =ROUNDUP(F35,0) -> 0 | I35: [DERIVED] N/SHEET: not applicable (see note) | none: No access panel shown in the gypsum ceilings or walls (A1.1, A1.2, A4.1, A4.2) (A1.2)
A36: Drywall screws #7 x 1-1/4" Type S bugle head (board on 25/20 ga studs) | B36: PCS | C36: 9586.1 | D36: 0 | E36: =C36*D36 -> 0 | F36: =C36+E36 -> 9586.1 | G36: each | H36: =ROUNDUP(F36,0) -> 9587 | I36: [DERIVED] N/SHEET: GA-216 | Inputs!B20 (Drywall screws per SF of board = 1.2) x 7988.42 SF of board | J36: =Inputs!$B$20*7988.42 -> 9586.104
A37: Framing screws #8-18 x 1/2" pan head (25/20 ga studs) -> printed product: #10 screws, each stud flange to track (S1.1 7.E) | B37: PCS | C37: 684 | D37: 0 | E37: =C37*D37 -> 0 | F37: =C37+E37 -> 684 | G37: each | H37: =ROUNDUP(F37,0) -> 684 | I37: [DERIVED] N/SHEET: driver = the board / stud / bottom track rows of this sheet | Inputs!B21 (Framing screws per stud piece = 4) x 171 stud pieces | Breakdown [DERIVED]: 4 x 171 stud pieces of the 25/20 ga walls and other framing [S24-OFF 9 + S24-RR 12 + S24-RR104S 6 + S41-B-H 3 + S41-B-V 5 + S41-C-H 3 + S41-C-V 4 + S42-H1 22 + S42-H2 14 + S42-V1 28 + S42-V2 6 + S43-OFF-E 7 + S43-OFF-S 11 + S43-OFF-W 7 + S43-RR-S 19 + S43-RR103-W 7 + S61-RR 8 (walls 171); minus 167 pieces of walls without track (S21-E1, S21-E2, S21-N, S21-S, S21-W1, S21-W2; R80e.74)] = 684 | J37: =Inputs!$B$21*171 -> 684
A38: Power-driven fasteners, slab pins for the bottom track -> printed product: Simpson Titen HD 3/8" @ 48" O.C. (S1.1 7.F/7.G; 3/S5.1, 4/S5.1) | B38: PCS | C38: 37.76 | D38: 0 | E38: =C38*D38 -> 0 | F38: =C38+E38 -> 37.76 | G38: each | H38: =ROUNDUP(F38,0) -> 38 | I38: [DERIVED] N/SHEET: slab pin spacing: see the operation (Inputs yield) | 151.04 LF of interior bottom track on slab / Inputs!B22 (Power-driven pin spacing (ft) = 4) | J38: =151.04/Inputs!$B$22 -> 37.76
A39: Expansion anchors Hilti 1/4" Kwik Bolt II, exterior bottom track @ 8" O.C. -> printed product: Simpson Titen HD 3/8" @ 48" O.C. (S1.1 7.F/7.G) | B39: PCS | C39: 6 | D39: 0 | E39: =C39*D39 -> 0 | F39: =C39+E39 -> 6 | G39: each | H39: =ROUNDUP(F39,0) -> 6 | I39: [DERIVED] N/SHEET: driver = the board / stud / bottom track rows of this sheet | 24 LF of exterior bottom track on slab / Inputs!B25 (Expansion anchor spacing (ft) = 4) | J39: =24/Inputs!$B$25 -> 6
A40: Joint compound, all purpose | B40: LB | C40: 607.95 | D40: 0 | E40: =C40*D40 -> 0 | F40: =C40+E40 -> 607.95 | G40: lb | H40: =ROUNDUP(F40,0) -> 608 | I40: [DERIVED] N/SHEET: driver = the board / stud / bottom track rows of this sheet | Inputs!B23 (Joint compound (lb per SF) = 0.072) x 8443.73 SF of board | J40: =Inputs!$B$23*8443.73 -> 607.94856
...

Sheet Pending Items
A1: RFI | B1: Question / condition | C1: Delta of each alternative
A2: RFI-ACC-gypsum-board-jamb-return | B2: gypsum board jamb return: jamb return width not dimensioned | C2: (A) Plans / specs: delta -10.86 sf | (B) Trade code: no applicable code provision cited | (C) Other: ____
A3: RFI-ACC-slab-pins | B3: slab pins: pin spacing: carried one pin every 48.0" (S1.1 7.G (intermediate anchors @ 48" O.C. max); 3/S5.1, 4/S5.1 TITEN HD 3/8" @ 48" O.C. (MAX.)); alternatives: one row @ 16" / one row @ 24" | C3: (A) Plans / specs: delta 16in: 75.52 pcs; 24in: 37.76 pcs | (B) Trade code: no applicable code provision cited | (C) Other: ____
A4: RFI-ACC-stud-reinforcement-mep | B4: stud reinforcement MEP: MEP sheets excluded by the estimator 2026-10-31: no duct / pipe crossing read (RFI-08) | C4: (A) Plans / specs: delta per duct crossing: + MAX(1, ROUNDUP(width/24")) plates + 1 sleeve | (B) Trade code: no applicable code provision cited | (C) Other: ____
A5: RFI-01 | B5: Top of studs / Z-furring at the PEMB roof: bottom of purlin elevation not printed - where: S21-*, S42-H1, S42-H2, S42-V1, S42-V2, VEST-HD-* - carried: loaded to the top of purlin / eave elevation (conservative, rule 53.3) | C5: (A) Studs and furring stop under the PEMB purlins / eave strut; T.O. eave 114'-7 1/2" (E) to 116'-4 3/4" (W) printed, purlin depth by P.E.M.B. shop drawings (A1.1 general note D) | 2/A3.2, 1/A3.1, 3/S5.1 | delta minus purlin depth (~8" typical Z purlin) on every full-height stud, furring and board face: about -0.67 ft x LF of S21 (250.7 LF), S42 full (46.8 LF), heads | (B) Code: no height rule; AISI S240 / ASTM C754 require the stud to bear on structure - height from shop drawings | AISI S240-20 B1; ASTM C754 sec. 6 | delta same as A | (C) Other: ____
A6: RFI-02 | B6: S24 Z-furring height and board on the CMU above the 8'-6" hard lid (office 102, R.R. 103/104) - where: S24-OFF, S24-RR, S24-RR104S - carried: S24 Z-furring loaded to the eave (14.625 / 14.71 ft) = 336.89 LF (misc item ZF-S24); board only to 8'-6" on the studs | C6: (A) S24/A1.1 draws 150ZF125-18 Z-furring + polyiso on the CMU behind the 8'-6" stud lining; height not stated (S21 goes to the roof per 3/A3.2) | S24/A1.1 | delta + Z-furring 24" O.C. x 14.6 ft on 11.0 + 16.17 + 8.5 = 35.7 LF of CMU (about 19 pcs) and, if boarded above the hard lid, + 35.7 x 6.1 = 218 SF 5/8" Type X | (B) No code requirement for furring above a ceiling (energy code continuity of insulation only) | IECC C402.1 (insulation continuity) | delta none | (C) Other: ____
A7: RFI-03 | B7: S42 header wall extension east of the S42 vertical wall - where: S42-H2 - carried: included (drawn on A1.1) | C7: (A) A1.1 draws the header double line ~7.2 ft past the S42 corner (to the dimension line); S4.1 framing key plan ends the dashed header at the corner | A1.1, S4.1 | delta -7.2 LF of header wall (S42-H2 25.44 -> 18.27 ft) and its board / nailers | (B) No code item | n/a | delta n/a | (C) Other: ____
A8: RFI-04 | B8: CLOSED (plan check): south facade 36'-0" stucco panel - the band measures 36.0 ft on A1.1, as printed - where: EXT-SOUTH-BAND, S21-S openings - carried: 36'-0" printed and measured | C8: (A) printed and measured agree | A1.1, A2.1 | delta 0 | (B) no code provision | n/a | delta 0 | (C) Other: ____
A9: RFI-05 | B9: Hard-lid ceilings office/restrooms: board on top of the 600S162-54 joists - where: office 102, R.R. 103, R.R. 104 - carried: bottom (ceiling) board only | C9: (A) 7/A4.2 key 6 leaders reach the top of the joist box; schedule C-3 is the ceiling below | 7/A4.2, A1.2 | delta + 88 + 133.2 = 221.2 SF 5/8" Type X (WR in restrooms) if boarded on top | (B) Code: not required unless a rated assembly | IBC 2021 703.2 (rated assemblies only) | delta none | (C) Other: ____
A10: RFI-06 | B10: Entry pier / head interior finish and returns - where: EXT-PIER-*, EXT-HEAD-8 - carried: 5/8" Type X face loaded; RC and 1/4" not loaded (no family) | C10: (A) 1/A3.1, 7/A3.2, 1/A5.2: 5/8" Type X over 1/4" gypsum board on 087F125-33 resilient channel @ 24" horiz.; pier side returns not dimensioned | 1/A3.1, 7/A3.2, 1/A5.2 | delta + 1/4" gypsum about 349 SF and + 087F125-33 RC about 243 LF (piers 2 x 10 rows x 6.0 + head 4 rows x 30.67); returns + ~2 x 2 x 1.2 ft x 20.7 ft studs/sheathing; head underside (1/A5.2): +36 SF 5/8" X, +36 SF 1/4", +30.67 LF corner bead | (B) Code: no requirement | n/a | delta n/a | (C) Other: ____
A11: RFI-07 | B11: Restroom wall finish W-4 sanitary wall and ceiling panel system - where: R.R. 103, R.R. 104 - carried: not loaded (finish trade); frp_none_reason | C11: (A) A1.2 schedule W-4 at R.R. 103/104 walls (MFG refer project manual) | A1.2 | delta + FRP-type panel on 4 walls of each restroom: about 2 x (2 x 7.83 + 2 x 8.5) x 8.5 = 555 SF if in the drywall scope | (B) Code: smooth nonabsorbent surface to 4'-0" at urinals / water closets | IBC 2021 1210.2.2 | delta finish to 4'-0" only: about 260 SF | (C) Other: ____
A12: RFI-08 | B12: MEP sweep excluded by the estimator (2026-10-31) - where: all stud walls - carried: 0 counted | C12: (A) MEP sheets not read: duct / pipe penetrations, framed openings and stud reinforcement not counted | estimator order in this session, 2026-10-31 (exclude all electrical, civil, cabinet and MEP sheets) | delta per duct crossing a stud wall: + MAX(1, ROUNDUP(width/24")) plates and 1 sleeve | (B) Code: n/a | n/a | delta n/a | (C) Other: ____
... A31: RFI-27 | B31: #10 screws per flange not printed (S1.1 7.E) - where: all framing - carried: loaded #10 framing screws, 4 per stud (2 flanges x 2 ends); none on the Z-furring without track | C31: (A) #10 screws printed | S1.1 | delta 0 (count by the skill standing yield) | (B) n/a | n/a | delta 0 | (C) Other: ____

Sheet Review Items
A1: 0 questions in total, asked ONE at a time in this order: floor plan (partition types A-Z), then the details the floor plan calls, in order
A2: # | B2: Phase | C2: Type / order | D2: Item | E2: Sheet + detail | F2: Image

Sheet Scope Checklist
A1: Scope ID | B1: Scope | C1: Status | D1: Note (quantity, NOT APPLICABLE + sheet, or RFI)
A2: ALC-01 | B2: Interior partition framing (studs + tracks) | C2: QUANTIFIED | D2: Types S24, S41, S42, S43, S61 (A1.1 wall types; 5/A4.2, 6/A4.2, 7/A4.2): 3-5/8" and 6" 20 ga studs and tracks in Material Summary; S21 / S24 Z-furring in its own row.
A3: ALC-02 | B3: Exterior wall framing (CFMF) | C3: QUANTIFIED | D3: Entry piers + head wall over storefront A (8" 800S162-54 + 6" 600S162-54 @ 16", 1/A3.1, 2/A3.1, 3/S5.3), south stucco panel 600S162-43 (1/A3.4), vestibule heads 600S162-54 (3/A3.1, S4.1 key note 3, RFI-05).
A4: ALC-03 | B4: Parapet framing | C4: NOT APPLICABLE | D4: Parapets are CMU to T.O. masonry with PEMB coping (A2.1, A3.1-A3.2); the CFMF above storefront A up to T.O. metal stud 120'-8" (2/A3.1) is counted in the exterior head wall (ALC-02).
A5: ALC-04 | B5: Top / deflection and bottom track | C5: QUANTIFIED | D5: Bottom and top / deflection track by stud size (A1.1 note 2.C deflection channels at walls to roof structure; 3/S5.1, 4/S5.1); heads row for the vestibule heads.
A6: ALC-05 | B6: Headers, sills and jambs at openings | C6: QUANTIFIED | D6: Header / box beam and additional head track by headers.py from the door / window schedules (A5.1, A5.2); CMU openings by mason (RFI-13).
A7: ALC-06 | B7: Bracing / bridging | C7: QUANTIFIED | D7: Horizontal stud bridging @ 4'-0" O.C. vertical (A1.1 note 2.F) as C.R. channel rows; S42 header kickers / struts (1/S5.1, 2/S5.1, 5/S5.1, RFI-09); diagonal flat strap (note 2.B) in RFI-12.
A8: ALC-07 | B8: Gypsum board on walls (layers per type) | C8: QUANTIFIED | D8: 5/8" Type X on every type (A1.1 wall types S21-S61); faces to the hard-lid ceiling or to the purlin (RFI-01, RFI-02).
A9: ALC-08 | B9: Moisture / abuse / special board at wet areas | C9: QUANTIFIED | D9: 5/8" Type X moisture resistant at restrooms 103 / 104 walls and ceilings (A1.1 note 3.B, A1.2, 1A/A4.1).
A10: ALC-09 | B10: Exterior gypsum / glass mat sheathing | C10: QUANTIFIED | D10: 5/8" glass mat sheathing at the entry piers (1/A3.1 key 19) and the south stucco panel (1/A3.4); head wall over storefront A takes FRT plywood (2/A3.1 key 34).
A11: ALC-10 | B11: FRT plywood sheathing / substrate | C11: QUANTIFIED | D11: 5/8" exterior FRT plywood sheathing on the head wall face and storefront head soffit (2/A3.1, 3/A3.1 key 34) + 5/8" FRT plywood backing 8'-0" to 10'-0" at the S41 box-outs (key note 5, 4/A4.2).
A12: ALC-11 | B12: Gypsum board ceilings | C12: QUANTIFIED | D12: C-3 gypsum hard-lid ceilings: office 102 + vestibule 100A (Type X) and restrooms 103 / 104 (Type X W.R.) (A1.2, 7/A4.2, 3/A3.1); top-side board in RFI-05.
... A26: ALC-X25 | B26: batt insulation | C26: NOT APPLICABLE | D26: EXCLUDED (estimator criterion: no insulation)

Sheet _reglas
A1: reglas.py compuerta OK
A2: {"canon": "cfa960a6638155ff5d56ce5fd83cc62a165f60d7eb7e046365bb68421227fd37", "evidencias": "049573fa2d17514c730615e6fbddf8604988953fd9bc7e79bd0720f6d13c30e7", "familias_out": "09324434699caa73f5fcd5d7637ef1e9ec67baf98aadd5079a8f61f81550660c", "reglas": "416b0052865ced4ef0056681dee972ee1f64972ce9e9e9d6b84a5bdb739dd0c5", "version": "v73"}
