Workbook

Sheet Inputs
A1: Barnes & Noble #3566, 3173 Cinema Point, Colorado Springs CO | METAL FRAMING & DRYWALL TAKEOFF
A2: Bid set: planos_BN_limpios.pdf · 2026-10-29 · Edit ONLY the yellow cells.
A4: PARAMETER | B4: VALUE | C4: NOTE / SOURCE
A5: Waste - ALL METAL, any type | B5: 0.15 | C5: Estimator standing rule: 15% on everything that is metal.
A6: Waste - EVERYTHING THAT IS NOT METAL | B6: 0.06 | C6: Estimator standing rule: same figure as board.
A7: Board sheet width (ft) | B7: 4 | C7: Sheet size is a parameter; buy the size that wastes least.
A8: Board sheet length (ft) | B8: 12 | C8: Change it and every sheet count re-rounds.
A9: SF per board sheet | B9: =B7*B8 -> 48 | C9: Width x length.
A10: Stud stock length (ft) | B10: 24 | C10: Printed wall heights 23'-0" to 23'-8" (1,2/A-400A, 1,2/A-400B): a 20 ft stick cannot make a stud; 24 ft stock (RFI-C06).
A11: Track stock length (ft) | B11: 10 | C11: Track, sill track and purlin: runs.
A12: Floor plan scale (pt/ft) | B12: n/a | C12: Project value (not used in this take-off: heights are per wall in the Partition Takeoff).
A13: B.O. Deck (ft) | B13: n/a | C13: Project value (not used in this take-off: heights are per wall in the Partition Takeoff).
A14: T.O. Parapet (ft) | B14: n/a | C14: Project value (not used in this take-off: heights are per wall in the Partition Takeoff).
A15: Sealant coverage (LF per tube) | B15: 25 | C15: Sealant yield per tube - set your supplier's figure.
A16: C.R. channel stock length (ft) | B16: 16 | C16: 1-1/2" cold-rolled channel (bracing, carrying channel).
A17: Hat / furring channel stock (ft) | B17: 12 | C17: 7/8" hat furring channel.
A18: Trim stick length (ft) | B18: 10 | C18: Corner bead, casing bead, shadow molding, PVC trim.
A19: Hanger wire purchase | B19: continuous coil (LF) | C19: Bought by LF from a continuous coil; the hanger count goes on its own PCS row.
A20: Drywall screws per SF of board | B20: 0.46 | C20: Wall board screws: 24" o.c. on 16" o.c. studs + 12" o.c. butt joints = 0.46 per SF (8.E/A-410). Ceilings use 0.83 per SF (12" o.c.), see RFI-D03.
A21: Framing screws per stud piece | B21: 4 | C21: YIELD: 2 per stud-to-track connection, each end.
A22: Power-driven pin spacing (ft) | B22: 1.3333333 | C22: Pins: 2 rows @ 16" (8.F/A-410, conservative vs 9/A-410 @ 24", RFI-D01). Net pins come from the Partition Takeoff, not from this cell.
A23: Joint compound (lb per SF) | B23: 0.072 | C23: YIELD: 72 lb per 1,000 SF, level 4 (estimator criterion).
A24: Joint tape (LF per SF) | B24: 0.37 | C24: YIELD: 370 LF per 1,000 SF.
A25: Expansion anchor spacing (ft) | B25: 0.66666667 | C25: YIELD: exterior bottom track on slab.
A26: 2x lumber stock length (ft) | B26: 16 | C26: 2x wood / FRT blocking: 16 ft sticks (estimator decision 2026-10-27).
A27: Drywall grid main tee length (ft) | B27: 12 | C27: USG DGLW26 main tee (manufacturer length).
A28: Drywall grid cross tee length (ft) | B28: 4 | C28: USG DGLW424 cross tee (manufacturer length).
A29: Grid channel / angle molding length (ft) | B29: 12 | C29: USG DGCM27 / DGWM24 molding (manufacturer length).
A30: FRP panel (SF per panel) | B30: 40 | C30: FRP-1 panel 4'x10' (estimator to confirm the panel size).

Sheet Partition Takeoff
A1: ORGANIZED PARTITION TAKEOFF - Barnes & Noble #3566, 3173 Cinema Point, Colorado Springs CO
A2: Grouped by partition type. Every row cites its DETAIL/SHEET and its status.
A4: Partition / Scope | B4: Wall # | C4: Length (LF) | D4: Height (FT) | E4: Layers | F4: Stud Size | G4: Stud O.C. (in) | H4: Board (SF) | I4: Location | J4: Source (DETAIL/SHEET) | K4: Status
A5: TYPE 2
A6: 2 #2-01a - Stock Rm 111 / Sales 101 partition, V line x=497-500pt, y 560-1289 pt (N end at N ext. wall to corridor N wall) | B6: 2-01a | C6: 81 | D6: 23.667 | E6: 2 | F6: 3-5/8" | G6: 16 | H6: 3778 | I6: Stock Rm 111 / Sales 101 partition, V line x=497-500pt, y 560-1289 pt (N end at N ext. wall to corridor N wall) | Board by face: A[Stock Rm 111 open to deck: GWB58 0.00-23.67] | B[Sales 101 open to deck: GWB58 0.00-23.67] | J6: 1/A-101 | K6: [DERIVED]
A7: 2 #2-01b - Stock Rm 111 / Corridor 110 wall, same line x=497-500pt, y 1292-1409 | B7: 2-01b | C7: 12.917 | D7: 23.667 | E7: 2 | F7: 3-5/8" | G7: 16 | H7: 428.4 | I7: Stock Rm 111 / Corridor 110 wall, same line x=497-500pt, y 1292-1409 | Board by face: A[Stock Rm 111 open to deck: GWB58 0.00-23.67] | B[Corridor 110 ACT-3 9'-0": GWB58 0.00-9.50] | J7: 1/A-101 | K7: [DERIVED]
A8: 2 #2-02 - BOH N wall, H line y=1289-1292pt, x 500-1011 (corridor 110 / break 106 / mgr 105 vs sales) | B8: 2-02 | C8: 56.83 | D8: 23 | E8: 2 | F8: 3-5/8" | G8: 16 | H8: 1805 | I8: BOH N wall, H line y=1289-1292pt, x 500-1011 (corridor 110 / break 106 / mgr 105 vs sales) | Board by face: A[Sales 101 open to deck: GWB58 0.00-23.00] | B[Corridor 110/Break 106/Mgr 105 ACT-3 9'-0": GWB58 0.00-9.50] | J8: 1/A-101 | K8: [DERIVED]
A9: 2 #2-03 - Women's RR 109 west wall, V line x=556-560pt, y 1341-1409 | B9: 2-03 | C9: 7.5 | D9: 23 | E9: 2 | F9: 3-5/8" | G9: 16 | H9: 142.6 | I9: Women's RR 109 west wall, V line x=556-560pt, y 1341-1409 | Board by face: A[Corridor ACT-3: GWB58 0.00-9.50] | B[Women's RR GWB clg 9'-0" (tile 6'-7" by others): CB58 0.00-1.17+WR58 1.17-9.00+GWB58 9.00-9.50] | J9: 1/A-101,1/A-200 | K9: [DERIVED]
A10: 2 #2-04 - Women's RR 109 N wall incl. 6" jamb stub + door 9 R.O. + pony wall, H line y=1337-1341pt, x 560-622 | B10: 2-04 | C10: 6.917 | D10: 23 | E10: 2 | F10: 3-5/8" | G10: 16 | H10: 84.7 | I10: Women's RR 109 N wall incl. 6" jamb stub + door 9 R.O. + pony wall, H line y=1337-1341pt, x 560-622 | Board by face: A[Corridor/hall ACT-3: GWB58 0.00-9.50] | B[Women's RR: CB58 0.00-1.17+WR58 1.17-9.00+GWB58 9.00-9.50] | J10: 1/A-101 | K10: [DERIVED]
A11: 2 #2-05 - Lav/chase face (between RRs), H line y=1354-1357pt, x 622-658 | B11: 2-05 | C11: 4 | D11: 23 | E11: 2 | F11: 3-5/8" | G11: 16 | H11: 76 | I11: Lav/chase face (between RRs), H line y=1354-1357pt, x 622-658 | Board by face: A[Hall recess: GWB58 0.00-9.50] | B[Women's/Men's RR lav wall: CB58 0.00-1.17+WR58 1.17-9.00+GWB58 9.00-9.50] | J11: 1/A-101,1/A-200 | K11: [DERIVED]
A12: 2 #2-06 - Chase returns x2 (V 618-622 & 658-662, y 1341-1353) | B12: 2-06 | C12: 2.666 | D12: 23 | E12: 2 | F12: 3-5/8" | G12: 16 | H12: 50.7 | I12: Chase returns x2 (V 618-622 & 658-662, y 1341-1353) | Board by face: A[Hall recess: GWB58 0.00-9.50] | B[RR: CB58 0.00-1.17+WR58 1.17-9.00+GWB58 9.00-9.50] | J12: 1/A-101 | K12: [DERIVED]
A13: 2 #2-07 - Men's RR 108 N wall incl. pony wall, door 8 R.O., 6" stub, H line y=1337-1341pt, x 658-720 | B13: 2-07 | C13: 6.917 | D13: 23 | E13: 2 | F13: 3-5/8" | G13: 16 | H13: 84.7 | I13: Men's RR 108 N wall incl. pony wall, door 8 R.O., 6" stub, H line y=1337-1341pt, x 658-720 | Board by face: A[Hall ACT-3: GWB58 0.00-9.50] | B[Men's RR: CB58 0.00-1.17+WR58 1.17-9.00+GWB58 9.00-9.50] | J13: 1/A-101 | K13: [DERIVED]
A14: 2 #2-08 - Men's RR 108 E wall / Janitor 107 W wall, V line x=720-724pt, y 1341-1409 | B14: 2-08 | C14: 7.5 | D14: 23 | E14: 2 | F14: 3-5/8" | G14: 16 | H14: 243.8 | I14: Men's RR 108 E wall / Janitor 107 W wall, V line x=720-724pt, y 1341-1409 | Board by face: A[Men's RR: CB58 0.00-1.17+WR58 1.17-9.00+GWB58 9.00-9.50] | B[Janitor closet 107 open to deck: WR58 0.00-23.00+FRP 0.00-8.00] | J14: 1/A-101,1/A-200 | K14: [DERIVED]
A15: 2 #2-09 - Janitor 107 N wall (door 7), H line y=1337-1341pt, x 724-760 | B15: 2-09 | C15: 4 | D15: 23 | E15: 2 | F15: 3-5/8" | G15: 16 | H15: 88 | I15: Janitor 107 N wall (door 7), H line y=1337-1341pt, x 724-760 | Board by face: A[Hall ACT-3: GWB58 0.00-9.50] | B[Janitor 107: WR58 0.00-23.00+FRP 0.00-8.00] | J15: 1/A-101,1/A-200 | K15: [DERIVED]
A16: 2 #2-10a - Hall E closure / Break Rm 106 W wall (door 5), V line x=760-764, y 1292-1341 | B16: 2-10a | C16: 5.417 | D16: 23 | E16: 2 | F16: 3-5/8" | G16: 16 | H16: 60.9 | I16: Hall E closure / Break Rm 106 W wall (door 5), V line x=760-764, y 1292-1341 | Board by face: A[Hall ACT-3: GWB58 0.00-9.50] | B[Break 106 ACT-3: GWB58 0.00-9.50] | J16: 1/A-101 | K16: [DERIVED]
A17: 2 #2-10b - Janitor 107 E wall / Break 106 W wall, V line x=760-764, y 1341-1409 | B17: 2-10b | C17: 7.5 | D17: 23 | E17: 2 | F17: 3-5/8" | G17: 16 | H17: 243.7 | I17: Janitor 107 E wall / Break 106 W wall, V line x=760-764, y 1341-1409 | Board by face: A[Janitor 107: WR58 0.00-23.00+FRP 0.00-8.00] | B[Break 106 ACT-3: GWB58 0.00-9.50] | J17: 1/A-101,1/A-200 | K17: [DERIVED]
... A20: 2 #2-13 - Storage 112 W end wall, V line x=1487-1491, y 560-605 | B20: 2-13 | C20: 5 | D20: 23 | E20: 2 | F20: 3-5/8" | G20: 16 | H20: 230 | I20: Storage 112 W end wall, V line x=1487-1491, y 560-605 | Board by face: A[Sales 101: GWB58 0.00-23.00] | B[Storage 112: GWB58 0.00-23.00] | J20: 1/A-101 | K20: [DERIVED]
B21: SUBTOTAL TYPE 2 | C21: =SUM(C6:C20) -> 269.831 | H21: =SUM(H6:H20) -> 9720.4
A22: TYPE 3
A23: 3 #3-01 - Cafe seating bar partition west unit (x~1500-1585pt, y 1160-1240pt) | B23: 3-01 | C23: 19.333 | D23: 8 | E23: 2 | F23: 3-5/8" | G23: 16 | H23: 309.3 | I23: Cafe seating bar partition west unit (x~1500-1585pt, y 1160-1240pt) | Board by face: A[Cafe seating side (both faces): GWB58 0.00-8.00] | B[Opposite face: GWB58 0.00-8.00] | J23: 1/A-101 | K23: [DERIVED]
A24: 3 #3-02 - Cafe seating bar partition east unit (x~1720-1835pt) | B24: 3-02 | C24: 19.333 | D24: 8 | E24: 2 | F24: 3-5/8" | G24: 16 | H24: 309.3 | I24: Cafe seating bar partition east unit (x~1720-1835pt) | Board by face: A[Cafe seating side (both faces): GWB58 0.00-8.00] | B[Opposite face: GWB58 0.00-8.00] | J24: 1/A-101 | K24: [DERIVED]
B25: SUBTOTAL TYPE 3 | C25: =SUM(C23:C24) -> 38.666 | H25: =SUM(H23:H24) -> 618.6
A26: TYPE 4
A27: 4 #4-01 - Sales floor center X feature wall (2 arcs + 2 end caps + returns), x~1500-1740pt, y~860-1120pt | B27: 4-01 | C27: 75.5 | D27: 7.5 | E27: 2 | F27: 3-5/8" | G27: 16 | H27: 1132.5 | I27: Sales floor center X feature wall (2 arcs + 2 end caps + returns), x~1500-1740pt, y~860-1120pt | Board by face: A[Outside/concave face: GWB58 0.00-7.50] | B[Inside face: GWB58 0.00-7.50] | J27: 1/A-101 | K27: [DERIVED]
B28: SUBTOTAL TYPE 4 | C28: =SUM(C27:C27) -> 75.5 | H28: =SUM(H27:H27) -> 1132.5
A29: TYPE 5
A30: 5 #5-01 - Central RR chase wall (Women's|Men's), V line x=637-642pt, y 1357-1409 | B30: 5-01 | C30: 5.69 | D30: 23 | E30: 2 | F30: 6" | G30: 16 | H30: 108.1 | I30: Central RR chase wall (Women's|Men's), V line x=637-642pt, y 1357-1409 | Board by face: A[Women's RR: CB58 0.00-1.17+WR58 1.17-9.00+GWB58 9.00-9.50] | B[Men's RR: CB58 0.00-1.17+WR58 1.17-9.00+GWB58 9.00-9.50] | J30: 1/A-101,1/A-200 | K30: [DERIVED]
B31: SUBTOTAL TYPE 5 | C31: =SUM(C30:C30) -> 5.69 | H31: =SUM(H30:H30) -> 108.1
A32: TYPE E1
A33: E1 #E1-01 - Cafe sales S wall on existing CMU, x 1267-1951 | B33: E1-01 | C33: 19 | D33: 23 | E33: 1 | F33: 6" | G33: 16 | H33: 228 | I33: Cafe sales S wall on existing CMU, x 1267-1951 | Board by face: A[Cafe sales GWB clg 11'-6"/11'-0" (zone RFI-B11): CB12 0.00-12.00] | J33: 1/A-221 | K33: [DERIVED]
A34: E1 #E1-02 - Cafe sales W-end stub / pier (1'-0" thick) x~1216-1267 | B34: E1-02 | C34: 2.667 | D34: 23 | E34: 1 | F34: 6" | G34: 16 | H34: 32 | I34: Cafe sales W-end stub / pier (1'-0" thick) x~1216-1267 | Board by face: A[Cafe sales: CB12 0.00-12.00] | J34: 1/A-221 | K34: [PENDING]
B35: SUBTOTAL TYPE E1 | C35: =SUM(C33:C34) -> 21.667 | H35: =SUM(H33:H34) -> 260
A36: TYPE E2
A37: E2 #E2-01 - Workroom 104 S wall on existing CMU (H line y~792-812), x 191-1216 | B37: E2-01 | C37: 28.49 | D37: 23 | E37: 1 | F37: 6" | G37: 16 | H37: 299.1 | I37: Workroom 104 S wall on existing CMU (H line y~792-812), x 191-1216 | Board by face: A[Workroom 104: FRT58 0.00-10.50+FRP 0.50-10.00] | J37: 1/A-221 | K37: [DERIVED]
B38: SUBTOTAL TYPE E2 | C38: =SUM(C37:C37) -> 28.49 | H38: =SUM(H37:H37) -> 299.1
A39: TYPE F
A40: F #F-01 - Cafe SE column box 3'-3" x 3'-3" | B40: F-01 | C40: 13 | D40: 23 | E40: 1 | F40: 3-5/8" | G40: 16 | H40: 156 | I40: Cafe SE column box 3'-3" x 3'-3" | Board by face: A[Cafe sales: FRT58 0.00-12.00] | J40: 1/A-221 | K40: [PENDING]
B41: SUBTOTAL TYPE F | C41: =SUM(C40:C40) -> 13 | H41: =SUM(H40:H40) -> 156
A42: TYPE H1
A43: H1 #H1-01 - Workroom 104 N wall (H line), x 191-1216 (A-221 pt) | B43: H1-01 | C43: 28.49 | D43: 23 | E43: 2 | F43: 6" | G43: 16 | H43: 954.4 | I43: Workroom 104 N wall (H line), x 191-1216 (A-221 pt) | Board by face: A[Sales 101 open to deck: GWB58 0.00-23.00] | B[Workroom 104 ACT-1 10'-0": FRT58 0.00-10.50+FRP 0.50-10.00] | J43: 1/A-221 | K43: [DERIVED]
...

Sheet Material Summary
A1: MATERIAL SUMMARY - NET / WASTE / PURCHASE
A2: Waste lives HERE, in its own column, applied ONCE: Pieces = ROUNDUP(Net x (1 + waste) / stock). Every stock length, coverage and yield is an Inputs cell.
A3: Material | B3: Unit | C3: Net | D3: Waste % | E3: Waste | F3: Purchase | G3: Selling unit | H3: Pieces to buy | I3: Where it comes from | J3: Yield check (live formula)
A4: 3-5/8" metal stud 20 ga (gauge not printed, RFI-C01) - partitions, counters, column wraps, soffits | B4: LF | C4: 7683.97 | D4: =Inputs!$B$5 -> 0.15 | E4: =C4*D4 -> 1152.5955 | F4: =C4+E4 -> 8836.5655 | G4: stick 24 ft | H4: =ROUNDUP(F4/Inputs!$B$10,0) -> 369 | I4: [DERIVED] Partition Takeoff (studs + jamb studs x height), 1/A-101, 1/A-221; column wraps 1/A-101 C25 (9 tags counted); soffit 2/A-221; stud size 2/A-410, 3/A-410
A5: 6" metal stud 20 ga (gauge not printed, RFI-C01) - type 5, cafe/workroom walls, G&G soffit | B5: LF | C5: 2227.42 | D5: =Inputs!$B$5 -> 0.15 | E5: =C5*D5 -> 334.113 | F5: =C5+E5 -> 2561.533 | G5: stick 24 ft | H5: =ROUNDUP(F5/Inputs!$B$10,0) -> 107 | I5: [DERIVED] Partition Takeoff, 5/A-410, 1/A-221, section G/A-221, 3/A-221
A6: 3-5/8" metal stud 18 ga - vestibule boxed columns (2 per column x 4) | B6: LF | C6: 84 | D6: =Inputs!$B$5 -> 0.15 | E6: =C6*D6 -> 12.6 | F6: =C6+E6 -> 96.6 | G6: stick 24 ft | H6: =ROUNDUP(F6/Inputs!$B$10,0) -> 5 | I6: [DERIVED] 1/A-210 plan (4 boxed columns), 8/A-210 (18 ga printed); height 10'-6" B.O. ceiling 1/A-121
A7: 8" metal stud 18 ga - vestibule nested box beam (2 studs x 12'-8") | B7: LF | C7: 25.34 | D7: =Inputs!$B$5 -> 0.15 | E7: =C7*D7 -> 3.801 | F7: =C7+E7 -> 29.141 | G7: stick 24 ft | H7: =ROUNDUP(F7/Inputs!$B$10,0) -> 2 | I7: [DERIVED] 8/A-210 (2) 8"x18 ga studs; run 12'-8" between corner posts 1/A-210, 4/A-210
A8: 8" metal joist @ 16" o.c. - vestibule roof (gauge not printed) | B8: LF | C8: 84.34 | D8: =Inputs!$B$5 -> 0.15 | E8: =C8*D8 -> 12.651 | F8: =C8+E8 -> 96.991 | G8: stick 24 ft | H8: =ROUNDUP(F8/Inputs!$B$10,0) -> 5 | I8: [PENDING] 1/A-210, 4/A-210; 11 joists x 7'-8" (RFI-B04)
A9: 8" metal stud as ledger at existing storefront - vestibule (gauge not printed) | B9: LF | C9: 12.67 | D9: =Inputs!$B$5 -> 0.15 | E9: =C9*D9 -> 1.9005 | F9: =C9+E9 -> 14.5705 | G9: stick 24 ft | H9: =ROUNDUP(F9/Inputs!$B$10,0) -> 1 | I9: [PENDING] 4/A-210 "8" LEDGER"; length = beam run 12'-8" (RFI-B04)
A10: 3-5/8" bottom track 20 ga (floor) | B10: LF | C10: 441.24 | D10: =Inputs!$B$5 -> 0.15 | E10: =C10*D10 -> 66.186 | F10: =C10+E10 -> 507.426 | G10: run 10 ft | H10: =ROUNDUP(F10/Inputs!$B$11,0) -> 51 | I10: [DERIVED] Partition Takeoff bottom track (not deducted at doors), 1/A-101, 1/A-221, 2/A-410
A11: 3-5/8" top track 20 ga, slotted deflection (full-height walls to deck) | B11: LF | C11: 292.35 | D11: =Inputs!$B$5 -> 0.15 | E11: =C11*D11 -> 43.8525 | F11: =C11+E11 -> 336.2025 | G11: run 10 ft | H11: =ROUNDUP(F11/Inputs!$B$11,0) -> 34 | I11: [DERIVED] Partition Takeoff top track, 2/A-410, 5/A-410, 4/A-410
A12: 3-5/8" top track 20 ga, fixed (partial-height walls and counters) | B12: LF | C12: 148.89 | D12: =Inputs!$B$5 -> 0.15 | E12: =C12*D12 -> 22.3335 | F12: =C12+E12 -> 171.2235 | G12: run 10 ft | H12: =ROUNDUP(F12/Inputs!$B$11,0) -> 18 | I12: [DERIVED] Partition Takeoff top track, 3/A-410, 4/A-410, 1/A-221 sections B, C, D
A13: 3-5/8" track 20 ga - column wraps and soffits (top + bottom) | B13: LF | C13: 200.15 | D13: =Inputs!$B$5 -> 0.15 | E13: =C13*D13 -> 30.0225 | F13: =C13+E13 -> 230.1725 | G13: run 10 ft | H13: =ROUNDUP(F13/Inputs!$B$11,0) -> 24 | I13: [DERIVED] 1/A-101 C25 (9 wraps x 8.0 LF x 2), 2/A-221 soffit (2 x 28.07 LF)
A14: 3-5/8" track 20 ga at door heads (2 pieces, R.O. + 1'-4") | B14: LF | C14: 0 | D14: =Inputs!$B$5 -> 0.15 | E14: =C14*D14 -> 0 | F14: =C14+E14 -> 0 | G14: run 10 ft | H14: =ROUNDUP(F14/Inputs!$B$11,0) -> 0 | I14: [PENDING] No header schedule or head detail printed (1/A-500 shows jamb only): carried 0 LF; delta in RFI-B21
A15: 3-5/8" fire-stop track at ceiling line (TYP) | B15: LF | C15: 159.53 | D15: =Inputs!$B$5 -> 0.15 | E15: =C15*D15 -> 23.9295 | F15: =C15+E15 -> 183.4595 | G15: run 10 ft | H15: =ROUNDUP(F15/Inputs!$B$11,0) -> 19 | I15: [PENDING] 4/A-410, 8/A-410 fire stop at ceiling line TYP; all 3-5/8" walls to deck with a ceiling on at least one face: 2-01b, 2-02 to 2-11 (incl. 2-08, 2-10b), H2a-01, H2b-01, F-01, H3 not here (6") (RFI-B19)
A16: 6" bottom track 20 ga (floor) | B16: LF | C16: 106.16 | D16: =Inputs!$B$5 -> 0.15 | E16: =C16*D16 -> 15.924 | F16: =C16+E16 -> 122.084 | G16: run 10 ft | H16: =ROUNDUP(F16/Inputs!$B$11,0) -> 13 | I16: [DERIVED] Partition Takeoff, 5/A-410, section G/A-221, 1/A-221
A17: 6" top track 20 ga, slotted deflection (full-height walls to deck) | B17: LF | C17: 106.16 | D17: =Inputs!$B$5 -> 0.15 | E17: =C17*D17 -> 15.924 | F17: =C17+E17 -> 122.084 | G17: run 10 ft | H17: =ROUNDUP(F17/Inputs!$B$11,0) -> 13 | I17: [DERIVED] Partition Takeoff, 5/A-410, section E/A-221, section H/A-221
A18: 6" track 20 ga - G&G soffit (top + bottom) | B18: LF | C18: 14.75 | D18: =Inputs!$B$5 -> 0.15 | E18: =C18*D18 -> 2.2125 | F18: =C18+E18 -> 16.9625 | G18: run 10 ft | H18: =ROUNDUP(F18/Inputs!$B$11,0) -> 2 | I18: [PENDING] 3/A-221 (RFI-B14)
A19: 6" fire-stop track at ceiling line (TYP) | B19: LF | C19: 106.15 | D19: =Inputs!$B$5 -> 0.15 | E19: =C19*D19 -> 15.9225 | F19: =C19+E19 -> 122.0725 | G19: run 10 ft | H19: =ROUNDUP(F19/Inputs!$B$11,0) -> 13 | I19: [PENDING] 4/A-410, 8/A-410 fire stop TYP; 6" walls to deck with a ceiling on a face: 5-01, H1-01, H1-02, E1-01, E1-02, E2-01, H3-01, H3-02 (RFI-B19)
A20: 3-5/8" track 16 ga - vestibule boxed columns | B20: LF | C20: 3.33 | D20: =Inputs!$B$5 -> 0.15 | E20: =C20*D20 -> 0.4995 | F20: =C20+E20 -> 3.8295 | G20: run 10 ft | H20: =ROUNDUP(F20/Inputs!$B$11,0) -> 1 | I20: [DERIVED] 8/A-210 (4 columns, 5" each)
A21: 6" runner track 16 ga - vestibule nested box beam | B21: LF | C21: 25.34 | D21: =Inputs!$B$5 -> 0.15 | E21: =C21*D21 -> 3.801 | F21: =C21+E21 -> 29.141 | G21: stick 24 ft | H21: =ROUNDUP(F21/Inputs!$B$10,0) -> 2 | I21: [DERIVED] 8/A-210 (6"x16 ga top and bottom track), run 12'-8" 1/A-210
A22: 20 ga x 2" min deep relief channel at top of full-height walls | B22: LF | C22: 398.51 | D22: =Inputs!$B$5 -> 0.15 | E22: =C22*D22 -> 59.7765 | F22: =C22+E22 -> 458.2865 | G22: channel 10 ft | H22: =ROUNDUP(F22/10,0) -> 46 | I22: [PENDING] 5/A-410 typ. connection detail "CONTINUOUS 20 GA X 2" MIN DEEP RELIEF CHANNEL"; LF = top track of walls to deck (RFI-D02)
A23: 1-1/2" C.R. channel 16 ga - bracing @ 4'-0" o.c. (note 4/A-410) | B23: LF | C23: 2110.44 | D23: =Inputs!$B$5 -> 0.15 | E23: =C23*D23 -> 316.566 | F23: =C23+E23 -> 2427.006 | G23: C.R. channel 16 ft | H23: =ROUNDUP(F23/Inputs!$B$16,0) -> 152 | I23: [DERIVED] Partition Takeoff bracing rows x LF, note 4/A-410, 5/A-410 (first row 4'-0" above floor)
A24: 2x2 16 ga clip angle at C.R. channel / stud crossings | B24: EA | C24: 1771 | D24: =Inputs!$B$5 -> 0.15 | E24: =C24*D24 -> 265.65 | F24: =C24+E24 -> 2036.65 | G24: ea | H24: =ROUNDUP(F24,0) -> 2037 | I24: [DERIVED] 5/A-410: one 2"x2"x16 ga clip per stud per bracing row
A25: Moment clip 3-5/8" x 20 ga at partial-height wall base (1 per stud) | B25: EA | C25: 90 | D25: =Inputs!$B$5 -> 0.15 | E25: =C25*D25 -> 13.5 | F25: =C25+E25 -> 103.5 | G25: ea | H25: =ROUNDUP(F25,0) -> 104 | I25: [DERIVED] A/A-410, 3/A-410, 4/A-410, 1/A-101 (types 3 and 4)
A26: Clip angles 3x3x16 ga at vestibule nested beam | B26: EA | C26: 4 | D26: 0 | E26: =C26*D26 -> 0 | F26: =C26+E26 -> 4 | G26: ea | H26: =ROUNDUP(F26,0) -> 4 | I26: [PENDING] 7/A-210 (2 per end), RFI-B04
A27: 2x4 FRT wood blocking - receiving tables (3 levels x 2 tables) | B27: LF | C27: 103.5 | D27: =Inputs!$B$6 -> 0.06 | E27: =C27*D27 -> 6.21 | F27: =C27+E27 -> 109.71 | G27: 2x lumber 16 ft | H27: =ROUNDUP(F27/Inputs!$B$26,0) -> 7 | I27: [PENDING] 8/A-413, 8A/A-413, key note 2/A-111 (RFI-B08)
A28: FRT wood blocking - office walls, 3 rows at 1'-4" (2x4 assumed, size not printed) | B28: LF | C28: 64.26 | D28: =Inputs!$B$6 -> 0.06 | E28: =C28*D28 -> 3.8556 | F28: =C28+E28 -> 68.1156 | G28: 2x lumber 16 ft | H28: =ROUNDUP(F28/Inputs!$B$26,0) -> 5 | I28: [DERIVED] 3,4/A-412 "F.R.T. BLOCKING IN WALL BEHIND GWB"; rows x (8'-6" + 12'-11") 1/A-412 (RFI-B08)
A29: FRT wood blocking - break room kitchen unit, 1 row (2x4 assumed) | B29: LF | C29: 5.33 | D29: =Inputs!$B$6 -> 0.06 | E29: =C29*D29 -> 0.3198 | F29: =C29+E29 -> 5.6498 | G29: 2x lumber 16 ft | H29: =ROUNDUP(F29/Inputs!$B$26,0) -> 1 | I29: [PENDING] 6/A-412 "PROVIDE BLOCKING IN PARTITION FOR CABINETS AS REQUIRED"; unit 2'-9" + 2'-7" (RFI-B08)
A30: 5/8" FRT plywood | B30: SF | C30: 1350.35 | D30: =Inputs!$B$6 -> 0.06 | E30: =C30*D30 -> 81.021 | F30: =C30+E30 -> 1431.371 | G30: 4x12 ft sheet | H30: =ROUNDUP(F30/32,0) -> 45 | I30: [DERIVED] Partition Takeoff col FRT 5/8 (cafe/workroom/G&G walls, 1/A-221, sections E, F, H, I) + soffit plywood below T.O. WD-1 only (2,3/A-221)
A31: 3/4" FRT plywood | B31: SF | C31: 255.85 | D31: =Inputs!$B$6 -> 0.06 | E31: =C31*D31 -> 15.351 | F31: =C31+E31 -> 271.201 | G31: 4x12 ft sheet | H31: =ROUNDUP(F31/32,0) -> 9 | I31: [DERIVED] counters A-D 1/A-221; janitor backing 11/A-200 (23 SF); menu-board plywood 4/A-226A (35.7 SF, thickness not printed); RR grab-bar backing 2,3,4/A-200, 21/A-201 (PENDING); vestibule roof deck 4/A-210 (PENDING)
A32: 3/4" FRT plywood lavatory backing panels (size not read) | B32: EA | C32: 2 | D32: 0 | E32: =C32*D32 -> 0 | F32: =C32+E32 -> 2 | G32: ea | H32: =ROUNDUP(F32,0) -> 2 | I32: [PENDING] 26/A-201, 4/A-200 (RFI-B08)
A33: 5/8" gypsum board (GWB) | B33: SF | C33: 14242.81 | D33: =Inputs!$B$6 -> 0.06 | E33: =C33*D33 -> 854.5686 | F33: =C33+E33 -> 15097.379 | G33: 4x12 ft sheet | H33: =ROUNDUP(F33/Inputs!$B$9,0) -> 315 | I33: [DERIVED] Partition Takeoff col GWB 5/8; GWB ceilings 1/A-121 (C-03..C-06); soffit: cafe exposed face above T.O. WD-1 + inner face + undersides, G&G exposed face above T.O. WD-1 + underside (2,3/A-221); column wraps 1/A-101 C25; vestibule columns 6/A-210
A34: 5/8" W.R. gypsum board (moisture resistant) | B34: SF | C34: 874.2 | D34: =Inputs!$B$6 -> 0.06 | E34: =C34*D34 -> 52.452 | F34: =C34+E34 -> 926.652 | G34: 4x12 ft sheet | H34: =ROUNDUP(F34/Inputs!$B$9,0) -> 20 | I34: [DERIVED] Partition Takeoff col W.R. 5/8 (restroom, janitor 2/A-410 note 2, note 7); RR GWB ceilings 1/A-121 'walls and ceiling'
A35: 5/8" cement board | B35: SF | C35: 47.1 | D35: =Inputs!$B$6 -> 0.06 | E35: =C35*D35 -> 2.826 | F35: =C35+E35 -> 49.926 | G35: 4x12 ft sheet | H35: =ROUNDUP(F35/Inputs!$B$9,0) -> 2 | I35: [DERIVED] restroom base 1'-2" 22/A-201, 2,3,4/A-200
A36: 1/2" cement board | B36: SF | C36: 437.5 | D36: =Inputs!$B$6 -> 0.06 | E36: =C36*D36 -> 26.25 | F36: =C36+E36 -> 463.75 | G36: 4x12 ft sheet | H36: =ROUNDUP(F36/Inputs!$B$9,0) -> 10 | I36: [DERIVED] E1 and counters 1/A-221, sections E, B, C, D/A-221
A37: FRP-1 panels | B37: SF | C37: 959 | D37: =Inputs!$B$6 -> 0.06 | E37: =C37*D37 -> 57.54 | F37: =C37+E37 -> 1016.54 | G37: FRP panel 40 SF (Inputs) | H37: =ROUNDUP(F37/Inputs!$B$30,0) -> 26 | I37: [DERIVED] workroom FRP-1 from 6" above floor to 10'-0" (3,4/A-225 J-mold at 6" base; 1-4/A-226B pattern full height), janitor 9-12/A-200 (8'-0" hold), counters 1/A-221
A38: Thermafiber SAFB sound/fire insulation, full cavity | B38: SF | C38: 7155.1 | D38: =Inputs!$B$6 -> 0.06 | E38: =C38*D38 -> 429.306 | F38: =C38+E38 -> 7584.406 | G38: SF | H38: =ROUNDUP(F38,0) -> 7585 | I38: [DERIVED] Partition Takeoff col insulation, 2/A-410, 5/A-410, section G/A-221 (H1 only), 1/A-101 table (RFI-B05)
A39: 3-1/2" sound attenuation blanket above GWB / ACT ceilings (toilets, offices, break room) | B39: SF | C39: 479.72 | D39: =Inputs!$B$6 -> 0.06 | E39: =C39*D39 -> 28.7832 | F39: =C39+E39 -> 508.5032 | G39: SF | H39: =ROUNDUP(F39,0) -> 509 | I39: [PENDING] 2/A-410 "FINISHED CEILING (SOUND ATTENUATION BLANKETS AT TOILETS, OFFICES, AND BREAK ROOM ONLY)"; 1/A-101 table leaves the CEILING column blank (conflict, RFI-B17); RR 130.0 + break 240.1 + manager 109.7 SF
A40: Corner bead - column wraps, vestibule columns, type 3 posts, type 4 X wall | B40: LF | C40: 674 | D40: =Inputs!$B$6 -> 0.06 | E40: =C40*D40 -> 40.44 | F40: =C40+E40 -> 714.44 | G40: trim stick 10 ft | H40: =ROUNDUP(F40/Inputs!$B$18,0) -> 72 | I40: [DERIVED] 1/A-101 C25, 6/A-210, 4/A-410 (type 4 count PENDING, RFI-B06)
...

Sheet Pending Items
A1: RFI | B1: Question / condition | C1: Delta of each alternative
A2: RFI-01 | B2: Exterior walls (types 1, 1A, 1B, 1C) are EXISTING (A-101 legend 'EXISTING EXTERIOR WALL'; DM-101 key notes 3 and 6: patch and repair, facade to remain). 1/A-410 prints '5/8" GYP BD BY FUTURE TENANT' on the interior face and A-002 gives perimeter studs, insulation and vapor barrier to the Landlord. Base: excluded from the take-off (no row in the Partition Takeoff or Material Summary). Does the tenant GC install the interior GWB face? | C2: If yes (Alt A): +7,824 SF 5/8" GWB over 340.5 LF x 23'-0"/23'-8" (N 15'-7" + 158.8 ft, W 64.8 ft less 6.3 ft door, angled 23.7 ft, S 20'-11" + 6.2 + 50.6 ft) = +3,599 screws. If the tenant also frames (Alt B): +255 studs at 23'-0", +681 LF track, R-21 and vapor barrier 7,824 SF each. East facade piers (1B/1C) are not dimensioned: + piers x 21'-9" x 1 face. Stud o.c. is not printed for 1/1A/1B/1C (16" assumed; 24" cuts studs by about one third).
A3: RFI-04 | B3: Types 3 and 4 partial-height walls (T.O. WALL 8'-0" / 7'-6" A.F.F.): studs run 'to bottom of nested stud bracing' with no top-cap detail. | C3: Base: track cap + GWB both faces to T.O. WALL. Alt: GWB wraps the top = + L x wall thickness (type 3: 38.7 LF x 0.40 ft = +15.5 SF; type 4: 75.5 LF x 0.40 ft = +30.2 SF).
A4: RFI-07 | B4: Wet-area backing under restroom tile (tile 6'-7" on 2,3,4/A-200). 22/A-201 prints 1'-2" cement board base; 2/A-410 note 2 and note 7 print W.R. gypsum board above to the B.O. gyp ceiling; A-101 general note 8 allows moisture-resistant drywall or cement board. Base: cement board to 1'-2", W.R. above. | C4: If cement board is required behind all tile to 6'-7": +218.7 SF 5/8" cement board, -218.7 SF W.R. board (price delta only).
A5: RFI-08 | B5: GWB ceiling and soffit framing system (restrooms 9'-0", vestibule 10'-6", cafe 9'-0"/11'-6"/11'-0", seating cloud 12'-0", G&G 7'-1"): A-121 prints 12 ga hanger wire @ 48" o.c. but no furring/carrying channel layout. Not quantified (no suspension rows). | C5: Alt: 7/8" hat furring @ 16" o.c. = 0.75 LF per SF of GWB ceiling = 882 LF on 1,176.5 SF; hanger wire 1 per 16 SF = 74 hangers; carrying channel @ 48" o.c. = 0.25 LF per SF = 294 LF.
A6: RFI-10 | B6: Demising wall (A-101 key note C5: patch/repair, add GWB/furring as required) has no extent printed; storage 112 north face. | C6: Base: patch only (0). Alt: new GWB face = L x 23'-0" per face with L about 37 ft by vector (start of demising not printed) = +851 SF.
A7: RFI-11 | B7: No rated new partition is tagged (A-410 note 1 and the UL detail sheets apply only to rated assemblies; the construction legend has no rated line). Base: no rating. | C7: If 1-hr rating is required on the types 2/5 walls: +1 layer on affected faces = +5,926 SF GWB (about half of the wall board SF) and fire safing at deck.
A8: RFI-15 | B8: Corner guards: spec A-001A Div 05 calls 2"x2"x72" metal corner guards at outside corners; A-101 note C22 calls stainless 48" A.F.F. at stock-room outside corners; A-131 req. 6 calls 2x2 full-height stainless in the workroom. | C8: Workroom 60.0 LF carried. Stock room C22: outside corners not itemised: 4 ea at door 11 jambs and wall ends x 4'-0" = +16 LF. Spec 72" guards at all other outside GWB corners: + corner count x 6'-0".
A9: RFI-B03 | B9: Type 5 (6" studs) wall length 5-01 is not printed on A-101 (7" thickness read from the plan confirms the type; vector length 5.69 ft). | C9: Each +/-1'-0" = +/-1 stud (23 LF), +/-23 SF board per face set, +/-1.0 LF track pair.
A10: RFI-B04 | B10: Vestibule framing (A-210): columns (4 boxed 5"x5", counted on 1/A-210), nested box beam on the W line 12'-8" between corner posts (1/A-210, 4/A-210), 8" joists @ 16" o.c. span 7'-8" with 8" ledger and 3/4" plywood deck. Joist gauge, ledger material and whether the storefront vendor (Div 08) furnishes the assembly are not printed. Screws: (8) #10-16 TEKS @ 16" o.c. read as 8 per 16" station. | C10: If excluded as storefront scope: -84 LF stud (columns), -25.3 LF stud, -25.3 LF track, -84.3 LF joist, -12.7 LF ledger, -97 SF GWB ceiling, -97 SF plywood, -70 SF column GWB, -168 LF bead, -376 TEKS. If (8) TEKS means 8 per column / per beam only: -344 TEKS.
A11: RFI-B05 | B11: Insulation. (a) Thermafiber SAFB 'full cavity' (A-410 types 2, 5; H1) carried to full stud height. (b) 1/A-101 note: 3-1/2" sound blankets in the WALLS of rooms 103-112 (all ten rooms, ceiling column blank), but section G/A-221 prints 'WALL TYPE H2 NO SOUND CONTROL INSULATION' and E1/E2/F/H3/I show none: H2 and the cafe-side tags follow the printed H2 note. | C11: (a) Stopping the blanket at ceiling line + 6" (9'-6") on walls with ACT/GWB ceilings both sides: -802 SF. (b) Adding blankets to H2a (9.5 LF x 23'-0") and H3 (9.65 LF x 23'-0"): +440 SF.
A12: RFI-B06 | B12: Type 4 X wall (A-101): 2 arcs 25'-1" printed (R32'-9"), caps 9'-0" printed, return length per end not printed (1'-10" taken from the printed 1'-10" dims, 4 returns). | C12: Each +/-1'-0" of return length = +/-4 LF wall = +/-60 SF board (both faces at 7'-6"), +/-3 studs. Corner count for bead (12) from plan geometry.
... A37: RFI-D04 | B37: Menu-board FRT plywood blocking (dashed on 4/A-226A): thickness and extent beyond the five printed frames (4 x 24"x31" + 1 x 70"x31") are not printed; carried 35.7 SF 3/4". | C37: If the dashed zone is the full tile field (23'-3" x 6'-3"): +109 SF.

Sheet Review Items
A1: 28 questions in total, asked ONE at a time in this order: floor plan (partition types A-Z), then the details the floor plan calls, in order
A2: # | B2: Phase | C2: Type / order | D2: Item | E2: Sheet + detail | F2: Image
A3: 1/28 | B3: Floor plan | C3: 2 | D3: Verify tag count and location of type 2 (15 wall rows) | E3: 1/A-101 | F3: Zoom crop of 1/A-101 (>= 200 dpi) around the tags / detail
A4: 2/28 | B4: Floor plan | C4: 3 | D4: Verify tag count and location of type 3 (2 wall rows) | E4: 1/A-101 | F4: Zoom crop of 1/A-101 (>= 200 dpi) around the tags / detail
A5: 3/28 | B5: Floor plan | C5: 4 | D5: Verify tag count and location of type 4 (1 wall rows) | E5: 1/A-101 | F5: Zoom crop of 1/A-101 (>= 200 dpi) around the tags / detail
A6: 4/28 | B6: Floor plan | C6: 5 | D6: Verify tag count and location of type 5 (1 wall rows) | E6: 1/A-101 | F6: Zoom crop of 1/A-101 (>= 200 dpi) around the tags / detail
A7: 5/28 | B7: Floor plan | C7: E1 | D7: Verify tag count and location of type E1 (2 wall rows); PENDING rows: E1-02 | E7: 1/A-221 | F7: Zoom crop of 1/A-221 (>= 200 dpi) around the tags / detail
A8: 6/28 | B8: Floor plan | C8: E2 | D8: Verify tag count and location of type E2 (1 wall rows) | E8: 1/A-221 | F8: Zoom crop of 1/A-221 (>= 200 dpi) around the tags / detail
A9: 7/28 | B9: Floor plan | C9: F | D9: Verify tag count and location of type F (1 wall rows); PENDING rows: F-01 | E9: 1/A-221 | F9: Zoom crop of 1/A-221 (>= 200 dpi) around the tags / detail
A10: 8/28 | B10: Floor plan | C10: H1 | D10: Verify tag count and location of type H1 (2 wall rows) | E10: 1/A-221 | F10: Zoom crop of 1/A-221 (>= 200 dpi) around the tags / detail
A11: 9/28 | B11: Floor plan | C11: H2a | D11: Verify tag count and location of type H2a (1 wall rows) | E11: 1/A-221 | F11: Zoom crop of 1/A-221 (>= 200 dpi) around the tags / detail
A12: 10/28 | B12: Floor plan | C12: H2b | D12: Verify tag count and location of type H2b (1 wall rows) | E12: 1/A-221 | F12: Zoom crop of 1/A-221 (>= 200 dpi) around the tags / detail
A13: 11/28 | B13: Floor plan | C13: H3a | D13: Verify tag count and location of type H3a (1 wall rows) | E13: 1/A-221 | F13: Zoom crop of 1/A-221 (>= 200 dpi) around the tags / detail
... A19: 17/28 | B19: Floor plan | C19: CTR D | D19: Verify tag count and location of type CTR D (1 wall rows); PENDING rows: CA-D | E19: 1/A-221 | F19: Zoom crop of 1/A-221 (>= 200 dpi) around the tags / detail
A20: 18/28 | B20: Detail | C20: 1 | D20: Exterior wall details 1, 1A, 1B, 1C (scope Alt A) | E20: 1/A-410 | F20: Zoom crop of 1/A-410 (>= 200 dpi) around the tags / detail
A21: 19/28 | B21: Detail | C21: 2 | D21: Type 2 layers, W.R. wet side, deflection track | E21: 2/A-410 | F21: Zoom crop of 2/A-410 (>= 200 dpi) around the tags / detail
A22: 20/28 | B22: Detail | C22: 3 | D22: Type 3 partial height, stud schedule (gauge) | E22: 3/A-410 | F22: Zoom crop of 3/A-410 (>= 200 dpi) around the tags / detail
A23: 21/28 | B23: Detail | C23: 4 | D23: Type 4 partial height, slip track | E23: 4/A-410 | F23: Zoom crop of 4/A-410 (>= 200 dpi) around the tags / detail
A24: 22/28 | B24: Detail | C24: 5 | D24: Type 5 and lateral bracing / clip angles | E24: 5/A-410 | F24: Zoom crop of 5/A-410 (>= 200 dpi) around the tags / detail
A25: 23/28 | B25: Detail | C25: 6 | D25: Fastener notes 8.A-8.F, fire stop TYP | E25: 8/A-410 | F25: Zoom crop of 8/A-410 (>= 200 dpi) around the tags / detail
A26: 24/28 | B26: Detail | C26: 7 | D26: Moment clip base connection | E26: A/A-410 | F26: Zoom crop of A/A-410 (>= 200 dpi) around the tags / detail
A27: 25/28 | B27: Detail | C27: 8 | D27: Vestibule framing plan | E27: 1/A-210 | F27: Zoom crop of 1/A-210 (>= 200 dpi) around the tags / detail
A28: 26/28 | B28: Detail | C28: 9 | D28: Vestibule column / beam details | E28: 8/A-210 | F28: Zoom crop of 8/A-210 (>= 200 dpi) around the tags / detail
A29: 27/28 | B29: Detail | C29: 10 | D29: Section G wall layers per face | E29: G/A-221 | F29: Zoom crop of G/A-221 (>= 200 dpi) around the tags / detail
A30: 28/28 | B30: Detail | C30: 11 | D30: Janitor 3/4" FRT plywood area | E30: 11/A-200 | F30: Zoom crop of 11/A-200 (>= 200 dpi) around the tags / detail

Sheet Scope Checklist
A1: Scope ID | B1: Scope | C1: Status | D1: Note (quantity, NOT APPLICABLE + sheet, or RFI)
A2: ALC-01 | B2: Interior partition framing (types 2, 3, 4, 5, cafe/workroom tags) | C2: QUANTIFIED | D2: Partition Takeoff, 2-5/A-410, 1/A-101, 1/A-221
A3: ALC-02 | B3: Existing exterior walls (types 1, 1A, 1B, 1C): excluded, no rows; tenant GWB face by RFI | C3: RFI | D3: Existing walls (A-101 legend, DM-101 key notes 3, 6); not in Partition Takeoff or Material Summary; RFI-01, 1-1C/A-410
A4: ALC-03 | B4: Header track at door openings | C4: RFI | D4: No header schedule or head detail printed (1/A-500); 0 LF carried, RFI-B21
A5: ALC-04 | B5: Nested stud bracing and clip angles (4 TEK screws per clip) | C5: QUANTIFIED | D5: note 4/A-410, 5/A-410 (RFI-C02)
A6: ALC-05 | B6: Blocking and FRT plywood backing | C6: RFI | D6: Receiving table, office walls, kitchen, menu board carried; steel shelving PENDING (RFI-B08), 7/A-413, 3,4,6/A-412
A7: ALC-06 | B7: Gypsum board 5/8" regular, W.R., cement board, FRT plywood | C7: QUANTIFIED | D7: Material Summary, 2/A-410, 22/A-201, 1/A-221
A8: ALC-07 | B8: Type X gypsum board | C8: RFI | D8: RFI-C03, A-001A Div 09
A9: ALC-08 | B9: GWB ceilings and soffits (layers per face from 2,3/A-221) | C9: QUANTIFIED | D9: 1/A-121, 2/A-221, 3/A-221 (zones PENDING, RFI-B11, RFI-B14)
A10: ALC-09 | B10: Acoustical ceilings ACT-1 / ACT-3 | C10: NOT APPLICABLE | D10: Ceiling sub, 1/A-121
A11: ALC-10 | B11: Ceiling sound blankets 3-1/2" (toilets, offices, break room) | C11: QUANTIFIED | D11: 2/A-410 vs 1/A-101 table conflict, RFI-B17
A12: ALC-11 | B12: Wall insulation Thermafiber SAFB | C12: QUANTIFIED | D12: 2/A-410, 5/A-410, section G/A-221 (RFI-B05)
... A22: ALC-21 | B22: Relief channel at top of full-height walls | C22: RFI | D22: 5/A-410 typ. connection detail, RFI-D02
